Workbook

Sheet Dashboard P1
D1: Savannah Tank Sales Dashboard | S1: - | T1: =TODAY() -> 46078
B3: 2026 YTD Order Intake vs. Plan | T3: Factory Backlog by Week (Hours)
C29: YTD Actual | E29: ='2026'!U18 -> 2450001 | I29: YTD Target | K29: 3250000 | N29: Difference | P29: =E29-K29 -> -799999 | Q29: =E29/K29-1 -> -0.24615354
T32: Key Stats
T35: Order Intake | Y35: Month | AA35: Quarter | AC35: YTD
AP36: Month
U37: Orders % Target | Y37: =LOOKUP('2026'!AP5,'2026'!T5:T16,'2026'!U5:U16)/'2026'!V5 -> 0.11928629 | AA37: =LOOKUP('2026'!AQ5,'2026'!T21:T24,'2026'!U21:U24)/'2026'!V21 -> 0.51578968 | AC37: ='2026'!U18/'2026'!V18 -> 0.12250005 | AP37: Red | AQ37: 1000000 | AS37: Value | AT37: =VLOOKUP('2026'!AP5,'2026'!T5:U16,2,FALSE) -> 208751
AP38: Amber | AQ38: 200000 | AS38: Pointer | AT38: 20000
U39: Period % Complete | Y39: ='2026'!AP9 -> 0.9 | AA39: ='2026'!AQ9 -> 0.61538462 | AC39: ='2026'!AR9 -> 0.15267176 | AP39: Green | AQ39: 200000 | AS39: End | AT39: =(AQ40*2)-AT37 -> 2591249
AP40: Invisible | AQ40: 1400000
T43: Backlog | Y43: Month | AA43: Quarter | AC43: YTD
AP44: Quarter
U45: Weeks Above Target | Y45: ='2026'!P17 -> 0 | AA45: ='2026'!P9+'2026'!P13+'2026'!P17 -> 0 | AC45: ='2026'!M58 -> 8 | AP45: Red | AQ45: 3000000 | AS45: Value | AT45: =VLOOKUP('2026'!AQ5,'2026'!T21:U24,2,FALSE) -> 2450001
AP46: Amber | AQ46: 600000 | AS46: Pointer | AT46: 50000
U47: Weeks Below Target | Y47: ='2026'!Q17 -> 0 | AA47: ='2026'!Q8+'2026'!Q12+'2026'!Q17 -> 0 | AC47: ='2026'!N58 -> 0 | AP47: Green | AQ47: 600000 | AS47: End | AT47: =(AQ48*2)-AT45 -> 5949999
AP48: Invisible | AQ48: 4200000
U49: Weeks in Red Zone | Y49: 0 | AA49: 0 | AC49: ='2026'!O58 -> 0

Sheet Dashboard P2
B1: Savannah Tank Sales Dashboard | K1: - | L1: =TODAY() -> 46078
B3: 2026 Quotes | L3: Sales Funnel (30 Days)
L4: Deal Name | M4: Company | N4: Amount | O4: Man Hours | P4: Close Date | Q4: Prob% | R4: Prob $ | S4: Prob Hrs.
L5: 9399 | M5: SNF | N5: 452250 | O5: 1308 | P5: January | Q5: 0.9 | R5: =N5*Q5 -> 407025 | S5: =O5*Q5 -> 1177.2
L6: 9238 | M6: VEi Global | N6: 46500 | O6: 227 | P6: January | Q6: 0.9 | R6: =N6*Q6 -> 41850 | S6: =O6*Q6 -> 204.3
L7: 9192 | M7: IMI Industrial Services Group | N7: 264500 | O7: 958 | P7: January | Q7: 0.2 | R7: =N7*Q7 -> 52900 | S7: =O7*Q7 -> 191.6
L8: 9042 | M8: Perdue Chicken | N8: 297000 | O8: 1350 | P8: February | Q8: 0.5 | R8: =N8*Q8 -> 148500 | S8: =O8*Q8 -> 675
L9: 9039 | M9: Wellons | N9: 69500 | O9: 314 | P9: January | Q9: 0.5 | R9: =N9*Q9 -> 34750 | S9: =O9*Q9 -> 157
L10: 9166 | M10: Syensqo | N10: 910000 | O10: 823 | P10: January | Q10: 0.5 | R10: =N10*Q10 -> 455000 | S10: =O10*Q10 -> 411.5
L11: 9087 | M11: Franklin Engineering Group | N11: 1034000 | O11: 2298 | P11: January | Q11: 0.5 | R11: =N11*Q11 -> 517000 | S11: =O11*Q11 -> 1149
L12: 9338 | M12: Valmet | N12: 1041000 | O12: 1 | P12: January | Q12: 0.2 | R12: =N12*Q12 -> 208200 | S12: =O12*Q12 -> 0.2
L13: 9378 | M13: Fortera | N13: 3620000 | O13: 7400 | P13: January | Q13: 0.5 | R13: =N13*Q13 -> 1810000 | S13: =O13*Q13 -> 3700
L14: 9366 | M14: Andritz | N14: 32250 | O14: 104 | P14: January | Q14: 0.3 | R14: =N14*Q14 -> 9675 | S14: =O14*Q14 -> 31.2
L15: 9417 | M15: Kiewit | N15: 424000 | O15: 1169 | P15: February | Q15: 0.5 | R15: =N15*Q15 -> 212000 | S15: =O15*Q15 -> 584.5
L16: 9344 | M16: EPIC Systems Group | N16: 103750 | O16: 521 | P16: February | Q16: 0.4 | R16: =N16*Q16 -> 41500 | S16: =O16*Q16 -> 208.4
L17: 9228 | M17: National Gypsum | N17: 95000 | O17: 382 | P17: February | Q17: 0.75 | R17: =N17*Q17 -> 71250 | S17: =O17*Q17 -> 286.5
B18: YTD Actual | C18: ='2026'!AC18 -> 49 | E18: YTD Target | F18: 64 | H18: Difference | I18: =C18-F18 -> -15 | J18: =C18/F18-1 -> -0.234375
N19: =SUM(N5:N18) -> 8389750 | O19: =SUM(O5:O18) -> 16855 | R19: =SUM(R5:R18) -> 4009650 | S19: =SUM(S5:S18) -> 8776.4
B20: 2026 Quotes | L20: Value Added Sales $ (Orders) / Quoted Labor Hour
B36: YTD Actual | C36: ='2026'!AG18 -> 11750000 | E36: YTD Target | F36: 22000000 | H36: Difference | I36: =C36-F36 -> -10250000 | J36: =C36/F36-1 -> -0.46590909
L43: Month
L44: Red | M44: 650000 | O44: Value | P44: ='2026'!G58 -> 1094518
L45: Amber | M45: 150000 | O45: Pointer | P45: 20000
L46: Green | M46: 650000 | O46: End | P46: =(M47*2)-P44 -> 1905482
L47: Invisible | M47: 1500000
L51: VA $ / Hour
L52: Red | M52: 150 | O52: Value | P52: ='2026'!H58 -> 205.67654
L53: Green | M53: 10 | O53: Pointer | P53: 3
L54: Amber | M54: 65 | O54: End | P54: =(M56*2)-P52 -> 234.32346
L55: Amber
L56: Invisible | M56: 220

Sheet 2026
P2: Month | Q2: Month | R2: Month
E3: Order Intake | J3: Backlog (Hours) | M3: > Target | N3: < Target | O3: < Red | P3: > Target | Q3: < Target | R3: < Red | T3: Order Intake | AC3: # of Quotes (Non-Budget) | AG3: Non-Budget Quote $ | AO3: Date: | AP3: =TODAY() -> 46078
A4: Year | B4: Week of | C4: Month | D4: Week | E4: $ | F4: Hours | G4: VA $ | H4: VA $ / Hr. | J4: Actual | K4: Target | L4: Red | T4: Month | U4: Act. | V4: Forecast | W4: YTD Act. | X4: YTD Target | Y4: YTD Orig. | AB4: Month | AC4: Act. | AD4: Target | AE4: YTD Act. | AF4: YTD Target | AG4: Act. | AH4: Target | AI4: YTD Act. | AJ4: YTD Target
A5: 2026 | B5: 46028 | C5: Jan | D5: 1 | E5: ='[1]Data Collection'!$C2 -> 494500 | F5: ='[1]Data Collection'!$D2 -> 1380 | G5: ='[1]Data Collection'!$E2 -> 217469 | H5: =IFERROR(G5/F5,) -> 157.58623 | J5: 22873 | K5: 18000 | L5: 12000 | M5: =IF(J5>8000,1,0) -> 1 | N5: =IF(J5<K5,1,0) -> 0 | O5: =IF(J5<L5,1,0) -> 0 | T5: 1 | U5: ='[1]Data Collection'!$J2 -> 2241250 | V5: 1750000 | W5: =U5 -> 2241250 | X5: =V5 -> 1750000 | AB5: Jan | AC5: 27 | AD5: 32 | AE5: =AC5 -> 27 | AF5: =AD5 -> 32 | AG5: 10850000 | AH5: 11000000 | AI5: =AG5 -> 10850000 | AJ5: =AH5 -> 11000000 | AO5: Current Month | AP5: =MONTH(AP3) -> 2 | AQ5: =ROUNDUP(MONTH(AP3)/3,0) -> 1
A6: 2026 | B6: 46035 | D6: 2 | E6: ='[1]Data Collection'!$C3 -> 1744400 | F6: ='[1]Data Collection'!$D3 -> 3153 | G6: ='[1]Data Collection'!$E3 -> 749710 | H6: =IFERROR(G6/F6,) -> 237.77672 | J6: =J5-640+F6 -> 25386 | K6: 18000 | L6: 12000 | M6: =IF(J6>8000,1,0) -> 1 | N6: =IF(J6<K6,1,0) -> 0 | O6: =IF(J6<L6,1,0) -> 0 | T6: 2 | U6: ='[1]Data Collection'!$J3 -> 208751 | V6: 1500000 | W6: =W5+U6 -> 2450001 | X6: =X5+V6 -> 3250000 | AB6: Feb | AC6: 22 | AD6: 32 | AE6: =AE5+AC6 -> 49 | AF6: =AF5+AD6 -> 64 | AG6: 900000 | AH6: 11000000 | AI6: =AI5+AG6 -> 11750000 | AJ6: =AJ5+AH6 -> 22000000 | AP6: Month | AQ6: QTR | AR6: YTD
A7: 2026 | B7: 46042 | D7: 3 | E7: ='[1]Data Collection'!$C4 -> 0 | F7: ='[1]Data Collection'!$D4 -> 0 | G7: ='[1]Data Collection'!$E4 -> 0 | H7: =IFERROR(G7/F7,) -> 0 | J7: =J6-640+F7 -> 24746 | K7: 18000 | L7: 12000 | M7: =IF(J7>8000,1,0) -> 1 | N7: =IF(J7<K7,1,0) -> 0 | O7: =IF(J7<L7,1,0) -> 0 | T7: 3 | U7: ='[1]Data Collection'!$J4 -> 0 | V7: 1500000 | X7: =X6+V7 -> 4750000 | AB7: Mar | AD7: 30 | AE7: =AE6+AC7 -> 49 | AF7: =AF6+AD7 -> 94 | AH7: 11000000 | AI7: =AI6+AG7 -> 11750000 | AJ7: =AJ6+AH7 -> 33000000 | AO7: BUS DAY # | AP7: =NETWORKDAYS(VLOOKUP(AP5,AO13:AP24,2,FALSE),AP3, {"1/3/2024","5/30/2024","7/4/2024","9/5/2024","11/24/2024","11/25/2024","12/23/2024","12/26/2024"}) -> 18 | AQ7: =NETWORKDAYS(VLOOKUP(AQ5,AS13:AT16,2),AP3,{"1/3/2024","5/30/2024","7/4/2024","9/5/2024","11/24/2024","11/25/2024","12/23/2024","12/26/2024"}) -> 40 | AR7: =NETWORKDAYS(AP13,AP3,{"1/3/2024","5/30/2024","7/4/2024","9/5/2024","11/24/2024","11/25/2024","12/23/2024","12/26/2024"}) -> 40
A8: 2026 | B8: 46049 | D8: 4 | E8: ='[1]Data Collection'!$C5 -> 2350 | F8: ='[1]Data Collection'!$D5 -> 12.55 | G8: ='[1]Data Collection'!$E5 -> 2017 | H8: =IFERROR(G8/F8,) -> 160.71713 | J8: =J7-640+F8 -> 24118.55 | K8: 18000 | L8: 12000 | M8: =IF(J8>8000,1,0) -> 1 | N8: =IF(J8<K8,1,0) -> 0 | O8: =IF(J8<L8,1,0) -> 0 | P8: =SUM(M4:M8) -> 4 | Q8: =SUM(N5:N8) -> 0 | R8: =SUM(O5:O8) -> 0 | T8: 4 | U8: ='[1]Data Collection'!$J5 -> 0 | V8: 1750000 | X8: =X7+V8 -> 6500000 | AB8: Apr | AD8: 30 | AE8: =AE7+AC8 -> 49 | AF8: =AF7+AD8 -> 124 | AH8: 11000000 | AI8: =AI7+AG8 -> 11750000 | AJ8: =AJ7+AH8 -> 44000000 | AO8: BUS DAYS: | AP8: =LOOKUP(AP5,AO13:AO24,AQ13:AQ24) -> 20 | AQ8: =LOOKUP(AQ5,AS13:AS16,AU13:AU16) -> 65 | AR8: =NETWORKDAYS("1/1/24","12/31/24") -> 262
A9: 2026 | B9: 46056 | C9: Feb | D9: 5 | E9: ='[1]Data Collection'!$C6 -> 138750 | F9: ='[1]Data Collection'!$D6 -> 515 | G9: ='[1]Data Collection'!$E6 -> 84857 | H9: =IFERROR(G9/F9,) -> 164.77087 | J9: =J8-640+F9 -> 23993.55 | K9: 18000 | L9: 12000 | M9: =IF(J9>8000,1,0) -> 1 | N9: =IF(J9<K9,1,0) -> 0 | O9: =IF(J9<L9,1,0) -> 0 | T9: 5 | U9: ='[1]Data Collection'!$J6 -> 0 | V9: 1750000 | X9: =X8+V9 -> 8250000 | AB9: May | AD9: 32 | AE9: =AE8+AC9 -> 49 | AF9: =AF8+AD9 -> 156 | AH9: 11000000 | AI9: =AI8+AG9 -> 11750000 | AJ9: =AJ8+AH9 -> 55000000 | AO9: % Compl | AP9: =AP7/AP8 -> 0.9 | AQ9: =AQ7/AQ8 -> 0.61538462 | AR9: =AR7/AR8 -> 0.15267176
A10: 2026 | B10: 46063 | D10: 6 | E10: ='[1]Data Collection'!$C7 -> 70000 | F10: ='[1]Data Collection'!$D7 -> 260 | G10: ='[1]Data Collection'!$E7 -> 40464 | H10: =IFERROR(G10/F10,) -> 155.63077 | J10: =J9-640+F10 -> 23613.55 | K10: 18000 | L10: 12000 | M10: =IF(J10>8000,1,0) -> 1 | N10: =IF(J10<K10,1,0) -> 0 | O10: =IF(J10<L10,1,0) -> 0 | T10: 6 | U10: ='[1]Data Collection'!$J7 -> 0 | V10: 1750000 | X10: =X9+V10 -> 10000000 | AB10: Jun | AD10: 32 | AE10: =AE9+AC10 -> 49 | AF10: =AF9+AD10 -> 188 | AH10: 11000000 | AI10: =AI9+AG10 -> 11750000 | AJ10: =AJ9+AH10 -> 66000000
A11: 2026 | B11: 46070 | D11: 7 | E11: ='[1]Data Collection'!$C8 -> 0 | F11: ='[1]Data Collection'!$D8 -> 0 | G11: ='[1]Data Collection'!$E8 -> 0 | H11: =IFERROR(G11/F11,) -> 0 | J11: =J10-640+F11 -> 22973.55 | K11: 18000 | L11: 12000 | M11: =IF(J11>8000,1,0) -> 1 | N11: =IF(J11<K11,1,0) -> 0 | O11: =IF(J11<L11,1,0) -> 0 | T11: 7 | U11: ='[1]Data Collection'!$J8 -> 0 | V11: 1750000 | X11: =X10+V11 -> 11750000 | AB11: Jul | AD11: 32 | AE11: =AE10+AC11 -> 49 | AF11: =AF10+AD11 -> 220 | AH11: 11000000 | AI11: =AI10+AG11 -> 11750000 | AJ11: =AJ10+AH11 -> 77000000
A12: 2026 | B12: 46077 | D12: 8 | E12: ='[1]Data Collection'!$C9 -> 1 | F12: ='[1]Data Collection'!$D9 -> 1 | G12: ='[1]Data Collection'!$E9 -> 1 | H12: =IFERROR(G12/F12,) -> 1 | J12: =J11-640+F12 -> 22334.55 | K12: 18000 | L12: 12000 | M12: =IF(J12>8000,1,0) -> 1 | N12: =IF(J12<K12,1,0) -> 0 | O12: =IF(J12<L12,1,0) -> 0 | P12: =SUM(M9:M12) -> 4 | Q12: =SUM(N9:N12) -> 0 | R12: =SUM(O9:O12) -> 0 | T12: 8 | U12: ='[1]Data Collection'!$J9 -> 0 | V12: 1750000 | X12: =X11+V12 -> 13500000 | AB12: Aug | AD12: 32 | AE12: =AE11+AC12 -> 49 | AF12: =AF11+AD12 -> 252 | AH12: 11000000 | AI12: =AI11+AG12 -> 11750000 | AJ12: =AJ11+AH12 -> 88000000
A13: 2026 | B13: 46084 | C13: Mar | D13: 9 | E13: ='[1]Data Collection'!$C10 -> 0 | F13: ='[1]Data Collection'!$D10 -> 0 | G13: ='[1]Data Collection'!$E10 -> 0 | H13: =IFERROR(G13/F13,) -> 0 | K13: 18000 | L13: 12000 | T13: 9 | U13: ='[1]Data Collection'!$J10 -> 0 | V13: 1500000 | X13: =X12+V13 -> 15000000 | AB13: Sep | AD13: 32 | AE13: =AE12+AC13 -> 49 | AF13: =AF12+AD13 -> 284 | AH13: 11000000 | AI13: =AI12+AG13 -> 11750000 | AJ13: =AJ12+AH13 -> 99000000 | AO13: 1 | AP13: 46023 | AQ13: =NETWORKDAYS(AP13,AP14) -> 22 | AR13: 1ST QTR | AS13: 1 | AT13: 46023 | AU13: =NETWORKDAYS(AP13,AP16) -> 65
A14: 2026 | B14: 46091 | D14: 10 | E14: ='[1]Data Collection'!$C11 -> 0 | F14: ='[1]Data Collection'!$D11 -> 0 | G14: ='[1]Data Collection'!$E11 -> 0 | H14: =IFERROR(G14/F14,) -> 0 | K14: 18000 | L14: 12000 | T14: 10 | U14: ='[1]Data Collection'!$J11 -> 0 | V14: 1500000 | X14: =X13+V14 -> 16500000 | AB14: Oct | AD14: 32 | AE14: =AE13+AC14 -> 49 | AF14: =AF13+AD14 -> 316 | AH14: 11000000 | AI14: =AI13+AG14 -> 11750000 | AJ14: =AJ13+AH14 -> 110000000 | AO14: 2 | AP14: 46054 | AQ14: =NETWORKDAYS(AP14,AP15) -> 20 | AR14: 1ST QTR | AS14: 2 | AT14: 46113 | AU14: =NETWORKDAYS(AP16,AP19) -> 66
A15: 2026 | B15: 46098 | D15: 11 | E15: ='[1]Data Collection'!$C12 -> 0 | F15: ='[1]Data Collection'!$D12 -> 0 | G15: ='[1]Data Collection'!$E12 -> 0 | H15: =IFERROR(G15/F15,) -> 0 | K15: 18000 | L15: 12000 | T15: 11 | U15: ='[1]Data Collection'!$J12 -> 0 | V15: 1500000 | X15: =X14+V15 -> 18000000 | AB15: Nov | AD15: 32 | AE15: =AE14+AC15 -> 49 | AF15: =AF14+AD15 -> 348 | AH15: 11000000 | AI15: =AI14+AG15 -> 11750000 | AJ15: =AJ14+AH15 -> 121000000 | AO15: 3 | AP15: 46082 | AQ15: =NETWORKDAYS(AP15,AP16) -> 23 | AR15: 1ST QTR | AS15: 3 | AT15: 46204 | AU15: =NETWORKDAYS(AP19,AP22) -> 67
A16: 2026 | B16: 46105 | D16: 12 | E16: ='[1]Data Collection'!$C13 -> 0 | F16: ='[1]Data Collection'!$D13 -> 0 | G16: ='[1]Data Collection'!$E13 -> 0 | H16: =IFERROR(G16/F16,) -> 0 | K16: 18000 | L16: 12000 | T16: 12 | U16: ='[1]Data Collection'!$J13 -> 0 | V16: 2000000 | X16: =X15+V16 -> 20000000 | AB16: Dec | AD16: 32 | AE16: =AE15+AC16 -> 49 | AF16: =AF15+AD16 -> 380 | AH16: 11000000 | AI16: =AI15+AG16 -> 11750000 | AJ16: =AJ15+AH16 -> 132000000 | AO16: 4 | AP16: 46113 | AQ16: =NETWORKDAYS(AP16,AP17) -> 23 | AR16: 2ND QTR | AS16: 4 | AT16: 46296 | AU16: =NETWORKDAYS(AP22,"12/31/25") -> -197
A17: 2026 | B17: 46112 | D17: 13 | E17: ='[1]Data Collection'!$C14 -> 0 | F17: ='[1]Data Collection'!$D14 -> 0 | G17: ='[1]Data Collection'!$E14 -> 0 | H17: =IFERROR(G17/F17,) -> 0 | K17: 18000 | L17: 12000 | AO17: 5 | AP17: 46143 | AQ17: =NETWORKDAYS(AP17,AP18) -> 22 | AR17: 2ND QTR
A18: 2026 | B18: 46119 | C18: Apr | D18: 14 | E18: ='[1]Data Collection'!$C15 -> 0 | F18: ='[1]Data Collection'!$D15 -> 0 | G18: ='[1]Data Collection'!$E15 -> 0 | H18: =IFERROR(G18/F18,) -> 0 | K18: 18000 | L18: 12000 | T18: YTD | U18: =SUM(U5:U17) -> 2450001 | V18: =SUM(V5:V17) -> 20000000 | X18: 1750000 | AB18: YTD | AC18: =SUM(AC5:AC17) -> 49 | AD18: =SUM(AD5:AD17) -> 380 | AG18: =SUM(AG5:AG17) -> 11750000 | AH18: =SUM(AH5:AH17) -> 132000000 | AO18: 6 | AP18: 46174 | AQ18: =NETWORKDAYS(AP18,AP19) -> 23 | AR18: 2ND QTR
A19: 2026 | B19: 46126 | D19: 15 | E19: ='[1]Data Collection'!$C16 -> 0 | F19: ='[1]Data Collection'!$D16 -> 0 | G19: ='[1]Data Collection'!$E16 -> 0 | H19: =IFERROR(G19/F19,) -> 0 | K19: 18000 | L19: 12000 | AB19: Gap | AE19: =AE13-AF13 -> -235 | AI19: =AG18-AJ16 -> -120250000 | AO19: 7 | AP19: 46204 | AQ19: =NETWORKDAYS(AP19,AP20) -> 23 | AR19: 3RD QTR
A20: 2026 | B20: 46133 | D20: 16 | E20: ='[1]Data Collection'!$C17 -> 0 | F20: ='[1]Data Collection'!$D17 -> 0 | G20: ='[1]Data Collection'!$E17 -> 0 | H20: =IFERROR(G20/F20,) -> 0 | K20: 18000 | L20: 12000 | AO20: 8 | AP20: 46235 | AQ20: =NETWORKDAYS(AP20,AP21) -> 22 | AR20: 3RD QTR
A21: 2026 | B21: 46140 | D21: 17 | E21: ='[1]Data Collection'!$C18 -> 0 | F21: ='[1]Data Collection'!$D18 -> 0 | G21: ='[1]Data Collection'!$E18 -> 0 | H21: =IFERROR(G21/F21,) -> 0 | K21: 18000 | L21: 12000 | T21: 1 | U21: =SUM(U5:U7) -> 2450001 | V21: =SUM(V5:V7) -> 4750000 | AO21: 9 | AP21: 46266 | AQ21: =NETWORKDAYS(AP21,AP22) -> 23 | AR21: 3RD QTR
A22: 2026 | B22: 46147 | C22: May | D22: 18 | E22: ='[1]Data Collection'!$C19 -> 0 | F22: ='[1]Data Collection'!$D19 -> 0 | G22: ='[1]Data Collection'!$E19 -> 0 | H22: =IFERROR(G22/F22,) -> 0 | K22: 18000 | L22: 12000 | T22: 2 | U22: =SUM(U8:U10) -> 0 | V22: =SUM(V8:V10) -> 5250000 | AO22: 10 | AP22: 46296 | AQ22: =NETWORKDAYS(AP22,AP23) -> 22 | AR22: 4TH QTR
A23: 2026 | B23: 46154 | D23: 19 | E23: ='[1]Data Collection'!$C20 -> 0 | F23: ='[1]Data Collection'!$D20 -> 0 | G23: ='[1]Data Collection'!$E20 -> 0 | H23: =IFERROR(G23/F23,) -> 0 | K23: 18000 | L23: 12000 | T23: 3 | U23: =SUM(U11:U13) -> 0 | V23: =SUM(V11:V13) -> 5000000 | AO23: 11 | AP23: 46327 | AQ23: =NETWORKDAYS(AP23,AP24) -> 22 | AR23: 4TH QTR
A24: 2026 | B24: 46161 | D24: 20 | E24: ='[1]Data Collection'!$C21 -> 0 | F24: ='[1]Data Collection'!$D21 -> 0 | G24: ='[1]Data Collection'!$E21 -> 0 | H24: =IFERROR(G24/F24,) -> 0 | K24: 18000 | L24: 12000 | T24: 4 | U24: =SUM(U14:U16) -> 0 | V24: =SUM(V14:V16) -> 5000000 | AO24: 12 | AP24: 46357 | AQ24: =NETWORKDAYS(AP24,"12/31/25") -> -240 | AR24: 4TH QTR
A25: 2026 | B25: 46168 | D25: 21 | E25: ='[1]Data Collection'!$C22 -> 0 | F25: ='[1]Data Collection'!$D22 -> 0 | G25: ='[1]Data Collection'!$E22 -> 0 | H25: =IFERROR(G25/F25,) -> 0 | K25: 18000 | L25: 12000
A26: 2026 | B26: 46175 | C26: Jun | D26: 22 | E26: ='[1]Data Collection'!$C23 -> 0 | F26: ='[1]Data Collection'!$D23 -> 0 | G26: ='[1]Data Collection'!$E23 -> 0 | H26: =IFERROR(G26/F26,) -> 0 | K26: 18000 | L26: 12000
A27: 2026 | B27: 46182 | D27: 23 | E27: ='[1]Data Collection'!$C24 -> 0 | F27: ='[1]Data Collection'!$D24 -> 0 | G27: ='[1]Data Collection'!$E24 -> 0 | H27: =IFERROR(G27/F27,) -> 0 | K27: 18000 | L27: 12000
A28: 2026 | B28: 46189 | D28: 24 | E28: ='[1]Data Collection'!$C25 -> 0 | F28: ='[1]Data Collection'!$D25 -> 0 | G28: ='[1]Data Collection'!$E25 -> 0 | H28: =IFERROR(G28/F28,) -> 0 | K28: 18000 | L28: 12000
A29: 2026 | B29: 46196 | D29: 25 | E29: ='[1]Data Collection'!$C26 -> 0 | F29: ='[1]Data Collection'!$D26 -> 0 | G29: ='[1]Data Collection'!$E26 -> 0 | H29: =IFERROR(G29/F29,) -> 0 | K29: 18000 | L29: 12000
A30: 2026 | B30: 46203 | D30: 26 | E30: ='[1]Data Collection'!$C27 -> 0 | F30: ='[1]Data Collection'!$D27 -> 0 | G30: ='[1]Data Collection'!$E27 -> 0 | H30: =IFERROR(G30/F30,) -> 0 | K30: 18000 | L30: 12000
A31: 2026 | B31: 46210 | C31: Jul | D31: 27 | E31: ='[1]Data Collection'!$C28 -> 0 | F31: ='[1]Data Collection'!$D28 -> 0 | G31: ='[1]Data Collection'!$E28 -> 0 | H31: =IFERROR(G31/F31,) -> 0 | K31: 18000 | L31: 12000
A32: 2026 | B32: 46217 | D32: 28 | E32: ='[1]Data Collection'!$C29 -> 0 | F32: ='[1]Data Collection'!$D29 -> 0 | G32: ='[1]Data Collection'!$E29 -> 0 | H32: =IFERROR(G32/F32,) -> 0 | K32: 18000 | L32: 12000
A33: 2026 | B33: 46224 | D33: 29 | E33: ='[1]Data Collection'!$C30 -> 0 | F33: ='[1]Data Collection'!$D30 -> 0 | G33: ='[1]Data Collection'!$E30 -> 0 | H33: =IFERROR(G33/F33,) -> 0 | K33: 18000 | L33: 12000
A34: 2026 | B34: 46231 | D34: 30 | E34: ='[1]Data Collection'!$C31 -> 0 | F34: ='[1]Data Collection'!$D31 -> 0 | G34: ='[1]Data Collection'!$E31 -> 0 | H34: =IFERROR(G34/F34,) -> 0 | K34: 18000 | L34: 12000
A35: 2026 | B35: 46238 | C35: Aug | D35: 31 | E35: ='[1]Data Collection'!$C32 -> 0 | F35: ='[1]Data Collection'!$D32 -> 0 | G35: ='[1]Data Collection'!$E32 -> 0 | H35: =IFERROR(G35/F35,) -> 0 | K35: 18000 | L35: 12000
A36: 2026 | B36: 46245 | D36: 32 | E36: ='[1]Data Collection'!$C33 -> 0 | F36: ='[1]Data Collection'!$D33 -> 0 | G36: ='[1]Data Collection'!$E33 -> 0 | H36: =IFERROR(G36/F36,) -> 0 | K36: 18000 | L36: 12000
A37: 2026 | B37: 46252 | D37: 33 | E37: ='[1]Data Collection'!$C34 -> 0 | F37: ='[1]Data Collection'!$D34 -> 0 | G37: ='[1]Data Collection'!$E34 -> 0 | H37: =IFERROR(G37/F37,) -> 0 | K37: 18000 | L37: 12000
A38: 2026 | B38: 46259 | D38: 34 | E38: ='[1]Data Collection'!$C35 -> 0 | F38: ='[1]Data Collection'!$D35 -> 0 | G38: ='[1]Data Collection'!$E35 -> 0 | H38: =IFERROR(G38/F38,) -> 0 | K38: 18000 | L38: 12000
A39: 2026 | B39: 46266 | C39: Sep | D39: 35 | E39: ='[1]Data Collection'!$C36 -> 0 | F39: ='[1]Data Collection'!$D36 -> 0 | G39: ='[1]Data Collection'!$E36 -> 0 | H39: =IFERROR(G39/F39,) -> 0 | K39: 18000 | L39: 12000
A40: 2026 | B40: 46273 | D40: 36 | E40: ='[1]Data Collection'!$C37 -> 0 | F40: ='[1]Data Collection'!$D37 -> 0 | G40: ='[1]Data Collection'!$E37 -> 0 | H40: =IFERROR(G40/F40,) -> 0 | K40: 18000 | L40: 12000
A41: 2026 | B41: 46280 | D41: 37 | E41: ='[1]Data Collection'!$C38 -> 0 | F41: ='[1]Data Collection'!$D38 -> 0 | G41: ='[1]Data Collection'!$E38 -> 0 | H41: =IFERROR(G41/F41,) -> 0 | K41: 18000 | L41: 12000
...
