Workbook

Sheet Supplier Profile & Audit Plan
A1: VSAC-Report-Template-2021 V1c | C1: Red text = Required
A2: Supplier to complete light-green cells | C2: Vertiv to complete light-yellow cells
A3: Vertiv Supplier Audit Checklist
A4: Supplier Profile & Audit Plan
E5: 1.0 SUPPLIER PROFILE (Supplier to Complete)
A6: Savannah Tank & Equipment Corp. | E6: Supplier (Company name)
E7: Facility Address
E8: Facility Address (cont)
E9: City
E10: State / Province
E11: Country
E12: Mail/PIN Code
E13: Supplier's Telephone No.
E14: Supplier's Web-site
E15: Year Started Operations
E16: Other Location 1
E17: Other Location 2
E18: Other Location 3
A19: Name | B19: Phone | C19: email Address | E19: Supplier Contacts
E20: President
E21: Plant Manager
E22: Quality Manager
E23: Customer Service Manager
E24: Sales Manager
E25: Engineering Manager
E26: Other - Type Title here.
E27: Other - Type Title here.
E28: Annual Sales (USD)
E29: Capacity/Year (Units)
E30: Plant Size (total)
E31: Actual Capacity
... E37: Contract Expiration
A38: Quality System Certification Status | E38: Quality System Certification Status
E39: Quality Standard
E40: Location Certified
E41: Expiration Date
E42: ISO / TS Registrar
E43: Accreditation Body
E44: 2.0 AUDIT PLAN (Vertiv to Complete)
A45: AMER | E45: Vertiv Region
...

Sheet Checklist
D1: Supplier to complete light-green cells | E1: Vertiv to complete light-yellow cells | F1: Not Applicable | G1: Not Verified | H1: =COUNTIF(H7:H86,100) -> 0 | I1: =COUNTIF(I7:I86,100) -> 0 | J1: =COUNTIF(J7:J86,100) -> 0 | K1: =IF(SUM($I$1:$J$1)>=2,"Refer to VSAC Auditor Scoring Guide when using score of '100'.","") | M1: VSAC-Report-Template-2021 V1c | T1: Correct Row Order | W1: Hide >> | AB1: Supplier Self-Audit | AC1: 0 | AD1: 40 | AE1: 60 | AF1: 70 | AG1: 80 | AH1: 100 | AI1: Status | AJ1: << Hide
W2: Hide >> | AB2: On-Site Audit | AC2: 0 | AD2: 40 | AE2: 60 | AF2: 70 | AG2: 80 | AH2: 100 | AI2: Open | AJ2: << Hide
D3: STANDARD CHECKLIST | E3: =IF('Supplier Profile & Audit Plan'!$A$6="","",'Supplier Profile & Audit Plan'!$A$6) -> Savannah Tank & Equipment Corp. | H3: Supplier Self Audit SCORE | I3: On-Site Audit SCORE | J3: After CA Verif. SCORE | K3: AUDIT FINDINGS & OBSERVATIONS | L3: Supplier CA Req'd? (Y / N) | M3: Completion Date (mm/dd/yyyy) | N3: CA Status | O3: ROOT CAUSE & Scope of Problem Including Other Areas | P3: REMEDIAL ACTION Immediate Actions Taken to Address Issue / Finding | Q3: CORRECTIVE ACTION Taken to Address Root Cause & Prevent Recurrence | R3: PREVENTIVE ACTION Actions Taken to Prevent Similar Issues in Other Areas | S3: CONTROLS Deployed to Monitor CA/PA Effectiveness | W3: Hide >> | X3: Supp. Score (w/o n/a's) | Y3: On-Site Score (w/o n/a's) | Z3: After Verif .Score (w/o n/a's) | AB3: Adjusted | AC3: 0 | AD3: 40 | AE3: 60 | AF3: 70 | AG3: 80 | AH3: 100 | AI3: Closed | AJ3: << Hide
D4: =IF('Supplier Profile & Audit Plan'!$A$47>0,'Supplier Profile & Audit Plan'!$A$47,'Supplier Profile & Audit Plan'!$A$46) -> TBD | E4: =IF('Supplier Profile & Audit Plan'!$A$49="","",'Supplier Profile & Audit Plan'!$A$49) -> Sheet Metal & Enclosure | W4: Hide >> | AI4: <blank> | AJ4: << Hide
D5: Requirements | E5: Typical Objective Evidence | W5: Hide >> | AJ5: << Hide
D6: Go to: Findings | E6: Go to: Corrective Actions | K6: Go to: Scoring Guidelines | O6: Go to: Corrective Action Instructions | W6: Hide >> | AJ6: << Hide
A7: Bottom | B7: 1.0 QUALITY MANAGEMENT | C7: 1.1 | D7: The quality system is documented, controlled, and maintained to clearly describe current practice. Documented procedures required. Records required. | E7: Quality manual and all QS procedures show revision control (sign-offs & dates), history of changes. | L7: =IF(I7="","",IF(F7<>"","",IF(I7>=70,"N","Y"))) | N7: =IF(I7="","",IF(I7>=70,"",IF(SUM(IF(I7>=70,1,-1)+IF(J7>=70,1,-1))>=0,"Closed","Open"))) | T7: 1 | W7: Hide >> | X7: =IF(COUNTA($F7,$G7)>0,"n/a",IF(H7="","",H7)) | Y7: =IF(COUNTA($F7,$G7)>0,"n/a",IF(I7="","",I7)) | Z7: =IF(COUNTA($F7,$G7)>0,"n/a",IF(J7="","",J7)) | AJ7: << Hide
A8: 1 | C8: 1.2 | D8: Organizational development with roles and responsibilities should be in place to support business strategy and operations. Quality function should be clear. | E8: Business strategy (or plan), organization chart. | L8: =IF(I8="","",IF(F8<>"","",IF(I8>=70,"N","Y"))) | N8: =IF(I8="","",IF(I8>=70,"",IF(SUM(IF(I8>=70,1,-1)+IF(J8>=70,1,-1))>=0,"Closed","Open"))) | T8: 2 | W8: Hide >> | X8: =IF(COUNTA($F8,$G8)>0,"n/a",IF(H8="","",H8)) | Y8: =IF(COUNTA($F8,$G8)>0,"n/a",IF(I8="","",I8)) | Z8: =IF(COUNTA($F8,$G8)>0,"n/a",IF(J8="","",J8)) | AJ8: << Hide
A9: 2 | C9: 1.3 | D9: Quality reports, trend charts and data analysis identify areas of opportunity and are used by management on a routine basis. Records required. | E9: Product quality yield data, top problems and corresponding improvement actions, status of preventive/corrective actions taken, internal audit results, records of customer quality issues and resolution | L9: =IF(I9="","",IF(F9<>"","",IF(I9>=70,"N","Y"))) | N9: =IF(I9="","",IF(I9>=70,"",IF(SUM(IF(I9>=70,1,-1)+IF(J9>=70,1,-1))>=0,"Closed","Open"))) | T9: 3 | W9: Hide >> | X9: =IF(COUNTA($F9,$G9)>0,"n/a",IF(H9="","",H9)) | Y9: =IF(COUNTA($F9,$G9)>0,"n/a",IF(I9="","",I9)) | Z9: =IF(COUNTA($F9,$G9)>0,"n/a",IF(J9="","",J9)) | AJ9: << Hide
A10: 3 | C10: 1.4 | D10: Quality performance targets are clearly defined, included in the business plan and monitored for improvements. | E10: Strategic and tactical objectives, goals, action plans, etc. | L10: =IF(I10="","",IF(F10<>"","",IF(I10>=70,"N","Y"))) | N10: =IF(I10="","",IF(I10>=70,"",IF(SUM(IF(I10>=70,1,-1)+IF(J10>=70,1,-1))>=0,"Closed","Open"))) | T10: 4 | W10: Hide >> | X10: =IF(COUNTA($F10,$G10)>0,"n/a",IF(H10="","",H10)) | Y10: =IF(COUNTA($F10,$G10)>0,"n/a",IF(I10="","",I10)) | Z10: =IF(COUNTA($F10,$G10)>0,"n/a",IF(J10="","",J10)) | AJ10: << Hide
A11: 4 | C11: 1.5 | D11: Quality records are maintained. A record control system is in place for the identification, storage, protection, retrieval, retention time, and disposition of quality records. | E11: Procedures, list of records to be kept with retention periods specified | L11: =IF(I11="","",IF(F11<>"","",IF(I11>=70,"N","Y"))) | N11: =IF(I11="","",IF(I11>=70,"",IF(SUM(IF(I11>=70,1,-1)+IF(J11>=70,1,-1))>=0,"Closed","Open"))) | T11: 5 | W11: Hide >> | X11: =IF(COUNTA($F11,$G11)>0,"n/a",IF(H11="","",H11)) | Y11: =IF(COUNTA($F11,$G11)>0,"n/a",IF(I11="","",I11)) | Z11: =IF(COUNTA($F11,$G11)>0,"n/a",IF(J11="","",J11)) | AJ11: << Hide
A12: 5 | C12: 1.6 | D12: Executive management participates in periodic quality system reviews that address quality related feedback from customers and internal quality metrics. Records required. | E12: Analysis of field failures, inspection yields, resource needs, internal audit results, corrective action status, etc. Evidence of regularly scheduled executive management review of performance | L12: =IF(I12="","",IF(F12<>"","",IF(I12>=70,"N","Y"))) | N12: =IF(I12="","",IF(I12>=70,"",IF(SUM(IF(I12>=70,1,-1)+IF(J12>=70,1,-1))>=0,"Closed","Open"))) | T12: 6 | W12: Hide >> | X12: =IF(COUNTA($F12,$G12)>0,"n/a",IF(H12="","",H12)) | Y12: =IF(COUNTA($F12,$G12)>0,"n/a",IF(I12="","",I12)) | Z12: =IF(COUNTA($F12,$G12)>0,"n/a",IF(J12="","",J12)) | AJ12: << Hide
A13: 6 | B13: 2.0 CONTINUOUS IMPROVEMENT | C13: 2.1 | D13: Improvement actions are taken based on the analysis of significant business trends, design reviews, customer satisfaction surveys or other meaningful inputs. Documented procedures required. Records required. | E13: Management review meetings, goal setting, performance measurement, internal audits, action plans, customer surveys | L13: =IF(I13="","",IF(F13<>"","",IF(I13>=70,"N","Y"))) | N13: =IF(I13="","",IF(I13>=70,"",IF(SUM(IF(I13>=70,1,-1)+IF(J13>=70,1,-1))>=0,"Closed","Open"))) | T13: 7 | W13: Hide >> | X13: =IF(COUNTA($F13,$G13)>0,"n/a",IF(H13="","",H13)) | Y13: =IF(COUNTA($F13,$G13)>0,"n/a",IF(I13="","",I13)) | Z13: =IF(COUNTA($F13,$G13)>0,"n/a",IF(J13="","",J13)) | AJ13: << Hide
A14: 7 | C14: 2.2 | D14: A formal approach is used to actively pursue cost containment and other continual improvement activities throughout the organization. Documented procedures required. Records required. | E14: Employee involvement / recognition program, Lean, Six Sigma, kaizen, SIC, 5-S, cost reduction program, preventive actions | L14: =IF(I14="","",IF(F14<>"","",IF(I14>=70,"N","Y"))) | N14: =IF(I14="","",IF(I14>=70,"",IF(SUM(IF(I14>=70,1,-1)+IF(J14>=70,1,-1))>=0,"Closed","Open"))) | T14: 8 | W14: Hide >> | X14: =IF(COUNTA($F14,$G14)>0,"n/a",IF(H14="","",H14)) | Y14: =IF(COUNTA($F14,$G14)>0,"n/a",IF(I14="","",I14)) | Z14: =IF(COUNTA($F14,$G14)>0,"n/a",IF(J14="","",J14)) | AJ14: << Hide
A15: 8 | C15: 2.3 | D15: A corrective action system is in place that provides root cause analysis and takes timely and effective action to prevent recurrence. Documented procedures required. Records required. | E15: Corrective action records, trend charts, meeting minutes, nonconformance frequency & cost analysis. Does CA system cover customer, internal & supplier issues? | L15: =IF(I15="","",IF(F15<>"","",IF(I15>=70,"N","Y"))) | N15: =IF(I15="","",IF(I15>=70,"",IF(SUM(IF(I15>=70,1,-1)+IF(J15>=70,1,-1))>=0,"Closed","Open"))) | T15: 9 | W15: Hide >> | X15: =IF(COUNTA($F15,$G15)>0,"n/a",IF(H15="","",H15)) | Y15: =IF(COUNTA($F15,$G15)>0,"n/a",IF(I15="","",I15)) | Z15: =IF(COUNTA($F15,$G15)>0,"n/a",IF(J15="","",J15)) | AJ15: << Hide
A16: 9 | C16: 2.4 | D16: Contingency plans (risk mitigation) have been developed that describe actions to be taken in the event of a major interruption of facility and / or the manufacturing process. | E16: Process covering natural disasters, utility interruptions, labor shortages, key equipment failures, major production issues. | L16: =IF(I16="","",IF(F16<>"","",IF(I16>=70,"N","Y"))) | N16: =IF(I16="","",IF(I16>=70,"",IF(SUM(IF(I16>=70,1,-1)+IF(J16>=70,1,-1))>=0,"Closed","Open"))) | T16: 10 | W16: Hide >> | X16: =IF(COUNTA($F16,$G16)>0,"n/a",IF(H16="","",H16)) | Y16: =IF(COUNTA($F16,$G16)>0,"n/a",IF(I16="","",I16)) | Z16: =IF(COUNTA($F16,$G16)>0,"n/a",IF(J16="","",J16)) | AJ16: << Hide
A17: 10 | B17: 3.0 COMPETENCE DEVELOPMENT | C17: 3.1 | D17: The skill and education level required for each job is documented and appropriate training / re-training is provided. Records required. | E17: Job descriptions, job skills assessment, training records, training manuals. Look for use of training aids & work instructions at work stations. | L17: =IF(I17="","",IF(F17<>"","",IF(I17>=70,"N","Y"))) | N17: =IF(I17="","",IF(I17>=70,"",IF(SUM(IF(I17>=70,1,-1)+IF(J17>=70,1,-1))>=0,"Closed","Open"))) | T17: 11 | W17: Hide >> | X17: =IF(COUNTA($F17,$G17)>0,"n/a",IF(H17="","",H17)) | Y17: =IF(COUNTA($F17,$G17)>0,"n/a",IF(I17="","",I17)) | Z17: =IF(COUNTA($F17,$G17)>0,"n/a",IF(J17="","",J17)) | AJ17: << Hide
A18: 11 | C18: 3.2 | D18: Employee qualification / certification is maintained where the quality outcome of the process cannot be verified and is strongly dependent upon operator skill. Records required. | E18: Qualification records, certification history, etc. | L18: =IF(I18="","",IF(F18<>"","",IF(I18>=70,"N","Y"))) | N18: =IF(I18="","",IF(I18>=70,"",IF(SUM(IF(I18>=70,1,-1)+IF(J18>=70,1,-1))>=0,"Closed","Open"))) | T18: 12 | W18: Hide >> | X18: =IF(COUNTA($F18,$G18)>0,"n/a",IF(H18="","",H18)) | Y18: =IF(COUNTA($F18,$G18)>0,"n/a",IF(I18="","",I18)) | Z18: =IF(COUNTA($F18,$G18)>0,"n/a",IF(J18="","",J18)) | AJ18: << Hide
A19: 12 | C19: 3.3 | D19: Suitable methods are used to verify training effectiveness. Records required. | E19: Records of student testing, production quality records, audit records, interview workers to validate training records. Look for use of training aids & work instructions at work stations. | L19: =IF(I19="","",IF(F19<>"","",IF(I19>=70,"N","Y"))) | N19: =IF(I19="","",IF(I19>=70,"",IF(SUM(IF(I19>=70,1,-1)+IF(J19>=70,1,-1))>=0,"Closed","Open"))) | T19: 13 | W19: Hide >> | X19: =IF(COUNTA($F19,$G19)>0,"n/a",IF(H19="","",H19)) | Y19: =IF(COUNTA($F19,$G19)>0,"n/a",IF(I19="","",I19)) | Z19: =IF(COUNTA($F19,$G19)>0,"n/a",IF(J19="","",J19)) | AJ19: << Hide
A20: 13 | B20: 4.0 DESIGN AND DEVELOPMENT OF PRODUCTS AND SERVICES | C20: 4.1 | D20: Customer needs and requirements are incorporated into product designs and/or manufacturing processes. Critical-to-Quality (CTQ) characteristics are identified and understood. Records required. | E20: Market studies, customer/end-user surveys, technical design reviews, mfg process capability studies, formal process qualification plan, manufacturing verification tests, pilot runs, Procedures, design / process review minutes, FMEA's, etc. | L20: =IF(I20="","",IF(F20<>"","",IF(I20>=70,"N","Y"))) | N20: =IF(I20="","",IF(I20>=70,"",IF(SUM(IF(I20>=70,1,-1)+IF(J20>=70,1,-1))>=0,"Closed","Open"))) | T20: 14 | W20: Hide >> | X20: =IF(COUNTA($F20,$G20)>0,"n/a",IF(H20="","",H20)) | Y20: =IF(COUNTA($F20,$G20)>0,"n/a",IF(I20="","",I20)) | Z20: =IF(COUNTA($F20,$G20)>0,"n/a",IF(J20="","",J20)) | AJ20: << Hide
A21: 14 | C21: 4.2 | D21: Product specifications and drawings are generated, controlled and maintained for new or changed product designs. Records required. | E21: Complete product characteristics, application requirements, and other information essential for its safe and proper use and eventual disposal, etc. | L21: =IF(I21="","",IF(F21<>"","",IF(I21>=70,"N","Y"))) | N21: =IF(I21="","",IF(I21>=70,"",IF(SUM(IF(I21>=70,1,-1)+IF(J21>=70,1,-1))>=0,"Closed","Open"))) | T21: 15 | W21: Hide >> | X21: =IF(COUNTA($F21,$G21)>0,"n/a",IF(H21="","",H21)) | Y21: =IF(COUNTA($F21,$G21)>0,"n/a",IF(I21="","",I21)) | Z21: =IF(COUNTA($F21,$G21)>0,"n/a",IF(J21="","",J21)) | AJ21: << Hide
A22: 15 | C22: 4.3 | D22: Design validation is an integral part of the design process and occurs prior to production release.Approval mechanism is clear. Records required. | E22: Design results, manufacturability, productivity and cost studies, confirmation that product fulfills its specified requirements or intended use or applications, design-FMEA, etc. | L22: =IF(I22="","",IF(F22<>"","",IF(I22>=70,"N","Y"))) | N22: =IF(I22="","",IF(I22>=70,"",IF(SUM(IF(I22>=70,1,-1)+IF(J22>=70,1,-1))>=0,"Closed","Open"))) | T22: 16 | W22: Hide >> | X22: =IF(COUNTA($F22,$G22)>0,"n/a",IF(H22="","",H22)) | Y22: =IF(COUNTA($F22,$G22)>0,"n/a",IF(I22="","",I22)) | Z22: =IF(COUNTA($F22,$G22)>0,"n/a",IF(J22="","",J22)) | AJ22: << Hide
A23: 16 | C23: 4.4 | D23: Human and technical resources are adequate to meet Vertiv’s requirements for design collaboration, tooling design and electronic drawing and data exchange. NPI project team is clearly developed. | E23: Qualification of technical staff. Equipment/software capabilities; CAD, PRO-E, etc. Experience, equipment and technical knowledge for products to be produced for Vertiv NPI project organization chart | L23: =IF(I23="","",IF(F23<>"","",IF(I23>=70,"N","Y"))) | N23: =IF(I23="","",IF(I23>=70,"",IF(SUM(IF(I23>=70,1,-1)+IF(J23>=70,1,-1))>=0,"Closed","Open"))) | T23: 17 | W23: Hide >> | X23: =IF(COUNTA($F23,$G23)>0,"n/a",IF(H23="","",H23)) | Y23: =IF(COUNTA($F23,$G23)>0,"n/a",IF(I23="","",I23)) | Z23: =IF(COUNTA($F23,$G23)>0,"n/a",IF(J23="","",J23)) | AJ23: << Hide
A24: 17 | C24: 4.5 | D24: New and revised customer specifications are reviewed and implemented in a timely manner. | E24: Technical review of methods to be used, capability studies on similar parts, documented review procedure, PPAP process, APQP (e.g. DFA, design reviews, process quality system review, packaging evaluation, etc) | L24: =IF(I24="","",IF(F24<>"","",IF(I24>=70,"N","Y"))) | N24: =IF(I24="","",IF(I24>=70,"",IF(SUM(IF(I24>=70,1,-1)+IF(J24>=70,1,-1))>=0,"Closed","Open"))) | T24: 18 | W24: Hide >> | X24: =IF(COUNTA($F24,$G24)>0,"n/a",IF(H24="","",H24)) | Y24: =IF(COUNTA($F24,$G24)>0,"n/a",IF(I24="","",I24)) | Z24: =IF(COUNTA($F24,$G24)>0,"n/a",IF(J24="","",J24)) | AJ24: << Hide
A25: 18 | C25: 4.6 | D25: Process and quality control documents are well in place and used for production start-up, as important deliverables transisioning from NPI to production ramp up. | E25: Customer specifications, engineering drawings, change notices, work instructions and specifications as applicable, documented procedures | L25: =IF(I25="","",IF(F25<>"","",IF(I25>=70,"N","Y"))) | N25: =IF(I25="","",IF(I25>=70,"",IF(SUM(IF(I25>=70,1,-1)+IF(J25>=70,1,-1))>=0,"Closed","Open"))) | T25: 19 | W25: Hide >> | X25: =IF(COUNTA($F25,$G25)>0,"n/a",IF(H25="","",H25)) | Y25: =IF(COUNTA($F25,$G25)>0,"n/a",IF(I25="","",I25)) | Z25: =IF(COUNTA($F25,$G25)>0,"n/a",IF(J25="","",J25)) | AJ25: << Hide
A26: Bottom | C26: 4.7 | D26: Customer notification / approval occurs for changes to Control Plans, manufacturing site, product transfers, raw material or product obsolescence. Records required. | E26: Customer notification procedure/evidence on major changes, signed material / process change requests | L26: =IF(I26="","",IF(F26<>"","",IF(I26>=70,"N","Y"))) | N26: =IF(I26="","",IF(I26>=70,"",IF(SUM(IF(I26>=70,1,-1)+IF(J26>=70,1,-1))>=0,"Closed","Open"))) | T26: 20 | W26: Hide >> | X26: =IF(COUNTA($F26,$G26)>0,"n/a",IF(H26="","",H26)) | Y26: =IF(COUNTA($F26,$G26)>0,"n/a",IF(I26="","",I26)) | Z26: =IF(COUNTA($F26,$G26)>0,"n/a",IF(J26="","",J26)) | AJ26: << Hide
A27: 1 | B27: 5.0 QUALITY PLANNING | C27: 5.1 | D27: Production samples are inspected and provided to customers upon request. Records required. | E27: Completed PPAP or similar forms, inspection reports, availability of qualified resources | L27: =IF(I27="","",IF(F27<>"","",IF(I27>=70,"N","Y"))) | N27: =IF(I27="","",IF(I27>=70,"",IF(SUM(IF(I27>=70,1,-1)+IF(J27>=70,1,-1))>=0,"Closed","Open"))) | T27: 21 | W27: Hide >> | X27: =IF(COUNTA($F27,$G27)>0,"n/a",IF(H27="","",H27)) | Y27: =IF(COUNTA($F27,$G27)>0,"n/a",IF(I27="","",I27)) | Z27: =IF(COUNTA($F27,$G27)>0,"n/a",IF(J27="","",J27)) | AJ27: << Hide
A28: 2 | C28: 5.2 | D28: Reliability test plans are developed and routinely followed. Testing is used to verify design spec's, drive design improvements and provide an on-going check of materials and workmanship. Documented procedures required. Records required. | E28: Reliability test plans, test reports, improvement/corrective actions taken, design changes implemented | L28: =IF(I28="","",IF(F28<>"","",IF(I28>=70,"N","Y"))) | N28: =IF(I28="","",IF(I28>=70,"",IF(SUM(IF(I28>=70,1,-1)+IF(J28>=70,1,-1))>=0,"Closed","Open"))) | T28: 22 | W28: Hide >> | X28: =IF(COUNTA($F28,$G28)>0,"n/a",IF(H28="","",H28)) | Y28: =IF(COUNTA($F28,$G28)>0,"n/a",IF(I28="","",I28)) | Z28: =IF(COUNTA($F28,$G28)>0,"n/a",IF(J28="","",J28)) | AJ28: << Hide
A29: 3 | C29: 5.3 | D29: Product reliability test data is available upon request and historical test performance data shows a highly stable process and product design. Records required. | E29: Reliability test summary reports/charts | L29: =IF(I29="","",IF(F29<>"","",IF(I29>=70,"N","Y"))) | N29: =IF(I29="","",IF(I29>=70,"",IF(SUM(IF(I29>=70,1,-1)+IF(J29>=70,1,-1))>=0,"Closed","Open"))) | T29: 23 | W29: Hide >> | X29: =IF(COUNTA($F29,$G29)>0,"n/a",IF(H29="","",H29)) | Y29: =IF(COUNTA($F29,$G29)>0,"n/a",IF(I29="","",I29)) | Z29: =IF(COUNTA($F29,$G29)>0,"n/a",IF(J29="","",J29)) | AJ29: << Hide
A30: 4 | B30: 6.0 PROCUREMENT | C30: 6.1 | D30: A formal process is used for the selection, qualification and re-qualification of suppliers. Records required. | E30: Supplier quality system audits and related corrective actions, engineering testing and approval records, plant production trials | L30: =IF(I30="","",IF(F30<>"","",IF(I30>=70,"N","Y"))) | N30: =IF(I30="","",IF(I30>=70,"",IF(SUM(IF(I30>=70,1,-1)+IF(J30>=70,1,-1))>=0,"Closed","Open"))) | T30: 24 | W30: Hide >> | X30: =IF(COUNTA($F30,$G30)>0,"n/a",IF(H30="","",H30)) | Y30: =IF(COUNTA($F30,$G30)>0,"n/a",IF(I30="","",I30)) | Z30: =IF(COUNTA($F30,$G30)>0,"n/a",IF(J30="","",J30)) | AJ30: << Hide
A31: 5 | C31: 6.2 | D31: Purchases from unapproved suppliers are prevented by a properly controlled and available Approved Supplier List (ASL). Records required. | E31: ASL, procedures for control and use of ASL, production material receipt records, counterfeit part prevention measures in place as appropriate/applicable | L31: =IF(I31="","",IF(F31<>"","",IF(I31>=70,"N","Y"))) | N31: =IF(I31="","",IF(I31>=70,"",IF(SUM(IF(I31>=70,1,-1)+IF(J31>=70,1,-1))>=0,"Closed","Open"))) | T31: 25 | W31: Hide >> | X31: =IF(COUNTA($F31,$G31)>0,"n/a",IF(H31="","",H31)) | Y31: =IF(COUNTA($F31,$G31)>0,"n/a",IF(I31="","",I31)) | Z31: =IF(COUNTA($F31,$G31)>0,"n/a",IF(J31="","",J31)) | AJ31: << Hide
A32: 6 | C32: 6.3 | D32: Improvement actions are taken to continuously improve performance of the supplier base. Records required. | E32: Supplier performance analysis (e.g. delivery, quality, cost, technology, etc), performance trends, supplier audit reports, Inflation Model, documented goals regarding raw material cost containment | L32: =IF(I32="","",IF(F32<>"","",IF(I32>=70,"N","Y"))) | N32: =IF(I32="","",IF(I32>=70,"",IF(SUM(IF(I32>=70,1,-1)+IF(J32>=70,1,-1))>=0,"Closed","Open"))) | T32: 26 | W32: Hide >> | X32: =IF(COUNTA($F32,$G32)>0,"n/a",IF(H32="","",H32)) | Y32: =IF(COUNTA($F32,$G32)>0,"n/a",IF(I32="","",I32)) | Z32: =IF(COUNTA($F32,$G32)>0,"n/a",IF(J32="","",J32)) | AJ32: << Hide
A33: 7 | C33: 6.4 | D33: A supplier quality assurance system ensures that all purchased product or material conforms to defined specifications and applicable regulatory or customer requirements. Records required. | E33: Receiving inspection, supplier audits, source inspection, qualification testing, Certificate of Compliance (COC), component marking, labeling, etc. | L33: =IF(I33="","",IF(F33<>"","",IF(I33>=70,"N","Y"))) | N33: =IF(I33="","",IF(I33>=70,"",IF(SUM(IF(I33>=70,1,-1)+IF(J33>=70,1,-1))>=0,"Closed","Open"))) | T33: 27 | W33: Hide >> | X33: =IF(COUNTA($F33,$G33)>0,"n/a",IF(H33="","",H33)) | Y33: =IF(COUNTA($F33,$G33)>0,"n/a",IF(I33="","",I33)) | Z33: =IF(COUNTA($F33,$G33)>0,"n/a",IF(J33="","",J33)) | AJ33: << Hide
A34: 8 | C34: 6.5 | D34: A system exists for the identification, verification and protection of customer supplied product that includes notifying the customer if product is damaged or lost. Records required. | E34: Procedures, segregation during storage, limited and controlled access to stored inventories | L34: =IF(I34="","",IF(F34<>"","",IF(I34>=70,"N","Y"))) | N34: =IF(I34="","",IF(I34>=70,"",IF(SUM(IF(I34>=70,1,-1)+IF(J34>=70,1,-1))>=0,"Closed","Open"))) | T34: 28 | W34: Hide >> | X34: =IF(COUNTA($F34,$G34)>0,"n/a",IF(H34="","",H34)) | Y34: =IF(COUNTA($F34,$G34)>0,"n/a",IF(I34="","",I34)) | Z34: =IF(COUNTA($F34,$G34)>0,"n/a",IF(J34="","",J34)) | AJ34: << Hide
A35: 9 | B35: 7.0 INCOMING MATERIAL | C35: 7.1 | D35: Receiving inspection is performed per documented procedures and detailed work instructions. Records required. | E35: Procedures, inspection instructions resources (manpower and equipment) allocated for incoming inspection | L35: =IF(I35="","",IF(F35<>"","",IF(I35>=70,"N","Y"))) | N35: =IF(I35="","",IF(I35>=70,"",IF(SUM(IF(I35>=70,1,-1)+IF(J35>=70,1,-1))>=0,"Closed","Open"))) | T35: 29 | W35: Hide >> | X35: =IF(COUNTA($F35,$G35)>0,"n/a",IF(H35="","",H35)) | Y35: =IF(COUNTA($F35,$G35)>0,"n/a",IF(I35="","",I35)) | Z35: =IF(COUNTA($F35,$G35)>0,"n/a",IF(J35="","",J35)) | AJ35: << Hide
A36: 10 | C36: 7.2 | D36: Inspected material is adequately identified as to acceptance or rejection and traceable to receiving inspection report. Records required. | E36: Quality Control label, marking or use of designated hold area as indicated in the procedure, adherence to FIFO practices | L36: =IF(I36="","",IF(F36<>"","",IF(I36>=70,"N","Y"))) | N36: =IF(I36="","",IF(I36>=70,"",IF(SUM(IF(I36>=70,1,-1)+IF(J36>=70,1,-1))>=0,"Closed","Open"))) | T36: 30 | W36: Hide >> | X36: =IF(COUNTA($F36,$G36)>0,"n/a",IF(H36="","",H36)) | Y36: =IF(COUNTA($F36,$G36)>0,"n/a",IF(I36="","",I36)) | Z36: =IF(COUNTA($F36,$G36)>0,"n/a",IF(J36="","",J36)) | AJ36: << Hide
A37: 11 | C37: 7.3 | D37: Supplier corrective action requests require root cause investigation and records show responses are analyzed. Documented procedures required. Records required. | E37: Availability of written procedure, standardized Corrective Action form, analysis of corrective action cycle time and closure measurements | L37: =IF(I37="","",IF(F37<>"","",IF(I37>=70,"N","Y"))) | N37: =IF(I37="","",IF(I37>=70,"",IF(SUM(IF(I37>=70,1,-1)+IF(J37>=70,1,-1))>=0,"Closed","Open"))) | T37: 31 | W37: Hide >> | X37: =IF(COUNTA($F37,$G37)>0,"n/a",IF(H37="","",H37)) | Y37: =IF(COUNTA($F37,$G37)>0,"n/a",IF(I37="","",I37)) | Z37: =IF(COUNTA($F37,$G37)>0,"n/a",IF(J37="","",J37)) | AJ37: << Hide
A38: 12 | B38: 8.0 MANUFACTURING QUALITY | C38: 8.1 | D38: There is a formal method used to qualify new or rebuilt production equipment prior to production use. | E38: Qualification plan that includes established goals for process yields/up-time, etc. and record of process capability, review and approval, etc. | L38: =IF(I38="","",IF(F38<>"","",IF(I38>=70,"N","Y"))) | N38: =IF(I38="","",IF(I38>=70,"",IF(SUM(IF(I38>=70,1,-1)+IF(J38>=70,1,-1))>=0,"Closed","Open"))) | T38: 32 | W38: Hide >> | X38: =IF(COUNTA($F38,$G38)>0,"n/a",IF(H38="","",H38)) | Y38: =IF(COUNTA($F38,$G38)>0,"n/a",IF(I38="","",I38)) | Z38: =IF(COUNTA($F38,$G38)>0,"n/a",IF(J38="","",J38)) | AJ38: << Hide
A39: 13 | C39: 8.2 | D39: Control Plans are used to plan and deploy inspection and test functions throughout the production process. | E39: Process flow diagram, statistical tools to be used, key inspection points, inspection frequency, records, control responsibility, inspection/test method, gaging used, acceptable yield rates | L39: =IF(I39="","",IF(F39<>"","",IF(I39>=70,"N","Y"))) | N39: =IF(I39="","",IF(I39>=70,"",IF(SUM(IF(I39>=70,1,-1)+IF(J39>=70,1,-1))>=0,"Closed","Open"))) | T39: 33 | W39: Hide >> | X39: =IF(COUNTA($F39,$G39)>0,"n/a",IF(H39="","",H39)) | Y39: =IF(COUNTA($F39,$G39)>0,"n/a",IF(I39="","",I39)) | Z39: =IF(COUNTA($F39,$G39)>0,"n/a",IF(J39="","",J39)) | AJ39: << Hide
A40: 14 | C40: 8.3 | D40: Appropriate work instructions are available where needed that accurately describe all work methods including inspections and tests to be done during production. | E40: Sample size, frequency, method, document control dates/revision level, etc. Handling procedures for Electro-Static Discharge (ESD) | L40: =IF(I40="","",IF(F40<>"","",IF(I40>=70,"N","Y"))) | N40: =IF(I40="","",IF(I40>=70,"",IF(SUM(IF(I40>=70,1,-1)+IF(J40>=70,1,-1))>=0,"Closed","Open"))) | T40: 34 | W40: Hide >> | X40: =IF(COUNTA($F40,$G40)>0,"n/a",IF(H40="","",H40)) | Y40: =IF(COUNTA($F40,$G40)>0,"n/a",IF(I40="","",I40)) | Z40: =IF(COUNTA($F40,$G40)>0,"n/a",IF(J40="","",J40)) | AJ40: << Hide
...

Sheet Audit Results
A1: Note: The Audit Results page fills in automatically with the exception of a few fields near the bottom of the page. | L1: VSAC-Report-Template-2021 V1c | Z1: Hide >>> | AA1: =Checklist!U92 -> 0 | AD1: <<< Hide
B2: Vertiv Supplier Audit Checklist | G2: Supplier: | H2: =IF('Supplier Profile & Audit Plan'!$A$6="","",'Supplier Profile & Audit Plan'!$A$6) -> Savannah Tank & Equipment Corp.
C3: Audit Results | G3: Commodity: | H3: =IF('Supplier Profile & Audit Plan'!A49="","",'Supplier Profile & Audit Plan'!A49) -> Sheet Metal & Enclosure
G4: =IF('Supplier Profile & Audit Plan'!A46="","",'Supplier Profile & Audit Plan'!A46) | L4: Section Scores
A5: Vertiv Region: | C5: =IF('Supplier Profile & Audit Plan'!$A$45="","",'Supplier Profile & Audit Plan'!$A$45) -> AMER | G5: Supplier Self-Audit SCORE | H5: On-Site Audit SCORE | I5: CA Req'd? (Y) | J5: CA Status (Open) | K5: After CA Verif. SCORE | L5: Supplier Self-Audit SCORE | M5: On-Site Audit SCORE | N5: After CA Verif. SCORE
A6: Standard Checklist Section | C6: Total Req'mnts | D6: Mandatory Req'mnts | E6: Req. No.
AA7: Audit Team Recommendation | AB7: Final Disposition
A8: 1 | B8: Quality Management | C8: 6 | D8: 3 | E8: M | F8: 1.1 | G8: =Checklist!X7 | H8: =Checklist!Y7 | I8: =Checklist!L7 | J8: =IF(H8="","",IF(Checklist!N7="","",Checklist!N7)) | K8: =Checklist!Z7 | L8: =IF(SUM(G8:G13)=0,"0",SUM(G8:G13)/($C8-(COUNTIF(G8:G13,"n/a")))) -> 0 | M8: =IF(SUM(H8:H13)=0,"0",SUM(H8:H13)/($C8-(COUNTIF(H8:H13,"n/a")))) -> 0 | N8: =IF(SUM(K8:K13)=0,"0",SUM(K8:K13)/($C8-(COUNTIF(K8:K13,"n/a")))) -> 0 | AA8: Passed | AB8: Approved
E9: M | F9: 1.2 | G9: =Checklist!X8 | H9: =Checklist!Y8 | I9: =Checklist!L8 | J9: =IF(H9="","",IF(Checklist!N8="","",Checklist!N8)) | K9: =Checklist!Z8 | AA9: Conditional Approval | AB9: Conditionally Approved
F10: 1.3 | G10: =Checklist!X9 | H10: =Checklist!Y9 | I10: =Checklist!L9 | J10: =IF(H10="","",IF(Checklist!N9="","",Checklist!N9)) | K10: =Checklist!Z9 | AA10: Rejected | AB10: Not Approved
F11: 1.4 | G11: =Checklist!X10 | H11: =Checklist!Y10 | I11: =Checklist!L10 | J11: =IF(H11="","",IF(Checklist!N10="","",Checklist!N10)) | K11: =Checklist!Z10
E12: M | F12: 1.5 | G12: =Checklist!X11 | H12: =Checklist!Y11 | I12: =Checklist!L11 | J12: =IF(H12="","",IF(Checklist!N11="","",Checklist!N11)) | K12: =Checklist!Z11
F13: 1.6 | G13: =Checklist!X12 | H13: =Checklist!Y12 | I13: =Checklist!L12 | J13: =IF(H13="","",IF(Checklist!N12="","",Checklist!N12)) | K13: =Checklist!Z12 | AA13: 3 | AB13: =IF(SUM(G12:G14)=0,"",SUM(G12:G14)/($C12-(COUNTIF(G12:G14,"n/a"))))
A14: 2 | B14: Continuous Improvement | C14: 4 | D14: 1 | F14: 2.1 | G14: =Checklist!X13 | H14: =Checklist!Y13 | I14: =Checklist!L13 | J14: =IF(H14="","",IF(Checklist!N13="","",Checklist!N13)) | K14: =Checklist!Z13 | L14: =IF(SUM(G14:G17)=0,"0",SUM(G14:G17)/($C14-(COUNTIF(G14:G17,"n/a")))) -> 0 | M14: =IF(SUM(H14:H17)=0,"0",SUM(H14:H17)/($C14-(COUNTIF(H14:H17,"n/a")))) -> 0 | N14: =IF(SUM(K14:K17)=0,"0",SUM(K14:K17)/($C14-(COUNTIF(K14:K17,"n/a")))) -> 0 | AA14: 4 | AB14: =IF(SUM(G8:G11)=0,"",SUM(G8:G11)/($C8-(COUNTIF(G8:G11,"n/a"))))
F15: 2.2 | G15: =Checklist!X14 | H15: =Checklist!Y14 | I15: =Checklist!L14 | J15: =IF(H15="","",IF(Checklist!N14="","",Checklist!N14)) | K15: =Checklist!Z14 | AA15: 5 | AB15: =IF(SUM(G33:G37)=0,"",SUM(G33:G37)/($C8-(COUNTIF(G33:G37,"n/a"))))
E16: M | F16: 2.3 | G16: =Checklist!X15 | H16: =Checklist!Y15 | I16: =Checklist!L15 | J16: =IF(H16="","",IF(Checklist!N15="","",Checklist!N15)) | K16: =Checklist!Z15 | AA16: 6 | AB16: =IF(SUM(G41:G46)=0,"",SUM(G41:G46)/($C41-(COUNTIF(G41:G46,"n/a"))))
F17: 2.4 | G17: =Checklist!X16 | H17: =Checklist!Y16 | I17: =Checklist!L16 | J17: =IF(H17="","",IF(Checklist!N16="","",Checklist!N16)) | K17: =Checklist!Z16 | AA17: 15 | AB17: =IF(SUM(G74:G88)=0,"",SUM(G74:G88)/($C74-(COUNTIF(G74:G88,"n/a"))))
A18: 3 | B18: Competence Development | C18: 3 | D18: 1 | E18: M | F18: 3.1 | G18: =Checklist!X17 | H18: =Checklist!Y17 | I18: =Checklist!L17 | J18: =IF(H18="","",IF(Checklist!N17="","",Checklist!N17)) | K18: =Checklist!Z17 | L18: =IF(SUM(G18:G20)=0,"0",SUM(G18:G20)/($C18-(COUNTIF(G18:G20,"n/a")))) -> 0 | M18: =IF(SUM(H18:H20)=0,"0",SUM(H18:H20)/($C18-(COUNTIF(H18:H20,"n/a")))) -> 0 | N18: =IF(SUM(K18:K20)=0,"0",SUM(K18:K20)/($C18-(COUNTIF(K18:K20,"n/a")))) -> 0 | AB18: '=IF(COUNTA($G6,$H6)>0,"n/a",IF(I6="","",I6))
F19: 3.2 | G19: =Checklist!X18 | H19: =Checklist!Y18 | I19: =Checklist!L18 | J19: =IF(H19="","",IF(Checklist!N18="","",Checklist!N18)) | K19: =Checklist!Z18 | AB19: =SUM(COUNTIF(H8:H83,0),COUNTIF(H8:H83,40),COUNTIF(H8:H83,60),COUNTIF(H8:H83,70),COUNTIF(H8:H83,80),COUNTIF(H8:H83,100))
F20: 3.3 | G20: =Checklist!X19 | H20: =Checklist!Y19 | I20: =Checklist!L19 | J20: =IF(H20="","",IF(Checklist!N19="","",Checklist!N19)) | K20: =Checklist!Z19 | AB20: '=IF(K87="",IF(H87<>"",IF(H87>=0.7,"Acceptable",IF('Std Checklist'!CA117=0,"Action Required","Not Acceptable")),""),IF(C114="Approved", "Acceptable","Not Acceptable"))
A21: 4 | B21: Design and development of products and services | C21: 7 | D21: 3 | F21: 4.1 | G21: =Checklist!X20 | H21: =Checklist!Y20 | I21: =Checklist!L20 | J21: =IF(H21="","",IF(Checklist!N20="","",Checklist!N20)) | K21: =Checklist!Z20 | L21: =IF(SUM(G21:G27)=0,"0",SUM(G21:G27)/($C21-(COUNTIF(G21:G27,"n/a")))) -> 0 | M21: =IF(SUM(H21:H27)=0,"0",SUM(H21:H27)/($C21-(COUNTIF(H21:H27,"n/a")))) -> 0 | N21: =IF(SUM(K21:K27)=0,"0",SUM(K21:K27)/($C21-(COUNTIF(K21:K27,"n/a")))) -> 0
F22: 4.2 | G22: =Checklist!X21 | H22: =Checklist!Y21 | I22: =Checklist!L21 | J22: =IF(H22="","",IF(Checklist!N21="","",Checklist!N21)) | K22: =Checklist!Z21 | AA22: M | AB22: 1.1 | AC22: =H8
F23: 4.3 | G23: =Checklist!X22 | H23: =Checklist!Y22 | I23: =Checklist!L22 | J23: =IF(H23="","",IF(Checklist!N22="","",Checklist!N22)) | K23: =Checklist!Z22 | AA23: M | AB23: 1.2 | AC23: =H9
F24: 4.4 | G24: =Checklist!X23 | H24: =Checklist!Y23 | I24: =Checklist!L23 | J24: =IF(H24="","",IF(Checklist!N23="","",Checklist!N23)) | K24: =Checklist!Z23 | AA24: M | AB24: 1.5 | AC24: =H12
E25: M | F25: 4.5 | G25: =Checklist!X24 | H25: =Checklist!Y24 | I25: =Checklist!L24 | J25: =IF(H25="","",IF(Checklist!N24="","",Checklist!N24)) | K25: =Checklist!Z24 | AA25: M | AB25: 2.3 | AC25: =H16
E26: M | F26: 4.6 | G26: =Checklist!X25 | H26: =Checklist!Y25 | I26: =Checklist!L25 | J26: =IF(H26="","",IF(Checklist!N25="","",Checklist!N25)) | K26: =Checklist!Z25 | AA26: M | AB26: 3.1 | AC26: =H18
E27: M | F27: 4.7 | G27: =Checklist!X26 | H27: =Checklist!Y26 | I27: =Checklist!L26 | J27: =IF(H27="","",IF(Checklist!N26="","",Checklist!N26)) | K27: =Checklist!Z26 | AA27: M | AB27: 4.5 | AC27: =H25
A28: 5 | B28: Quality Planning | C28: 3 | D28: 0 | F28: 5.1 | G28: =Checklist!X27 | H28: =Checklist!Y27 | I28: =Checklist!L27 | J28: =IF(H28="","",IF(Checklist!N27="","",Checklist!N27)) | K28: =Checklist!Z27 | L28: =IF(SUM(G28:G30)=0,"0",SUM(G28:G30)/($C28-(COUNTIF(G28:G30,"n/a")))) -> 0 | M28: =IF(SUM(H28:H30)=0,"0",SUM(H28:H30)/($C28-(COUNTIF(H28:H30,"n/a")))) -> 0 | N28: =IF(SUM(K28:K30)=0,"0",SUM(K28:K30)/($C28-(COUNTIF(K28:K30,"n/a")))) -> 0 | AA28: M | AB28: 4.6 | AC28: =H26
F29: 5.2 | G29: =Checklist!X28 | H29: =Checklist!Y28 | I29: =Checklist!L28 | J29: =IF(H29="","",IF(Checklist!N28="","",Checklist!N28)) | K29: =Checklist!Z28 | AA29: M | AB29: 4.7 | AC29: =H27
F30: 5.3 | G30: =Checklist!X29 | H30: =Checklist!Y29 | I30: =Checklist!L29 | J30: =IF(H30="","",IF(Checklist!N29="","",Checklist!N29)) | K30: =Checklist!Z29 | AA30: M | AB30: 6.2 | AC30: =H32
A31: 6 | B31: Procurement | C31: 5 | D31: 3 | F31: 6.1 | G31: =Checklist!X30 | H31: =Checklist!Y30 | I31: =Checklist!L30 | J31: =IF(H31="","",IF(Checklist!N30="","",Checklist!N30)) | K31: =Checklist!Z30 | L31: =IF(SUM(G31:G35)=0,"0",SUM(G31:G35)/($C31-(COUNTIF(G31:G35,"n/a")))) -> 0 | M31: =IF(SUM(H31:H35)=0,"0",SUM(H31:H35)/($C31-(COUNTIF(H31:H35,"n/a")))) -> 0 | N31: =IF(SUM(K31:K35)=0,"0",SUM(K31:K35)/($C31-(COUNTIF(K31:K35,"n/a")))) -> 0 | AA31: M | AB31: 6.3 | AC31: =H33
E32: M | F32: 6.2 | G32: =Checklist!X31 | H32: =Checklist!Y31 | I32: =Checklist!L31 | J32: =IF(H32="","",IF(Checklist!N31="","",Checklist!N31)) | K32: =Checklist!Z31 | AA32: M | AB32: 6.4 | AC32: =H34
E33: M | F33: 6.3 | G33: =Checklist!X32 | H33: =Checklist!Y32 | I33: =Checklist!L32 | J33: =IF(H33="","",IF(Checklist!N32="","",Checklist!N32)) | K33: =Checklist!Z32 | AA33: M | AB33: 7.1 | AC33: =H36
E34: M | F34: 6.4 | G34: =Checklist!X33 | H34: =Checklist!Y33 | I34: =Checklist!L33 | J34: =IF(H34="","",IF(Checklist!N33="","",Checklist!N33)) | K34: =Checklist!Z33 | AA34: M | AB34: 7.2 | AC34: =H37
F35: 6.5 | G35: =Checklist!X34 | H35: =Checklist!Y34 | I35: =Checklist!L34 | J35: =IF(H35="","",IF(Checklist!N34="","",Checklist!N34)) | K35: =Checklist!Z34 | AA35: M | AB35: 7.3 | AC35: =H38
A36: 7 | B36: Incoming Material | C36: 3 | D36: 3 | E36: M | F36: 7.1 | G36: =Checklist!X35 | H36: =Checklist!Y35 | I36: =Checklist!L35 | J36: =IF(H36="","",IF(Checklist!N35="","",Checklist!N35)) | K36: =Checklist!Z35 | L36: =IF(SUM(G36:G38)=0,"0",SUM(G36:G38)/($C36-(COUNTIF(G36:G38,"n/a")))) -> 0 | M36: =IF(SUM(H36:H38)=0,"0",SUM(H36:H38)/($C36-(COUNTIF(H36:H38,"n/a")))) -> 0 | N36: =IF(SUM(K36:K38)=0,"0",SUM(K36:K38)/($C36-(COUNTIF(K36:K38,"n/a")))) -> 0 | AA36: M | AB36: 8.2 | AC36: =H40
E37: M | F37: 7.2 | G37: =Checklist!X36 | H37: =Checklist!Y36 | I37: =Checklist!L36 | J37: =IF(H37="","",IF(Checklist!N36="","",Checklist!N36)) | K37: =Checklist!Z36 | AA37: M | AB37: 8.4 | AC37: =H42
E38: M | F38: 7.3 | G38: =Checklist!X37 | H38: =Checklist!Y37 | I38: =Checklist!L37 | J38: =IF(H38="","",IF(Checklist!N37="","",Checklist!N37)) | K38: =Checklist!Z37 | AA38: M | AB38: 8.5 | AC38: =H43
A39: 8 | B39: Manufacturing Quality | C39: 9 | D39: 3 | F39: 8.1 | G39: =Checklist!X38 | H39: =Checklist!Y38 | I39: =Checklist!L38 | J39: =IF(H39="","",IF(Checklist!N38="","",Checklist!N38)) | K39: =Checklist!Z38 | L39: =IF(SUM(G39:G47)=0,"0",SUM(G39:G47)/($C39-(COUNTIF(G39:G47,"n/a")))) -> 0 | M39: =IF(SUM(H39:H47)=0,"0",SUM(H39:H47)/($C39-(COUNTIF(H39:H47,"n/a")))) -> 0 | N39: =+IF(SUM(K39:K47)=0,"0",SUM(K39:K47)/($C39-(COUNTIF(K39:K47,"n/a")))) -> 0 | AA39: M | AB39: 9.1 | AC39: =H48
E40: M | F40: 8.2 | G40: =Checklist!X39 | H40: =Checklist!Y39 | I40: =Checklist!L39 | J40: =IF(H40="","",IF(Checklist!N39="","",Checklist!N39)) | K40: =Checklist!Z39 | AA40: M | AB40: 9.4 | AC40: =H51
...

Sheet Technical Assessment - Generic
D1: Supplier to complete light-green cells | E1: Vertiv to complete light-yellow cells | H1: =COUNTIF(H7:H13,100) -> 0 | I1: =COUNTIF(I7:I13,100) -> 0 | J1: =IF(SUM($H$1:$I$1)>=2,"Refer to VSAC Auditor Scoring Guide when using score of '100'.","") | N1: VSAC-Report-Template-2021 V1c | S1: Correct Row Order | W1: Hide >> | AA1: Supplier Self-Audit | AH1: Status | AI1: << Hide
W2: Hide >> | AA2: On-Site Audit | AB2: 0 | AC2: 40 | AD2: 60 | AE2: 70 | AF2: 80 | AG2: 100 | AH2: Open | AI2: << Hide
D3: Technical Assessment | E3: =IF('Supplier Profile & Audit Plan'!$A$6="","",'Supplier Profile & Audit Plan'!$A$6) -> Savannah Tank & Equipment Corp. | F3: Not Applicable | G3: Not Verified | H3: On-Site Audit SCORE | I3: After CA Verif. SCORE | J3: AUDIT FINDINGS & OBSERVATIONS | K3: Supplier CA Req'd? (Y / N) | L3: Completion Date (mm/dd/yyyy) | M3: CA Status | N3: ROOT CAUSE & Scope of Problem Including Other Areas | O3: REMEDIAL ACTION Immediate Actions Taken to Address Issue / Finding | P3: CORRECTIVE ACTION Taken to Address Root Cause & Prevent Recurrence | Q3: PREVENTIVE ACTION Actions Taken to Prevent Similar Issues in Other Areas | R3: CONTROLS Deployed to Monitor CA/PA Effectiveness | W3: Hide >> | X3: On-Site Score (w/o n/a's) | Y3: After Verif .Score (w/o n/a's) | AA3: Adjusted | AB3: 0 | AC3: 40 | AD3: 60 | AE3: 70 | AF3: 80 | AG3: 100 | AH3: Closed | AI3: << Hide
D4: =IF('Supplier Profile & Audit Plan'!$A$47>0,'Supplier Profile & Audit Plan'!$A$47,'Supplier Profile & Audit Plan'!$A$46) -> TBD | E4: =IF('Supplier Profile & Audit Plan'!$A$49="","",'Supplier Profile & Audit Plan'!$A$49) -> Sheet Metal & Enclosure | W4: Hide >> | AH4: <blank> | AI4: << Hide
D5: General Requirements | E5: Specific Requirements for Product Type | W5: Hide >> | AI5: << Hide
D6: Go to: Findings | E6: Go to: Corrective Actions | J6: Go to: Scoring Guidelines | N6: Go to: Corrective Action Instructions | W6: Hide >> | AI6: << Hide
A7: Bottom | B7: 1.0 PRODUCT / PROCESS KNOWLEDGE | C7: 1.1 | D7: Product Knowledge Supplier has adequate experience in design / development and manufacture of similar products | K7: =IF(H7="","",IF(F7<>"","",IF(H7>=70,"N","Y"))) | M7: =IF(H7="","",IF(H7>=70,"",IF(SUM(IF(H7>=70,1,-1)+IF(I7>=70,1,-1))>=0,"Closed","Open"))) | S7: 1 | W7: Hide >> | X7: =IF(COUNTA($F7,$G7)>0,"n/a",IF(H7="","",H7)) | Y7: =IF(COUNTA($F7,$G7)>0,"n/a",IF(I7="","",I7)) | AI7: << Hide
A8: 1 | C8: 1.2 | D8: Process Knowledge Expert understanding of typical requirements (e.g. performance, cosmetic, functional) and how to manufacture to meet requirements; understanding of key process parameters and how they are controlled. | E8: Adequate engineering resources to design or modify Vertiv products | S8: 2 | W8: Hide >> | X8: =IF(COUNTA($F8,$G8)>0,"n/a",IF(H8="","",H8)) | Y8: =IF(COUNTA($F8,$G8)>0,"n/a",IF(I8="","",I8)) | AI8: << Hide
A9: 2 | B9: 2.0 MANUFACTURING EQUIPMENT/TOOLS | C9: 2.1 | D9: Manufacturing Equipment Supplier has appropriate machines and tooling to manufacture product Supplier has adequate capacity including: 1) Equipment and tooling; 2) Manpower; 3) Floor space; 4) Adequate time for PM or unscheduled downtime; 5) Increased demand. | K9: =IF(H9="","",IF(F9<>"","",IF(H9>=70,"N","Y"))) | M9: =IF(H9="","",IF(H9>=70,"",IF(SUM(IF(H9>=70,1,-1)+IF(I9>=70,1,-1))>=0,"Closed","Open"))) | S9: 5 | W9: Hide >> | X9: =IF(COUNTA($F9,$G9)>0,"n/a",IF(H9="","",H9)) | Y9: =IF(COUNTA($F9,$G9)>0,"n/a",IF(I9="","",I9)) | AI9: << Hide
A10: 3 | C10: 2.2 | D10: Production Environment Supplier's factory environment is appropriate for manufacture of Vertiv product within specifications | E10: Presence of a clean room ESD equipment and program Temperature and humidity control | K10: =IF(H10="","",IF(F10<>"","",IF(H10>=70,"N","Y"))) | M10: =IF(H10="","",IF(H10>=70,"",IF(SUM(IF(H10>=70,1,-1)+IF(I10>=70,1,-1))>=0,"Closed","Open"))) | S10: 6 | X10: =IF(COUNTA($F10,$G10)>0,"n/a",IF(H10="","",H10)) | Y10: =IF(COUNTA($F10,$G10)>0,"n/a",IF(I10="","",I10))
A11: 4 | C11: 2.3 | D11: Testing Equipment/Capability Supplier has fixtures, measurement and testing equipment for Vertiv products | K11: =IF(H11="","",IF(F11<>"","",IF(H11>=70,"N","Y"))) | M11: =IF(H11="","",IF(H11>=70,"",IF(SUM(IF(H11>=70,1,-1)+IF(I11>=70,1,-1))>=0,"Closed","Open"))) | S11: 7 | W11: Hide >> | X11: =IF(COUNTA($F11,$G11)>0,"n/a",IF(H11="","",H11)) | Y11: =IF(COUNTA($F11,$G11)>0,"n/a",IF(I11="","",I11)) | AI11: << Hide
A12: Bottom | B12: 3.0 ABILITY TO MEET DRAWINGS & SPECIFICATIONS | C12: 3.1 | D12: Clear understanding of VERTIV's tolerances, specifications, agency requirements, functional and testing requirements. | E12: UL, IPC | K12: =IF(H12="","",IF(F12<>"","",IF(H12>=70,"N","Y"))) | M12: =IF(H12="","",IF(H12>=70,"",IF(SUM(IF(H12>=70,1,-1)+IF(I12>=70,1,-1))>=0,"Closed","Open"))) | S12: 9 | W12: Hide >> | X12: =IF(COUNTA($F12,$G12)>0,"n/a",IF(H12="","",H12)) | Y12: =IF(COUNTA($F12,$G12)>0,"n/a",IF(I12="","",I12)) | AI12: << Hide
A13: 1 | C13: 3.2 | D13: Proven ability to meet all requirements as demonstrated via compliance to either VERTIV or equivalent requirements by prototype part submissions, current production, etc | K13: =IF(H13="","",IF(F13<>"","",IF(H13>=70,"N","Y"))) | M13: =IF(H13="","",IF(H13>=70,"",IF(SUM(IF(H13>=70,1,-1)+IF(I13>=70,1,-1))>=0,"Closed","Open"))) | S13: 10 | W13: Hide >> | X13: =IF(COUNTA($F13,$G13)>0,"n/a",IF(H13="","",H13)) | Y13: =IF(COUNTA($F13,$G13)>0,"n/a",IF(I13="","",I13)) | AI13: << Hide
A14: 2 | B14: 4.0 ADDITIONAL REQUIREMENTS | C14: 4 | D14: XXX - This row is for Vertiv SQE to write down the additional requirements if there is any. Please place "x" in "Not Applicable" Cell F14 if there is no “additional requirement”. | K14: =IF(H14="","",IF(F14<>"","",IF(H14>=70,"N","Y"))) | M14: =IF(H14="","",IF(H14>=70,"",IF(SUM(IF(H14>=70,1,-1)+IF(I14>=70,1,-1))>=0,"Closed","Open"))) | S14: 11 | X14: =IF(COUNTA($F14,$G14)>0,"n/a",IF(H14="","",H14)) | Y14: =IF(COUNTA($F14,$G14)>0,"n/a",IF(I14="","",I14))
A15: . | S15: .
D16: TOTAL SCORES FOR THIS CHECKLIST ONLY | F16: Not Applicable | G16: Not Verified | H16: On-Site Audit Std Chklst SCORE | I16: After CAPA Verif. Std Chklst SCORE | K16: On-Site Audit Findings | AJ16: Pass
D17: Sum of Scores (excluding "n/a" & "Not Verified"): | H17: =SUM($X$7:$X$14) -> 0 | I17: =SUM($Y$7:$Y$14) -> 0 | K17: Corrective Action plans will be submitted on (date): | AJ17: Fail
E18: Maximum Total Score Available: | F18: =COUNTA(F7:F14) -> 0 | G18: =COUNTA(G7:G14) -> 0 | H18: =(COUNTA($D$7:$D$14)-($F18+$G18))*100 -> 800 | I18: =(COUNTA($D$7:$D$14)-($F18+$G18))*100 -> 800 | K18: Vertiv Audit Leader (name & title):
E19: Standard Checklist Score: | H19: =(H17/H18) -> 0 | I19: =(I17/I18) -> 0 | K19: Supplier QA Representative (name & title):
D20: Date: | F20: =IF('Supplier Profile & Audit Plan'!$A$47="","",'Supplier Profile & Audit Plan'!$A$47) -> TBD | K20: CA-PA Verification & Finding Closure Date:
K21: =COUNTIF(K7:K14,"Y") -> 0 | M21: =COUNTIF(M7:M14,"Open") -> 0
G22: Summary and Conclusion:
D24: Vertiv auditor to use scoring instructions below when assigning On-Site Audit Score. | R24: Top
D25: Scoring Instructions for Vertiv On-Site Audit
D26: Based on On-Site audit evidence, select score that best describes level of compliance to the Requirement. If Requirement does not apply to product to be purchased, place "x" in the "Not Applicable" column.
D27: 0 = NO EVIDENCE PROVIDED; Corrective action required
D28: 40 = RARELY COMPLIES; Corrective action required
D29: 60 = SOME NON-COMPLIANCES; Corrective action required
D30: 70 = NO NON-COMPLIANCES; Meets Minimum Requirement / No CA required
D31: 80 = NO NON-COMPLIANCES; Exceeds Minimum Requirement / No CA required
D32: 100 = NO NON-COMPLIANCES; Excellent / Highly commendable
D33: Supplier Corrective Action plan
D34: Supplier must record their corrective and preventive actions that will address each Finding. This is typed in the columns to the right of Findings on the Standard Checklist.
D35: Supplier Corrective Action & Preventive Action (CAPA) plan must address:
D36: Root Cause of the problem; should look beyond specific incident cited in Finding
... D38: Corrective Action; actions to address root cause and prevent recurrence
D39: Preventive Action; actions to prevent the occurrence of similar problems in other areas | N39: `
D40: Controls; controls & self-monitoring steps to ensure continued CA/PA effectiveness
D41: Supplier to return the completed VSAC Workbook to the Vertiv auditor by the date agreed upon.
D42: Supplier to provide documented objective evidence that each CAPA has been implemented by the completion date specified.
...
