Workbook
Name Dates: #REF!
Name Dates: #REF!
Name Dates: 'Actual Dates'!$A$4:$AE$156
Name Jobs: #REF!
Name Jobs: #REF!
Name Jobs: 'Date Calcs'!$A$5:$AG$133
Name Ship: 'Ship Date'!$A$5:$AE$138

Sheet Drawing Submittal
A1: Drawing Submittal
F2: On Track
F3: At Risk
F4: Late | I4: No Y | J4: No Y
A5: Job # | B5: Customer | C5: Rev. | D5: Target | E5: Actual | F5: Days +/- | G5: Status | I5: Submitted | J5: Approved | S5: 0 | T5: 1 | U5: 2 | V5: 3 | W5: 4
A6: ='Actual Dates'!A4 -> 24-046 | B6: =_xlfn.IFNA(VLOOKUP(A6,'Date Calcs'!A:B,2,),"") -> SYMS Engineering | C6: =VLOOKUP(A6,'Actual Dates'!A:AE,18,) -> 4 | D6: =Z6 -> 45533 | E6: =IF(VLOOKUP(A6,Dates,20,FALSE())="",TODAY(),VLOOKUP(A6,Dates,20,FALSE())) -> 45883 | F6: =IFERROR(ROUND(IF(A6="","",IF(E6=0,D6-Date!$B$3,D6-E6)),0),"") -> -350 | G6: =_xlfn.IFNA(VLOOKUP(A6,'RTR v2'!A:AW,48,FALSE)," ") | I6: =IF(VLOOKUP(A6,Dates,2,)="N","N",IF(VLOOKUP(A6,Dates,3,)="N","N",IF(VLOOKUP(A6,Dates,4,)="N","N",IF(VLOOKUP(A6,Dates,5,)="N","N","Y")))) -> Y | J6: =VLOOKUP(A6,Dates,7,) -> y | M6: =IF(N6="Y",N6," ") | O6: =IF(P6<1,0,IF(VLOOKUP($A6,'Actual Dates'!$A:$G,5,0)="Y",1,0)) -> 1 | P6: =IF(Q6<1,0,IF(VLOOKUP($A6,'Actual Dates'!$A:$G,4,0)="Y",1,0)) -> 1 | Q6: =IF(R6<1,0,IF(VLOOKUP($A6,'Actual Dates'!$A:$G,3,0)="Y",1,0)) -> 1 | R6: =IF(VLOOKUP($A6,'Actual Dates'!$A:$G,2,0)="Y",1,0) -> 1 | S6: =_xlfn.IFNA(+VLOOKUP(A6,'Date Calcs'!A:AG,8,),TODAY()) -> 45540 | T6: =_xlfn.IFNA(VLOOKUP(A6,'Date Calcs'!A:AG,10,),TODAY()) -> 45789 | U6: =_xlfn.IFNA(+VLOOKUP(A6,'Date Calcs'!A:AG,12,),TODAY()) -> 45853 | V6: =_xlfn.IFNA(+VLOOKUP(A6,'Date Calcs'!A:AG,14,),TODAY()) -> 45875 | W6: =_xlfn.IFNA(+VLOOKUP(A6,'Date Calcs'!A:AG,16,),TODAY()) -> 45533 | X6: =_xlfn.IFNA(IF(C6=0,VLOOKUP(A6,'Date Calcs'!A:AG,8,),IF(C6=1,VLOOKUP(A6,'Date Calcs'!A:AG,10,),IF(C6=2,VLOOKUP(A6,'Date Calcs'!A:AG,12,),IF(C6=3,VLOOKUP(A6,'Date Calcs'!A:AG,14,),4)))),TODAY()) -> 4 | Y6: =_xlfn.IFNA(IF(X6=4,W6,X6),TODAY()) -> 45533 | Z6: =_xlfn.IFNA(Y6+(VLOOKUP(A6,'Date Calcs'!A:W,22,0)*7),TODAY()) -> 45533
A7: ='Actual Dates'!A5 -> 25-010 | B7: =_xlfn.IFNA(VLOOKUP(A7,'Date Calcs'!A:B,2,),"") -> Kimberly Clark | C7: =VLOOKUP(A7,'Actual Dates'!A:AE,18,) -> 3 | D7: =Z7 -> 45911 | E7: =IF(VLOOKUP(A7,Dates,20,FALSE())="",TODAY(),VLOOKUP(A7,Dates,20,FALSE())) -> 45897 | F7: =IFERROR(ROUND(IF(A7="","",IF(E7=0,D7-Date!$B$3,D7-E7)),0),"") -> 14 | G7: =_xlfn.IFNA(VLOOKUP(A7,'RTR v2'!A:AW,48,FALSE)," ") -> 46076 | I7: =IF(VLOOKUP(A7,Dates,2,)="N","N",IF(VLOOKUP(A7,Dates,3,)="N","N",IF(VLOOKUP(A7,Dates,4,)="N","N",IF(VLOOKUP(A7,Dates,5,)="N","N","Y")))) -> Y | J7: =VLOOKUP(A7,Dates,7,) -> y | M7: =IF(N7="Y",N7," ") | N7: =IF(R7="Y",R7,IF(Q7="Y",Q7,IF(P7="Y",P7,O7))) -> 1 | O7: =IF(P7<1,0,IF(VLOOKUP($A7,'Actual Dates'!$A:$G,5,0)="Y",1,0)) -> 1 | P7: =IF(Q7<1,0,IF(VLOOKUP($A7,'Actual Dates'!$A:$G,4,0)="Y",1,0)) -> 1 | Q7: =IF(R7<1,0,IF(VLOOKUP($A7,'Actual Dates'!$A:$G,3,0)="Y",1,0)) -> 1 | R7: =IF(VLOOKUP($A7,'Actual Dates'!$A:$G,2,0)="Y",1,0) -> 1 | S7: =_xlfn.IFNA(+VLOOKUP(A7,'Date Calcs'!A:AG,8,),TODAY()) -> 45720 | T7: =_xlfn.IFNA(VLOOKUP(A7,'Date Calcs'!A:AG,10,),TODAY()) -> 45841 | U7: =_xlfn.IFNA(+VLOOKUP(A7,'Date Calcs'!A:AG,12,),TODAY()) -> 45897 | V7: =_xlfn.IFNA(+VLOOKUP(A7,'Date Calcs'!A:AG,14,),TODAY()) -> 45911 | W7: =_xlfn.IFNA(+VLOOKUP(A7,'Date Calcs'!A:AG,16,),TODAY()) -> 45699 | X7: =_xlfn.IFNA(IF(C7=0,VLOOKUP(A7,'Date Calcs'!A:AG,8,),IF(C7=1,VLOOKUP(A7,'Date Calcs'!A:AG,10,),IF(C7=2,VLOOKUP(A7,'Date Calcs'!A:AG,12,),IF(C7=3,VLOOKUP(A7,'Date Calcs'!A:AG,14,),4)))),TODAY()) -> 45911 | Y7: =_xlfn.IFNA(IF(X7=4,W7,X7),TODAY()) -> 45911 | Z7: =_xlfn.IFNA(Y7+(VLOOKUP(A7,'Date Calcs'!A:W,22,0)*7),TODAY()) -> 45911 | AA7: =_xlfn.IFNA(VLOOKUP(A7,'RTR v2'!$A:$AW,46,0),"") -> 0
A8: ='Actual Dates'!A6 -> 25-011 | B8: =_xlfn.IFNA(VLOOKUP(A8,'Date Calcs'!A:B,2,),"") -> Kimberly Clark | C8: =VLOOKUP(A8,'Actual Dates'!A:AE,18,) -> 3 | D8: =Z8 -> 45918 | E8: =IF(VLOOKUP(A8,Dates,20,FALSE())="",TODAY(),VLOOKUP(A8,Dates,20,FALSE())) -> 45904 | F8: =IFERROR(ROUND(IF(A8="","",IF(E8=0,D8-Date!$B$3,D8-E8)),0),"") -> 14 | G8: =_xlfn.IFNA(VLOOKUP(A8,'RTR v2'!A:AW,48,FALSE)," ") -> 46057 | I8: =IF(VLOOKUP(A8,Dates,2,)="N","N",IF(VLOOKUP(A8,Dates,3,)="N","N",IF(VLOOKUP(A8,Dates,4,)="N","N",IF(VLOOKUP(A8,Dates,5,)="N","N","Y")))) -> Y | J8: =VLOOKUP(A8,Dates,7,) -> y | M8: =IF(N8="Y",N8," ") | N8: =IF(R8="Y",R8,IF(Q8="Y",Q8,IF(P8="Y",P8,O8))) -> 1 | O8: =IF(P8<1,0,IF(VLOOKUP($A8,'Actual Dates'!$A:$G,5,0)="Y",1,0)) -> 1 | P8: =IF(Q8<1,0,IF(VLOOKUP($A8,'Actual Dates'!$A:$G,4,0)="Y",1,0)) -> 1 | Q8: =IF(R8<1,0,IF(VLOOKUP($A8,'Actual Dates'!$A:$G,3,0)="Y",1,0)) -> 1 | R8: =IF(VLOOKUP($A8,'Actual Dates'!$A:$G,2,0)="Y",1,0) -> 1 | S8: =_xlfn.IFNA(+VLOOKUP(A8,'Date Calcs'!A:AG,8,),TODAY()) -> 45720 | T8: =_xlfn.IFNA(VLOOKUP(A8,'Date Calcs'!A:AG,10,),TODAY()) -> 45813 | U8: =_xlfn.IFNA(+VLOOKUP(A8,'Date Calcs'!A:AG,12,),TODAY()) -> 45904 | V8: =_xlfn.IFNA(+VLOOKUP(A8,'Date Calcs'!A:AG,14,),TODAY()) -> 45918 | W8: =_xlfn.IFNA(+VLOOKUP(A8,'Date Calcs'!A:AG,16,),TODAY()) -> 45699 | X8: =_xlfn.IFNA(IF(C8=0,VLOOKUP(A8,'Date Calcs'!A:AG,8,),IF(C8=1,VLOOKUP(A8,'Date Calcs'!A:AG,10,),IF(C8=2,VLOOKUP(A8,'Date Calcs'!A:AG,12,),IF(C8=3,VLOOKUP(A8,'Date Calcs'!A:AG,14,),4)))),TODAY()) -> 45918 | Y8: =_xlfn.IFNA(IF(X8=4,W8,X8),TODAY()) -> 45918 | Z8: =_xlfn.IFNA(Y8+(VLOOKUP(A8,'Date Calcs'!A:W,22,0)*7),TODAY()) -> 45918 | AA8: =_xlfn.IFNA(VLOOKUP(A8,'RTR v2'!$A:$AW,46,0),"") -> 0
A9: ='Actual Dates'!A7 -> 25-012 | B9: =_xlfn.IFNA(VLOOKUP(A9,'Date Calcs'!A:B,2,),"") -> Kimberly Clark | C9: =VLOOKUP(A9,'Actual Dates'!A:AE,18,) -> 3 | D9: =Z9 -> 45918 | E9: =IF(VLOOKUP(A9,Dates,20,FALSE())="",TODAY(),VLOOKUP(A9,Dates,20,FALSE())) -> 45904 | F9: =IFERROR(ROUND(IF(A9="","",IF(E9=0,D9-Date!$B$3,D9-E9)),0),"") -> 14 | G9: =_xlfn.IFNA(VLOOKUP(A9,'RTR v2'!A:AW,48,FALSE)," ") -> 46111 | I9: =IF(VLOOKUP(A9,Dates,2,)="N","N",IF(VLOOKUP(A9,Dates,3,)="N","N",IF(VLOOKUP(A9,Dates,4,)="N","N",IF(VLOOKUP(A9,Dates,5,)="N","N","Y")))) -> Y | J9: =VLOOKUP(A9,Dates,7,) -> y | M9: =IF(N9="Y",N9," ") | N9: =IF(R9="Y",R9,IF(Q9="Y",Q9,IF(P9="Y",P9,O9))) -> 1 | O9: =IF(P9<1,0,IF(VLOOKUP($A9,'Actual Dates'!$A:$G,5,0)="Y",1,0)) -> 1 | P9: =IF(Q9<1,0,IF(VLOOKUP($A9,'Actual Dates'!$A:$G,4,0)="Y",1,0)) -> 1 | Q9: =IF(R9<1,0,IF(VLOOKUP($A9,'Actual Dates'!$A:$G,3,0)="Y",1,0)) -> 1 | R9: =IF(VLOOKUP($A9,'Actual Dates'!$A:$G,2,0)="Y",1,0) -> 1 | S9: =_xlfn.IFNA(+VLOOKUP(A9,'Date Calcs'!A:AG,8,),TODAY()) -> 45720 | T9: =_xlfn.IFNA(VLOOKUP(A9,'Date Calcs'!A:AG,10,),TODAY()) -> 45813 | U9: =_xlfn.IFNA(+VLOOKUP(A9,'Date Calcs'!A:AG,12,),TODAY()) -> 45904 | V9: =_xlfn.IFNA(+VLOOKUP(A9,'Date Calcs'!A:AG,14,),TODAY()) -> 45918 | W9: =_xlfn.IFNA(+VLOOKUP(A9,'Date Calcs'!A:AG,16,),TODAY()) -> 45699 | X9: =_xlfn.IFNA(IF(C9=0,VLOOKUP(A9,'Date Calcs'!A:AG,8,),IF(C9=1,VLOOKUP(A9,'Date Calcs'!A:AG,10,),IF(C9=2,VLOOKUP(A9,'Date Calcs'!A:AG,12,),IF(C9=3,VLOOKUP(A9,'Date Calcs'!A:AG,14,),4)))),TODAY()) -> 45918 | Y9: =_xlfn.IFNA(IF(X9=4,W9,X9),TODAY()) -> 45918 | Z9: =_xlfn.IFNA(Y9+(VLOOKUP(A9,'Date Calcs'!A:W,22,0)*7),TODAY()) -> 45918 | AA9: =_xlfn.IFNA(VLOOKUP(A9,'RTR v2'!$A:$AW,46,0),"")
A10: ='Actual Dates'!A8 -> 25-013 | B10: =_xlfn.IFNA(VLOOKUP(A10,'Date Calcs'!A:B,2,),"") -> Kimberly Clark | C10: =VLOOKUP(A10,'Actual Dates'!A:AE,18,) -> 2 | D10: =Z10 -> 45826 | E10: =IF(VLOOKUP(A10,Dates,20,FALSE())="",TODAY(),VLOOKUP(A10,Dates,20,FALSE())) -> 45904 | F10: =IFERROR(ROUND(IF(A10="","",IF(E10=0,D10-Date!$B$3,D10-E10)),0),"") -> -78 | G10: =_xlfn.IFNA(VLOOKUP(A10,'RTR v2'!A:AW,48,FALSE)," ") -> 46111 | I10: =IF(VLOOKUP(A10,Dates,2,)="N","N",IF(VLOOKUP(A10,Dates,3,)="N","N",IF(VLOOKUP(A10,Dates,4,)="N","N",IF(VLOOKUP(A10,Dates,5,)="N","N","Y")))) -> Y | J10: =VLOOKUP(A10,Dates,7,) -> y | M10: =IF(N10="Y",N10," ") | N10: =IF(R10="Y",R10,IF(Q10="Y",Q10,IF(P10="Y",P10,O10))) -> 1 | O10: =IF(P10<1,0,IF(VLOOKUP($A10,'Actual Dates'!$A:$G,5,0)="Y",1,0)) -> 1 | P10: =IF(Q10<1,0,IF(VLOOKUP($A10,'Actual Dates'!$A:$G,4,0)="Y",1,0)) -> 1 | Q10: =IF(R10<1,0,IF(VLOOKUP($A10,'Actual Dates'!$A:$G,3,0)="Y",1,0)) -> 1 | R10: =IF(VLOOKUP($A10,'Actual Dates'!$A:$G,2,0)="Y",1,0) -> 1 | S10: =_xlfn.IFNA(+VLOOKUP(A10,'Date Calcs'!A:AG,8,),TODAY()) -> 45720 | T10: =_xlfn.IFNA(VLOOKUP(A10,'Date Calcs'!A:AG,10,),TODAY()) -> 45813 | U10: =_xlfn.IFNA(+VLOOKUP(A10,'Date Calcs'!A:AG,12,),TODAY()) -> 45826 | V10: =_xlfn.IFNA(+VLOOKUP(A10,'Date Calcs'!A:AG,14,),TODAY()) -> 45840 | W10: =_xlfn.IFNA(+VLOOKUP(A10,'Date Calcs'!A:AG,16,),TODAY()) -> 45699 | X10: =_xlfn.IFNA(IF(C10=0,VLOOKUP(A10,'Date Calcs'!A:AG,8,),IF(C10=1,VLOOKUP(A10,'Date Calcs'!A:AG,10,),IF(C10=2,VLOOKUP(A10,'Date Calcs'!A:AG,12,),IF(C10=3,VLOOKUP(A10,'Date Calcs'!A:AG,14,),4)))),TODAY()) -> 45826 | Y10: =_xlfn.IFNA(IF(X10=4,W10,X10),TODAY()) -> 45826 | Z10: =_xlfn.IFNA(Y10+(VLOOKUP(A10,'Date Calcs'!A:W,22,0)*7),TODAY()) -> 45826 | AA10: =_xlfn.IFNA(VLOOKUP(A10,'RTR v2'!$A:$AW,46,0),"")
A11: ='Actual Dates'!A9 -> 25-014 | B11: =_xlfn.IFNA(VLOOKUP(A11,'Date Calcs'!A:B,2,),"") -> Kimberly Clark | C11: =VLOOKUP(A11,'Actual Dates'!A:AE,18,) -> 2 | D11: =Z11 -> 45819 | E11: =IF(VLOOKUP(A11,Dates,20,FALSE())="",TODAY(),VLOOKUP(A11,Dates,20,FALSE())) -> 45805 | F11: =IFERROR(ROUND(IF(A11="","",IF(E11=0,D11-Date!$B$3,D11-E11)),0),"") -> 14 | G11: =_xlfn.IFNA(VLOOKUP(A11,'RTR v2'!A:AW,48,FALSE)," ") -> 45967 | I11: =IF(VLOOKUP(A11,Dates,2,)="N","N",IF(VLOOKUP(A11,Dates,3,)="N","N",IF(VLOOKUP(A11,Dates,4,)="N","N",IF(VLOOKUP(A11,Dates,5,)="N","N","Y")))) -> Y | J11: =VLOOKUP(A11,Dates,7,) -> y | M11: =IF(N11="Y",N11," ") | N11: =IF(R11="Y",R11,IF(Q11="Y",Q11,IF(P11="Y",P11,O11))) -> 1 | O11: =IF(P11<1,0,IF(VLOOKUP($A11,'Actual Dates'!$A:$G,5,0)="Y",1,0)) -> 1 | P11: =IF(Q11<1,0,IF(VLOOKUP($A11,'Actual Dates'!$A:$G,4,0)="Y",1,0)) -> 1 | Q11: =IF(R11<1,0,IF(VLOOKUP($A11,'Actual Dates'!$A:$G,3,0)="Y",1,0)) -> 1 | R11: =IF(VLOOKUP($A11,'Actual Dates'!$A:$G,2,0)="Y",1,0) -> 1 | S11: =_xlfn.IFNA(+VLOOKUP(A11,'Date Calcs'!A:AG,8,),TODAY()) -> 45720 | T11: =_xlfn.IFNA(VLOOKUP(A11,'Date Calcs'!A:AG,10,),TODAY()) -> 45798 | U11: =_xlfn.IFNA(+VLOOKUP(A11,'Date Calcs'!A:AG,12,),TODAY()) -> 45819 | V11: =_xlfn.IFNA(+VLOOKUP(A11,'Date Calcs'!A:AG,14,),TODAY()) -> 45833 | W11: =_xlfn.IFNA(+VLOOKUP(A11,'Date Calcs'!A:AG,16,),TODAY()) -> 45699 | X11: =_xlfn.IFNA(IF(C11=0,VLOOKUP(A11,'Date Calcs'!A:AG,8,),IF(C11=1,VLOOKUP(A11,'Date Calcs'!A:AG,10,),IF(C11=2,VLOOKUP(A11,'Date Calcs'!A:AG,12,),IF(C11=3,VLOOKUP(A11,'Date Calcs'!A:AG,14,),4)))),TODAY()) -> 45819 | Y11: =_xlfn.IFNA(IF(X11=4,W11,X11),TODAY()) -> 45819 | Z11: =_xlfn.IFNA(Y11+(VLOOKUP(A11,'Date Calcs'!A:W,22,0)*7),TODAY()) -> 45819 | AA11: =_xlfn.IFNA(VLOOKUP(A11,'RTR v2'!$A:$AW,46,0),"") -> 0
A12: ='Actual Dates'!A10 -> 25-015 | B12: =_xlfn.IFNA(VLOOKUP(A12,'Date Calcs'!A:B,2,),"") -> Kimberly Clark | C12: =VLOOKUP(A12,'Actual Dates'!A:AE,18,) -> 2 | D12: =Z12 -> 45819 | E12: =IF(VLOOKUP(A12,Dates,20,FALSE())="",TODAY(),VLOOKUP(A12,Dates,20,FALSE())) -> 45805 | F12: =IFERROR(ROUND(IF(A12="","",IF(E12=0,D12-Date!$B$3,D12-E12)),0),"") -> 14 | G12: =_xlfn.IFNA(VLOOKUP(A12,'RTR v2'!A:AW,48,FALSE)," ") -> 45967 | I12: =IF(VLOOKUP(A12,Dates,2,)="N","N",IF(VLOOKUP(A12,Dates,3,)="N","N",IF(VLOOKUP(A12,Dates,4,)="N","N",IF(VLOOKUP(A12,Dates,5,)="N","N","Y")))) -> Y | J12: =VLOOKUP(A12,Dates,7,) -> y | M12: =IF(N12="Y",N12," ") | N12: =IF(R12="Y",R12,IF(Q12="Y",Q12,IF(P12="Y",P12,O12))) -> 1 | O12: =IF(P12<1,0,IF(VLOOKUP($A12,'Actual Dates'!$A:$G,5,0)="Y",1,0)) -> 1 | P12: =IF(Q12<1,0,IF(VLOOKUP($A12,'Actual Dates'!$A:$G,4,0)="Y",1,0)) -> 1 | Q12: =IF(R12<1,0,IF(VLOOKUP($A12,'Actual Dates'!$A:$G,3,0)="Y",1,0)) -> 1 | R12: =IF(VLOOKUP($A12,'Actual Dates'!$A:$G,2,0)="Y",1,0) -> 1 | S12: =_xlfn.IFNA(+VLOOKUP(A12,'Date Calcs'!A:AG,8,),TODAY()) -> 45720 | T12: =_xlfn.IFNA(VLOOKUP(A12,'Date Calcs'!A:AG,10,),TODAY()) -> 45798 | U12: =_xlfn.IFNA(+VLOOKUP(A12,'Date Calcs'!A:AG,12,),TODAY()) -> 45819 | V12: =_xlfn.IFNA(+VLOOKUP(A12,'Date Calcs'!A:AG,14,),TODAY()) -> 45833 | W12: =_xlfn.IFNA(+VLOOKUP(A12,'Date Calcs'!A:AG,16,),TODAY()) -> 45699 | X12: =_xlfn.IFNA(IF(C12=0,VLOOKUP(A12,'Date Calcs'!A:AG,8,),IF(C12=1,VLOOKUP(A12,'Date Calcs'!A:AG,10,),IF(C12=2,VLOOKUP(A12,'Date Calcs'!A:AG,12,),IF(C12=3,VLOOKUP(A12,'Date Calcs'!A:AG,14,),4)))),TODAY()) -> 45819 | Y12: =_xlfn.IFNA(IF(X12=4,W12,X12),TODAY()) -> 45819 | Z12: =_xlfn.IFNA(Y12+(VLOOKUP(A12,'Date Calcs'!A:W,22,0)*7),TODAY()) -> 45819 | AA12: =_xlfn.IFNA(VLOOKUP(A12,'RTR v2'!$A:$AW,46,0),"") -> 0
A13: ='Actual Dates'!A11 -> 25-016 | B13: =_xlfn.IFNA(VLOOKUP(A13,'Date Calcs'!A:B,2,),"") -> Kimberly Clark | C13: =VLOOKUP(A13,'Actual Dates'!A:AE,18,) -> 2 | D13: =Z13 -> 45819 | E13: =IF(VLOOKUP(A13,Dates,20,FALSE())="",TODAY(),VLOOKUP(A13,Dates,20,FALSE())) -> 45805 | F13: =IFERROR(ROUND(IF(A13="","",IF(E13=0,D13-Date!$B$3,D13-E13)),0),"") -> 14 | G13: =_xlfn.IFNA(VLOOKUP(A13,'RTR v2'!A:AW,48,FALSE)," ") -> 46076 | I13: =IF(VLOOKUP(A13,Dates,2,)="N","N",IF(VLOOKUP(A13,Dates,3,)="N","N",IF(VLOOKUP(A13,Dates,4,)="N","N",IF(VLOOKUP(A13,Dates,5,)="N","N","Y")))) -> Y | J13: =VLOOKUP(A13,Dates,7,) -> y | M13: =IF(N13="Y",N13," ") | N13: =IF(R13="Y",R13,IF(Q13="Y",Q13,IF(P13="Y",P13,O13))) -> 1 | O13: =IF(P13<1,0,IF(VLOOKUP($A13,'Actual Dates'!$A:$G,5,0)="Y",1,0)) -> 1 | P13: =IF(Q13<1,0,IF(VLOOKUP($A13,'Actual Dates'!$A:$G,4,0)="Y",1,0)) -> 1 | Q13: =IF(R13<1,0,IF(VLOOKUP($A13,'Actual Dates'!$A:$G,3,0)="Y",1,0)) -> 1 | R13: =IF(VLOOKUP($A13,'Actual Dates'!$A:$G,2,0)="Y",1,0) -> 1 | S13: =_xlfn.IFNA(+VLOOKUP(A13,'Date Calcs'!A:AG,8,),TODAY()) -> 45720 | T13: =_xlfn.IFNA(VLOOKUP(A13,'Date Calcs'!A:AG,10,),TODAY()) -> 45798 | U13: =_xlfn.IFNA(+VLOOKUP(A13,'Date Calcs'!A:AG,12,),TODAY()) -> 45819 | V13: =_xlfn.IFNA(+VLOOKUP(A13,'Date Calcs'!A:AG,14,),TODAY()) -> 45833 | W13: =_xlfn.IFNA(+VLOOKUP(A13,'Date Calcs'!A:AG,16,),TODAY()) -> 45699 | X13: =_xlfn.IFNA(IF(C13=0,VLOOKUP(A13,'Date Calcs'!A:AG,8,),IF(C13=1,VLOOKUP(A13,'Date Calcs'!A:AG,10,),IF(C13=2,VLOOKUP(A13,'Date Calcs'!A:AG,12,),IF(C13=3,VLOOKUP(A13,'Date Calcs'!A:AG,14,),4)))),TODAY()) -> 45819 | Y13: =_xlfn.IFNA(IF(X13=4,W13,X13),TODAY()) -> 45819 | Z13: =_xlfn.IFNA(Y13+(VLOOKUP(A13,'Date Calcs'!A:W,22,0)*7),TODAY()) -> 45819 | AA13: =_xlfn.IFNA(VLOOKUP(A13,'RTR v2'!$A:$AW,46,0),"") -> 0
A14: ='Actual Dates'!A12 -> 25-017 | B14: =_xlfn.IFNA(VLOOKUP(A14,'Date Calcs'!A:B,2,),"") -> Kimberly Clark | C14: =VLOOKUP(A14,'Actual Dates'!A:AE,18,) -> 2 | D14: =Z14 -> 45783 | E14: =IF(VLOOKUP(A14,Dates,20,FALSE())="",TODAY(),VLOOKUP(A14,Dates,20,FALSE())) -> 45769 | F14: =IFERROR(ROUND(IF(A14="","",IF(E14=0,D14-Date!$B$3,D14-E14)),0),"") -> 14 | G14: =_xlfn.IFNA(VLOOKUP(A14,'RTR v2'!A:AW,48,FALSE)," ") -> 46043 | I14: =IF(VLOOKUP(A14,Dates,2,)="N","N",IF(VLOOKUP(A14,Dates,3,)="N","N",IF(VLOOKUP(A14,Dates,4,)="N","N",IF(VLOOKUP(A14,Dates,5,)="N","N","Y")))) -> Y | J14: =VLOOKUP(A14,Dates,7,) -> y | M14: =IF(N14="Y",N14," ") | N14: =IF(R14="Y",R14,IF(Q14="Y",Q14,IF(P14="Y",P14,O14))) -> 1 | O14: =IF(P14<1,0,IF(VLOOKUP($A14,'Actual Dates'!$A:$G,5,0)="Y",1,0)) -> 1 | P14: =IF(Q14<1,0,IF(VLOOKUP($A14,'Actual Dates'!$A:$G,4,0)="Y",1,0)) -> 1 | Q14: =IF(R14<1,0,IF(VLOOKUP($A14,'Actual Dates'!$A:$G,3,0)="Y",1,0)) -> 1 | R14: =IF(VLOOKUP($A14,'Actual Dates'!$A:$G,2,0)="Y",1,0) -> 1 | S14: =_xlfn.IFNA(+VLOOKUP(A14,'Date Calcs'!A:AG,8,),TODAY()) -> 45720 | T14: =_xlfn.IFNA(VLOOKUP(A14,'Date Calcs'!A:AG,10,),TODAY()) -> 45761 | U14: =_xlfn.IFNA(+VLOOKUP(A14,'Date Calcs'!A:AG,12,),TODAY()) -> 45783 | V14: =_xlfn.IFNA(+VLOOKUP(A14,'Date Calcs'!A:AG,14,),TODAY()) -> 45797 | W14: =_xlfn.IFNA(+VLOOKUP(A14,'Date Calcs'!A:AG,16,),TODAY()) -> 45699 | X14: =_xlfn.IFNA(IF(C14=0,VLOOKUP(A14,'Date Calcs'!A:AG,8,),IF(C14=1,VLOOKUP(A14,'Date Calcs'!A:AG,10,),IF(C14=2,VLOOKUP(A14,'Date Calcs'!A:AG,12,),IF(C14=3,VLOOKUP(A14,'Date Calcs'!A:AG,14,),4)))),TODAY()) -> 45783 | Y14: =_xlfn.IFNA(IF(X14=4,W14,X14),TODAY()) -> 45783 | Z14: =_xlfn.IFNA(Y14+(VLOOKUP(A14,'Date Calcs'!A:W,22,0)*7),TODAY()) -> 45783 | AA14: =_xlfn.IFNA(VLOOKUP(A14,'RTR v2'!$A:$AW,46,0),"") -> 0
A15: ='Actual Dates'!A13 -> 25-018 | B15: =_xlfn.IFNA(VLOOKUP(A15,'Date Calcs'!A:B,2,),"") -> Kimberly Clark | C15: =VLOOKUP(A15,'Actual Dates'!A:AE,18,) -> 3 | D15: =Z15 -> 45919 | E15: =IF(VLOOKUP(A15,Dates,20,FALSE())="",TODAY(),VLOOKUP(A15,Dates,20,FALSE())) -> 45905 | F15: =IFERROR(ROUND(IF(A15="","",IF(E15=0,D15-Date!$B$3,D15-E15)),0),"") -> 14 | G15: =_xlfn.IFNA(VLOOKUP(A15,'RTR v2'!A:AW,48,FALSE)," ") -> 46097 | I15: =IF(VLOOKUP(A15,Dates,2,)="N","N",IF(VLOOKUP(A15,Dates,3,)="N","N",IF(VLOOKUP(A15,Dates,4,)="N","N",IF(VLOOKUP(A15,Dates,5,)="N","N","Y")))) -> Y | J15: =VLOOKUP(A15,Dates,7,) -> y | M15: =IF(N15="Y",N15," ") | N15: =IF(R15="Y",R15,IF(Q15="Y",Q15,IF(P15="Y",P15,O15))) -> 1 | O15: =IF(P15<1,0,IF(VLOOKUP($A15,'Actual Dates'!$A:$G,5,0)="Y",1,0)) -> 1 | P15: =IF(Q15<1,0,IF(VLOOKUP($A15,'Actual Dates'!$A:$G,4,0)="Y",1,0)) -> 1 | Q15: =IF(R15<1,0,IF(VLOOKUP($A15,'Actual Dates'!$A:$G,3,0)="Y",1,0)) -> 1 | R15: =IF(VLOOKUP($A15,'Actual Dates'!$A:$G,2,0)="Y",1,0) -> 1 | S15: =_xlfn.IFNA(+VLOOKUP(A15,'Date Calcs'!A:AG,8,),TODAY()) -> 45720 | T15: =_xlfn.IFNA(VLOOKUP(A15,'Date Calcs'!A:AG,10,),TODAY()) -> 45859 | U15: =_xlfn.IFNA(+VLOOKUP(A15,'Date Calcs'!A:AG,12,),TODAY()) -> 45897 | V15: =_xlfn.IFNA(+VLOOKUP(A15,'Date Calcs'!A:AG,14,),TODAY()) -> 45919 | W15: =_xlfn.IFNA(+VLOOKUP(A15,'Date Calcs'!A:AG,16,),TODAY()) -> 45699 | X15: =_xlfn.IFNA(IF(C15=0,VLOOKUP(A15,'Date Calcs'!A:AG,8,),IF(C15=1,VLOOKUP(A15,'Date Calcs'!A:AG,10,),IF(C15=2,VLOOKUP(A15,'Date Calcs'!A:AG,12,),IF(C15=3,VLOOKUP(A15,'Date Calcs'!A:AG,14,),4)))),TODAY()) -> 45919 | Y15: =_xlfn.IFNA(IF(X15=4,W15,X15),TODAY()) -> 45919 | Z15: =_xlfn.IFNA(Y15+(VLOOKUP(A15,'Date Calcs'!A:W,22,0)*7),TODAY()) -> 45919 | AA15: =_xlfn.IFNA(VLOOKUP(A15,'RTR v2'!$A:$AW,46,0),"")
A16: ='Actual Dates'!A14 -> 25-019 | B16: =_xlfn.IFNA(VLOOKUP(A16,'Date Calcs'!A:B,2,),"") -> Kimberly Clark | C16: =VLOOKUP(A16,'Actual Dates'!A:AE,18,) -> 3 | D16: =Z16 -> 45919 | E16: =IF(VLOOKUP(A16,Dates,20,FALSE())="",TODAY(),VLOOKUP(A16,Dates,20,FALSE())) -> 45905 | F16: =IFERROR(ROUND(IF(A16="","",IF(E16=0,D16-Date!$B$3,D16-E16)),0),"") -> 14 | G16: =_xlfn.IFNA(VLOOKUP(A16,'RTR v2'!A:AW,48,FALSE)," ") -> 46076 | I16: =IF(VLOOKUP(A16,Dates,2,)="N","N",IF(VLOOKUP(A16,Dates,3,)="N","N",IF(VLOOKUP(A16,Dates,4,)="N","N",IF(VLOOKUP(A16,Dates,5,)="N","N","Y")))) -> Y | J16: =VLOOKUP(A16,Dates,7,) -> y | M16: =IF(N16="Y",N16," ") | N16: =IF(R16="Y",R16,IF(Q16="Y",Q16,IF(P16="Y",P16,O16))) -> 1 | O16: =IF(P16<1,0,IF(VLOOKUP($A16,'Actual Dates'!$A:$G,5,0)="Y",1,0)) -> 1 | P16: =IF(Q16<1,0,IF(VLOOKUP($A16,'Actual Dates'!$A:$G,4,0)="Y",1,0)) -> 1 | Q16: =IF(R16<1,0,IF(VLOOKUP($A16,'Actual Dates'!$A:$G,3,0)="Y",1,0)) -> 1 | R16: =IF(VLOOKUP($A16,'Actual Dates'!$A:$G,2,0)="Y",1,0) -> 1 | S16: =_xlfn.IFNA(+VLOOKUP(A16,'Date Calcs'!A:AG,8,),TODAY()) -> 45720 | T16: =_xlfn.IFNA(VLOOKUP(A16,'Date Calcs'!A:AG,10,),TODAY()) -> 45833 | U16: =_xlfn.IFNA(+VLOOKUP(A16,'Date Calcs'!A:AG,12,),TODAY()) -> 45904 | V16: =_xlfn.IFNA(+VLOOKUP(A16,'Date Calcs'!A:AG,14,),TODAY()) -> 45919 | W16: =_xlfn.IFNA(+VLOOKUP(A16,'Date Calcs'!A:AG,16,),TODAY()) -> 45699 | X16: =_xlfn.IFNA(IF(C16=0,VLOOKUP(A16,'Date Calcs'!A:AG,8,),IF(C16=1,VLOOKUP(A16,'Date Calcs'!A:AG,10,),IF(C16=2,VLOOKUP(A16,'Date Calcs'!A:AG,12,),IF(C16=3,VLOOKUP(A16,'Date Calcs'!A:AG,14,),4)))),TODAY()) -> 45919 | Y16: =_xlfn.IFNA(IF(X16=4,W16,X16),TODAY()) -> 45919 | Z16: =_xlfn.IFNA(Y16+(VLOOKUP(A16,'Date Calcs'!A:W,22,0)*7),TODAY()) -> 45919 | AA16: =_xlfn.IFNA(VLOOKUP(A16,'RTR v2'!$A:$AW,46,0),"") -> 0
A17: ='Actual Dates'!A15 -> 25-020 | B17: =_xlfn.IFNA(VLOOKUP(A17,'Date Calcs'!A:B,2,),"") -> Kimberly Clark | C17: =VLOOKUP(A17,'Actual Dates'!A:AE,18,) -> 4 | D17: =Z17 -> 45699 | E17: =IF(VLOOKUP(A17,Dates,20,FALSE())="",TODAY(),VLOOKUP(A17,Dates,20,FALSE())) -> 45895 | F17: =IFERROR(ROUND(IF(A17="","",IF(E17=0,D17-Date!$B$3,D17-E17)),0),"") -> -196 | G17: =_xlfn.IFNA(VLOOKUP(A17,'RTR v2'!A:AW,48,FALSE)," ") -> 46058 | I17: =IF(VLOOKUP(A17,Dates,2,)="N","N",IF(VLOOKUP(A17,Dates,3,)="N","N",IF(VLOOKUP(A17,Dates,4,)="N","N",IF(VLOOKUP(A17,Dates,5,)="N","N","Y")))) -> Y | J17: =VLOOKUP(A17,Dates,7,) -> y | M17: =IF(N17="Y",N17," ") | N17: =IF(R17="Y",R17,IF(Q17="Y",Q17,IF(P17="Y",P17,O17))) -> 1 | O17: =IF(P17<1,0,IF(VLOOKUP($A17,'Actual Dates'!$A:$G,5,0)="Y",1,0)) -> 1 | P17: =IF(Q17<1,0,IF(VLOOKUP($A17,'Actual Dates'!$A:$G,4,0)="Y",1,0)) -> 1 | Q17: =IF(R17<1,0,IF(VLOOKUP($A17,'Actual Dates'!$A:$G,3,0)="Y",1,0)) -> 1 | R17: =IF(VLOOKUP($A17,'Actual Dates'!$A:$G,2,0)="Y",1,0) -> 1 | S17: =_xlfn.IFNA(+VLOOKUP(A17,'Date Calcs'!A:AG,8,),TODAY()) -> 45720 | T17: =_xlfn.IFNA(VLOOKUP(A17,'Date Calcs'!A:AG,10,),TODAY()) -> 45813 | U17: =_xlfn.IFNA(+VLOOKUP(A17,'Date Calcs'!A:AG,12,),TODAY()) -> 45869 | V17: =_xlfn.IFNA(+VLOOKUP(A17,'Date Calcs'!A:AG,14,),TODAY()) -> 45897 | W17: =_xlfn.IFNA(+VLOOKUP(A17,'Date Calcs'!A:AG,16,),TODAY()) -> 45699 | X17: =_xlfn.IFNA(IF(C17=0,VLOOKUP(A17,'Date Calcs'!A:AG,8,),IF(C17=1,VLOOKUP(A17,'Date Calcs'!A:AG,10,),IF(C17=2,VLOOKUP(A17,'Date Calcs'!A:AG,12,),IF(C17=3,VLOOKUP(A17,'Date Calcs'!A:AG,14,),4)))),TODAY()) -> 4 | Y17: =_xlfn.IFNA(IF(X17=4,W17,X17),TODAY()) -> 45699 | Z17: =_xlfn.IFNA(Y17+(VLOOKUP(A17,'Date Calcs'!A:W,22,0)*7),TODAY()) -> 45699 | AA17: =_xlfn.IFNA(VLOOKUP(A17,'RTR v2'!$A:$AW,46,0),"") -> 0
A18: ='Actual Dates'!A16 -> 25-021 | B18: =_xlfn.IFNA(VLOOKUP(A18,'Date Calcs'!A:B,2,),"") -> Kimberly Clark | C18: =VLOOKUP(A18,'Actual Dates'!A:AE,18,) -> 3 | D18: =Z18 -> 45916 | E18: =IF(VLOOKUP(A18,Dates,20,FALSE())="",TODAY(),VLOOKUP(A18,Dates,20,FALSE())) -> 45902 | F18: =IFERROR(ROUND(IF(A18="","",IF(E18=0,D18-Date!$B$3,D18-E18)),0),"") -> 14 | G18: =_xlfn.IFNA(VLOOKUP(A18,'RTR v2'!A:AW,48,FALSE)," ") -> 46073 | I18: =IF(VLOOKUP(A18,Dates,2,)="N","N",IF(VLOOKUP(A18,Dates,3,)="N","N",IF(VLOOKUP(A18,Dates,4,)="N","N",IF(VLOOKUP(A18,Dates,5,)="N","N","Y")))) -> Y | J18: =VLOOKUP(A18,Dates,7,) -> y | M18: =IF(N18="Y",N18," ") | N18: =IF(R18="Y",R18,IF(Q18="Y",Q18,IF(P18="Y",P18,O18))) -> 1 | O18: =IF(P18<1,0,IF(VLOOKUP($A18,'Actual Dates'!$A:$G,5,0)="Y",1,0)) -> 1 | P18: =IF(Q18<1,0,IF(VLOOKUP($A18,'Actual Dates'!$A:$G,4,0)="Y",1,0)) -> 1 | Q18: =IF(R18<1,0,IF(VLOOKUP($A18,'Actual Dates'!$A:$G,3,0)="Y",1,0)) -> 1 | R18: =IF(VLOOKUP($A18,'Actual Dates'!$A:$G,2,0)="Y",1,0) -> 1 | S18: =_xlfn.IFNA(+VLOOKUP(A18,'Date Calcs'!A:AG,8,),TODAY()) -> 45720 | T18: =_xlfn.IFNA(VLOOKUP(A18,'Date Calcs'!A:AG,10,),TODAY()) -> 45833 | U18: =_xlfn.IFNA(+VLOOKUP(A18,'Date Calcs'!A:AG,12,),TODAY()) -> 45904 | V18: =_xlfn.IFNA(+VLOOKUP(A18,'Date Calcs'!A:AG,14,),TODAY()) -> 45916 | W18: =_xlfn.IFNA(+VLOOKUP(A18,'Date Calcs'!A:AG,16,),TODAY()) -> 45699 | X18: =_xlfn.IFNA(IF(C18=0,VLOOKUP(A18,'Date Calcs'!A:AG,8,),IF(C18=1,VLOOKUP(A18,'Date Calcs'!A:AG,10,),IF(C18=2,VLOOKUP(A18,'Date Calcs'!A:AG,12,),IF(C18=3,VLOOKUP(A18,'Date Calcs'!A:AG,14,),4)))),TODAY()) -> 45916 | Y18: =_xlfn.IFNA(IF(X18=4,W18,X18),TODAY()) -> 45916 | Z18: =_xlfn.IFNA(Y18+(VLOOKUP(A18,'Date Calcs'!A:W,22,0)*7),TODAY()) -> 45916 | AA18: =_xlfn.IFNA(VLOOKUP(A18,'RTR v2'!$A:$AW,46,0),"") -> 0
... A350: ='Actual Dates'!A348 -> 0 | B350: =_xlfn.IFNA(VLOOKUP(A350,'Date Calcs'!A:B,2,),"") | C350: =VLOOKUP(A350,'Actual Dates'!A:AE,18,) -> 0 | D350: =Z350 -> 46115 | E350: =IF(VLOOKUP(A350,Dates,20,FALSE())="",TODAY(),VLOOKUP(A350,Dates,20,FALSE())) -> 46115 | F350: =IFERROR(ROUND(IF(A350="","",IF(E350=0,D350-Date!$B$3,D350-E350)),0),"") -> 0 | G350: =_xlfn.IFNA(VLOOKUP(A350,'RTR v2'!A:AW,48,FALSE)," ") | I350: =IF(VLOOKUP(A350,Dates,2,)="N","N",IF(VLOOKUP(A350,Dates,3,)="N","N",IF(VLOOKUP(A350,Dates,4,)="N","N",IF(VLOOKUP(A350,Dates,5,)="N","N","Y")))) -> N | J350: =VLOOKUP(A350,Dates,7,) | M350: =IF(N350="Y",N350," ") | N350: =IF(R350="Y",R350,IF(Q350="Y",Q350,IF(P350="Y",P350,O350))) -> 0 | O350: =IF(P350<1,0,IF(VLOOKUP($A350,'Actual Dates'!$A:$G,5,0)="Y",1,0)) -> 0 | P350: =IF(Q350<1,0,IF(VLOOKUP($A350,'Actual Dates'!$A:$G,4,0)="Y",1,0)) -> 0 | Q350: =IF(R350<1,0,IF(VLOOKUP($A350,'Actual Dates'!$A:$G,3,0)="Y",1,0)) -> 0 | R350: =IF(VLOOKUP($A350,'Actual Dates'!$A:$G,2,0)="Y",1,0) -> 0 | S350: =_xlfn.IFNA(+VLOOKUP(A350,'Date Calcs'!A:AG,8,),TODAY()) -> 46115 | T350: =_xlfn.IFNA(VLOOKUP(A350,'Date Calcs'!A:AG,10,),TODAY()) -> 46115 | U350: =_xlfn.IFNA(+VLOOKUP(A350,'Date Calcs'!A:AG,12,),TODAY()) -> 46115 | V350: =_xlfn.IFNA(+VLOOKUP(A350,'Date Calcs'!A:AG,14,),TODAY()) -> 46115 | W350: =_xlfn.IFNA(+VLOOKUP(A350,'Date Calcs'!A:AG,16,),TODAY()) -> 46115 | X350: =_xlfn.IFNA(IF(C350=0,VLOOKUP(A350,'Date Calcs'!A:AG,8,),IF(C350=1,VLOOKUP(A350,'Date Calcs'!A:AG,10,),IF(C350=2,VLOOKUP(A350,'Date Calcs'!A:AG,12,),IF(C350=3,VLOOKUP(A350,'Date Calcs'!A:AG,14,),4)))),TODAY()) -> 46115 | Y350: =_xlfn.IFNA(IF(X350=4,W350,X350),TODAY()) -> 46115 | Z350: =_xlfn.IFNA(Y350+(VLOOKUP(A350,'Date Calcs'!A:W,22,0)*7),TODAY()) -> 46115 | AA350: =_xlfn.IFNA(VLOOKUP(A350,'RTR v2'!$A:$AW,46,0),"") -> 0
A351: ='Actual Dates'!A349 -> 0 | B351: =_xlfn.IFNA(VLOOKUP(A351,'Date Calcs'!A:B,2,),"") | C351: =VLOOKUP(A351,'Actual Dates'!A:AE,18,) -> 0 | D351: =Z351 -> 46115 | E351: =IF(VLOOKUP(A351,Dates,20,FALSE())="",TODAY(),VLOOKUP(A351,Dates,20,FALSE())) -> 46115 | F351: =IFERROR(ROUND(IF(A351="","",IF(E351=0,D351-Date!$B$3,D351-E351)),0),"") -> 0 | G351: =_xlfn.IFNA(VLOOKUP(A351,'RTR v2'!A:AW,48,FALSE)," ") | I351: =IF(VLOOKUP(A351,Dates,2,)="N","N",IF(VLOOKUP(A351,Dates,3,)="N","N",IF(VLOOKUP(A351,Dates,4,)="N","N",IF(VLOOKUP(A351,Dates,5,)="N","N","Y")))) -> N | J351: =VLOOKUP(A351,Dates,7,) | M351: =IF(N351="Y",N351," ") | N351: =IF(R351="Y",R351,IF(Q351="Y",Q351,IF(P351="Y",P351,O351))) -> 0 | O351: =IF(P351<1,0,IF(VLOOKUP($A351,'Actual Dates'!$A:$G,5,0)="Y",1,0)) -> 0 | P351: =IF(Q351<1,0,IF(VLOOKUP($A351,'Actual Dates'!$A:$G,4,0)="Y",1,0)) -> 0 | Q351: =IF(R351<1,0,IF(VLOOKUP($A351,'Actual Dates'!$A:$G,3,0)="Y",1,0)) -> 0 | R351: =IF(VLOOKUP($A351,'Actual Dates'!$A:$G,2,0)="Y",1,0) -> 0 | S351: =_xlfn.IFNA(+VLOOKUP(A351,'Date Calcs'!A:AG,8,),TODAY()) -> 46115 | T351: =_xlfn.IFNA(VLOOKUP(A351,'Date Calcs'!A:AG,10,),TODAY()) -> 46115 | U351: =_xlfn.IFNA(+VLOOKUP(A351,'Date Calcs'!A:AG,12,),TODAY()) -> 46115 | V351: =_xlfn.IFNA(+VLOOKUP(A351,'Date Calcs'!A:AG,14,),TODAY()) -> 46115 | W351: =_xlfn.IFNA(+VLOOKUP(A351,'Date Calcs'!A:AG,16,),TODAY()) -> 46115 | X351: =_xlfn.IFNA(IF(C351=0,VLOOKUP(A351,'Date Calcs'!A:AG,8,),IF(C351=1,VLOOKUP(A351,'Date Calcs'!A:AG,10,),IF(C351=2,VLOOKUP(A351,'Date Calcs'!A:AG,12,),IF(C351=3,VLOOKUP(A351,'Date Calcs'!A:AG,14,),4)))),TODAY()) -> 46115 | Y351: =_xlfn.IFNA(IF(X351=4,W351,X351),TODAY()) -> 46115 | Z351: =_xlfn.IFNA(Y351+(VLOOKUP(A351,'Date Calcs'!A:W,22,0)*7),TODAY()) -> 46115
A352: ='Actual Dates'!A350 -> 0 | B352: =_xlfn.IFNA(VLOOKUP(A352,'Date Calcs'!A:B,2,),"") | C352: =VLOOKUP(A352,'Actual Dates'!A:AE,18,) -> 0 | D352: =Z352 -> 46115 | E352: =IF(VLOOKUP(A352,Dates,20,FALSE())="",TODAY(),VLOOKUP(A352,Dates,20,FALSE())) -> 46115 | F352: =IFERROR(ROUND(IF(A352="","",IF(E352=0,D352-Date!$B$3,D352-E352)),0),"") -> 0 | G352: =_xlfn.IFNA(VLOOKUP(A352,'RTR v2'!A:AW,48,FALSE)," ") | I352: =IF(VLOOKUP(A352,Dates,2,)="N","N",IF(VLOOKUP(A352,Dates,3,)="N","N",IF(VLOOKUP(A352,Dates,4,)="N","N",IF(VLOOKUP(A352,Dates,5,)="N","N","Y")))) -> N | J352: =VLOOKUP(A352,Dates,7,) | M352: =IF(N352="Y",N352," ") | N352: =IF(R352="Y",R352,IF(Q352="Y",Q352,IF(P352="Y",P352,O352))) -> 0 | O352: =IF(P352<1,0,IF(VLOOKUP($A352,'Actual Dates'!$A:$G,5,0)="Y",1,0)) -> 0 | P352: =IF(Q352<1,0,IF(VLOOKUP($A352,'Actual Dates'!$A:$G,4,0)="Y",1,0)) -> 0 | Q352: =IF(R352<1,0,IF(VLOOKUP($A352,'Actual Dates'!$A:$G,3,0)="Y",1,0)) -> 0 | R352: =IF(VLOOKUP($A352,'Actual Dates'!$A:$G,2,0)="Y",1,0) -> 0 | S352: =_xlfn.IFNA(+VLOOKUP(A352,'Date Calcs'!A:AG,8,),TODAY()) -> 46115 | T352: =_xlfn.IFNA(VLOOKUP(A352,'Date Calcs'!A:AG,10,),TODAY()) -> 46115 | U352: =_xlfn.IFNA(+VLOOKUP(A352,'Date Calcs'!A:AG,12,),TODAY()) -> 46115 | V352: =_xlfn.IFNA(+VLOOKUP(A352,'Date Calcs'!A:AG,14,),TODAY()) -> 46115 | W352: =_xlfn.IFNA(+VLOOKUP(A352,'Date Calcs'!A:AG,16,),TODAY()) -> 46115 | X352: =_xlfn.IFNA(IF(C352=0,VLOOKUP(A352,'Date Calcs'!A:AG,8,),IF(C352=1,VLOOKUP(A352,'Date Calcs'!A:AG,10,),IF(C352=2,VLOOKUP(A352,'Date Calcs'!A:AG,12,),IF(C352=3,VLOOKUP(A352,'Date Calcs'!A:AG,14,),4)))),TODAY()) -> 46115 | Y352: =_xlfn.IFNA(IF(X352=4,W352,X352),TODAY()) -> 46115 | Z352: =_xlfn.IFNA(Y352+(VLOOKUP(A352,'Date Calcs'!A:W,22,0)*7),TODAY()) -> 46115
A353: ='Actual Dates'!A351 -> 0 | B353: =_xlfn.IFNA(VLOOKUP(A353,'Date Calcs'!A:B,2,),"") | C353: =VLOOKUP(A353,'Actual Dates'!A:AE,18,) -> 0 | D353: =Z353 -> 46115 | E353: =IF(VLOOKUP(A353,Dates,20,FALSE())="",TODAY(),VLOOKUP(A353,Dates,20,FALSE())) -> 46115 | F353: =IFERROR(ROUND(IF(A353="","",IF(E353=0,D353-Date!$B$3,D353-E353)),0),"") -> 0 | G353: =_xlfn.IFNA(VLOOKUP(A353,'RTR v2'!A:AW,48,FALSE)," ") | I353: =IF(VLOOKUP(A353,Dates,2,)="N","N",IF(VLOOKUP(A353,Dates,3,)="N","N",IF(VLOOKUP(A353,Dates,4,)="N","N",IF(VLOOKUP(A353,Dates,5,)="N","N","Y")))) -> N | J353: =VLOOKUP(A353,Dates,7,) | M353: =IF(N353="Y",N353," ") | N353: =IF(R353="Y",R353,IF(Q353="Y",Q353,IF(P353="Y",P353,O353))) -> 0 | O353: =IF(P353<1,0,IF(VLOOKUP($A353,'Actual Dates'!$A:$G,5,0)="Y",1,0)) -> 0 | P353: =IF(Q353<1,0,IF(VLOOKUP($A353,'Actual Dates'!$A:$G,4,0)="Y",1,0)) -> 0 | Q353: =IF(R353<1,0,IF(VLOOKUP($A353,'Actual Dates'!$A:$G,3,0)="Y",1,0)) -> 0 | R353: =IF(VLOOKUP($A353,'Actual Dates'!$A:$G,2,0)="Y",1,0) -> 0 | S353: =_xlfn.IFNA(+VLOOKUP(A353,'Date Calcs'!A:AG,8,),TODAY()) -> 46115 | T353: =_xlfn.IFNA(VLOOKUP(A353,'Date Calcs'!A:AG,10,),TODAY()) -> 46115 | U353: =_xlfn.IFNA(+VLOOKUP(A353,'Date Calcs'!A:AG,12,),TODAY()) -> 46115 | V353: =_xlfn.IFNA(+VLOOKUP(A353,'Date Calcs'!A:AG,14,),TODAY()) -> 46115 | W353: =_xlfn.IFNA(+VLOOKUP(A353,'Date Calcs'!A:AG,16,),TODAY()) -> 46115 | X353: =_xlfn.IFNA(IF(C353=0,VLOOKUP(A353,'Date Calcs'!A:AG,8,),IF(C353=1,VLOOKUP(A353,'Date Calcs'!A:AG,10,),IF(C353=2,VLOOKUP(A353,'Date Calcs'!A:AG,12,),IF(C353=3,VLOOKUP(A353,'Date Calcs'!A:AG,14,),4)))),TODAY()) -> 46115 | Y353: =_xlfn.IFNA(IF(X353=4,W353,X353),TODAY()) -> 46115 | Z353: =_xlfn.IFNA(Y353+(VLOOKUP(A353,'Date Calcs'!A:W,22,0)*7),TODAY()) -> 46115
A354: ='Actual Dates'!A352 -> 0 | B354: =_xlfn.IFNA(VLOOKUP(A354,'Date Calcs'!A:B,2,),"") | C354: =VLOOKUP(A354,'Actual Dates'!A:AE,18,) -> 0 | D354: =Z354 -> 46115 | E354: =IF(VLOOKUP(A354,Dates,20,FALSE())="",TODAY(),VLOOKUP(A354,Dates,20,FALSE())) -> 46115 | F354: =IFERROR(ROUND(IF(A354="","",IF(E354=0,D354-Date!$B$3,D354-E354)),0),"") -> 0 | G354: =_xlfn.IFNA(VLOOKUP(A354,'RTR v2'!A:AW,48,FALSE)," ") | I354: =IF(VLOOKUP(A354,Dates,2,)="N","N",IF(VLOOKUP(A354,Dates,3,)="N","N",IF(VLOOKUP(A354,Dates,4,)="N","N",IF(VLOOKUP(A354,Dates,5,)="N","N","Y")))) -> N | J354: =VLOOKUP(A354,Dates,7,) | M354: =IF(N354="Y",N354," ") | N354: =IF(R354="Y",R354,IF(Q354="Y",Q354,IF(P354="Y",P354,O354))) -> 0 | O354: =IF(P354<1,0,IF(VLOOKUP($A354,'Actual Dates'!$A:$G,5,0)="Y",1,0)) -> 0 | P354: =IF(Q354<1,0,IF(VLOOKUP($A354,'Actual Dates'!$A:$G,4,0)="Y",1,0)) -> 0 | Q354: =IF(R354<1,0,IF(VLOOKUP($A354,'Actual Dates'!$A:$G,3,0)="Y",1,0)) -> 0 | R354: =IF(VLOOKUP($A354,'Actual Dates'!$A:$G,2,0)="Y",1,0) -> 0 | S354: =_xlfn.IFNA(+VLOOKUP(A354,'Date Calcs'!A:AG,8,),TODAY()) -> 46115 | T354: =_xlfn.IFNA(VLOOKUP(A354,'Date Calcs'!A:AG,10,),TODAY()) -> 46115 | U354: =_xlfn.IFNA(+VLOOKUP(A354,'Date Calcs'!A:AG,12,),TODAY()) -> 46115 | V354: =_xlfn.IFNA(+VLOOKUP(A354,'Date Calcs'!A:AG,14,),TODAY()) -> 46115 | W354: =_xlfn.IFNA(+VLOOKUP(A354,'Date Calcs'!A:AG,16,),TODAY()) -> 46115 | X354: =_xlfn.IFNA(IF(C354=0,VLOOKUP(A354,'Date Calcs'!A:AG,8,),IF(C354=1,VLOOKUP(A354,'Date Calcs'!A:AG,10,),IF(C354=2,VLOOKUP(A354,'Date Calcs'!A:AG,12,),IF(C354=3,VLOOKUP(A354,'Date Calcs'!A:AG,14,),4)))),TODAY()) -> 46115 | Y354: =_xlfn.IFNA(IF(X354=4,W354,X354),TODAY()) -> 46115 | Z354: =_xlfn.IFNA(Y354+(VLOOKUP(A354,'Date Calcs'!A:W,22,0)*7),TODAY()) -> 46115
A355: ='Actual Dates'!A353 -> 0 | B355: =_xlfn.IFNA(VLOOKUP(A355,'Date Calcs'!A:B,2,),"") | C355: =VLOOKUP(A355,'Actual Dates'!A:AE,18,) -> 0 | D355: =Z355 -> 46115 | E355: =IF(VLOOKUP(A355,Dates,20,FALSE())="",TODAY(),VLOOKUP(A355,Dates,20,FALSE())) -> 46115 | F355: =IFERROR(ROUND(IF(A355="","",IF(E355=0,D355-Date!$B$3,D355-E355)),0),"") -> 0 | G355: =_xlfn.IFNA(VLOOKUP(A355,'RTR v2'!A:AW,48,FALSE)," ") | I355: =IF(VLOOKUP(A355,Dates,2,)="N","N",IF(VLOOKUP(A355,Dates,3,)="N","N",IF(VLOOKUP(A355,Dates,4,)="N","N",IF(VLOOKUP(A355,Dates,5,)="N","N","Y")))) -> N | J355: =VLOOKUP(A355,Dates,7,) | M355: =IF(N355="Y",N355," ") | N355: =IF(R355="Y",R355,IF(Q355="Y",Q355,IF(P355="Y",P355,O355))) -> 0 | O355: =IF(P355<1,0,IF(VLOOKUP($A355,'Actual Dates'!$A:$G,5,0)="Y",1,0)) -> 0 | P355: =IF(Q355<1,0,IF(VLOOKUP($A355,'Actual Dates'!$A:$G,4,0)="Y",1,0)) -> 0 | Q355: =IF(R355<1,0,IF(VLOOKUP($A355,'Actual Dates'!$A:$G,3,0)="Y",1,0)) -> 0 | R355: =IF(VLOOKUP($A355,'Actual Dates'!$A:$G,2,0)="Y",1,0) -> 0 | S355: =_xlfn.IFNA(+VLOOKUP(A355,'Date Calcs'!A:AG,8,),TODAY()) -> 46115 | T355: =_xlfn.IFNA(VLOOKUP(A355,'Date Calcs'!A:AG,10,),TODAY()) -> 46115 | U355: =_xlfn.IFNA(+VLOOKUP(A355,'Date Calcs'!A:AG,12,),TODAY()) -> 46115 | V355: =_xlfn.IFNA(+VLOOKUP(A355,'Date Calcs'!A:AG,14,),TODAY()) -> 46115 | W355: =_xlfn.IFNA(+VLOOKUP(A355,'Date Calcs'!A:AG,16,),TODAY()) -> 46115 | X355: =_xlfn.IFNA(IF(C355=0,VLOOKUP(A355,'Date Calcs'!A:AG,8,),IF(C355=1,VLOOKUP(A355,'Date Calcs'!A:AG,10,),IF(C355=2,VLOOKUP(A355,'Date Calcs'!A:AG,12,),IF(C355=3,VLOOKUP(A355,'Date Calcs'!A:AG,14,),4)))),TODAY()) -> 46115 | Y355: =_xlfn.IFNA(IF(X355=4,W355,X355),TODAY()) -> 46115 | Z355: =_xlfn.IFNA(Y355+(VLOOKUP(A355,'Date Calcs'!A:W,22,0)*7),TODAY()) -> 46115
A356: ='Actual Dates'!A354 -> 0 | B356: =_xlfn.IFNA(VLOOKUP(A356,'Date Calcs'!A:B,2,),"") | C356: =VLOOKUP(A356,'Actual Dates'!A:AE,18,) -> 0 | D356: =Z356 -> 46115 | E356: =IF(VLOOKUP(A356,Dates,20,FALSE())="",TODAY(),VLOOKUP(A356,Dates,20,FALSE())) -> 46115 | F356: =IFERROR(ROUND(IF(A356="","",IF(E356=0,D356-Date!$B$3,D356-E356)),0),"") -> 0 | G356: =_xlfn.IFNA(VLOOKUP(A356,'RTR v2'!A:AW,48,FALSE)," ") | I356: =IF(VLOOKUP(A356,Dates,2,)="N","N",IF(VLOOKUP(A356,Dates,3,)="N","N",IF(VLOOKUP(A356,Dates,4,)="N","N",IF(VLOOKUP(A356,Dates,5,)="N","N","Y")))) -> N | J356: =VLOOKUP(A356,Dates,7,) | M356: =IF(N356="Y",N356," ") | N356: =IF(R356="Y",R356,IF(Q356="Y",Q356,IF(P356="Y",P356,O356))) -> 0 | O356: =IF(P356<1,0,IF(VLOOKUP($A356,'Actual Dates'!$A:$G,5,0)="Y",1,0)) -> 0 | P356: =IF(Q356<1,0,IF(VLOOKUP($A356,'Actual Dates'!$A:$G,4,0)="Y",1,0)) -> 0 | Q356: =IF(R356<1,0,IF(VLOOKUP($A356,'Actual Dates'!$A:$G,3,0)="Y",1,0)) -> 0 | R356: =IF(VLOOKUP($A356,'Actual Dates'!$A:$G,2,0)="Y",1,0) -> 0 | S356: =_xlfn.IFNA(+VLOOKUP(A356,'Date Calcs'!A:AG,8,),TODAY()) -> 46115 | T356: =_xlfn.IFNA(VLOOKUP(A356,'Date Calcs'!A:AG,10,),TODAY()) -> 46115 | U356: =_xlfn.IFNA(+VLOOKUP(A356,'Date Calcs'!A:AG,12,),TODAY()) -> 46115 | V356: =_xlfn.IFNA(+VLOOKUP(A356,'Date Calcs'!A:AG,14,),TODAY()) -> 46115 | W356: =_xlfn.IFNA(+VLOOKUP(A356,'Date Calcs'!A:AG,16,),TODAY()) -> 46115 | X356: =_xlfn.IFNA(IF(C356=0,VLOOKUP(A356,'Date Calcs'!A:AG,8,),IF(C356=1,VLOOKUP(A356,'Date Calcs'!A:AG,10,),IF(C356=2,VLOOKUP(A356,'Date Calcs'!A:AG,12,),IF(C356=3,VLOOKUP(A356,'Date Calcs'!A:AG,14,),4)))),TODAY()) -> 46115 | Y356: =_xlfn.IFNA(IF(X356=4,W356,X356),TODAY()) -> 46115 | Z356: =_xlfn.IFNA(Y356+(VLOOKUP(A356,'Date Calcs'!A:W,22,0)*7),TODAY()) -> 46115
A357: ='Actual Dates'!A355 -> 0 | B357: =_xlfn.IFNA(VLOOKUP(A357,'Date Calcs'!A:B,2,),"") | C357: =VLOOKUP(A357,'Actual Dates'!A:AE,18,) -> 0 | D357: =Z357 -> 46115 | E357: =IF(VLOOKUP(A357,Dates,20,FALSE())="",TODAY(),VLOOKUP(A357,Dates,20,FALSE())) -> 46115 | F357: =IFERROR(ROUND(IF(A357="","",IF(E357=0,D357-Date!$B$3,D357-E357)),0),"") -> 0 | G357: =_xlfn.IFNA(VLOOKUP(A357,'RTR v2'!A:AW,48,FALSE)," ") | I357: =IF(VLOOKUP(A357,Dates,2,)="N","N",IF(VLOOKUP(A357,Dates,3,)="N","N",IF(VLOOKUP(A357,Dates,4,)="N","N",IF(VLOOKUP(A357,Dates,5,)="N","N","Y")))) -> N | J357: =VLOOKUP(A357,Dates,7,) | M357: =IF(N357="Y",N357," ") | N357: =IF(R357="Y",R357,IF(Q357="Y",Q357,IF(P357="Y",P357,O357))) -> 0 | O357: =IF(P357<1,0,IF(VLOOKUP($A357,'Actual Dates'!$A:$G,5,0)="Y",1,0)) -> 0 | P357: =IF(Q357<1,0,IF(VLOOKUP($A357,'Actual Dates'!$A:$G,4,0)="Y",1,0)) -> 0 | Q357: =IF(R357<1,0,IF(VLOOKUP($A357,'Actual Dates'!$A:$G,3,0)="Y",1,0)) -> 0 | R357: =IF(VLOOKUP($A357,'Actual Dates'!$A:$G,2,0)="Y",1,0) -> 0 | S357: =_xlfn.IFNA(+VLOOKUP(A357,'Date Calcs'!A:AG,8,),TODAY()) -> 46115 | T357: =_xlfn.IFNA(VLOOKUP(A357,'Date Calcs'!A:AG,10,),TODAY()) -> 46115 | U357: =_xlfn.IFNA(+VLOOKUP(A357,'Date Calcs'!A:AG,12,),TODAY()) -> 46115 | V357: =_xlfn.IFNA(+VLOOKUP(A357,'Date Calcs'!A:AG,14,),TODAY()) -> 46115 | W357: =_xlfn.IFNA(+VLOOKUP(A357,'Date Calcs'!A:AG,16,),TODAY()) -> 46115 | X357: =_xlfn.IFNA(IF(C357=0,VLOOKUP(A357,'Date Calcs'!A:AG,8,),IF(C357=1,VLOOKUP(A357,'Date Calcs'!A:AG,10,),IF(C357=2,VLOOKUP(A357,'Date Calcs'!A:AG,12,),IF(C357=3,VLOOKUP(A357,'Date Calcs'!A:AG,14,),4)))),TODAY()) -> 46115 | Y357: =_xlfn.IFNA(IF(X357=4,W357,X357),TODAY()) -> 46115 | Z357: =_xlfn.IFNA(Y357+(VLOOKUP(A357,'Date Calcs'!A:W,22,0)*7),TODAY()) -> 46115
A358: ='Actual Dates'!A356 -> 0 | B358: =_xlfn.IFNA(VLOOKUP(A358,'Date Calcs'!A:B,2,),"") | C358: =VLOOKUP(A358,'Actual Dates'!A:AE,18,) -> 0 | D358: =Z358 -> 46115 | E358: =IF(VLOOKUP(A358,Dates,20,FALSE())="",TODAY(),VLOOKUP(A358,Dates,20,FALSE())) -> 46115 | F358: =IFERROR(ROUND(IF(A358="","",IF(E358=0,D358-Date!$B$3,D358-E358)),0),"") -> 0 | G358: =_xlfn.IFNA(VLOOKUP(A358,'RTR v2'!A:AW,48,FALSE)," ") | I358: =IF(VLOOKUP(A358,Dates,2,)="N","N",IF(VLOOKUP(A358,Dates,3,)="N","N",IF(VLOOKUP(A358,Dates,4,)="N","N",IF(VLOOKUP(A358,Dates,5,)="N","N","Y")))) -> N | J358: =VLOOKUP(A358,Dates,7,) | M358: =IF(N358="Y",N358," ") | N358: =IF(R358="Y",R358,IF(Q358="Y",Q358,IF(P358="Y",P358,O358))) -> 0 | O358: =IF(P358<1,0,IF(VLOOKUP($A358,'Actual Dates'!$A:$G,5,0)="Y",1,0)) -> 0 | P358: =IF(Q358<1,0,IF(VLOOKUP($A358,'Actual Dates'!$A:$G,4,0)="Y",1,0)) -> 0 | Q358: =IF(R358<1,0,IF(VLOOKUP($A358,'Actual Dates'!$A:$G,3,0)="Y",1,0)) -> 0 | R358: =IF(VLOOKUP($A358,'Actual Dates'!$A:$G,2,0)="Y",1,0) -> 0 | S358: =_xlfn.IFNA(+VLOOKUP(A358,'Date Calcs'!A:AG,8,),TODAY()) -> 46115 | T358: =_xlfn.IFNA(VLOOKUP(A358,'Date Calcs'!A:AG,10,),TODAY()) -> 46115 | U358: =_xlfn.IFNA(+VLOOKUP(A358,'Date Calcs'!A:AG,12,),TODAY()) -> 46115 | V358: =_xlfn.IFNA(+VLOOKUP(A358,'Date Calcs'!A:AG,14,),TODAY()) -> 46115 | W358: =_xlfn.IFNA(+VLOOKUP(A358,'Date Calcs'!A:AG,16,),TODAY()) -> 46115 | X358: =_xlfn.IFNA(IF(C358=0,VLOOKUP(A358,'Date Calcs'!A:AG,8,),IF(C358=1,VLOOKUP(A358,'Date Calcs'!A:AG,10,),IF(C358=2,VLOOKUP(A358,'Date Calcs'!A:AG,12,),IF(C358=3,VLOOKUP(A358,'Date Calcs'!A:AG,14,),4)))),TODAY()) -> 46115 | Y358: =_xlfn.IFNA(IF(X358=4,W358,X358),TODAY()) -> 46115 | Z358: =_xlfn.IFNA(Y358+(VLOOKUP(A358,'Date Calcs'!A:W,22,0)*7),TODAY()) -> 46115
A359: ='Actual Dates'!A357 -> 0 | B359: =_xlfn.IFNA(VLOOKUP(A359,'Date Calcs'!A:B,2,),"") | C359: =VLOOKUP(A359,'Actual Dates'!A:AE,18,) -> 0 | D359: =Z359 -> 46115 | E359: =IF(VLOOKUP(A359,Dates,20,FALSE())="",TODAY(),VLOOKUP(A359,Dates,20,FALSE())) -> 46115 | F359: =IFERROR(ROUND(IF(A359="","",IF(E359=0,D359-Date!$B$3,D359-E359)),0),"") -> 0 | G359: =_xlfn.IFNA(VLOOKUP(A359,'RTR v2'!A:AW,48,FALSE)," ") | I359: =IF(VLOOKUP(A359,Dates,2,)="N","N",IF(VLOOKUP(A359,Dates,3,)="N","N",IF(VLOOKUP(A359,Dates,4,)="N","N",IF(VLOOKUP(A359,Dates,5,)="N","N","Y")))) -> N | J359: =VLOOKUP(A359,Dates,7,) | M359: =IF(N359="Y",N359," ") | N359: =IF(R359="Y",R359,IF(Q359="Y",Q359,IF(P359="Y",P359,O359))) -> 0 | O359: =IF(P359<1,0,IF(VLOOKUP($A359,'Actual Dates'!$A:$G,5,0)="Y",1,0)) -> 0 | P359: =IF(Q359<1,0,IF(VLOOKUP($A359,'Actual Dates'!$A:$G,4,0)="Y",1,0)) -> 0 | Q359: =IF(R359<1,0,IF(VLOOKUP($A359,'Actual Dates'!$A:$G,3,0)="Y",1,0)) -> 0 | R359: =IF(VLOOKUP($A359,'Actual Dates'!$A:$G,2,0)="Y",1,0) -> 0 | S359: =_xlfn.IFNA(+VLOOKUP(A359,'Date Calcs'!A:AG,8,),TODAY()) -> 46115 | T359: =_xlfn.IFNA(VLOOKUP(A359,'Date Calcs'!A:AG,10,),TODAY()) -> 46115 | U359: =_xlfn.IFNA(+VLOOKUP(A359,'Date Calcs'!A:AG,12,),TODAY()) -> 46115 | V359: =_xlfn.IFNA(+VLOOKUP(A359,'Date Calcs'!A:AG,14,),TODAY()) -> 46115 | W359: =_xlfn.IFNA(+VLOOKUP(A359,'Date Calcs'!A:AG,16,),TODAY()) -> 46115 | X359: =_xlfn.IFNA(IF(C359=0,VLOOKUP(A359,'Date Calcs'!A:AG,8,),IF(C359=1,VLOOKUP(A359,'Date Calcs'!A:AG,10,),IF(C359=2,VLOOKUP(A359,'Date Calcs'!A:AG,12,),IF(C359=3,VLOOKUP(A359,'Date Calcs'!A:AG,14,),4)))),TODAY()) -> 46115 | Y359: =_xlfn.IFNA(IF(X359=4,W359,X359),TODAY()) -> 46115 | Z359: =_xlfn.IFNA(Y359+(VLOOKUP(A359,'Date Calcs'!A:W,22,0)*7),TODAY()) -> 46115
A360: ='Actual Dates'!A358 -> 0 | B360: =_xlfn.IFNA(VLOOKUP(A360,'Date Calcs'!A:B,2,),"") | C360: =VLOOKUP(A360,'Actual Dates'!A:AE,18,) -> 0 | D360: =Z360 -> 46115 | E360: =IF(VLOOKUP(A360,Dates,20,FALSE())="",TODAY(),VLOOKUP(A360,Dates,20,FALSE())) -> 46115 | F360: =IFERROR(ROUND(IF(A360="","",IF(E360=0,D360-Date!$B$3,D360-E360)),0),"") -> 0 | G360: =_xlfn.IFNA(VLOOKUP(A360,'RTR v2'!A:AW,48,FALSE)," ") | I360: =IF(VLOOKUP(A360,Dates,2,)="N","N",IF(VLOOKUP(A360,Dates,3,)="N","N",IF(VLOOKUP(A360,Dates,4,)="N","N",IF(VLOOKUP(A360,Dates,5,)="N","N","Y")))) -> N | J360: =VLOOKUP(A360,Dates,7,) | M360: =IF(N360="Y",N360," ") | N360: =IF(R360="Y",R360,IF(Q360="Y",Q360,IF(P360="Y",P360,O360))) -> 0 | O360: =IF(P360<1,0,IF(VLOOKUP($A360,'Actual Dates'!$A:$G,5,0)="Y",1,0)) -> 0 | P360: =IF(Q360<1,0,IF(VLOOKUP($A360,'Actual Dates'!$A:$G,4,0)="Y",1,0)) -> 0 | Q360: =IF(R360<1,0,IF(VLOOKUP($A360,'Actual Dates'!$A:$G,3,0)="Y",1,0)) -> 0 | R360: =IF(VLOOKUP($A360,'Actual Dates'!$A:$G,2,0)="Y",1,0) -> 0 | S360: =_xlfn.IFNA(+VLOOKUP(A360,'Date Calcs'!A:AG,8,),TODAY()) -> 46115 | T360: =_xlfn.IFNA(VLOOKUP(A360,'Date Calcs'!A:AG,10,),TODAY()) -> 46115 | U360: =_xlfn.IFNA(+VLOOKUP(A360,'Date Calcs'!A:AG,12,),TODAY()) -> 46115 | V360: =_xlfn.IFNA(+VLOOKUP(A360,'Date Calcs'!A:AG,14,),TODAY()) -> 46115 | W360: =_xlfn.IFNA(+VLOOKUP(A360,'Date Calcs'!A:AG,16,),TODAY()) -> 46115 | X360: =_xlfn.IFNA(IF(C360=0,VLOOKUP(A360,'Date Calcs'!A:AG,8,),IF(C360=1,VLOOKUP(A360,'Date Calcs'!A:AG,10,),IF(C360=2,VLOOKUP(A360,'Date Calcs'!A:AG,12,),IF(C360=3,VLOOKUP(A360,'Date Calcs'!A:AG,14,),4)))),TODAY()) -> 46115 | Y360: =_xlfn.IFNA(IF(X360=4,W360,X360),TODAY()) -> 46115 | Z360: =_xlfn.IFNA(Y360+(VLOOKUP(A360,'Date Calcs'!A:W,22,0)*7),TODAY()) -> 46115
A361: ='Actual Dates'!A359 -> 0 | B361: =_xlfn.IFNA(VLOOKUP(A361,'Date Calcs'!A:B,2,),"") | C361: =VLOOKUP(A361,'Actual Dates'!A:AE,18,) -> 0 | D361: =Z361 -> 46115 | E361: =IF(VLOOKUP(A361,Dates,20,FALSE())="",TODAY(),VLOOKUP(A361,Dates,20,FALSE())) -> 46115 | F361: =IFERROR(ROUND(IF(A361="","",IF(E361=0,D361-Date!$B$3,D361-E361)),0),"") -> 0 | G361: =_xlfn.IFNA(VLOOKUP(A361,'RTR v2'!A:AW,48,FALSE)," ") | I361: =IF(VLOOKUP(A361,Dates,2,)="N","N",IF(VLOOKUP(A361,Dates,3,)="N","N",IF(VLOOKUP(A361,Dates,4,)="N","N",IF(VLOOKUP(A361,Dates,5,)="N","N","Y")))) -> N | J361: =VLOOKUP(A361,Dates,7,) | M361: =IF(N361="Y",N361," ") | N361: =IF(R361="Y",R361,IF(Q361="Y",Q361,IF(P361="Y",P361,O361))) -> 0 | O361: =IF(P361<1,0,IF(VLOOKUP($A361,'Actual Dates'!$A:$G,5,0)="Y",1,0)) -> 0 | P361: =IF(Q361<1,0,IF(VLOOKUP($A361,'Actual Dates'!$A:$G,4,0)="Y",1,0)) -> 0 | Q361: =IF(R361<1,0,IF(VLOOKUP($A361,'Actual Dates'!$A:$G,3,0)="Y",1,0)) -> 0 | R361: =IF(VLOOKUP($A361,'Actual Dates'!$A:$G,2,0)="Y",1,0) -> 0 | S361: =_xlfn.IFNA(+VLOOKUP(A361,'Date Calcs'!A:AG,8,),TODAY()) -> 46115 | T361: =_xlfn.IFNA(VLOOKUP(A361,'Date Calcs'!A:AG,10,),TODAY()) -> 46115 | U361: =_xlfn.IFNA(+VLOOKUP(A361,'Date Calcs'!A:AG,12,),TODAY()) -> 46115 | V361: =_xlfn.IFNA(+VLOOKUP(A361,'Date Calcs'!A:AG,14,),TODAY()) -> 46115 | W361: =_xlfn.IFNA(+VLOOKUP(A361,'Date Calcs'!A:AG,16,),TODAY()) -> 46115 | X361: =_xlfn.IFNA(IF(C361=0,VLOOKUP(A361,'Date Calcs'!A:AG,8,),IF(C361=1,VLOOKUP(A361,'Date Calcs'!A:AG,10,),IF(C361=2,VLOOKUP(A361,'Date Calcs'!A:AG,12,),IF(C361=3,VLOOKUP(A361,'Date Calcs'!A:AG,14,),4)))),TODAY()) -> 46115 | Y361: =_xlfn.IFNA(IF(X361=4,W361,X361),TODAY()) -> 46115 | Z361: =_xlfn.IFNA(Y361+(VLOOKUP(A361,'Date Calcs'!A:W,22,0)*7),TODAY()) -> 46115

Sheet Cust Dwg Return
A1: Drawing Return From Customer
F2: On Track
F3: At Risk
F4: Late | I4: Blanks only | J4: Blanks only
A5: Job # | B5: Customer | C5: Rev. | D5: Target | E5: Actual | F5: Days +/- | G5: Status | I5: Returned | J5: Approved
A6: ='Drawing Submittal'!A6 -> 24-046 | B6: =_xlfn.IFNA(VLOOKUP(A6,'Date Calcs'!A:AG,2,),"") -> SYMS Engineering | C6: =_xlfn.IFNA(VLOOKUP(A6,'Actual Dates'!A:AE,6,),"") -> 3 | D6: =IF(C6=" "," ",IF(C6=0,VLOOKUP(A6,'Date Calcs'!A:AG,9,),IF(C6=1,VLOOKUP(A6,'Date Calcs'!A:AG,11,),IF(C6=2,VLOOKUP(A6,'Date Calcs'!A:AG,13,),IF(C6=3,VLOOKUP(A6,'Date Calcs'!A:AG,15,),4))))) -> 45882 | E6: =IF(_xlfn.IFNA(IF(D6=" "," ",VLOOKUP(A6,'Actual Dates'!A:AE,20,0)),"")<1,"-",_xlfn.IFNA(IF(D6=" "," ",VLOOKUP(A6,'Actual Dates'!A:AE,20,0)),"")) -> 45883 | F6: =IFERROR(IF(A6="","",D6-Date!$B$3),"") -> -233 | I6: =IF(C6=0,IF(VLOOKUP(A6,Dates,9,)>0,1," "),IF(C6=1,IF(VLOOKUP(A6,Dates,11,)>0,1," "),IF(C6=2,IF(VLOOKUP(A6,Dates,13,)>0,1," "),IF(C6=3,IF(VLOOKUP(A6,Dates,15,)>0,1," "))))) -> 1 | J6: =VLOOKUP(A6,Dates,7,) -> y
A7: ='Drawing Submittal'!A7 -> 25-010 | B7: =_xlfn.IFNA(VLOOKUP(A7,'Date Calcs'!A:AG,2,),"") -> Kimberly Clark | C7: =_xlfn.IFNA(VLOOKUP(A7,'Actual Dates'!A:AE,6,),"") -> 2 | D7: =IF(C7=" "," ",IF(C7=0,VLOOKUP(A7,'Date Calcs'!A:AG,9,),IF(C7=1,VLOOKUP(A7,'Date Calcs'!A:AG,11,),IF(C7=2,VLOOKUP(A7,'Date Calcs'!A:AG,13,),IF(C7=3,VLOOKUP(A7,'Date Calcs'!A:AG,15,),4))))) -> 45904 | E7: =IF(_xlfn.IFNA(IF(D7=" "," ",VLOOKUP(A7,'Actual Dates'!A:AE,20,0)),"")<1,"-",_xlfn.IFNA(IF(D7=" "," ",VLOOKUP(A7,'Actual Dates'!A:AE,20,0)),"")) -> 45897 | F7: =IFERROR(IF(A7="","",D7-Date!$B$3),"") -> -211 | I7: =IF(C7=0,IF(VLOOKUP(A7,Dates,9,)>0,1," "),IF(C7=1,IF(VLOOKUP(A7,Dates,11,)>0,1," "),IF(C7=2,IF(VLOOKUP(A7,Dates,13,)>0,1," "),IF(C7=3,IF(VLOOKUP(A7,Dates,15,)>0,1," "))))) | J7: =VLOOKUP(A7,Dates,7,) -> y
A8: ='Drawing Submittal'!A8 -> 25-011 | B8: =_xlfn.IFNA(VLOOKUP(A8,'Date Calcs'!A:AG,2,),"") -> Kimberly Clark | C8: =_xlfn.IFNA(VLOOKUP(A8,'Actual Dates'!A:AE,6,),"") -> 2 | D8: =IF(C8=" "," ",IF(C8=0,VLOOKUP(A8,'Date Calcs'!A:AG,9,),IF(C8=1,VLOOKUP(A8,'Date Calcs'!A:AG,11,),IF(C8=2,VLOOKUP(A8,'Date Calcs'!A:AG,13,),IF(C8=3,VLOOKUP(A8,'Date Calcs'!A:AG,15,),4))))) -> 45911 | E8: =IF(_xlfn.IFNA(IF(D8=" "," ",VLOOKUP(A8,'Actual Dates'!A:AE,20,0)),"")<1,"-",_xlfn.IFNA(IF(D8=" "," ",VLOOKUP(A8,'Actual Dates'!A:AE,20,0)),"")) -> 45904 | F8: =IFERROR(IF(A8="","",D8-Date!$B$3),"") -> -204 | I8: =IF(C8=0,IF(VLOOKUP(A8,Dates,9,)>0,1," "),IF(C8=1,IF(VLOOKUP(A8,Dates,11,)>0,1," "),IF(C8=2,IF(VLOOKUP(A8,Dates,13,)>0,1," "),IF(C8=3,IF(VLOOKUP(A8,Dates,15,)>0,1," "))))) | J8: =VLOOKUP(A8,Dates,7,) -> y
A9: ='Drawing Submittal'!A9 -> 25-012 | B9: =_xlfn.IFNA(VLOOKUP(A9,'Date Calcs'!A:AG,2,),"") -> Kimberly Clark | C9: =_xlfn.IFNA(VLOOKUP(A9,'Actual Dates'!A:AE,6,),"") -> 2 | D9: =IF(C9=" "," ",IF(C9=0,VLOOKUP(A9,'Date Calcs'!A:AG,9,),IF(C9=1,VLOOKUP(A9,'Date Calcs'!A:AG,11,),IF(C9=2,VLOOKUP(A9,'Date Calcs'!A:AG,13,),IF(C9=3,VLOOKUP(A9,'Date Calcs'!A:AG,15,),4))))) -> 45911 | E9: =IF(_xlfn.IFNA(IF(D9=" "," ",VLOOKUP(A9,'Actual Dates'!A:AE,20,0)),"")<1,"-",_xlfn.IFNA(IF(D9=" "," ",VLOOKUP(A9,'Actual Dates'!A:AE,20,0)),"")) -> 45904 | F9: =IFERROR(IF(A9="","",D9-Date!$B$3),"") -> -204 | I9: =IF(C9=0,IF(VLOOKUP(A9,Dates,9,)>0,1," "),IF(C9=1,IF(VLOOKUP(A9,Dates,11,)>0,1," "),IF(C9=2,IF(VLOOKUP(A9,Dates,13,)>0,1," "),IF(C9=3,IF(VLOOKUP(A9,Dates,15,)>0,1," "))))) | J9: =VLOOKUP(A9,Dates,7,) -> y
A10: ='Drawing Submittal'!A10 -> 25-013 | B10: =_xlfn.IFNA(VLOOKUP(A10,'Date Calcs'!A:AG,2,),"") -> Kimberly Clark | C10: =_xlfn.IFNA(VLOOKUP(A10,'Actual Dates'!A:AE,6,),"") -> 1 | D10: =IF(C10=" "," ",IF(C10=0,VLOOKUP(A10,'Date Calcs'!A:AG,9,),IF(C10=1,VLOOKUP(A10,'Date Calcs'!A:AG,11,),IF(C10=2,VLOOKUP(A10,'Date Calcs'!A:AG,13,),IF(C10=3,VLOOKUP(A10,'Date Calcs'!A:AG,15,),4))))) -> 45819 | E10: =IF(_xlfn.IFNA(IF(D10=" "," ",VLOOKUP(A10,'Actual Dates'!A:AE,20,0)),"")<1,"-",_xlfn.IFNA(IF(D10=" "," ",VLOOKUP(A10,'Actual Dates'!A:AE,20,0)),"")) -> 45904 | F10: =IFERROR(IF(A10="","",D10-Date!$B$3),"") -> -296 | I10: =IF(C10=0,IF(VLOOKUP(A10,Dates,9,)>0,1," "),IF(C10=1,IF(VLOOKUP(A10,Dates,11,)>0,1," "),IF(C10=2,IF(VLOOKUP(A10,Dates,13,)>0,1," "),IF(C10=3,IF(VLOOKUP(A10,Dates,15,)>0,1," "))))) | J10: =VLOOKUP(A10,Dates,7,) -> y
A11: ='Drawing Submittal'!A11 -> 25-014 | B11: =_xlfn.IFNA(VLOOKUP(A11,'Date Calcs'!A:AG,2,),"") -> Kimberly Clark | C11: =_xlfn.IFNA(VLOOKUP(A11,'Actual Dates'!A:AE,6,),"") -> 1 | D11: =IF(C11=" "," ",IF(C11=0,VLOOKUP(A11,'Date Calcs'!A:AG,9,),IF(C11=1,VLOOKUP(A11,'Date Calcs'!A:AG,11,),IF(C11=2,VLOOKUP(A11,'Date Calcs'!A:AG,13,),IF(C11=3,VLOOKUP(A11,'Date Calcs'!A:AG,15,),4))))) -> 45812 | E11: =IF(_xlfn.IFNA(IF(D11=" "," ",VLOOKUP(A11,'Actual Dates'!A:AE,20,0)),"")<1,"-",_xlfn.IFNA(IF(D11=" "," ",VLOOKUP(A11,'Actual Dates'!A:AE,20,0)),"")) -> 45805 | F11: =IFERROR(IF(A11="","",D11-Date!$B$3),"") -> -303 | I11: =IF(C11=0,IF(VLOOKUP(A11,Dates,9,)>0,1," "),IF(C11=1,IF(VLOOKUP(A11,Dates,11,)>0,1," "),IF(C11=2,IF(VLOOKUP(A11,Dates,13,)>0,1," "),IF(C11=3,IF(VLOOKUP(A11,Dates,15,)>0,1," "))))) | J11: =VLOOKUP(A11,Dates,7,) -> y
A12: ='Drawing Submittal'!A12 -> 25-015 | B12: =_xlfn.IFNA(VLOOKUP(A12,'Date Calcs'!A:AG,2,),"") -> Kimberly Clark | C12: =_xlfn.IFNA(VLOOKUP(A12,'Actual Dates'!A:AE,6,),"") -> 1 | D12: =IF(C12=" "," ",IF(C12=0,VLOOKUP(A12,'Date Calcs'!A:AG,9,),IF(C12=1,VLOOKUP(A12,'Date Calcs'!A:AG,11,),IF(C12=2,VLOOKUP(A12,'Date Calcs'!A:AG,13,),IF(C12=3,VLOOKUP(A12,'Date Calcs'!A:AG,15,),4))))) -> 45812 | E12: =IF(_xlfn.IFNA(IF(D12=" "," ",VLOOKUP(A12,'Actual Dates'!A:AE,20,0)),"")<1,"-",_xlfn.IFNA(IF(D12=" "," ",VLOOKUP(A12,'Actual Dates'!A:AE,20,0)),"")) -> 45805 | F12: =IFERROR(IF(A12="","",D12-Date!$B$3),"") -> -303 | I12: =IF(C12=0,IF(VLOOKUP(A12,Dates,9,)>0,1," "),IF(C12=1,IF(VLOOKUP(A12,Dates,11,)>0,1," "),IF(C12=2,IF(VLOOKUP(A12,Dates,13,)>0,1," "),IF(C12=3,IF(VLOOKUP(A12,Dates,15,)>0,1," "))))) | J12: =VLOOKUP(A12,Dates,7,) -> y
A13: ='Drawing Submittal'!A13 -> 25-016 | B13: =_xlfn.IFNA(VLOOKUP(A13,'Date Calcs'!A:AG,2,),"") -> Kimberly Clark | C13: =_xlfn.IFNA(VLOOKUP(A13,'Actual Dates'!A:AE,6,),"") -> 1 | D13: =IF(C13=" "," ",IF(C13=0,VLOOKUP(A13,'Date Calcs'!A:AG,9,),IF(C13=1,VLOOKUP(A13,'Date Calcs'!A:AG,11,),IF(C13=2,VLOOKUP(A13,'Date Calcs'!A:AG,13,),IF(C13=3,VLOOKUP(A13,'Date Calcs'!A:AG,15,),4))))) -> 45812 | E13: =IF(_xlfn.IFNA(IF(D13=" "," ",VLOOKUP(A13,'Actual Dates'!A:AE,20,0)),"")<1,"-",_xlfn.IFNA(IF(D13=" "," ",VLOOKUP(A13,'Actual Dates'!A:AE,20,0)),"")) -> 45805 | F13: =IFERROR(IF(A13="","",D13-Date!$B$3),"") -> -303 | I13: =IF(C13=0,IF(VLOOKUP(A13,Dates,9,)>0,1," "),IF(C13=1,IF(VLOOKUP(A13,Dates,11,)>0,1," "),IF(C13=2,IF(VLOOKUP(A13,Dates,13,)>0,1," "),IF(C13=3,IF(VLOOKUP(A13,Dates,15,)>0,1," "))))) | J13: =VLOOKUP(A13,Dates,7,) -> y
A14: ='Drawing Submittal'!A14 -> 25-017 | B14: =_xlfn.IFNA(VLOOKUP(A14,'Date Calcs'!A:AG,2,),"") -> Kimberly Clark | C14: =_xlfn.IFNA(VLOOKUP(A14,'Actual Dates'!A:AE,6,),"") -> 1 | D14: =IF(C14=" "," ",IF(C14=0,VLOOKUP(A14,'Date Calcs'!A:AG,9,),IF(C14=1,VLOOKUP(A14,'Date Calcs'!A:AG,11,),IF(C14=2,VLOOKUP(A14,'Date Calcs'!A:AG,13,),IF(C14=3,VLOOKUP(A14,'Date Calcs'!A:AG,15,),4))))) -> 45776 | E14: =IF(_xlfn.IFNA(IF(D14=" "," ",VLOOKUP(A14,'Actual Dates'!A:AE,20,0)),"")<1,"-",_xlfn.IFNA(IF(D14=" "," ",VLOOKUP(A14,'Actual Dates'!A:AE,20,0)),"")) -> 45769 | F14: =IFERROR(IF(A14="","",D14-Date!$B$3),"") -> -339 | I14: =IF(C14=0,IF(VLOOKUP(A14,Dates,9,)>0,1," "),IF(C14=1,IF(VLOOKUP(A14,Dates,11,)>0,1," "),IF(C14=2,IF(VLOOKUP(A14,Dates,13,)>0,1," "),IF(C14=3,IF(VLOOKUP(A14,Dates,15,)>0,1," "))))) | J14: =VLOOKUP(A14,Dates,7,) -> y
A15: ='Drawing Submittal'!A15 -> 25-018 | B15: =_xlfn.IFNA(VLOOKUP(A15,'Date Calcs'!A:AG,2,),"") -> Kimberly Clark | C15: =_xlfn.IFNA(VLOOKUP(A15,'Actual Dates'!A:AE,6,),"") -> 2 | D15: =IF(C15=" "," ",IF(C15=0,VLOOKUP(A15,'Date Calcs'!A:AG,9,),IF(C15=1,VLOOKUP(A15,'Date Calcs'!A:AG,11,),IF(C15=2,VLOOKUP(A15,'Date Calcs'!A:AG,13,),IF(C15=3,VLOOKUP(A15,'Date Calcs'!A:AG,15,),4))))) -> 45912 | E15: =IF(_xlfn.IFNA(IF(D15=" "," ",VLOOKUP(A15,'Actual Dates'!A:AE,20,0)),"")<1,"-",_xlfn.IFNA(IF(D15=" "," ",VLOOKUP(A15,'Actual Dates'!A:AE,20,0)),"")) -> 45905 | F15: =IFERROR(IF(A15="","",D15-Date!$B$3),"") -> -203 | I15: =IF(C15=0,IF(VLOOKUP(A15,Dates,9,)>0,1," "),IF(C15=1,IF(VLOOKUP(A15,Dates,11,)>0,1," "),IF(C15=2,IF(VLOOKUP(A15,Dates,13,)>0,1," "),IF(C15=3,IF(VLOOKUP(A15,Dates,15,)>0,1," "))))) | J15: =VLOOKUP(A15,Dates,7,) -> y
A16: ='Drawing Submittal'!A16 -> 25-019 | B16: =_xlfn.IFNA(VLOOKUP(A16,'Date Calcs'!A:AG,2,),"") -> Kimberly Clark | C16: =_xlfn.IFNA(VLOOKUP(A16,'Actual Dates'!A:AE,6,),"") -> 2 | D16: =IF(C16=" "," ",IF(C16=0,VLOOKUP(A16,'Date Calcs'!A:AG,9,),IF(C16=1,VLOOKUP(A16,'Date Calcs'!A:AG,11,),IF(C16=2,VLOOKUP(A16,'Date Calcs'!A:AG,13,),IF(C16=3,VLOOKUP(A16,'Date Calcs'!A:AG,15,),4))))) -> 45912 | E16: =IF(_xlfn.IFNA(IF(D16=" "," ",VLOOKUP(A16,'Actual Dates'!A:AE,20,0)),"")<1,"-",_xlfn.IFNA(IF(D16=" "," ",VLOOKUP(A16,'Actual Dates'!A:AE,20,0)),"")) -> 45905 | F16: =IFERROR(IF(A16="","",D16-Date!$B$3),"") -> -203 | I16: =IF(C16=0,IF(VLOOKUP(A16,Dates,9,)>0,1," "),IF(C16=1,IF(VLOOKUP(A16,Dates,11,)>0,1," "),IF(C16=2,IF(VLOOKUP(A16,Dates,13,)>0,1," "),IF(C16=3,IF(VLOOKUP(A16,Dates,15,)>0,1," "))))) | J16: =VLOOKUP(A16,Dates,7,) -> y
A17: ='Drawing Submittal'!A17 -> 25-020 | B17: =_xlfn.IFNA(VLOOKUP(A17,'Date Calcs'!A:AG,2,),"") -> Kimberly Clark | C17: =_xlfn.IFNA(VLOOKUP(A17,'Actual Dates'!A:AE,6,),"") -> 3 | D17: =IF(C17=" "," ",IF(C17=0,VLOOKUP(A17,'Date Calcs'!A:AG,9,),IF(C17=1,VLOOKUP(A17,'Date Calcs'!A:AG,11,),IF(C17=2,VLOOKUP(A17,'Date Calcs'!A:AG,13,),IF(C17=3,VLOOKUP(A17,'Date Calcs'!A:AG,15,),4))))) -> 45902 | E17: =IF(_xlfn.IFNA(IF(D17=" "," ",VLOOKUP(A17,'Actual Dates'!A:AE,20,0)),"")<1,"-",_xlfn.IFNA(IF(D17=" "," ",VLOOKUP(A17,'Actual Dates'!A:AE,20,0)),"")) -> 45895 | F17: =IFERROR(IF(A17="","",D17-Date!$B$3),"") -> -213 | I17: =IF(C17=0,IF(VLOOKUP(A17,Dates,9,)>0,1," "),IF(C17=1,IF(VLOOKUP(A17,Dates,11,)>0,1," "),IF(C17=2,IF(VLOOKUP(A17,Dates,13,)>0,1," "),IF(C17=3,IF(VLOOKUP(A17,Dates,15,)>0,1," "))))) | J17: =VLOOKUP(A17,Dates,7,) -> y
... A34: ='Drawing Submittal'!A34 -> 25-039 | B34: =_xlfn.IFNA(VLOOKUP(A34,'Date Calcs'!A:AG,2,),"") -> Zachry | C34: =_xlfn.IFNA(VLOOKUP(A34,'Actual Dates'!A:AE,6,),"") -> 1 | D34: =IF(C34=" "," ",IF(C34=0,VLOOKUP(A34,'Date Calcs'!A:AG,9,),IF(C34=1,VLOOKUP(A34,'Date Calcs'!A:AG,11,),IF(C34=2,VLOOKUP(A34,'Date Calcs'!A:AG,13,),IF(C34=3,VLOOKUP(A34,'Date Calcs'!A:AG,15,),4))))) -> 45790 | E34: =IF(_xlfn.IFNA(IF(D34=" "," ",VLOOKUP(A34,'Actual Dates'!A:AE,20,0)),"")<1,"-",_xlfn.IFNA(IF(D34=" "," ",VLOOKUP(A34,'Actual Dates'!A:AE,20,0)),"")) -> 45783 | F34: =IFERROR(IF(A34="","",D34-Date!$B$3),"") -> -325 | I34: =IF(C34=0,IF(VLOOKUP(A34,Dates,9,)>0,1," "),IF(C34=1,IF(VLOOKUP(A34,Dates,11,)>0,1," "),IF(C34=2,IF(VLOOKUP(A34,Dates,13,)>0,1," "),IF(C34=3,IF(VLOOKUP(A34,Dates,15,)>0,1," "))))) | J34: =VLOOKUP(A34,Dates,7,) -> y
A35: ='Drawing Submittal'!A35 -> 25-040 | B35: =_xlfn.IFNA(VLOOKUP(A35,'Date Calcs'!A:AG,2,),"") -> NAK Kiln | C35: =_xlfn.IFNA(VLOOKUP(A35,'Actual Dates'!A:AE,6,),"") -> 1 | D35: =IF(C35=" "," ",IF(C35=0,VLOOKUP(A35,'Date Calcs'!A:AG,9,),IF(C35=1,VLOOKUP(A35,'Date Calcs'!A:AG,11,),IF(C35=2,VLOOKUP(A35,'Date Calcs'!A:AG,13,),IF(C35=3,VLOOKUP(A35,'Date Calcs'!A:AG,15,),4))))) -> 45736 | E35: =IF(_xlfn.IFNA(IF(D35=" "," ",VLOOKUP(A35,'Actual Dates'!A:AE,20,0)),"")<1,"-",_xlfn.IFNA(IF(D35=" "," ",VLOOKUP(A35,'Actual Dates'!A:AE,20,0)),"")) -> 45729 | F35: =IFERROR(IF(A35="","",D35-Date!$B$3),"") -> -379 | I35: =IF(C35=0,IF(VLOOKUP(A35,Dates,9,)>0,1," "),IF(C35=1,IF(VLOOKUP(A35,Dates,11,)>0,1," "),IF(C35=2,IF(VLOOKUP(A35,Dates,13,)>0,1," "),IF(C35=3,IF(VLOOKUP(A35,Dates,15,)>0,1," "))))) | J35: Y
A36: ='Drawing Submittal'!A36 -> 25-042 | B36: =_xlfn.IFNA(VLOOKUP(A36,'Date Calcs'!A:AG,2,),"") -> Andritz | C36: =_xlfn.IFNA(VLOOKUP(A36,'Actual Dates'!A:AE,6,),"") -> 2 | D36: =IF(C36=" "," ",IF(C36=0,VLOOKUP(A36,'Date Calcs'!A:AG,9,),IF(C36=1,VLOOKUP(A36,'Date Calcs'!A:AG,11,),IF(C36=2,VLOOKUP(A36,'Date Calcs'!A:AG,13,),IF(C36=3,VLOOKUP(A36,'Date Calcs'!A:AG,15,),4))))) -> 45806 | E36: =IF(_xlfn.IFNA(IF(D36=" "," ",VLOOKUP(A36,'Actual Dates'!A:AE,20,0)),"")<1,"-",_xlfn.IFNA(IF(D36=" "," ",VLOOKUP(A36,'Actual Dates'!A:AE,20,0)),"")) -> 45799 | F36: =IFERROR(IF(A36="","",D36-Date!$B$3),"") -> -309 | I36: =IF(C36=0,IF(VLOOKUP(A36,Dates,9,)>0,1," "),IF(C36=1,IF(VLOOKUP(A36,Dates,11,)>0,1," "),IF(C36=2,IF(VLOOKUP(A36,Dates,13,)>0,1," "),IF(C36=3,IF(VLOOKUP(A36,Dates,15,)>0,1," "))))) | J36: Y
A37: ='Drawing Submittal'!A37 -> 25-044 | B37: =_xlfn.IFNA(VLOOKUP(A37,'Date Calcs'!A:AG,2,),"") -> Noah Industrial | C37: =_xlfn.IFNA(VLOOKUP(A37,'Actual Dates'!A:AE,6,),"") -> 2 | D37: =IF(C37=" "," ",IF(C37=0,VLOOKUP(A37,'Date Calcs'!A:AG,9,),IF(C37=1,VLOOKUP(A37,'Date Calcs'!A:AG,11,),IF(C37=2,VLOOKUP(A37,'Date Calcs'!A:AG,13,),IF(C37=3,VLOOKUP(A37,'Date Calcs'!A:AG,15,),4))))) -> 45814 | E37: =IF(_xlfn.IFNA(IF(D37=" "," ",VLOOKUP(A37,'Actual Dates'!A:AE,20,0)),"")<1,"-",_xlfn.IFNA(IF(D37=" "," ",VLOOKUP(A37,'Actual Dates'!A:AE,20,0)),"")) -> 45807 | F37: =IFERROR(IF(A37="","",D37-Date!$B$3),"") -> -301 | I37: =IF(C37=0,IF(VLOOKUP(A37,Dates,9,)>0,1," "),IF(C37=1,IF(VLOOKUP(A37,Dates,11,)>0,1," "),IF(C37=2,IF(VLOOKUP(A37,Dates,13,)>0,1," "),IF(C37=3,IF(VLOOKUP(A37,Dates,15,)>0,1," "))))) | J37: Y
A38: ='Drawing Submittal'!A38 -> 25-045 | B38: =_xlfn.IFNA(VLOOKUP(A38,'Date Calcs'!A:AG,2,),"") -> ProPipe | C38: =_xlfn.IFNA(VLOOKUP(A38,'Actual Dates'!A:AE,6,),"") -> 3 | D38: =IF(C38=" "," ",IF(C38=0,VLOOKUP(A38,'Date Calcs'!A:AG,9,),IF(C38=1,VLOOKUP(A38,'Date Calcs'!A:AG,11,),IF(C38=2,VLOOKUP(A38,'Date Calcs'!A:AG,13,),IF(C38=3,VLOOKUP(A38,'Date Calcs'!A:AG,15,),4))))) -> 46029 | E38: =IF(_xlfn.IFNA(IF(D38=" "," ",VLOOKUP(A38,'Actual Dates'!A:AE,20,0)),"")<1,"-",_xlfn.IFNA(IF(D38=" "," ",VLOOKUP(A38,'Actual Dates'!A:AE,20,0)),"")) -> - | F38: =IFERROR(IF(A38="","",D38-Date!$B$3),"") -> -86 | I38: =IF(C38=0,IF(VLOOKUP(A38,Dates,9,)>0,1," "),IF(C38=1,IF(VLOOKUP(A38,Dates,11,)>0,1," "),IF(C38=2,IF(VLOOKUP(A38,Dates,13,)>0,1," "),IF(C38=3,IF(VLOOKUP(A38,Dates,15,)>0,1," "))))) -> 1 | J38: Y
A39: ='Drawing Submittal'!A39 -> 25-052 | B39: =_xlfn.IFNA(VLOOKUP(A39,'Date Calcs'!A:AG,2,),"") -> Kraton | C39: =_xlfn.IFNA(VLOOKUP(A39,'Actual Dates'!A:AE,6,),"") -> 3 | D39: =IF(C39=" "," ",IF(C39=0,VLOOKUP(A39,'Date Calcs'!A:AG,9,),IF(C39=1,VLOOKUP(A39,'Date Calcs'!A:AG,11,),IF(C39=2,VLOOKUP(A39,'Date Calcs'!A:AG,13,),IF(C39=3,VLOOKUP(A39,'Date Calcs'!A:AG,15,),4))))) -> 45874 | E39: =IF(_xlfn.IFNA(IF(D39=" "," ",VLOOKUP(A39,'Actual Dates'!A:AE,20,0)),"")<1,"-",_xlfn.IFNA(IF(D39=" "," ",VLOOKUP(A39,'Actual Dates'!A:AE,20,0)),"")) -> 45867 | F39: =IFERROR(IF(A39="","",D39-Date!$B$3),"") -> -241 | I39: =IF(C39=0,IF(VLOOKUP(A39,Dates,9,)>0,1," "),IF(C39=1,IF(VLOOKUP(A39,Dates,11,)>0,1," "),IF(C39=2,IF(VLOOKUP(A39,Dates,13,)>0,1," "),IF(C39=3,IF(VLOOKUP(A39,Dates,15,)>0,1," "))))) | J39: Y
A40: ='Drawing Submittal'!A40 -> 25-053 | B40: =_xlfn.IFNA(VLOOKUP(A40,'Date Calcs'!A:AG,2,),"") -> Andritz | C40: =_xlfn.IFNA(VLOOKUP(A40,'Actual Dates'!A:AE,6,),"") | D40: =IF(C40=" "," ",IF(C40=0,VLOOKUP(A40,'Date Calcs'!A:AG,9,),IF(C40=1,VLOOKUP(A40,'Date Calcs'!A:AG,11,),IF(C40=2,VLOOKUP(A40,'Date Calcs'!A:AG,13,),IF(C40=3,VLOOKUP(A40,'Date Calcs'!A:AG,15,),4))))) | E40: =IF(_xlfn.IFNA(IF(D40=" "," ",VLOOKUP(A40,'Actual Dates'!A:AE,20,0)),"")<1,"-",_xlfn.IFNA(IF(D40=" "," ",VLOOKUP(A40,'Actual Dates'!A:AE,20,0)),"")) | F40: =IFERROR(IF(A40="","",D40-Date!$B$3),"") | I40: =IF(C40=0,IF(VLOOKUP(A40,Dates,9,)>0,1," "),IF(C40=1,IF(VLOOKUP(A40,Dates,11,)>0,1," "),IF(C40=2,IF(VLOOKUP(A40,Dates,13,)>0,1," "),IF(C40=3,IF(VLOOKUP(A40,Dates,15,)>0,1," "))))) -> FALSE | J40: =VLOOKUP(A40,Dates,7,)
