Workbook

Sheet Build Plan w Hours
A1: Job #: | B1: 005-25
B2: Description: | C2: ='Sheet2-PASTE HERE!'!B1 -> P-50 REPLACEMENT | F2: Delivery Date: | G2: ='Sheet2-PASTE HERE!'!A13 -> 0
F4: Completed By
A5: Work Center | C5: Op # | D5: Task | E5: Est Hours | F5: Name | G5: Date | H5: QC Sign Off
A7: ='Sheet2-PASTE HERE!'!A17 -> PRE FAB | C7: ='Sheet2-PASTE HERE!'!I17 -> .010 | D7: ='Sheet2-PASTE HERE!'!K17 -> Receive Material | E7: ='Sheet2-PASTE HERE!'!F17 -> 0 | K7: =IF(A7="INSPECTION",1,0) -> 0 | L7: =IF(LEFT(C7,3)=".OI",1,0) -> 0
A8: ='Sheet2-PASTE HERE!'!A18 -> INSPECTION | C8: ='Sheet2-PASTE HERE!'!I18 -> .QC1 | D8: ='Sheet2-PASTE HERE!'!K18 -> UT top and bottom heads | E8: ='Sheet2-PASTE HERE!'!F18 -> 0 | K8: =IF(A8="INSPECTION",1,0) -> 1 | L8: =IF(LEFT(C8,3)=".OI",1,0) -> 0
A9: ='Sheet2-PASTE HERE!'!A19 -> PRE FAB | C9: ='Sheet2-PASTE HERE!'!I19 -> .100 | D9: ='Sheet2-PASTE HERE!'!K19 -> Cut nozzle pipe and clean | E9: ='Sheet2-PASTE HERE!'!F19 -> 7 | K9: =IF(A9="INSPECTION",1,0) -> 0 | L9: =IF(LEFT(C9,3)=".OI",1,0) -> 0
A10: ='Sheet2-PASTE HERE!'!A20 -> PRE FAB | C10: ='Sheet2-PASTE HERE!'!I20 -> .105 | D10: ='Sheet2-PASTE HERE!'!K20 -> Build nozzles and weld | E10: ='Sheet2-PASTE HERE!'!F20 -> 10 | K10: =IF(A10="INSPECTION",1,0) -> 0 | L10: =IF(LEFT(C10,3)=".OI",1,0) -> 0
A11: ='Sheet2-PASTE HERE!'!A21 -> PRE FAB | C11: ='Sheet2-PASTE HERE!'!I21 -> .107 | D11: ='Sheet2-PASTE HERE!'!K21 -> Build Repads for Nozzles, drill and tap holes | E11: ='Sheet2-PASTE HERE!'!F21 -> 2 | K11: =IF(A11="INSPECTION",1,0) -> 0 | L11: =IF(LEFT(C11,3)=".OI",1,0) -> 0
A12: ='Sheet2-PASTE HERE!'!A22 -> PRE FAB | C12: ='Sheet2-PASTE HERE!'!I22 -> .110 | D12: ='Sheet2-PASTE HERE!'!K22 -> Build dip tubes and weld_x000D_ A1 & A3 | E12: ='Sheet2-PASTE HERE!'!F22 -> 4 | K12: =IF(A12="INSPECTION",1,0) -> 0 | L12: =IF(LEFT(C12,3)=".OI",1,0) -> 0
A13: ='Sheet2-PASTE HERE!'!A23 -> PRE FAB | C13: ='Sheet2-PASTE HERE!'!I23 -> .115 | D13: ='Sheet2-PASTE HERE!'!K23 -> Make manway parts: cut clips, form handles, etc. | E13: ='Sheet2-PASTE HERE!'!F23 -> 1 | K13: =IF(A13="INSPECTION",1,0) -> 0 | L13: =IF(LEFT(C13,3)=".OI",1,0) -> 0
A14: ='Sheet2-PASTE HERE!'!A24 -> PRE FAB | C14: ='Sheet2-PASTE HERE!'!I24 -> .120 | D14: ='Sheet2-PASTE HERE!'!K24 -> Burn manway neck (CHECK BEFORE BURNING) - Clean and Bevel | E14: ='Sheet2-PASTE HERE!'!F24 -> 1 | K14: =IF(A14="INSPECTION",1,0) -> 0 | L14: =IF(LEFT(C14,3)=".OI",1,0) -> 0
A15: ='Sheet2-PASTE HERE!'!A25 -> PRE FAB | C15: ='Sheet2-PASTE HERE!'!I25 -> .125 | D15: ='Sheet2-PASTE HERE!'!K25 -> Roll manway neck | E15: ='Sheet2-PASTE HERE!'!F25 -> 1 | K15: =IF(A15="INSPECTION",1,0) -> 0 | L15: =IF(LEFT(C15,3)=".OI",1,0) -> 0
A16: ='Sheet2-PASTE HERE!'!A26 -> PRE FAB | C16: ='Sheet2-PASTE HERE!'!I26 -> .130 | D16: ='Sheet2-PASTE HERE!'!K26 -> Set up and weld manway flange and neck seam | E16: ='Sheet2-PASTE HERE!'!F26 -> 2 | K16: =IF(A16="INSPECTION",1,0) -> 0 | L16: =IF(LEFT(C16,3)=".OI",1,0) -> 0
A17: ='Sheet2-PASTE HERE!'!A27 -> PRE FAB | C17: ='Sheet2-PASTE HERE!'!I27 -> .135 | D17: ='Sheet2-PASTE HERE!'!K27 -> Build davit arm assembly and cover | E17: ='Sheet2-PASTE HERE!'!F27 -> 2 | K17: =IF(A17="INSPECTION",1,0) -> 0 | L17: =IF(LEFT(C17,3)=".OI",1,0) -> 0
A18: ='Sheet2-PASTE HERE!'!A28 -> PRE FAB | C18: ='Sheet2-PASTE HERE!'!I28 -> .155 | D18: ='Sheet2-PASTE HERE!'!K28 -> Burn and clean parts: lugs, supports, repads, base ring, etc. (CHECK!) | E18: ='Sheet2-PASTE HERE!'!F28 -> 18 | K18: =IF(A18="INSPECTION",1,0) -> 0 | L18: =IF(LEFT(C18,3)=".OI",1,0) -> 0
... A100: ='Sheet2-PASTE HERE!'!A110 -> 0 | C100: ='Sheet2-PASTE HERE!'!I110 -> 0 | D100: ='Sheet2-PASTE HERE!'!K110 -> 0 | E100: ='Sheet2-PASTE HERE!'!F110 -> 0 | K100: =IF(A100="INSPECTION",1,0) -> 0 | L100: =IF(LEFT(C100,3)=".OI",1,0) -> 0

Sheet Build Plan - No Hours
A1: Job #: | B1: 005-25
B2: Description: | C2: ='Sheet2-PASTE HERE!'!B1 -> P-50 REPLACEMENT | F2: Delivery Date: | G2: ='Sheet2-PASTE HERE!'!A13 -> 0
F4: Completed By
A5: Work Center | C5: Op # | D5: Task | E5: Est Hours | F5: Name | G5: Date | H5: QC Sign Off
A7: ='Sheet2-PASTE HERE!'!A17 -> PRE FAB | C7: ='Sheet2-PASTE HERE!'!I17 -> .010 | D7: ='Sheet2-PASTE HERE!'!K17 -> Receive Material | E7: ='Sheet2-PASTE HERE!'!F17 -> 0 | K7: =IF(A7="INSPECTION",1,0) -> 0 | L7: =IF(LEFT(C7,3)=".OI",1,0) -> 0
A8: ='Sheet2-PASTE HERE!'!A18 -> INSPECTION | C8: ='Sheet2-PASTE HERE!'!I18 -> .QC1 | D8: ='Sheet2-PASTE HERE!'!K18 -> UT top and bottom heads | E8: ='Sheet2-PASTE HERE!'!F18 -> 0 | K8: =IF(A8="INSPECTION",1,0) -> 1 | L8: =IF(LEFT(C8,3)=".OI",1,0) -> 0
A9: ='Sheet2-PASTE HERE!'!A19 -> PRE FAB | C9: ='Sheet2-PASTE HERE!'!I19 -> .100 | D9: ='Sheet2-PASTE HERE!'!K19 -> Cut nozzle pipe and clean | E9: ='Sheet2-PASTE HERE!'!F19 -> 7 | K9: =IF(A9="INSPECTION",1,0) -> 0 | L9: =IF(LEFT(C9,3)=".OI",1,0) -> 0
A10: ='Sheet2-PASTE HERE!'!A20 -> PRE FAB | C10: ='Sheet2-PASTE HERE!'!I20 -> .105 | D10: ='Sheet2-PASTE HERE!'!K20 -> Build nozzles and weld | E10: ='Sheet2-PASTE HERE!'!F20 -> 10 | K10: =IF(A10="INSPECTION",1,0) -> 0 | L10: =IF(LEFT(C10,3)=".OI",1,0) -> 0
A11: ='Sheet2-PASTE HERE!'!A21 -> PRE FAB | C11: ='Sheet2-PASTE HERE!'!I21 -> .107 | D11: ='Sheet2-PASTE HERE!'!K21 -> Build Repads for Nozzles, drill and tap holes | E11: ='Sheet2-PASTE HERE!'!F21 -> 2 | K11: =IF(A11="INSPECTION",1,0) -> 0 | L11: =IF(LEFT(C11,3)=".OI",1,0) -> 0
A12: ='Sheet2-PASTE HERE!'!A22 -> PRE FAB | C12: ='Sheet2-PASTE HERE!'!I22 -> .110 | D12: ='Sheet2-PASTE HERE!'!K22 -> Build dip tubes and weld_x000D_ A1 & A3 | E12: ='Sheet2-PASTE HERE!'!F22 -> 4 | K12: =IF(A12="INSPECTION",1,0) -> 0 | L12: =IF(LEFT(C12,3)=".OI",1,0) -> 0
A13: ='Sheet2-PASTE HERE!'!A23 -> PRE FAB | C13: ='Sheet2-PASTE HERE!'!I23 -> .115 | D13: ='Sheet2-PASTE HERE!'!K23 -> Make manway parts: cut clips, form handles, etc. | E13: ='Sheet2-PASTE HERE!'!F23 -> 1 | K13: =IF(A13="INSPECTION",1,0) -> 0 | L13: =IF(LEFT(C13,3)=".OI",1,0) -> 0
A14: ='Sheet2-PASTE HERE!'!A24 -> PRE FAB | C14: ='Sheet2-PASTE HERE!'!I24 -> .120 | D14: ='Sheet2-PASTE HERE!'!K24 -> Burn manway neck (CHECK BEFORE BURNING) - Clean and Bevel | E14: ='Sheet2-PASTE HERE!'!F24 -> 1 | K14: =IF(A14="INSPECTION",1,0) -> 0 | L14: =IF(LEFT(C14,3)=".OI",1,0) -> 0
A15: ='Sheet2-PASTE HERE!'!A25 -> PRE FAB | C15: ='Sheet2-PASTE HERE!'!I25 -> .125 | D15: ='Sheet2-PASTE HERE!'!K25 -> Roll manway neck | E15: ='Sheet2-PASTE HERE!'!F25 -> 1 | K15: =IF(A15="INSPECTION",1,0) -> 0 | L15: =IF(LEFT(C15,3)=".OI",1,0) -> 0
A16: ='Sheet2-PASTE HERE!'!A26 -> PRE FAB | C16: ='Sheet2-PASTE HERE!'!I26 -> .130 | D16: ='Sheet2-PASTE HERE!'!K26 -> Set up and weld manway flange and neck seam | E16: ='Sheet2-PASTE HERE!'!F26 -> 2 | K16: =IF(A16="INSPECTION",1,0) -> 0 | L16: =IF(LEFT(C16,3)=".OI",1,0) -> 0
A17: ='Sheet2-PASTE HERE!'!A27 -> PRE FAB | C17: ='Sheet2-PASTE HERE!'!I27 -> .135 | D17: ='Sheet2-PASTE HERE!'!K27 -> Build davit arm assembly and cover | E17: ='Sheet2-PASTE HERE!'!F27 -> 2 | K17: =IF(A17="INSPECTION",1,0) -> 0 | L17: =IF(LEFT(C17,3)=".OI",1,0) -> 0
A18: ='Sheet2-PASTE HERE!'!A28 -> PRE FAB | C18: ='Sheet2-PASTE HERE!'!I28 -> .155 | D18: ='Sheet2-PASTE HERE!'!K28 -> Burn and clean parts: lugs, supports, repads, base ring, etc. (CHECK!) | E18: ='Sheet2-PASTE HERE!'!F28 -> 18 | K18: =IF(A18="INSPECTION",1,0) -> 0 | L18: =IF(LEFT(C18,3)=".OI",1,0) -> 0
... A100: ='Sheet2-PASTE HERE!'!A110 -> 0 | C100: ='Sheet2-PASTE HERE!'!I110 -> 0 | D100: ='Sheet2-PASTE HERE!'!K110 -> 0 | E100: ='Sheet2-PASTE HERE!'!F110 -> 0 | K100: =IF(A100="INSPECTION",1,0) -> 0 | L100: =IF(LEFT(C100,3)=".OI",1,0) -> 0

Sheet Sheet2-PASTE HERE!
A1: Part: | B1: P-50 REPLACEMENT | C1: Customer PO: | D1: 4505134262 | E1: Quote: | F1: 9128 | G1: P-50 REPLACEMENT | H1: Line: | L1: Rev: | N1: Drawing: | R1: Order Qty: | S1: 1 | T1: / | U1: ea | V1: Order Date: | W1: 45678 | Y1: Make Qty: | Z1: 1 | AA1: / | AB1: ea | AC1: Est Hours: | AD1: 203
A3: Job Notes:
B7: Linked SO Lines | C7: Sales Order | D7: Part | E7: Order Qty | F7: Remaining Qty | G7: Due Date | H7: SO Line | I7: Description | J7: Customer
B12: Delivery Schedule | C12: Promised Date | D12: Promised Quantity | E12: Remaining Quantity | F12: Comments
B16: Routing | C16: Comments | D16: WC/Vendor | E16: Sch Start | F16: Oper/Serv | G16: Operation Key | H16: Sch End | I16: Description | J16: Setup | K16: Run Rate | L16: Run | M16: Name | N16: Date | O16: QC SignOff
A17: PRE FAB | B17: 51279 | C17: 0 | D17: Receive Material | E17: 0 | F17: 0 | G17: FixedHrs | H17: 0 | I17: .010 | J17: 0 | K17: Receive Material | L17: _________________ | M17: _________________ | N17: _________________
A18: INSPECTION | B18: 51280 | C18: 0 | D18: UT Top & Bottom Heads | E18: 0 | F18: 0 | G18: FixedHrs | H18: 0 | I18: .QC1 | J18: 0 | K18: UT top and bottom heads | L18: _________________ | M18: _________________ | N18: _________________
A19: PRE FAB | B19: 51281 | C19: 0 | D19: Cut Nozzle Pipe and Clean | E19: 0 | F19: 7 | G19: FixedHrs | H19: 7 | I19: .100 | J19: 0 | K19: Cut nozzle pipe and clean | L19: _________________ | M19: _________________ | N19: _________________
A20: PRE FAB | B20: 51282 | C20: 0 | D20: Build Nozzles-Weld | E20: 0 | F20: 10 | G20: FixedHrs | H20: 10 | I20: .105 | J20: 0 | K20: Build nozzles and weld | L20: _________________ | M20: _________________ | N20: _________________
A21: PRE FAB | B21: 51283 | C21: 0 | D21: Build Repads for Nozzles | E21: 0 | F21: 2 | G21: FixedHrs | H21: 2 | I21: .107 | J21: 0 | K21: Build Repads for Nozzles, drill and tap holes | L21: _________________ | M21: _________________ | N21: _________________
A22: PRE FAB | B22: 51284 | C22: 0 | D22: Build Dip Tubes-Weld | E22: 0 | F22: 4 | G22: FixedHrs | H22: 4 | I22: .110 | J22: 0 | K22: Build dip tubes and weld_x000D_ A1 & A3 | L22: _________________ | M22: _________________ | N22: _________________
A23: PRE FAB | B23: 51285 | C23: 0 | D23: Make Manway Parts | E23: 0 | F23: 1 | G23: FixedHrs | H23: 1 | I23: .115 | J23: 0 | K23: Make manway parts: cut clips, form handles, etc. | L23: _________________ | M23: _________________ | N23: _________________
A24: PRE FAB | B24: 51286 | C24: 0 | D24: Brn MW Neck, Clean, Bevel | E24: 0 | F24: 1 | G24: FixedHrs | H24: 1 | I24: .120 | J24: 0 | K24: Burn manway neck (CHECK BEFORE BURNING) - Clean and Bevel | L24: _________________ | M24: _________________ | N24: _________________
A25: PRE FAB | B25: 51287 | C25: 0 | D25: Roll Manway Neck | E25: 0 | F25: 1 | G25: FixedHrs | H25: 1 | I25: .125 | J25: 0 | K25: Roll manway neck | L25: _________________ | M25: _________________ | N25: _________________
A26: PRE FAB | B26: 51288 | C26: 0 | D26: S/U Weld MW Flg, Neck Sem | E26: 0 | F26: 2 | G26: FixedHrs | H26: 2 | I26: .130 | J26: 0 | K26: Set up and weld manway flange and neck seam | L26: _________________ | M26: _________________ | N26: _________________
A27: PRE FAB | B27: 51289 | C27: 0 | D27: Bld Davit Arm Aby Cover | E27: 0 | F27: 2 | G27: FixedHrs | H27: 2 | I27: .135 | J27: 0 | K27: Build davit arm assembly and cover | L27: _________________ | M27: _________________ | N27: _________________
A28: PRE FAB | B28: 51290 | C28: 0 | D28: Cut Parts on Burn Table | E28: 0 | F28: 18 | G28: FixedHrs | H28: 18 | I28: .155 | J28: 0 | K28: Burn and clean parts: lugs, supports, repads, base ring, etc. (CHECK!) | L28: _________________ | M28: _________________ | N28: _________________
A29: PRE FAB | B29: 51291 | C29: 0 | D29: Clean & Prep Parts | E29: 0 | F29: 7 | G29: FixedHrs | H29: 7 | I29: .156 | J29: 0 | L29: _________________ | M29: _________________ | N29: _________________
A30: PRE FAB | B30: 51292 | C30: 0 | D30: Build Supports | E30: 0 | F30: 6 | G30: FixedHrs | H30: 6 | I30: .165 | J30: 0 | K30: Build supports: legs, lugs, saddles_x000D_ MAKE (4) TOP COUPLING SUPPORTS & (4) BASE PLATES | L30: _________________ | M30: _________________ | N30: _________________
A31: PRE FAB | B31: 51293 | C31: 0 | D31: Bld Lift Lugs, Grd Lugs | E31: 0 | F31: 2 | G31: FixedHrs | H31: 2 | I31: .200 | J31: 0 | K31: Make lift lugs, ground lugs, etc. | L31: _________________ | M31: _________________ | N31: _________________
A32: PRE FAB | B32: 51294 | C32: 0 | D32: Cut, Make Baffle Supports | E32: 0 | F32: 3 | G32: FixedHrs | H32: 3 | I32: .225 | J32: 0 | K32: Cut and make baffle supports_x000D_ MAKE (6) BAFFLE SUPPORTS | L32: _________________ | M32: _________________ | N32: _________________
A33: PRE FAB | B33: 51295 | C33: 0 | D33: Build Baffles-Weld | E33: 0 | F33: 4 | G33: FixedHrs | H33: 4 | I33: .230 | J33: 0 | K33: Build baffles and weld_x000D_ MAKE (2) BAFFLES | L33: _________________ | M33: _________________ | N33: _________________
A34: PRE FAB | B34: 51296 | C34: 0 | D34: Wrap Top & Bottom Heads | E34: 0 | F34: 1 | G34: FixedHrs | H34: 1 | I34: .300 | J34: 0 | K34: Wrap top and bottom heads | L34: _________________ | M34: _________________ | N34: _________________
A35: INSPECTION | B35: 51297 | C35: 0 | D35: UT Shells | E35: 0 | F35: 0 | G35: FixedHrs | H35: 0 | I35: .QC3 | J35: 0 | K35: UT Shells | L35: _________________ | M35: _________________ | N35: _________________
A36: PRE FAB | B36: 51298 | C36: 0 | D36: BI, SQ, T&C Shells | E36: 0 | F36: 5 | G36: FixedHrs | H36: 5 | I36: .305 | J36: 0 | K36: Shells: bring in plate, square, trim and clean_x000D_ MAKE (1) DOUBLE SHELL | L36: _________________ | M36: _________________ | N36: _________________
A37: PRE FAB | B37: 51299 | C37: 0 | D37: Roll Shell, Tack-Weld I/S | E37: 0 | F37: 4 | G37: FixedHrs | H37: 4 | I37: .315 | J37: 0 | K37: Roll shells, tack and weld inside seams_x000D_ ROLL (1) DOUBLE SHELL; WELD O/S SEAM W/COBOT | L37: _________________ | M37: _________________ | N37: _________________
A38: INSPECTION | B38: 51300 | C38: 0 | D38: QC Inspection -Top/Bot/Co | E38: 0 | F38: 0 | G38: FixedHrs | H38: 0 | I38: .QC4 | J38: 0 | K38: QC Inspection - Top/Bottom/Cones | L38: _________________ | M38: _________________ | N38: _________________
A39: PRE FAB | B39: 51301 | C39: 0 | D39: L/O Top, B&C Holes | E39: 0 | F39: 2 | G39: FixedHrs | H39: 2 | I39: .355 | J39: 0 | K39: Lay out top head, burn and clean holes_x000D_ ON BURN TABLE | L39: _________________ | M39: _________________ | N39: _________________
A40: PRE FAB | B40: 51302 | C40: 0 | D40: Bevel Top Head | E40: 0 | F40: 5 | G40: FixedHrs | H40: 5 | I40: .360 | J40: 0 | K40: Bevel top head_x000D_ PREP NOZZLE OPENINGS FOR FULL PEN WELDS | L40: _________________ | M40: _________________ | N40: _________________
A41: PRE FAB | B41: 51303 | C41: 0 | D41: Set Nozzles & Lugs - Top | E41: 0 | F41: 7 | G41: FixedHrs | H41: 7 | I41: .365 | J41: 0 | K41: Set nozzles, lift lugs, etc. in top head - tack_x000D_ INCL (2) LIFT LUGS | L41: _________________ | M41: _________________ | N41: _________________
... A73: SHIPPING | B73: 51335 | C73: 0 | D73: Load on Truck | E73: 0 | F73: 3 | G73: FixedHrs | H73: 3 | I73: .960 | J73: 0 | K73: Load on truck | L73: _________________ | M73: _________________ | N73: _________________
B75: Part: | C75: P-50 REPLACEMENT | G75: Rev:

Sheet Tasks with Hours
A1: Job #: | B1: ='Build Plan w Hours'!B$1 -> 005-25 | C1: Description | E1: Assigned | G1: Hrs Used | I1: % Compl.
A2: Op #: | B2: ='Build Plan w Hours'!C7 -> .010 | C2: ='Build Plan w Hours'!D7 -> Receive Material
A4: Hours | B4: ='Build Plan w Hours'!E7 -> 0
A5: _
A7: Job #: | B7: ='Build Plan w Hours'!B$1 -> 005-25 | C7: Description | E7: Assigned | G7: Hrs Used | I7: % Compl.
A8: Op #: | B8: ='Build Plan w Hours'!C8 -> .QC1 | C8: ='Build Plan w Hours'!D8 -> UT top and bottom heads
A10: Hours | B10: ='Build Plan w Hours'!E8 -> 0
A11: _
A13: Job #: | B13: ='Build Plan w Hours'!B$1 -> 005-25 | C13: Description | E13: Assigned | G13: Hrs Used | I13: % Compl.
A14: Op #: | B14: ='Build Plan w Hours'!C9 -> .100 | C14: ='Build Plan w Hours'!D9 -> Cut nozzle pipe and clean
A16: Hours | B16: ='Build Plan w Hours'!E9 -> 7
A17: _
A19: Job #: | B19: ='Build Plan w Hours'!B$1 -> 005-25 | C19: Description | E19: Assigned | G19: Hrs Used | I19: % Compl.
A20: Op #: | B20: ='Build Plan w Hours'!C10 -> .105 | C20: ='Build Plan w Hours'!D10 -> Build nozzles and weld
A22: Hours | B22: ='Build Plan w Hours'!E10 -> 10
A23: _
A25: Job #: | B25: ='Build Plan w Hours'!B$1 -> 005-25 | C25: Description | E25: Assigned | G25: Hrs Used | I25: % Compl.
A26: Op #: | B26: ='Build Plan w Hours'!C11 -> .107 | C26: ='Build Plan w Hours'!D11 -> Build Repads for Nozzles, drill and tap holes
A28: Hours | B28: ='Build Plan w Hours'!E11 -> 2
A29: _
A31: Job #: | B31: ='Build Plan w Hours'!B$1 -> 005-25 | C31: Description | E31: Assigned | G31: Hrs Used | I31: % Compl.
A32: Op #: | B32: ='Build Plan w Hours'!C12 -> .110 | C32: ='Build Plan w Hours'!D12 -> Build dip tubes and weld_x000D_ A1 & A3
A34: Hours | B34: ='Build Plan w Hours'!E12 -> 4
A35: _
A37: Job #: | B37: ='Build Plan w Hours'!B$1 -> 005-25 | C37: Description | E37: Assigned | G37: Hrs Used | I37: % Compl.
A38: Op #: | B38: ='Build Plan w Hours'!C13 -> .115 | C38: ='Build Plan w Hours'!D13 -> Make manway parts: cut clips, form handles, etc.
A40: Hours | B40: ='Build Plan w Hours'!E13 -> 1
A41: _
A43: Job #: | B43: ='Build Plan w Hours'!B$1 -> 005-25 | C43: Description | E43: Assigned | G43: Hrs Used | I43: % Compl.
A44: Op #: | B44: ='Build Plan w Hours'!C14 -> .120 | C44: ='Build Plan w Hours'!D14 -> Burn manway neck (CHECK BEFORE BURNING) - Clean and Bevel
A46: Hours | B46: ='Build Plan w Hours'!E14 -> 1
A47: _
A49: Job #: | B49: ='Build Plan w Hours'!B$1 -> 005-25 | C49: Description | E49: Assigned | G49: Hrs Used | I49: % Compl.
A50: Op #: | B50: ='Build Plan w Hours'!C15 -> .125 | C50: ='Build Plan w Hours'!D15 -> Roll manway neck
A52: Hours | B52: ='Build Plan w Hours'!E15 -> 1
A53: _
A55: Job #: | B55: ='Build Plan w Hours'!B$1 -> 005-25 | C55: Description | E55: Assigned | G55: Hrs Used | I55: % Compl.
A56: Op #: | B56: ='Build Plan w Hours'!C16 -> .130 | C56: ='Build Plan w Hours'!D16 -> Set up and weld manway flange and neck seam
A58: Hours | B58: ='Build Plan w Hours'!E16 -> 2
A59: _
...

Sheet Tasks - No Hours
A1: Job #: | B1: ='Build Plan w Hours'!B$1 -> 005-25 | C1: Description | E1: Assigned | G1: Hrs Used | I1: % Compl.
A2: Op #: | B2: ='Build Plan w Hours'!C7 -> .010 | C2: ='Build Plan w Hours'!D7 -> Receive Material
A5: _
A7: Job #: | B7: ='Build Plan w Hours'!B$1 -> 005-25 | C7: Description | E7: Assigned | G7: Hrs Used | I7: % Compl.
A8: Op #: | B8: ='Build Plan w Hours'!C8 -> .QC1 | C8: ='Build Plan w Hours'!D8 -> UT top and bottom heads
A11: _
A13: Job #: | B13: ='Build Plan w Hours'!B$1 -> 005-25 | C13: Description | E13: Assigned | G13: Hrs Used | I13: % Compl.
A14: Op #: | B14: ='Build Plan w Hours'!C9 -> .100 | C14: ='Build Plan w Hours'!D9 -> Cut nozzle pipe and clean
A17: _
A19: Job #: | B19: ='Build Plan w Hours'!B$1 -> 005-25 | C19: Description | E19: Assigned | G19: Hrs Used | I19: % Compl.
A20: Op #: | B20: ='Build Plan w Hours'!C10 -> .105 | C20: ='Build Plan w Hours'!D10 -> Build nozzles and weld
A23: _
A25: Job #: | B25: ='Build Plan w Hours'!B$1 -> 005-25 | C25: Description | E25: Assigned | G25: Hrs Used | I25: % Compl.
A26: Op #: | B26: ='Build Plan w Hours'!C11 -> .107 | C26: ='Build Plan w Hours'!D11 -> Build Repads for Nozzles, drill and tap holes
A29: _
A31: Job #: | B31: ='Build Plan w Hours'!B$1 -> 005-25 | C31: Description | E31: Assigned | G31: Hrs Used | I31: % Compl.
A32: Op #: | B32: ='Build Plan w Hours'!C12 -> .110 | C32: ='Build Plan w Hours'!D12 -> Build dip tubes and weld_x000D_ A1 & A3
A35: _
A37: Job #: | B37: ='Build Plan w Hours'!B$1 -> 005-25 | C37: Description | E37: Assigned | G37: Hrs Used | I37: % Compl.
A38: Op #: | B38: ='Build Plan w Hours'!C13 -> .115 | C38: ='Build Plan w Hours'!D13 -> Make manway parts: cut clips, form handles, etc.
A41: _
A43: Job #: | B43: ='Build Plan w Hours'!B$1 -> 005-25 | C43: Description | E43: Assigned | G43: Hrs Used | I43: % Compl.
A44: Op #: | B44: ='Build Plan w Hours'!C14 -> .120 | C44: ='Build Plan w Hours'!D14 -> Burn manway neck (CHECK BEFORE BURNING) - Clean and Bevel
A47: _
A49: Job #: | B49: ='Build Plan w Hours'!B$1 -> 005-25 | C49: Description | E49: Assigned | G49: Hrs Used | I49: % Compl.
A50: Op #: | B50: ='Build Plan w Hours'!C15 -> .125 | C50: ='Build Plan w Hours'!D15 -> Roll manway neck
A53: _
A55: Job #: | B55: ='Build Plan w Hours'!B$1 -> 005-25 | C55: Description | E55: Assigned | G55: Hrs Used | I55: % Compl.
A56: Op #: | B56: ='Build Plan w Hours'!C16 -> .130 | C56: ='Build Plan w Hours'!D16 -> Set up and weld manway flange and neck seam
A59: _
A61: Job #: | B61: ='Build Plan w Hours'!B$1 -> 005-25 | C61: Description | E61: Assigned | G61: Hrs Used | I61: % Compl.
A62: Op #: | B62: ='Build Plan w Hours'!C17 -> .135 | C62: ='Build Plan w Hours'!D17 -> Build davit arm assembly and cover
A65: _
A67: Job #: | B67: ='Build Plan w Hours'!B$1 -> 005-25 | C67: Description | E67: Assigned | G67: Hrs Used | I67: % Compl.
A68: Op #: | B68: ='Build Plan w Hours'!C18 -> .155 | C68: ='Build Plan w Hours'!D18 -> Burn and clean parts: lugs, supports, repads, base ring, etc. (CHECK!)
A71: _
A73: Job #: | B73: ='Build Plan w Hours'!B$1 -> 005-25 | C73: Description | E73: Assigned | G73: Hrs Used | I73: % Compl.
A74: Op #: | B74: ='Build Plan w Hours'!C19 -> .156 | C74: ='Build Plan w Hours'!D19
A77: _
A79: Job #: | B79: ='Build Plan w Hours'!B$1 -> 005-25 | C79: Description | E79: Assigned | G79: Hrs Used | I79: % Compl.
...
