Workbook
Name Dates: '[1]Actual Dates'!$A$4:$AB$349
Name Dates: '[1]Actual Dates'!$A$4:$AB$349
Name Dates: 'Actual Dates'!$A$4:$AF$157
Name Jobs: '[1]Date Calcs'!$A$4:$AB$349
Name Jobs: '[1]Date Calcs'!$A$4:$AB$349
Name Jobs: 'Date Calcs'!$A$5:$AF$133
Name Ship: 'Date Calcs from Ship Date'!$A$5:$AE$133

Sheet Drawing Submittal
A1: Drawing Submittal
F2: On Track
F3: At Risk
F4: Late | I4: No Y | J4: No Y
A5: Job # | B5: Customer | C5: Rev. | D5: Target | E5: Actual | F5: Days +/- | G5: Status | I5: Submitted | J5: Approved
A6: 24-046 | B6: =VLOOKUP(A6,'Date Calcs'!A:B,2,) -> SYMS Engineering | C6: =VLOOKUP(A6,'Actual Dates'!A:AF,18,) -> 4 | D6: =IF(C6=0,VLOOKUP(A6,'Date Calcs'!A:AF,8,),IF(C6=1,VLOOKUP(A6,'Date Calcs'!A:AF,10,),IF(C6=2,VLOOKUP(A6,'Date Calcs'!A:AF,12,),IF(C6=3,VLOOKUP(A6,'Date Calcs'!A:AF,14,),4)))) -> 4 | F6: =ROUND(IF(A6="","",IF(E6=0,D6-Date!$B$3,D6-E6)),0) -> -46069 | I6: =IF(VLOOKUP(A6,Dates,2,)="N","N",IF(VLOOKUP(A6,Dates,3,)="N","N",IF(VLOOKUP(A6,Dates,4,)="N","N",IF(VLOOKUP(A6,Dates,5,)="N","N","Y")))) -> Y | J6: =VLOOKUP(A6,Dates,7,) -> y
A7: 24-047 | B7: =VLOOKUP(A7,'Date Calcs'!A:B,2,) -> #N/A | C7: =VLOOKUP(A7,'Actual Dates'!A:AF,18,) -> #N/A | D7: =IF(C7=0,VLOOKUP(A7,'Date Calcs'!A:AF,8,),IF(C7=1,VLOOKUP(A7,'Date Calcs'!A:AF,10,),IF(C7=2,VLOOKUP(A7,'Date Calcs'!A:AF,12,),IF(C7=3,VLOOKUP(A7,'Date Calcs'!A:AF,14,),4)))) -> #N/A | F7: =ROUND(IF(A7="","",IF(E7=0,D7-Date!$B$3,D7-E7)),0) -> #N/A | I7: =IF(VLOOKUP(A7,Dates,2,)="N","N",IF(VLOOKUP(A7,Dates,3,)="N","N",IF(VLOOKUP(A7,Dates,4,)="N","N",IF(VLOOKUP(A7,Dates,5,)="N","N","Y")))) -> #N/A | J7: =VLOOKUP(A7,Dates,7,) -> #N/A
A8: 24-048 | B8: =VLOOKUP(A8,'Date Calcs'!A:B,2,) -> #N/A | C8: =VLOOKUP(A8,'Actual Dates'!A:AF,18,) -> #N/A | D8: =IF(C8=0,VLOOKUP(A8,'Date Calcs'!A:AF,8,),IF(C8=1,VLOOKUP(A8,'Date Calcs'!A:AF,10,),IF(C8=2,VLOOKUP(A8,'Date Calcs'!A:AF,12,),IF(C8=3,VLOOKUP(A8,'Date Calcs'!A:AF,14,),4)))) -> #N/A | F8: =ROUND(IF(A8="","",IF(E8=0,D8-Date!$B$3,D8-E8)),0) -> #N/A | I8: =IF(VLOOKUP(A8,Dates,2,)="N","N",IF(VLOOKUP(A8,Dates,3,)="N","N",IF(VLOOKUP(A8,Dates,4,)="N","N",IF(VLOOKUP(A8,Dates,5,)="N","N","Y")))) -> #N/A | J8: =VLOOKUP(A8,Dates,7,) -> #N/A
A9: 25-052 | B9: =VLOOKUP(A9,'Date Calcs'!A:B,2,) -> Kraton | C9: =VLOOKUP(A9,'Actual Dates'!A:AF,18,) -> 4 | D9: =IF(C9=0,VLOOKUP(A9,'Date Calcs'!A:AF,8,),IF(C9=1,VLOOKUP(A9,'Date Calcs'!A:AF,10,),IF(C9=2,VLOOKUP(A9,'Date Calcs'!A:AF,12,),IF(C9=3,VLOOKUP(A9,'Date Calcs'!A:AF,14,),4)))) -> 4 | F9: =ROUND(IF(A9="","",IF(E9=0,D9-Date!$B$3,D9-E9)),0) -> -46069 | I9: =IF(VLOOKUP(A9,Dates,2,)="N","N",IF(VLOOKUP(A9,Dates,3,)="N","N",IF(VLOOKUP(A9,Dates,4,)="N","N",IF(VLOOKUP(A9,Dates,5,)="N","N","Y")))) -> Y | J9: =VLOOKUP(A9,Dates,7,) -> y
A10: 25-053 | B10: =VLOOKUP(A10,'Date Calcs'!A:B,2,) -> Andritz | C10: =VLOOKUP(A10,'Actual Dates'!A:AF,18,) -> 0 | D10: =IF(C10=0,VLOOKUP(A10,'Date Calcs'!A:AF,8,),IF(C10=1,VLOOKUP(A10,'Date Calcs'!A:AF,10,),IF(C10=2,VLOOKUP(A10,'Date Calcs'!A:AF,12,),IF(C10=3,VLOOKUP(A10,'Date Calcs'!A:AF,14,),4)))) -> 46027 | F10: =ROUND(IF(A10="","",IF(E10=0,D10-Date!$B$3,D10-E10)),0) -> -46 | I10: =IF(VLOOKUP(A10,Dates,2,)="N","N",IF(VLOOKUP(A10,Dates,3,)="N","N",IF(VLOOKUP(A10,Dates,4,)="N","N",IF(VLOOKUP(A10,Dates,5,)="N","N","Y")))) -> N | J10: =VLOOKUP(A10,Dates,7,) | K10: Spool piece 4A-1 CERTIFIED on 8/22/25
A11: 25-054 | B11: =VLOOKUP(A11,'Date Calcs'!A:B,2,) -> Chromascape | C11: =VLOOKUP(A11,'Actual Dates'!A:AF,18,) -> 3 | D11: =IF(C11=0,VLOOKUP(A11,'Date Calcs'!A:AF,8,),IF(C11=1,VLOOKUP(A11,'Date Calcs'!A:AF,10,),IF(C11=2,VLOOKUP(A11,'Date Calcs'!A:AF,12,),IF(C11=3,VLOOKUP(A11,'Date Calcs'!A:AF,14,),4)))) -> 45869 | F11: =ROUND(IF(A11="","",IF(E11=0,D11-Date!$B$3,D11-E11)),0) -> -204 | I11: =IF(VLOOKUP(A11,Dates,2,)="N","N",IF(VLOOKUP(A11,Dates,3,)="N","N",IF(VLOOKUP(A11,Dates,4,)="N","N",IF(VLOOKUP(A11,Dates,5,)="N","N","Y")))) -> Y | J11: =VLOOKUP(A11,Dates,7,) -> y
A12: 25-055 | B12: =VLOOKUP(A12,'Date Calcs'!A:B,2,) -> Airgas | C12: =VLOOKUP(A12,'Actual Dates'!A:AF,18,) -> 2 | D12: =IF(C12=0,VLOOKUP(A12,'Date Calcs'!A:AF,8,),IF(C12=1,VLOOKUP(A12,'Date Calcs'!A:AF,10,),IF(C12=2,VLOOKUP(A12,'Date Calcs'!A:AF,12,),IF(C12=3,VLOOKUP(A12,'Date Calcs'!A:AF,14,),4)))) -> 46022 | F12: =ROUND(IF(A12="","",IF(E12=0,D12-Date!$B$3,D12-E12)),0) -> -51 | I12: =IF(VLOOKUP(A12,Dates,2,)="N","N",IF(VLOOKUP(A12,Dates,3,)="N","N",IF(VLOOKUP(A12,Dates,4,)="N","N",IF(VLOOKUP(A12,Dates,5,)="N","N","Y")))) -> Y | J12: =VLOOKUP(A12,Dates,7,) -> y
A13: 25-077 | B13: =VLOOKUP(A13,'Date Calcs'!A:B,2,) -> Epic Systems | C13: =VLOOKUP(A13,'Actual Dates'!A:AF,18,) -> 3 | D13: =IF(C13=0,VLOOKUP(A13,'Date Calcs'!A:AF,8,),IF(C13=1,VLOOKUP(A13,'Date Calcs'!A:AF,10,),IF(C13=2,VLOOKUP(A13,'Date Calcs'!A:AF,12,),IF(C13=3,VLOOKUP(A13,'Date Calcs'!A:AF,14,),4)))) -> 45908 | F13: =ROUND(IF(A13="","",IF(E13=0,D13-Date!$B$3,D13-E13)),0) -> -165 | I13: =IF(VLOOKUP(A13,Dates,2,)="N","N",IF(VLOOKUP(A13,Dates,3,)="N","N",IF(VLOOKUP(A13,Dates,4,)="N","N",IF(VLOOKUP(A13,Dates,5,)="N","N","Y")))) -> Y | J13: =VLOOKUP(A13,Dates,7,) -> y
A14: 25-078 | B14: =VLOOKUP(A14,'Date Calcs'!A:B,2,) -> Epic Systems | C14: =VLOOKUP(A14,'Actual Dates'!A:AF,18,) -> 3 | D14: =IF(C14=0,VLOOKUP(A14,'Date Calcs'!A:AF,8,),IF(C14=1,VLOOKUP(A14,'Date Calcs'!A:AF,10,),IF(C14=2,VLOOKUP(A14,'Date Calcs'!A:AF,12,),IF(C14=3,VLOOKUP(A14,'Date Calcs'!A:AF,14,),4)))) -> 45908 | F14: =ROUND(IF(A14="","",IF(E14=0,D14-Date!$B$3,D14-E14)),0) -> -165 | I14: =IF(VLOOKUP(A14,Dates,2,)="N","N",IF(VLOOKUP(A14,Dates,3,)="N","N",IF(VLOOKUP(A14,Dates,4,)="N","N",IF(VLOOKUP(A14,Dates,5,)="N","N","Y")))) -> Y | J14: =VLOOKUP(A14,Dates,7,) -> y
A15: 25-079 | B15: =VLOOKUP(A15,'Date Calcs'!A:B,2,) -> Epic Systems | C15: =VLOOKUP(A15,'Actual Dates'!A:AF,18,) -> 3 | D15: =IF(C15=0,VLOOKUP(A15,'Date Calcs'!A:AF,8,),IF(C15=1,VLOOKUP(A15,'Date Calcs'!A:AF,10,),IF(C15=2,VLOOKUP(A15,'Date Calcs'!A:AF,12,),IF(C15=3,VLOOKUP(A15,'Date Calcs'!A:AF,14,),4)))) -> 45908 | F15: =ROUND(IF(A15="","",IF(E15=0,D15-Date!$B$3,D15-E15)),0) -> -165 | I15: =IF(VLOOKUP(A15,Dates,2,)="N","N",IF(VLOOKUP(A15,Dates,3,)="N","N",IF(VLOOKUP(A15,Dates,4,)="N","N",IF(VLOOKUP(A15,Dates,5,)="N","N","Y")))) -> Y | J15: =VLOOKUP(A15,Dates,7,) -> y
A16: 25-080 | B16: =VLOOKUP(A16,'Date Calcs'!A:B,2,) -> Domtar | C16: =VLOOKUP(A16,'Actual Dates'!A:AF,18,) -> 2 | D16: =IF(C16=0,VLOOKUP(A16,'Date Calcs'!A:AF,8,),IF(C16=1,VLOOKUP(A16,'Date Calcs'!A:AF,10,),IF(C16=2,VLOOKUP(A16,'Date Calcs'!A:AF,12,),IF(C16=3,VLOOKUP(A16,'Date Calcs'!A:AF,14,),4)))) -> 45904 | F16: =ROUND(IF(A16="","",IF(E16=0,D16-Date!$B$3,D16-E16)),0) -> -169 | I16: =IF(VLOOKUP(A16,Dates,2,)="N","N",IF(VLOOKUP(A16,Dates,3,)="N","N",IF(VLOOKUP(A16,Dates,4,)="N","N",IF(VLOOKUP(A16,Dates,5,)="N","N","Y")))) -> Y | J16: =VLOOKUP(A16,Dates,7,) -> y
A17: 25-083 | B17: =VLOOKUP(A17,'Date Calcs'!A:B,2,) -> Synthomer | C17: =VLOOKUP(A17,'Actual Dates'!A:AF,18,) -> 3 | D17: =IF(C17=0,VLOOKUP(A17,'Date Calcs'!A:AF,8,),IF(C17=1,VLOOKUP(A17,'Date Calcs'!A:AF,10,),IF(C17=2,VLOOKUP(A17,'Date Calcs'!A:AF,12,),IF(C17=3,VLOOKUP(A17,'Date Calcs'!A:AF,14,),4)))) -> 46062 | F17: =ROUND(IF(A17="","",IF(E17=0,D17-Date!$B$3,D17-E17)),0) -> -11 | I17: =IF(VLOOKUP(A17,Dates,2,)="N","N",IF(VLOOKUP(A17,Dates,3,)="N","N",IF(VLOOKUP(A17,Dates,4,)="N","N",IF(VLOOKUP(A17,Dates,5,)="N","N","Y")))) -> N | J17: =VLOOKUP(A17,Dates,7,) -> y
A18: 25-084 | B18: =VLOOKUP(A18,'Date Calcs'!A:B,2,) -> Atlas Minerals | C18: =VLOOKUP(A18,'Actual Dates'!A:AF,18,) -> 4 | D18: =IF(C18=0,VLOOKUP(A18,'Date Calcs'!A:AF,8,),IF(C18=1,VLOOKUP(A18,'Date Calcs'!A:AF,10,),IF(C18=2,VLOOKUP(A18,'Date Calcs'!A:AF,12,),IF(C18=3,VLOOKUP(A18,'Date Calcs'!A:AF,14,),4)))) -> 4 | F18: =ROUND(IF(A18="","",IF(E18=0,D18-Date!$B$3,D18-E18)),0) -> -46069 | I18: =IF(VLOOKUP(A18,Dates,2,)="N","N",IF(VLOOKUP(A18,Dates,3,)="N","N",IF(VLOOKUP(A18,Dates,4,)="N","N",IF(VLOOKUP(A18,Dates,5,)="N","N","Y")))) -> Y | J18: =VLOOKUP(A18,Dates,7,) -> y
A19: 25-085 | B19: =VLOOKUP(A19,'Date Calcs'!A:B,2,) -> Noah Industrial | C19: =VLOOKUP(A19,'Actual Dates'!A:AF,18,) -> 2 | D19: =IF(C19=0,VLOOKUP(A19,'Date Calcs'!A:AF,8,),IF(C19=1,VLOOKUP(A19,'Date Calcs'!A:AF,10,),IF(C19=2,VLOOKUP(A19,'Date Calcs'!A:AF,12,),IF(C19=3,VLOOKUP(A19,'Date Calcs'!A:AF,14,),4)))) -> 45902 | F19: =ROUND(IF(A19="","",IF(E19=0,D19-Date!$B$3,D19-E19)),0) -> -171 | I19: =IF(VLOOKUP(A19,Dates,2,)="N","N",IF(VLOOKUP(A19,Dates,3,)="N","N",IF(VLOOKUP(A19,Dates,4,)="N","N",IF(VLOOKUP(A19,Dates,5,)="N","N","Y")))) -> Y | J19: =VLOOKUP(A19,Dates,7,) -> y
A20: 25-087 | B20: =VLOOKUP(A20,'Date Calcs'!A:B,2,) -> Solvay | C20: =VLOOKUP(A20,'Actual Dates'!A:AF,18,) -> 2 | D20: =IF(C20=0,VLOOKUP(A20,'Date Calcs'!A:AF,8,),IF(C20=1,VLOOKUP(A20,'Date Calcs'!A:AF,10,),IF(C20=2,VLOOKUP(A20,'Date Calcs'!A:AF,12,),IF(C20=3,VLOOKUP(A20,'Date Calcs'!A:AF,14,),4)))) -> 45929 | F20: =ROUND(IF(A20="","",IF(E20=0,D20-Date!$B$3,D20-E20)),0) -> -144 | I20: =IF(VLOOKUP(A20,Dates,2,)="N","N",IF(VLOOKUP(A20,Dates,3,)="N","N",IF(VLOOKUP(A20,Dates,4,)="N","N",IF(VLOOKUP(A20,Dates,5,)="N","N","Y")))) -> Y | J20: =VLOOKUP(A20,Dates,7,) -> y
A21: 25-088 | B21: =VLOOKUP(A21,'Date Calcs'!A:B,2,) -> CIL Isotopes | C21: =VLOOKUP(A21,'Actual Dates'!A:AF,18,) -> 2 | D21: =IF(C21=0,VLOOKUP(A21,'Date Calcs'!A:AF,8,),IF(C21=1,VLOOKUP(A21,'Date Calcs'!A:AF,10,),IF(C21=2,VLOOKUP(A21,'Date Calcs'!A:AF,12,),IF(C21=3,VLOOKUP(A21,'Date Calcs'!A:AF,14,),4)))) -> 45929 | F21: =ROUND(IF(A21="","",IF(E21=0,D21-Date!$B$3,D21-E21)),0) -> -144 | I21: =IF(VLOOKUP(A21,Dates,2,)="N","N",IF(VLOOKUP(A21,Dates,3,)="N","N",IF(VLOOKUP(A21,Dates,4,)="N","N",IF(VLOOKUP(A21,Dates,5,)="N","N","Y")))) -> Y | J21: =VLOOKUP(A21,Dates,7,) -> y
A22: 25-089 | B22: =VLOOKUP(A22,'Date Calcs'!A:B,2,) -> Valmet | C22: =VLOOKUP(A22,'Actual Dates'!A:AF,18,) -> 2 | D22: =IF(C22=0,VLOOKUP(A22,'Date Calcs'!A:AF,8,),IF(C22=1,VLOOKUP(A22,'Date Calcs'!A:AF,10,),IF(C22=2,VLOOKUP(A22,'Date Calcs'!A:AF,12,),IF(C22=3,VLOOKUP(A22,'Date Calcs'!A:AF,14,),4)))) -> 46009 | F22: =ROUND(IF(A22="","",IF(E22=0,D22-Date!$B$3,D22-E22)),0) -> -64 | I22: =IF(VLOOKUP(A22,Dates,2,)="N","N",IF(VLOOKUP(A22,Dates,3,)="N","N",IF(VLOOKUP(A22,Dates,4,)="N","N",IF(VLOOKUP(A22,Dates,5,)="N","N","Y")))) -> Y | J22: =VLOOKUP(A22,Dates,7,) -> y | L22: RS
A23: 25-090 | B23: =VLOOKUP(A23,'Date Calcs'!A:B,2,) -> GAF | C23: =VLOOKUP(A23,'Actual Dates'!A:AF,18,) -> 1 | D23: =IF(C23=0,VLOOKUP(A23,'Date Calcs'!A:AF,8,),IF(C23=1,VLOOKUP(A23,'Date Calcs'!A:AF,10,),IF(C23=2,VLOOKUP(A23,'Date Calcs'!A:AF,12,),IF(C23=3,VLOOKUP(A23,'Date Calcs'!A:AF,14,),4)))) -> 45912 | F23: =ROUND(IF(A23="","",IF(E23=0,D23-Date!$B$3,D23-E23)),0) -> -161 | I23: =IF(VLOOKUP(A23,Dates,2,)="N","N",IF(VLOOKUP(A23,Dates,3,)="N","N",IF(VLOOKUP(A23,Dates,4,)="N","N",IF(VLOOKUP(A23,Dates,5,)="N","N","Y")))) -> Y | J23: =VLOOKUP(A23,Dates,7,) -> y
A24: 25-092 | B24: =VLOOKUP(A24,'Date Calcs'!A:B,2,) -> Symrise | C24: =VLOOKUP(A24,'Actual Dates'!A:AF,18,) -> 3 | D24: =IF(C24=0,VLOOKUP(A24,'Date Calcs'!A:AF,8,),IF(C24=1,VLOOKUP(A24,'Date Calcs'!A:AF,10,),IF(C24=2,VLOOKUP(A24,'Date Calcs'!A:AF,12,),IF(C24=3,VLOOKUP(A24,'Date Calcs'!A:AF,14,),4)))) -> 45971 | F24: =ROUND(IF(A24="","",IF(E24=0,D24-Date!$B$3,D24-E24)),0) -> -102 | I24: =IF(VLOOKUP(A24,Dates,2,)="N","N",IF(VLOOKUP(A24,Dates,3,)="N","N",IF(VLOOKUP(A24,Dates,4,)="N","N",IF(VLOOKUP(A24,Dates,5,)="N","N","Y")))) -> Y | J24: =VLOOKUP(A24,Dates,7,) -> y
A25: 25-093 | B25: =VLOOKUP(A25,'Date Calcs'!A:B,2,) -> Symrise | C25: =VLOOKUP(A25,'Actual Dates'!A:AF,18,) -> 3 | D25: =IF(C25=0,VLOOKUP(A25,'Date Calcs'!A:AF,8,),IF(C25=1,VLOOKUP(A25,'Date Calcs'!A:AF,10,),IF(C25=2,VLOOKUP(A25,'Date Calcs'!A:AF,12,),IF(C25=3,VLOOKUP(A25,'Date Calcs'!A:AF,14,),4)))) -> 45971 | F25: =ROUND(IF(A25="","",IF(E25=0,D25-Date!$B$3,D25-E25)),0) -> -102 | I25: =IF(VLOOKUP(A25,Dates,2,)="N","N",IF(VLOOKUP(A25,Dates,3,)="N","N",IF(VLOOKUP(A25,Dates,4,)="N","N",IF(VLOOKUP(A25,Dates,5,)="N","N","Y")))) -> Y | J25: =VLOOKUP(A25,Dates,7,) -> y
A26: 25-094 | B26: =VLOOKUP(A26,'Date Calcs'!A:B,2,) -> Kimberly Clark | C26: =VLOOKUP(A26,'Actual Dates'!A:AF,18,) -> 2 | D26: =IF(C26=0,VLOOKUP(A26,'Date Calcs'!A:AF,8,),IF(C26=1,VLOOKUP(A26,'Date Calcs'!A:AF,10,),IF(C26=2,VLOOKUP(A26,'Date Calcs'!A:AF,12,),IF(C26=3,VLOOKUP(A26,'Date Calcs'!A:AF,14,),4)))) -> 45993 | F26: =ROUND(IF(A26="","",IF(E26=0,D26-Date!$B$3,D26-E26)),0) -> -80 | I26: =IF(VLOOKUP(A26,Dates,2,)="N","N",IF(VLOOKUP(A26,Dates,3,)="N","N",IF(VLOOKUP(A26,Dates,4,)="N","N",IF(VLOOKUP(A26,Dates,5,)="N","N","Y")))) -> Y | J26: =VLOOKUP(A26,Dates,7,) -> y
A27: 25-095 | B27: =VLOOKUP(A27,'Date Calcs'!A:B,2,) -> Andritz | C27: =VLOOKUP(A27,'Actual Dates'!A:AF,18,) -> 3 | D27: =IF(C27=0,VLOOKUP(A27,'Date Calcs'!A:AF,8,),IF(C27=1,VLOOKUP(A27,'Date Calcs'!A:AF,10,),IF(C27=2,VLOOKUP(A27,'Date Calcs'!A:AF,12,),IF(C27=3,VLOOKUP(A27,'Date Calcs'!A:AF,14,),4)))) -> 46080 | F27: =ROUND(IF(A27="","",IF(E27=0,D27-Date!$B$3,D27-E27)),0) -> 7 | I27: =IF(VLOOKUP(A27,Dates,2,)="N","N",IF(VLOOKUP(A27,Dates,3,)="N","N",IF(VLOOKUP(A27,Dates,4,)="N","N",IF(VLOOKUP(A27,Dates,5,)="N","N","Y")))) -> Y | J27: =VLOOKUP(A27,Dates,7,)
A28: 25-096 | B28: =VLOOKUP(A28,'Date Calcs'!A:B,2,) -> Milliken | C28: =VLOOKUP(A28,'Actual Dates'!A:AF,18,) -> 2 | D28: =IF(C28=0,VLOOKUP(A28,'Date Calcs'!A:AF,8,),IF(C28=1,VLOOKUP(A28,'Date Calcs'!A:AF,10,),IF(C28=2,VLOOKUP(A28,'Date Calcs'!A:AF,12,),IF(C28=3,VLOOKUP(A28,'Date Calcs'!A:AF,14,),4)))) -> 45967 | F28: =ROUND(IF(A28="","",IF(E28=0,D28-Date!$B$3,D28-E28)),0) -> -106 | I28: =IF(VLOOKUP(A28,Dates,2,)="N","N",IF(VLOOKUP(A28,Dates,3,)="N","N",IF(VLOOKUP(A28,Dates,4,)="N","N",IF(VLOOKUP(A28,Dates,5,)="N","N","Y")))) -> Y | J28: =VLOOKUP(A28,Dates,7,) -> y
A29: 25-097 | B29: =VLOOKUP(A29,'Date Calcs'!A:B,2,) -> Milliken | C29: =VLOOKUP(A29,'Actual Dates'!A:AF,18,) -> 2 | D29: =IF(C29=0,VLOOKUP(A29,'Date Calcs'!A:AF,8,),IF(C29=1,VLOOKUP(A29,'Date Calcs'!A:AF,10,),IF(C29=2,VLOOKUP(A29,'Date Calcs'!A:AF,12,),IF(C29=3,VLOOKUP(A29,'Date Calcs'!A:AF,14,),4)))) -> 45967 | F29: =ROUND(IF(A29="","",IF(E29=0,D29-Date!$B$3,D29-E29)),0) -> -106 | I29: =IF(VLOOKUP(A29,Dates,2,)="N","N",IF(VLOOKUP(A29,Dates,3,)="N","N",IF(VLOOKUP(A29,Dates,4,)="N","N",IF(VLOOKUP(A29,Dates,5,)="N","N","Y")))) -> Y | J29: =VLOOKUP(A29,Dates,7,) -> y
A30: 25-098 | B30: =VLOOKUP(A30,'Date Calcs'!A:B,2,) -> Coastal Technologies | C30: =VLOOKUP(A30,'Actual Dates'!A:AF,18,) -> 2 | D30: =IF(C30=0,VLOOKUP(A30,'Date Calcs'!A:AF,8,),IF(C30=1,VLOOKUP(A30,'Date Calcs'!A:AF,10,),IF(C30=2,VLOOKUP(A30,'Date Calcs'!A:AF,12,),IF(C30=3,VLOOKUP(A30,'Date Calcs'!A:AF,14,),4)))) -> 45974 | F30: =ROUND(IF(A30="","",IF(E30=0,D30-Date!$B$3,D30-E30)),0) -> -99 | I30: =IF(VLOOKUP(A30,Dates,2,)="N","N",IF(VLOOKUP(A30,Dates,3,)="N","N",IF(VLOOKUP(A30,Dates,4,)="N","N",IF(VLOOKUP(A30,Dates,5,)="N","N","Y")))) -> Y | J30: =VLOOKUP(A30,Dates,7,) -> y
A31: 25-099 | B31: =VLOOKUP(A31,'Date Calcs'!A:B,2,) -> Burke Industrial | C31: =VLOOKUP(A31,'Actual Dates'!A:AF,18,) -> 2 | D31: =IF(C31=0,VLOOKUP(A31,'Date Calcs'!A:AF,8,),IF(C31=1,VLOOKUP(A31,'Date Calcs'!A:AF,10,),IF(C31=2,VLOOKUP(A31,'Date Calcs'!A:AF,12,),IF(C31=3,VLOOKUP(A31,'Date Calcs'!A:AF,14,),4)))) -> 45980 | F31: =ROUND(IF(A31="","",IF(E31=0,D31-Date!$B$3,D31-E31)),0) -> -93 | I31: =IF(VLOOKUP(A31,Dates,2,)="N","N",IF(VLOOKUP(A31,Dates,3,)="N","N",IF(VLOOKUP(A31,Dates,4,)="N","N",IF(VLOOKUP(A31,Dates,5,)="N","N","Y")))) -> Y | J31: =VLOOKUP(A31,Dates,7,) -> y
A32: 25-101 | B32: =VLOOKUP(A32,'Date Calcs'!A:B,2,) -> Harper Love | C32: =VLOOKUP(A32,'Actual Dates'!A:AF,18,) -> 2 | D32: =IF(C32=0,VLOOKUP(A32,'Date Calcs'!A:AF,8,),IF(C32=1,VLOOKUP(A32,'Date Calcs'!A:AF,10,),IF(C32=2,VLOOKUP(A32,'Date Calcs'!A:AF,12,),IF(C32=3,VLOOKUP(A32,'Date Calcs'!A:AF,14,),4)))) -> 46013 | F32: =ROUND(IF(A32="","",IF(E32=0,D32-Date!$B$3,D32-E32)),0) -> -60 | I32: =IF(VLOOKUP(A32,Dates,2,)="N","N",IF(VLOOKUP(A32,Dates,3,)="N","N",IF(VLOOKUP(A32,Dates,4,)="N","N",IF(VLOOKUP(A32,Dates,5,)="N","N","Y")))) -> Y | J32: =VLOOKUP(A32,Dates,7,) -> y | L32: RS
A33: 25-102 | B33: =VLOOKUP(A33,'Date Calcs'!A:B,2,) -> Epic Systems | C33: =VLOOKUP(A33,'Actual Dates'!A:AF,18,) -> 3 | D33: =IF(C33=0,VLOOKUP(A33,'Date Calcs'!A:AF,8,),IF(C33=1,VLOOKUP(A33,'Date Calcs'!A:AF,10,),IF(C33=2,VLOOKUP(A33,'Date Calcs'!A:AF,12,),IF(C33=3,VLOOKUP(A33,'Date Calcs'!A:AF,14,),4)))) -> 46079 | F33: =ROUND(IF(A33="","",IF(E33=0,D33-Date!$B$3,D33-E33)),0) -> 6 | I33: =IF(VLOOKUP(A33,Dates,2,)="N","N",IF(VLOOKUP(A33,Dates,3,)="N","N",IF(VLOOKUP(A33,Dates,4,)="N","N",IF(VLOOKUP(A33,Dates,5,)="N","N","Y")))) -> N | J33: =VLOOKUP(A33,Dates,7,)
A34: 25-103 | B34: =VLOOKUP(A34,'Date Calcs'!A:B,2,) -> Epic Systems | C34: =VLOOKUP(A34,'Actual Dates'!A:AF,18,) -> 3 | D34: =IF(C34=0,VLOOKUP(A34,'Date Calcs'!A:AF,8,),IF(C34=1,VLOOKUP(A34,'Date Calcs'!A:AF,10,),IF(C34=2,VLOOKUP(A34,'Date Calcs'!A:AF,12,),IF(C34=3,VLOOKUP(A34,'Date Calcs'!A:AF,14,),4)))) -> 46079 | F34: =ROUND(IF(A34="","",IF(E34=0,D34-Date!$B$3,D34-E34)),0) -> 6 | I34: =IF(VLOOKUP(A34,Dates,2,)="N","N",IF(VLOOKUP(A34,Dates,3,)="N","N",IF(VLOOKUP(A34,Dates,4,)="N","N",IF(VLOOKUP(A34,Dates,5,)="N","N","Y")))) -> N | J34: =VLOOKUP(A34,Dates,7,) -> y
A35: 25-104 | B35: =VLOOKUP(A35,'Date Calcs'!A:B,2,) -> Epic Systems | C35: =VLOOKUP(A35,'Actual Dates'!A:AF,18,) -> 3 | D35: =IF(C35=0,VLOOKUP(A35,'Date Calcs'!A:AF,8,),IF(C35=1,VLOOKUP(A35,'Date Calcs'!A:AF,10,),IF(C35=2,VLOOKUP(A35,'Date Calcs'!A:AF,12,),IF(C35=3,VLOOKUP(A35,'Date Calcs'!A:AF,14,),4)))) -> 46079 | F35: =ROUND(IF(A35="","",IF(E35=0,D35-Date!$B$3,D35-E35)),0) -> 6 | I35: =IF(VLOOKUP(A35,Dates,2,)="N","N",IF(VLOOKUP(A35,Dates,3,)="N","N",IF(VLOOKUP(A35,Dates,4,)="N","N",IF(VLOOKUP(A35,Dates,5,)="N","N","Y")))) -> N | J35: =VLOOKUP(A35,Dates,7,) -> y
A36: 25-105 | B36: =VLOOKUP(A36,'Date Calcs'!A:B,2,) -> Epic Systems | C36: =VLOOKUP(A36,'Actual Dates'!A:AF,18,) -> 3 | D36: =IF(C36=0,VLOOKUP(A36,'Date Calcs'!A:AF,8,),IF(C36=1,VLOOKUP(A36,'Date Calcs'!A:AF,10,),IF(C36=2,VLOOKUP(A36,'Date Calcs'!A:AF,12,),IF(C36=3,VLOOKUP(A36,'Date Calcs'!A:AF,14,),4)))) -> 46079 | F36: =ROUND(IF(A36="","",IF(E36=0,D36-Date!$B$3,D36-E36)),0) -> 6 | I36: =IF(VLOOKUP(A36,Dates,2,)="N","N",IF(VLOOKUP(A36,Dates,3,)="N","N",IF(VLOOKUP(A36,Dates,4,)="N","N",IF(VLOOKUP(A36,Dates,5,)="N","N","Y")))) -> N | J36: =VLOOKUP(A36,Dates,7,) -> y
A37: 25-106 | B37: =VLOOKUP(A37,'Date Calcs'!A:B,2,) -> Epic Systems | C37: =VLOOKUP(A37,'Actual Dates'!A:AF,18,) -> 3 | D37: =IF(C37=0,VLOOKUP(A37,'Date Calcs'!A:AF,8,),IF(C37=1,VLOOKUP(A37,'Date Calcs'!A:AF,10,),IF(C37=2,VLOOKUP(A37,'Date Calcs'!A:AF,12,),IF(C37=3,VLOOKUP(A37,'Date Calcs'!A:AF,14,),4)))) -> 46079 | F37: =ROUND(IF(A37="","",IF(E37=0,D37-Date!$B$3,D37-E37)),0) -> 6 | I37: =IF(VLOOKUP(A37,Dates,2,)="N","N",IF(VLOOKUP(A37,Dates,3,)="N","N",IF(VLOOKUP(A37,Dates,4,)="N","N",IF(VLOOKUP(A37,Dates,5,)="N","N","Y")))) -> N | J37: =VLOOKUP(A37,Dates,7,)
A38: 25-107 | B38: =VLOOKUP(A38,'Date Calcs'!A:B,2,) -> Epic Systems | C38: =VLOOKUP(A38,'Actual Dates'!A:AF,18,) -> 1 | D38: =IF(C38=0,VLOOKUP(A38,'Date Calcs'!A:AF,8,),IF(C38=1,VLOOKUP(A38,'Date Calcs'!A:AF,10,),IF(C38=2,VLOOKUP(A38,'Date Calcs'!A:AF,12,),IF(C38=3,VLOOKUP(A38,'Date Calcs'!A:AF,14,),4)))) -> 46062 | F38: =ROUND(IF(A38="","",IF(E38=0,D38-Date!$B$3,D38-E38)),0) -> -11 | I38: =IF(VLOOKUP(A38,Dates,2,)="N","N",IF(VLOOKUP(A38,Dates,3,)="N","N",IF(VLOOKUP(A38,Dates,4,)="N","N",IF(VLOOKUP(A38,Dates,5,)="N","N","Y")))) -> N | J38: =VLOOKUP(A38,Dates,7,) | L38: Tank size confirmed on 2/9/26 | P38: =D38+14 -> 46076
A39: 25-108 | B39: =VLOOKUP(A39,'Date Calcs'!A:B,2,) -> Epic Systems | C39: =VLOOKUP(A39,'Actual Dates'!A:AF,18,) -> 2 | D39: =IF(C39=0,VLOOKUP(A39,'Date Calcs'!A:AF,8,),IF(C39=1,VLOOKUP(A39,'Date Calcs'!A:AF,10,),IF(C39=2,VLOOKUP(A39,'Date Calcs'!A:AF,12,),IF(C39=3,VLOOKUP(A39,'Date Calcs'!A:AF,14,),4)))) -> 46078 | F39: =ROUND(IF(A39="","",IF(E39=0,D39-Date!$B$3,D39-E39)),0) -> 5 | I39: =IF(VLOOKUP(A39,Dates,2,)="N","N",IF(VLOOKUP(A39,Dates,3,)="N","N",IF(VLOOKUP(A39,Dates,4,)="N","N",IF(VLOOKUP(A39,Dates,5,)="N","N","Y")))) -> Y | J39: =VLOOKUP(A39,Dates,7,)
A40: 25-109 | B40: =VLOOKUP(A40,'Date Calcs'!A:B,2,) -> Epic Systems | C40: =VLOOKUP(A40,'Actual Dates'!A:AF,18,) -> 4 | D40: =IF(C40=0,VLOOKUP(A40,'Date Calcs'!A:AF,8,),IF(C40=1,VLOOKUP(A40,'Date Calcs'!A:AF,10,),IF(C40=2,VLOOKUP(A40,'Date Calcs'!A:AF,12,),IF(C40=3,VLOOKUP(A40,'Date Calcs'!A:AF,14,),4)))) -> 4 | F40: =ROUND(IF(A40="","",IF(E40=0,D40-Date!$B$3,D40-E40)),0) -> -46069 | I40: =IF(VLOOKUP(A40,Dates,2,)="N","N",IF(VLOOKUP(A40,Dates,3,)="N","N",IF(VLOOKUP(A40,Dates,4,)="N","N",IF(VLOOKUP(A40,Dates,5,)="N","N","Y")))) -> Y | J40: =VLOOKUP(A40,Dates,7,) -> y
...

Sheet Cust Dwg Return
A1: Drawing Return From Customer
F2: On Track
F3: At Risk
F4: Late | I4: Blanks only | J4: Blanks only
A5: Job # | B5: Customer | C5: Rev. | D5: Target | E5: Actual | F5: Days +/- | G5: Status | I5: Returned | J5: Approved
A6: 24-046 | B6: =VLOOKUP(A6,'Date Calcs'!A:AF,2,) -> SYMS Engineering | C6: =VLOOKUP(A6,'Actual Dates'!A:AF,6,) -> 3 | D6: =IF(C6=" "," ",IF(C6=0,VLOOKUP(A6,'Date Calcs'!A:AF,9,),IF(C6=1,VLOOKUP(A6,'Date Calcs'!A:AF,11,),IF(C6=2,VLOOKUP(A6,'Date Calcs'!A:AF,13,),IF(C6=3,VLOOKUP(A6,'Date Calcs'!A:AF,15,),4))))) -> 45882 | F6: =IF(A6="","",D6-Date!$B$3) -> -191 | I6: =IF(C6=0,IF(VLOOKUP(A6,Dates,9,)>0,1," "),IF(C6=1,IF(VLOOKUP(A6,Dates,11,)>0,1," "),IF(C6=2,IF(VLOOKUP(A6,Dates,13,)>0,1," "),IF(C6=3,IF(VLOOKUP(A6,Dates,15,)>0,1," "))))) -> 1 | J6: =VLOOKUP(A6,Dates,7,) -> y
A7: 25-052 | B7: =VLOOKUP(A7,Jobs,2,) -> Kraton | C7: =VLOOKUP(A7,Dates,6,) -> 3 | D7: =IF(C7=" "," ",IF(C7=0,VLOOKUP(A7,'Date Calcs'!A:AF,9,),IF(C7=1,VLOOKUP(A7,'Date Calcs'!A:AF,11,),IF(C7=2,VLOOKUP(A7,'Date Calcs'!A:AF,13,),IF(C7=3,VLOOKUP(A7,'Date Calcs'!A:AF,15,),4))))) -> 45874 | F7: =IF(A7="","",D7-Date!$B$3) -> -199 | I7: =IF(C7=0,IF(VLOOKUP(A7,Dates,9,)>0,1," "),IF(C7=1,IF(VLOOKUP(A7,Dates,11,)>0,1," "),IF(C7=2,IF(VLOOKUP(A7,Dates,13,)>0,1," "),IF(C7=3,IF(VLOOKUP(A7,Dates,15,)>0,1," "))))) | J7: =VLOOKUP(A7,Dates,7,) -> y
A8: 25-053 | B8: =VLOOKUP(A8,Jobs,2,) -> Andritz | C8: =VLOOKUP(A8,Dates,6,) | D8: =IF(C8=" "," ",IF(C8=0,VLOOKUP(A8,'Date Calcs'!A:AF,9,),IF(C8=1,VLOOKUP(A8,'Date Calcs'!A:AF,11,),IF(C8=2,VLOOKUP(A8,'Date Calcs'!A:AF,13,),IF(C8=3,VLOOKUP(A8,'Date Calcs'!A:AF,15,),4))))) | F8: =IF(A8="","",D8-Date!$B$3) -> #VALUE! | I8: =IF(C8=0,IF(VLOOKUP(A8,Dates,9,)>0,1," "),IF(C8=1,IF(VLOOKUP(A8,Dates,11,)>0,1," "),IF(C8=2,IF(VLOOKUP(A8,Dates,13,)>0,1," "),IF(C8=3,IF(VLOOKUP(A8,Dates,15,)>0,1," "))))) -> FALSE | J8: =VLOOKUP(A8,Dates,7,)
A9: 25-054 | B9: =VLOOKUP(A9,Jobs,2,) -> Chromascape | C9: =VLOOKUP(A9,Dates,6,) -> 2 | D9: =IF(C9=" "," ",IF(C9=0,VLOOKUP(A9,'Date Calcs'!A:AF,9,),IF(C9=1,VLOOKUP(A9,'Date Calcs'!A:AF,11,),IF(C9=2,VLOOKUP(A9,'Date Calcs'!A:AF,13,),IF(C9=3,VLOOKUP(A9,'Date Calcs'!A:AF,15,),4))))) -> 45862 | F9: =IF(A9="","",D9-Date!$B$3) -> -211 | I9: =IF(C9=0,IF(VLOOKUP(A9,Dates,9,)>0,1," "),IF(C9=1,IF(VLOOKUP(A9,Dates,11,)>0,1," "),IF(C9=2,IF(VLOOKUP(A9,Dates,13,)>0,1," "),IF(C9=3,IF(VLOOKUP(A9,Dates,15,)>0,1," "))))) | J9: =VLOOKUP(A9,Dates,7,) -> y
A10: 25-055 | B10: =VLOOKUP(A10,Jobs,2,) -> Airgas | C10: =VLOOKUP(A10,Dates,6,) -> 1 | D10: =IF(C10=" "," ",IF(C10=0,VLOOKUP(A10,'Date Calcs'!A:AF,9,),IF(C10=1,VLOOKUP(A10,'Date Calcs'!A:AF,11,),IF(C10=2,VLOOKUP(A10,'Date Calcs'!A:AF,13,),IF(C10=3,VLOOKUP(A10,'Date Calcs'!A:AF,15,),4))))) -> 46015 | F10: =IF(A10="","",D10-Date!$B$3) -> -58 | I10: =IF(C10=0,IF(VLOOKUP(A10,Dates,9,)>0,1," "),IF(C10=1,IF(VLOOKUP(A10,Dates,11,)>0,1," "),IF(C10=2,IF(VLOOKUP(A10,Dates,13,)>0,1," "),IF(C10=3,IF(VLOOKUP(A10,Dates,15,)>0,1," "))))) | J10: =VLOOKUP(A10,Dates,7,) -> y
A11: 25-074 | B11: =VLOOKUP(A11,Jobs,2,) -> Kemira | C11: =VLOOKUP(A11,Dates,6,) -> 1 | D11: =IF(C11=" "," ",IF(C11=0,VLOOKUP(A11,'Date Calcs'!A:AF,9,),IF(C11=1,VLOOKUP(A11,'Date Calcs'!A:AF,11,),IF(C11=2,VLOOKUP(A11,'Date Calcs'!A:AF,13,),IF(C11=3,VLOOKUP(A11,'Date Calcs'!A:AF,15,),4))))) -> 45867 | F11: =IF(A11="","",D11-Date!$B$3) -> -206 | I11: =IF(C11=0,IF(VLOOKUP(A11,Dates,9,)>0,1," "),IF(C11=1,IF(VLOOKUP(A11,Dates,11,)>0,1," "),IF(C11=2,IF(VLOOKUP(A11,Dates,13,)>0,1," "),IF(C11=3,IF(VLOOKUP(A11,Dates,15,)>0,1," "))))) | J11: =VLOOKUP(A11,Dates,7,) -> y
A12: 25-075 | B12: =VLOOKUP(A12,Jobs,2,) -> Kemira | C12: =VLOOKUP(A12,Dates,6,) -> 2 | D12: =IF(C12=" "," ",IF(C12=0,VLOOKUP(A12,'Date Calcs'!A:AF,9,),IF(C12=1,VLOOKUP(A12,'Date Calcs'!A:AF,11,),IF(C12=2,VLOOKUP(A12,'Date Calcs'!A:AF,13,),IF(C12=3,VLOOKUP(A12,'Date Calcs'!A:AF,15,),4))))) -> 45895 | F12: =IF(A12="","",D12-Date!$B$3) -> -178 | I12: =IF(C12=0,IF(VLOOKUP(A12,Dates,9,)>0,1," "),IF(C12=1,IF(VLOOKUP(A12,Dates,11,)>0,1," "),IF(C12=2,IF(VLOOKUP(A12,Dates,13,)>0,1," "),IF(C12=3,IF(VLOOKUP(A12,Dates,15,)>0,1," "))))) | J12: =VLOOKUP(A12,Dates,7,) -> y
A13: 25-076 | B13: =VLOOKUP(A13,Jobs,2,) -> Irving tissue | C13: =VLOOKUP(A13,Dates,6,) -> 1 | D13: =IF(C13=" "," ",IF(C13=0,VLOOKUP(A13,'Date Calcs'!A:AF,9,),IF(C13=1,VLOOKUP(A13,'Date Calcs'!A:AF,11,),IF(C13=2,VLOOKUP(A13,'Date Calcs'!A:AF,13,),IF(C13=3,VLOOKUP(A13,'Date Calcs'!A:AF,15,),4))))) -> 45895 | F13: =IF(A13="","",D13-Date!$B$3) -> -178 | I13: =IF(C13=0,IF(VLOOKUP(A13,Dates,9,)>0,1," "),IF(C13=1,IF(VLOOKUP(A13,Dates,11,)>0,1," "),IF(C13=2,IF(VLOOKUP(A13,Dates,13,)>0,1," "),IF(C13=3,IF(VLOOKUP(A13,Dates,15,)>0,1," "))))) | J13: =VLOOKUP(A13,Dates,7,) -> y
A14: 25-077 | B14: =VLOOKUP(A14,Jobs,2,) -> Epic Systems | C14: =VLOOKUP(A14,Dates,6,) -> 2 | D14: =IF(C14=" "," ",IF(C14=0,VLOOKUP(A14,'Date Calcs'!A:AF,9,),IF(C14=1,VLOOKUP(A14,'Date Calcs'!A:AF,11,),IF(C14=2,VLOOKUP(A14,'Date Calcs'!A:AF,13,),IF(C14=3,VLOOKUP(A14,'Date Calcs'!A:AF,15,),4))))) -> 45901 | F14: =IF(A14="","",D14-Date!$B$3) -> -172 | I14: =IF(C14=0,IF(VLOOKUP(A14,Dates,9,)>0,1," "),IF(C14=1,IF(VLOOKUP(A14,Dates,11,)>0,1," "),IF(C14=2,IF(VLOOKUP(A14,Dates,13,)>0,1," "),IF(C14=3,IF(VLOOKUP(A14,Dates,15,)>0,1," "))))) | J14: =VLOOKUP(A14,Dates,7,) -> y
A15: 25-078 | B15: =VLOOKUP(A15,Jobs,2,) -> Epic Systems | C15: =VLOOKUP(A15,Dates,6,) -> 2 | D15: =IF(C15=" "," ",IF(C15=0,VLOOKUP(A15,'Date Calcs'!A:AF,9,),IF(C15=1,VLOOKUP(A15,'Date Calcs'!A:AF,11,),IF(C15=2,VLOOKUP(A15,'Date Calcs'!A:AF,13,),IF(C15=3,VLOOKUP(A15,'Date Calcs'!A:AF,15,),4))))) -> 45901 | F15: =IF(A15="","",D15-Date!$B$3) -> -172 | I15: =IF(C15=0,IF(VLOOKUP(A15,Dates,9,)>0,1," "),IF(C15=1,IF(VLOOKUP(A15,Dates,11,)>0,1," "),IF(C15=2,IF(VLOOKUP(A15,Dates,13,)>0,1," "),IF(C15=3,IF(VLOOKUP(A15,Dates,15,)>0,1," "))))) | J15: =VLOOKUP(A15,Dates,7,) -> y
A16: 25-079 | B16: =VLOOKUP(A16,Jobs,2,) -> Epic Systems | C16: =VLOOKUP(A16,Dates,6,) -> 2 | D16: =IF(C16=" "," ",IF(C16=0,VLOOKUP(A16,'Date Calcs'!A:AF,9,),IF(C16=1,VLOOKUP(A16,'Date Calcs'!A:AF,11,),IF(C16=2,VLOOKUP(A16,'Date Calcs'!A:AF,13,),IF(C16=3,VLOOKUP(A16,'Date Calcs'!A:AF,15,),4))))) -> 45901 | F16: =IF(A16="","",D16-Date!$B$3) -> -172 | I16: =IF(C16=0,IF(VLOOKUP(A16,Dates,9,)>0,1," "),IF(C16=1,IF(VLOOKUP(A16,Dates,11,)>0,1," "),IF(C16=2,IF(VLOOKUP(A16,Dates,13,)>0,1," "),IF(C16=3,IF(VLOOKUP(A16,Dates,15,)>0,1," "))))) | J16: =VLOOKUP(A16,Dates,7,) -> y
A17: 25-080 | B17: =VLOOKUP(A17,Jobs,2,) -> Domtar | C17: =VLOOKUP(A17,Dates,6,) -> 1 | D17: =IF(C17=" "," ",IF(C17=0,VLOOKUP(A17,'Date Calcs'!A:AF,9,),IF(C17=1,VLOOKUP(A17,'Date Calcs'!A:AF,11,),IF(C17=2,VLOOKUP(A17,'Date Calcs'!A:AF,13,),IF(C17=3,VLOOKUP(A17,'Date Calcs'!A:AF,15,),4))))) -> 45897 | F17: =IF(A17="","",D17-Date!$B$3) -> -176 | I17: =IF(C17=0,IF(VLOOKUP(A17,Dates,9,)>0,1," "),IF(C17=1,IF(VLOOKUP(A17,Dates,11,)>0,1," "),IF(C17=2,IF(VLOOKUP(A17,Dates,13,)>0,1," "),IF(C17=3,IF(VLOOKUP(A17,Dates,15,)>0,1," "))))) | J17: =VLOOKUP(A17,Dates,7,) -> y
A18: 25-083 | B18: =VLOOKUP(A18,Jobs,2,) -> Synthomer | C18: =VLOOKUP(A18,Dates,6,) -> 2 | D18: =IF(C18=" "," ",IF(C18=0,VLOOKUP(A18,'Date Calcs'!A:AF,9,),IF(C18=1,VLOOKUP(A18,'Date Calcs'!A:AF,11,),IF(C18=2,VLOOKUP(A18,'Date Calcs'!A:AF,13,),IF(C18=3,VLOOKUP(A18,'Date Calcs'!A:AF,15,),4))))) -> 45972 | F18: =IF(A18="","",D18-Date!$B$3) -> -101 | I18: =IF(C18=0,IF(VLOOKUP(A18,Dates,9,)>0,1," "),IF(C18=1,IF(VLOOKUP(A18,Dates,11,)>0,1," "),IF(C18=2,IF(VLOOKUP(A18,Dates,13,)>0,1," "),IF(C18=3,IF(VLOOKUP(A18,Dates,15,)>0,1," "))))) -> 1 | J18: =VLOOKUP(A18,Dates,7,) -> y
... A34: 25-101 | B34: =VLOOKUP(A34,Jobs,2,) -> Harper Love | C34: =VLOOKUP(A34,Dates,6,) -> 1 | D34: =IF(C34=" "," ",IF(C34=0,VLOOKUP(A34,'Date Calcs'!A:AF,9,),IF(C34=1,VLOOKUP(A34,'Date Calcs'!A:AF,11,),IF(C34=2,VLOOKUP(A34,'Date Calcs'!A:AF,13,),IF(C34=3,VLOOKUP(A34,'Date Calcs'!A:AF,15,),4))))) -> 46006 | F34: =IF(A34="","",D34-Date!$B$3) -> -67 | I34: =IF(C34=0,IF(VLOOKUP(A34,Dates,9,)>0,1," "),IF(C34=1,IF(VLOOKUP(A34,Dates,11,)>0,1," "),IF(C34=2,IF(VLOOKUP(A34,Dates,13,)>0,1," "),IF(C34=3,IF(VLOOKUP(A34,Dates,15,)>0,1," "))))) | J34: =VLOOKUP(A34,Dates,7,) -> y
A35: 25-102 | B35: =VLOOKUP(A35,Jobs,2,) -> Epic Systems | C35: =VLOOKUP(A35,Dates,6,) -> 2 | D35: =IF(C35=" "," ",IF(C35=0,VLOOKUP(A35,'Date Calcs'!A:AF,9,),IF(C35=1,VLOOKUP(A35,'Date Calcs'!A:AF,11,),IF(C35=2,VLOOKUP(A35,'Date Calcs'!A:AF,13,),IF(C35=3,VLOOKUP(A35,'Date Calcs'!A:AF,15,),4))))) -> 46064 | F35: =IF(A35="","",D35-Date!$B$3) -> -9 | I35: =IF(C35=0,IF(VLOOKUP(A35,Dates,9,)>0,1," "),IF(C35=1,IF(VLOOKUP(A35,Dates,11,)>0,1," "),IF(C35=2,IF(VLOOKUP(A35,Dates,13,)>0,1," "),IF(C35=3,IF(VLOOKUP(A35,Dates,15,)>0,1," "))))) -> 1 | J35: Y
A36: 25-103 | B36: =VLOOKUP(A36,Jobs,2,) -> Epic Systems | C36: =VLOOKUP(A36,Dates,6,) -> 2 | D36: =IF(C36=" "," ",IF(C36=0,VLOOKUP(A36,'Date Calcs'!A:AF,9,),IF(C36=1,VLOOKUP(A36,'Date Calcs'!A:AF,11,),IF(C36=2,VLOOKUP(A36,'Date Calcs'!A:AF,13,),IF(C36=3,VLOOKUP(A36,'Date Calcs'!A:AF,15,),4))))) -> 46064 | F36: =IF(A36="","",D36-Date!$B$3) -> -9 | I36: =IF(C36=0,IF(VLOOKUP(A36,Dates,9,)>0,1," "),IF(C36=1,IF(VLOOKUP(A36,Dates,11,)>0,1," "),IF(C36=2,IF(VLOOKUP(A36,Dates,13,)>0,1," "),IF(C36=3,IF(VLOOKUP(A36,Dates,15,)>0,1," "))))) -> 1 | J36: Y
A37: 25-104 | B37: =VLOOKUP(A37,Jobs,2,) -> Epic Systems | C37: =VLOOKUP(A37,Dates,6,) -> 2 | D37: =IF(C37=" "," ",IF(C37=0,VLOOKUP(A37,'Date Calcs'!A:AF,9,),IF(C37=1,VLOOKUP(A37,'Date Calcs'!A:AF,11,),IF(C37=2,VLOOKUP(A37,'Date Calcs'!A:AF,13,),IF(C37=3,VLOOKUP(A37,'Date Calcs'!A:AF,15,),4))))) -> 46064 | F37: =IF(A37="","",D37-Date!$B$3) -> -9 | I37: =IF(C37=0,IF(VLOOKUP(A37,Dates,9,)>0,1," "),IF(C37=1,IF(VLOOKUP(A37,Dates,11,)>0,1," "),IF(C37=2,IF(VLOOKUP(A37,Dates,13,)>0,1," "),IF(C37=3,IF(VLOOKUP(A37,Dates,15,)>0,1," "))))) -> 1 | J37: Y
A38: 25-105 | B38: =VLOOKUP(A38,Jobs,2,) -> Epic Systems | C38: =VLOOKUP(A38,Dates,6,) -> 2 | D38: =IF(C38=" "," ",IF(C38=0,VLOOKUP(A38,'Date Calcs'!A:AF,9,),IF(C38=1,VLOOKUP(A38,'Date Calcs'!A:AF,11,),IF(C38=2,VLOOKUP(A38,'Date Calcs'!A:AF,13,),IF(C38=3,VLOOKUP(A38,'Date Calcs'!A:AF,15,),4))))) -> 46064 | F38: =IF(A38="","",D38-Date!$B$3) -> -9 | I38: =IF(C38=0,IF(VLOOKUP(A38,Dates,9,)>0,1," "),IF(C38=1,IF(VLOOKUP(A38,Dates,11,)>0,1," "),IF(C38=2,IF(VLOOKUP(A38,Dates,13,)>0,1," "),IF(C38=3,IF(VLOOKUP(A38,Dates,15,)>0,1," "))))) -> 1 | J38: Y
A39: 25-106 | B39: =VLOOKUP(A39,Jobs,2,) -> Epic Systems | C39: =VLOOKUP(A39,Dates,6,) -> 2 | D39: =IF(C39=" "," ",IF(C39=0,VLOOKUP(A39,'Date Calcs'!A:AF,9,),IF(C39=1,VLOOKUP(A39,'Date Calcs'!A:AF,11,),IF(C39=2,VLOOKUP(A39,'Date Calcs'!A:AF,13,),IF(C39=3,VLOOKUP(A39,'Date Calcs'!A:AF,15,),4))))) -> 46065 | F39: =IF(A39="","",D39-Date!$B$3) -> -8 | I39: =IF(C39=0,IF(VLOOKUP(A39,Dates,9,)>0,1," "),IF(C39=1,IF(VLOOKUP(A39,Dates,11,)>0,1," "),IF(C39=2,IF(VLOOKUP(A39,Dates,13,)>0,1," "),IF(C39=3,IF(VLOOKUP(A39,Dates,15,)>0,1," "))))) -> 1 | J39: Y
A40: 25-107 | B40: =VLOOKUP(A40,Jobs,2,) -> Epic Systems | C40: =VLOOKUP(A40,Dates,6,) -> 0 | D40: =IF(C40=" "," ",IF(C40=0,VLOOKUP(A40,'Date Calcs'!A:AF,9,),IF(C40=1,VLOOKUP(A40,'Date Calcs'!A:AF,11,),IF(C40=2,VLOOKUP(A40,'Date Calcs'!A:AF,13,),IF(C40=3,VLOOKUP(A40,'Date Calcs'!A:AF,15,),4))))) -> 46001 | F40: =IF(A40="","",D40-Date!$B$3) -> -72 | I40: =IF(C40=0,IF(VLOOKUP(A40,Dates,9,)>0,1," "),IF(C40=1,IF(VLOOKUP(A40,Dates,11,)>0,1," "),IF(C40=2,IF(VLOOKUP(A40,Dates,13,)>0,1," "),IF(C40=3,IF(VLOOKUP(A40,Dates,15,)>0,1," "))))) -> 1 | J40: =VLOOKUP(A40,Dates,7,)
A41: 25-108 | B41: =VLOOKUP(A41,Jobs,2,) -> Epic Systems | C41: =VLOOKUP(A41,Dates,6,) -> 1 | D41: =IF(C41=" "," ",IF(C41=0,VLOOKUP(A41,'Date Calcs'!A:AF,9,),IF(C41=1,VLOOKUP(A41,'Date Calcs'!A:AF,11,),IF(C41=2,VLOOKUP(A41,'Date Calcs'!A:AF,13,),IF(C41=3,VLOOKUP(A41,'Date Calcs'!A:AF,15,),4))))) -> 46071 | F41: =IF(A41="","",D41-Date!$B$3) -> -2 | I41: =IF(C41=0,IF(VLOOKUP(A41,Dates,9,)>0,1," "),IF(C41=1,IF(VLOOKUP(A41,Dates,11,)>0,1," "),IF(C41=2,IF(VLOOKUP(A41,Dates,13,)>0,1," "),IF(C41=3,IF(VLOOKUP(A41,Dates,15,)>0,1," "))))) | J41: =VLOOKUP(A41,Dates,7,)
A42: 25-109 | B42: =VLOOKUP(A42,Jobs,2,) -> Epic Systems | C42: =VLOOKUP(A42,Dates,6,) -> 3 | D42: =IF(C42=" "," ",IF(C42=0,VLOOKUP(A42,'Date Calcs'!A:AF,9,),IF(C42=1,VLOOKUP(A42,'Date Calcs'!A:AF,11,),IF(C42=2,VLOOKUP(A42,'Date Calcs'!A:AF,13,),IF(C42=3,VLOOKUP(A42,'Date Calcs'!A:AF,15,),4))))) -> 46059 | F42: =IF(A42="","",D42-Date!$B$3) -> -14 | I42: =IF(C42=0,IF(VLOOKUP(A42,Dates,9,)>0,1," "),IF(C42=1,IF(VLOOKUP(A42,Dates,11,)>0,1," "),IF(C42=2,IF(VLOOKUP(A42,Dates,13,)>0,1," "),IF(C42=3,IF(VLOOKUP(A42,Dates,15,)>0,1," "))))) -> 1 | J42: Y
A43: 25-110 | B43: =VLOOKUP(A43,Jobs,2,) -> Epic Systems | C43: =VLOOKUP(A43,Dates,6,) -> 3 | D43: =IF(C43=" "," ",IF(C43=0,VLOOKUP(A43,'Date Calcs'!A:AF,9,),IF(C43=1,VLOOKUP(A43,'Date Calcs'!A:AF,11,),IF(C43=2,VLOOKUP(A43,'Date Calcs'!A:AF,13,),IF(C43=3,VLOOKUP(A43,'Date Calcs'!A:AF,15,),4))))) -> 46059 | F43: =IF(A43="","",D43-Date!$B$3) -> -14 | I43: =IF(C43=0,IF(VLOOKUP(A43,Dates,9,)>0,1," "),IF(C43=1,IF(VLOOKUP(A43,Dates,11,)>0,1," "),IF(C43=2,IF(VLOOKUP(A43,Dates,13,)>0,1," "),IF(C43=3,IF(VLOOKUP(A43,Dates,15,)>0,1," "))))) | J43: =VLOOKUP(A43,Dates,7,)
A44: 25-111 | B44: =VLOOKUP(A44,Jobs,2,) -> Epic Systems | C44: =VLOOKUP(A44,Dates,6,) -> 3 | D44: =IF(C44=" "," ",IF(C44=0,VLOOKUP(A44,'Date Calcs'!A:AF,9,),IF(C44=1,VLOOKUP(A44,'Date Calcs'!A:AF,11,),IF(C44=2,VLOOKUP(A44,'Date Calcs'!A:AF,13,),IF(C44=3,VLOOKUP(A44,'Date Calcs'!A:AF,15,),4))))) -> 46059 | F44: =IF(A44="","",D44-Date!$B$3) -> -14 | I44: =IF(C44=0,IF(VLOOKUP(A44,Dates,9,)>0,1," "),IF(C44=1,IF(VLOOKUP(A44,Dates,11,)>0,1," "),IF(C44=2,IF(VLOOKUP(A44,Dates,13,)>0,1," "),IF(C44=3,IF(VLOOKUP(A44,Dates,15,)>0,1," "))))) | J44: =VLOOKUP(A44,Dates,7,)
A45: 25-112 | B45: =VLOOKUP(A45,Jobs,2,) -> Epic Systems | C45: =VLOOKUP(A45,Dates,6,) -> 3 | D45: =IF(C45=" "," ",IF(C45=0,VLOOKUP(A45,'Date Calcs'!A:AF,9,),IF(C45=1,VLOOKUP(A45,'Date Calcs'!A:AF,11,),IF(C45=2,VLOOKUP(A45,'Date Calcs'!A:AF,13,),IF(C45=3,VLOOKUP(A45,'Date Calcs'!A:AF,15,),4))))) -> 46059 | F45: =IF(A45="","",D45-Date!$B$3) -> -14 | I45: =IF(C45=0,IF(VLOOKUP(A45,Dates,9,)>0,1," "),IF(C45=1,IF(VLOOKUP(A45,Dates,11,)>0,1," "),IF(C45=2,IF(VLOOKUP(A45,Dates,13,)>0,1," "),IF(C45=3,IF(VLOOKUP(A45,Dates,15,)>0,1," "))))) | J45: =VLOOKUP(A45,Dates,7,)
A46: 25-113 | B46: =VLOOKUP(A46,Jobs,2,) -> Epic Systems | C46: =VLOOKUP(A46,Dates,6,) -> 2 | D46: =IF(C46=" "," ",IF(C46=0,VLOOKUP(A46,'Date Calcs'!A:AF,9,),IF(C46=1,VLOOKUP(A46,'Date Calcs'!A:AF,11,),IF(C46=2,VLOOKUP(A46,'Date Calcs'!A:AF,13,),IF(C46=3,VLOOKUP(A46,'Date Calcs'!A:AF,15,),4))))) -> 46065 | F46: =IF(A46="","",D46-Date!$B$3) -> -8 | I46: =IF(C46=0,IF(VLOOKUP(A46,Dates,9,)>0,1," "),IF(C46=1,IF(VLOOKUP(A46,Dates,11,)>0,1," "),IF(C46=2,IF(VLOOKUP(A46,Dates,13,)>0,1," "),IF(C46=3,IF(VLOOKUP(A46,Dates,15,)>0,1," "))))) | J46: =VLOOKUP(A46,Dates,7,)
A47: 25-114 | B47: =VLOOKUP(A47,Jobs,2,) -> #N/A | C47: =VLOOKUP(A47,Dates,6,) -> #N/A | D47: =IF(C47=" "," ",IF(C47=0,VLOOKUP(A47,'Date Calcs'!A:AF,9,),IF(C47=1,VLOOKUP(A47,'Date Calcs'!A:AF,11,),IF(C47=2,VLOOKUP(A47,'Date Calcs'!A:AF,13,),IF(C47=3,VLOOKUP(A47,'Date Calcs'!A:AF,15,),4))))) -> #N/A | F47: =IF(A47="","",D47-Date!$B$3) -> #N/A | I47: =IF(C47=0,IF(VLOOKUP(A47,Dates,9,)>0,1," "),IF(C47=1,IF(VLOOKUP(A47,Dates,11,)>0,1," "),IF(C47=2,IF(VLOOKUP(A47,Dates,13,)>0,1," "),IF(C47=3,IF(VLOOKUP(A47,Dates,15,)>0,1," "))))) -> #N/A | J47: =VLOOKUP(A47,Dates,7,) -> #N/A
A48: 25-115 | B48: =VLOOKUP(A48,Jobs,2,) -> Epic Systems | C48: =VLOOKUP(A48,Dates,6,) -> 2 | D48: =IF(C48=" "," ",IF(C48=0,VLOOKUP(A48,'Date Calcs'!A:AF,9,),IF(C48=1,VLOOKUP(A48,'Date Calcs'!A:AF,11,),IF(C48=2,VLOOKUP(A48,'Date Calcs'!A:AF,13,),IF(C48=3,VLOOKUP(A48,'Date Calcs'!A:AF,15,),4))))) -> 46059 | F48: =IF(A48="","",D48-Date!$B$3) -> -14 | I48: =IF(C48=0,IF(VLOOKUP(A48,Dates,9,)>0,1," "),IF(C48=1,IF(VLOOKUP(A48,Dates,11,)>0,1," "),IF(C48=2,IF(VLOOKUP(A48,Dates,13,)>0,1," "),IF(C48=3,IF(VLOOKUP(A48,Dates,15,)>0,1," "))))) -> 1 | J48: Y
A49: 25-116 | B49: =VLOOKUP(A49,Jobs,2,) -> Polynt | C49: =VLOOKUP(A49,Dates,6,) -> 1 | D49: =IF(C49=" "," ",IF(C49=0,VLOOKUP(A49,'Date Calcs'!A:AF,9,),IF(C49=1,VLOOKUP(A49,'Date Calcs'!A:AF,11,),IF(C49=2,VLOOKUP(A49,'Date Calcs'!A:AF,13,),IF(C49=3,VLOOKUP(A49,'Date Calcs'!A:AF,15,),4))))) -> 46038 | F49: =IF(A49="","",D49-Date!$B$3) -> -35 | I49: =IF(C49=0,IF(VLOOKUP(A49,Dates,9,)>0,1," "),IF(C49=1,IF(VLOOKUP(A49,Dates,11,)>0,1," "),IF(C49=2,IF(VLOOKUP(A49,Dates,13,)>0,1," "),IF(C49=3,IF(VLOOKUP(A49,Dates,15,)>0,1," "))))) -> 1 | J49: =VLOOKUP(A49,Dates,7,)
A50: 25-117 | B50: =VLOOKUP(A50,Jobs,2,) -> Merrick | C50: =VLOOKUP(A50,Dates,6,) -> 2 | D50: =IF(C50=" "," ",IF(C50=0,VLOOKUP(A50,'Date Calcs'!A:AF,9,),IF(C50=1,VLOOKUP(A50,'Date Calcs'!A:AF,11,),IF(C50=2,VLOOKUP(A50,'Date Calcs'!A:AF,13,),IF(C50=3,VLOOKUP(A50,'Date Calcs'!A:AF,15,),4))))) -> 46070 | F50: =IF(A50="","",D50-Date!$B$3) -> -3 | I50: =IF(C50=0,IF(VLOOKUP(A50,Dates,9,)>0,1," "),IF(C50=1,IF(VLOOKUP(A50,Dates,11,)>0,1," "),IF(C50=2,IF(VLOOKUP(A50,Dates,13,)>0,1," "),IF(C50=3,IF(VLOOKUP(A50,Dates,15,)>0,1," "))))) | J50: =VLOOKUP(A50,Dates,7,) -> y
A51: 25-118 | B51: =VLOOKUP(A51,Jobs,2,) -> Merrick | C51: =VLOOKUP(A51,Dates,6,) -> 2 | D51: =IF(C51=" "," ",IF(C51=0,VLOOKUP(A51,'Date Calcs'!A:AF,9,),IF(C51=1,VLOOKUP(A51,'Date Calcs'!A:AF,11,),IF(C51=2,VLOOKUP(A51,'Date Calcs'!A:AF,13,),IF(C51=3,VLOOKUP(A51,'Date Calcs'!A:AF,15,),4))))) -> 46076 | F51: =IF(A51="","",D51-Date!$B$3) -> 3 | I51: =IF(C51=0,IF(VLOOKUP(A51,Dates,9,)>0,1," "),IF(C51=1,IF(VLOOKUP(A51,Dates,11,)>0,1," "),IF(C51=2,IF(VLOOKUP(A51,Dates,13,)>0,1," "),IF(C51=3,IF(VLOOKUP(A51,Dates,15,)>0,1," "))))) | J51: =VLOOKUP(A51,Dates,7,) -> y
A52: 25-119 | B52: =VLOOKUP(A52,Jobs,2,) -> Vertiv | C52: =VLOOKUP(A52,Dates,6,) -> 1 | D52: =IF(C52=" "," ",IF(C52=0,VLOOKUP(A52,'Date Calcs'!A:AF,9,),IF(C52=1,VLOOKUP(A52,'Date Calcs'!A:AF,11,),IF(C52=2,VLOOKUP(A52,'Date Calcs'!A:AF,13,),IF(C52=3,VLOOKUP(A52,'Date Calcs'!A:AF,15,),4))))) -> 46001 | F52: =IF(A52="","",D52-Date!$B$3) -> -72 | I52: =IF(C52=0,IF(VLOOKUP(A52,Dates,9,)>0,1," "),IF(C52=1,IF(VLOOKUP(A52,Dates,11,)>0,1," "),IF(C52=2,IF(VLOOKUP(A52,Dates,13,)>0,1," "),IF(C52=3,IF(VLOOKUP(A52,Dates,15,)>0,1," "))))) | J52: =VLOOKUP(A52,Dates,7,) -> y
A53: 25-121 | B53: =VLOOKUP(A53,Jobs,2,) -> Kimberly Clark | C53: =VLOOKUP(A53,Dates,6,) -> 0 | D53: =IF(C53=" "," ",IF(C53=0,VLOOKUP(A53,'Date Calcs'!A:AF,9,),IF(C53=1,VLOOKUP(A53,'Date Calcs'!A:AF,11,),IF(C53=2,VLOOKUP(A53,'Date Calcs'!A:AF,13,),IF(C53=3,VLOOKUP(A53,'Date Calcs'!A:AF,15,),4))))) -> 46044 | F53: =IF(A53="","",D53-Date!$B$3) -> -29 | I53: =IF(C53=0,IF(VLOOKUP(A53,Dates,9,)>0,1," "),IF(C53=1,IF(VLOOKUP(A53,Dates,11,)>0,1," "),IF(C53=2,IF(VLOOKUP(A53,Dates,13,)>0,1," "),IF(C53=3,IF(VLOOKUP(A53,Dates,15,)>0,1," "))))) -> 1 | J53: =VLOOKUP(A53,Dates,7,)
A54: 25-122 | B54: =VLOOKUP(A54,Jobs,2,) -> Kimberly Clark | C54: =VLOOKUP(A54,Dates,6,) -> 0 | D54: =IF(C54=" "," ",IF(C54=0,VLOOKUP(A54,'Date Calcs'!A:AF,9,),IF(C54=1,VLOOKUP(A54,'Date Calcs'!A:AF,11,),IF(C54=2,VLOOKUP(A54,'Date Calcs'!A:AF,13,),IF(C54=3,VLOOKUP(A54,'Date Calcs'!A:AF,15,),4))))) -> 46044 | F54: =IF(A54="","",D54-Date!$B$3) -> -29 | I54: =IF(C54=0,IF(VLOOKUP(A54,Dates,9,)>0,1," "),IF(C54=1,IF(VLOOKUP(A54,Dates,11,)>0,1," "),IF(C54=2,IF(VLOOKUP(A54,Dates,13,)>0,1," "),IF(C54=3,IF(VLOOKUP(A54,Dates,15,)>0,1," "))))) -> 1 | J54: =VLOOKUP(A54,Dates,7,)
A55: 25-123 | B55: =VLOOKUP(A55,Jobs,2,) -> Kimberly Clark | C55: =VLOOKUP(A55,Dates,6,) -> 0 | D55: =IF(C55=" "," ",IF(C55=0,VLOOKUP(A55,'Date Calcs'!A:AF,9,),IF(C55=1,VLOOKUP(A55,'Date Calcs'!A:AF,11,),IF(C55=2,VLOOKUP(A55,'Date Calcs'!A:AF,13,),IF(C55=3,VLOOKUP(A55,'Date Calcs'!A:AF,15,),4))))) -> 46044 | F55: =IF(A55="","",D55-Date!$B$3) -> -29 | I55: =IF(C55=0,IF(VLOOKUP(A55,Dates,9,)>0,1," "),IF(C55=1,IF(VLOOKUP(A55,Dates,11,)>0,1," "),IF(C55=2,IF(VLOOKUP(A55,Dates,13,)>0,1," "),IF(C55=3,IF(VLOOKUP(A55,Dates,15,)>0,1," "))))) | J55: =VLOOKUP(A55,Dates,7,)
...

Sheet RTR v2
A1: Shop Release Readiness
D3: Pre-Approval | K3: After Return of Approval Drawings | AH3: Release to Shop By Ship Date
A5: Job # | B5: Customer | D5: App. Prints | F5: Long lead time | H5: Prelim BOM | K5: Final Calcs | M5: A.I. | O5: Cert Dwgs | Q5: Update BOM | S5: Stock Check | U5: Purch Recvd | W5: Final BOM | Y5: Build Plan | AA5: Burn File | AC5: QC Checklist | AE5: Released | AG5: Drop Dead Date Week of | AH5: Build Plan | AI5: Days to go | AJ5: QC Checklist | AK5: days to go | AL5: Burn File | AM5: days to go | AN5: All MAT. On hand | AO5: Purchase vs Release | AP5: Release to Shop | AQ5: days to go | AR5: Ship Date Week Of | AS5: Difference drop dead to ship | AT5: Logistics Confirmed | AU5: Actual Ship Date | AV5: COMMENTS
A6: 24-046 | B6: =VLOOKUP(A6,Jobs,2,) -> SYMS Engineering | D6: =IF(VLOOKUP($A6,Jobs,8,)>0,"Y"," ") -> Y | E6: =IF(VLOOKUP($A6,Dates,8,)>0,VLOOKUP($A6,Dates,8,)-VLOOKUP($A6,Jobs,8,)," ") -> 4 | F6: =IF(VLOOKUP($A6,Dates,16,)>0,"Y"," ") -> Y | G6: =IF(VLOOKUP($A6,Dates,16,)>0,VLOOKUP($A6,Dates,16,)-VLOOKUP($A6,Jobs,16,)," ") -> -2 | H6: =_xlfn.IFNA(IF(VLOOKUP($A10,Dates,17,)>0,"Y"," "),"") -> Y | I6: =IF(VLOOKUP($A10,Dates,17,)>0,VLOOKUP($A10,Dates,17,)-VLOOKUP($A10,Jobs,17,)," ") -> #VALUE! | K6: =IF(VLOOKUP($A6,Dates,19,)>0,"Y"," ") -> Y | L6: =IF(VLOOKUP($A6,Dates,19,)>0,VLOOKUP($A6,Dates,19,)-VLOOKUP($A6,Jobs,19,)," ") -> 4 | M6: =IF(VLOOKUP($A6,Dates,20,)>0,"Y"," ") | N6: =IF(VLOOKUP($A6,Dates,20,)>0,VLOOKUP($A6,Dates,20,)-VLOOKUP($A6,Jobs,20,)," ") | O6: =IF(VLOOKUP($A6,Dates,21,)>0,"Y"," ") -> Y | P6: =IF(VLOOKUP($A6,Dates,21,)>0,VLOOKUP($A6,Dates,21,)-VLOOKUP($A6,Jobs,21,)," ") -> -1 | Q6: =IF(VLOOKUP($A6,Dates,23,)>0,"Y"," ") -> Y | R6: =IF(VLOOKUP($A6,Dates,23,)>0,VLOOKUP($A6,Dates,23,)-VLOOKUP($A6,Jobs,23,)," ") -> -276 | S6: =IF(VLOOKUP($A6,Dates,24,)>0,"Y"," ") -> Y | T6: =IF(VLOOKUP($A6,Dates,24,)>0,VLOOKUP($A6,Dates,24,)-VLOOKUP($A6,Jobs,24,)," ") -> -3 | U6: =IF(VLOOKUP($A6,Dates,26,)>0,"Y"," ") -> Y | V6: =IF(VLOOKUP($A6,Dates,26,)>0,VLOOKUP($A6,Dates,26,)-VLOOKUP($A6,Jobs,26,)," ") -> -269 | W6: =IF(VLOOKUP($A6,Dates,27,)>0,"Y"," ") -> Y | X6: =IF(VLOOKUP($A6,Dates,27,)>0,VLOOKUP($A6,Dates,27,)-VLOOKUP($A6,Jobs,27,)," ") -> 69 | Y6: =IF(VLOOKUP($A6,Dates,28,)>0,"Y"," ") -> Y | Z6: =IF(VLOOKUP($A6,Dates,28,)>0,VLOOKUP($A6,Dates,28,)-VLOOKUP($A6,Jobs,28,)," ") -> 85 | AA6: =IF(VLOOKUP($A6,Dates,29,)>0,"Y"," ") -> Y | AB6: =IF(VLOOKUP($A6,Dates,29,)>0,VLOOKUP($A6,Dates,29,)-VLOOKUP($A6,Jobs,29,)," ") -> 80 | AC6: =IF(VLOOKUP($A6,Dates,30,)>0,"Y"," ") -> Y | AD6: =IF(VLOOKUP($A6,Dates,30,)>0,VLOOKUP($A6,Dates,30,)-VLOOKUP($A6,Jobs,30,)," ") -> 94 | AE6: =IF(VLOOKUP($A6,Dates,31,)>0,"Y"," ") -> Y | AF6: =IF(VLOOKUP($A6,Dates,31,)>0,VLOOKUP($A6,Dates,31,)-VLOOKUP($A6,Jobs,31,)," ") -> 95 | AG6: =_xlfn.IFNA(VLOOKUP(A6,Dates,22,FALSE),"") -> 46163 | AH6: =_xlfn.IFNA(IF(Y6="Y","DONE",VLOOKUP(A6,'Date Calcs from Ship Date'!A:AE,27,0)),"") -> DONE | AI6: =IFERROR(AH6-TODAY(),0) -> 0 | AJ6: =_xlfn.IFNA(IF(AC6="Y","DONE",VLOOKUP(A6,'Date Calcs from Ship Date'!A:AE,29,0)),"") -> DONE | AK6: =IFERROR(AJ6-TODAY(),0) -> 0 | AL6: =_xlfn.IFNA(IF(AA6="Y","DONE",VLOOKUP(A6,'Date Calcs from Ship Date'!A:AI,28,0)),"") -> DONE | AM6: =IFERROR(AL6-TODAY(),0) -> 0 | AN6: =IF(U6="Y","DONE",VLOOKUP(A6,'Date Calcs from Ship Date'!A:AE,25,0)) -> DONE | AO6: =IFERROR(AP6-AN6,0) -> 0 | AP6: =IF(AE6="Y","DONE",VLOOKUP(A6,'Date Calcs from Ship Date'!A:AE,30,0)) -> DONE | AQ6: =IFERROR(AP6-TODAY(),0) -> 0 | AR6: =_xlfn.IFNA(VLOOKUP(A6,'Date Calcs from Ship Date'!A:C,3,0),"") -> 46128 | AS6: =AG6-AR6 -> 35 | AU6: =IF(VLOOKUP(A6,Dates,32,)>0,VLOOKUP(A6,Dates,32,)," ")
A7: 25-053 | B7: =VLOOKUP(A7,Jobs,2,) -> Andritz | D7: =IF(VLOOKUP($A7,Jobs,8,)>0,"Y"," ") -> Y | E7: =IF(VLOOKUP($A7,Dates,8,)>0,VLOOKUP($A7,Dates,8,)-VLOOKUP($A7,Jobs,8,)," ") | F7: =IF(VLOOKUP($A7,Dates,16,)>0,"Y"," ") -> Y | G7: =IF(VLOOKUP($A7,Dates,16,)>0,VLOOKUP($A7,Dates,16,)-VLOOKUP($A7,Jobs,16,)," ") -> 58 | H7: =_xlfn.IFNA(IF(VLOOKUP($A11,Dates,17,)>0,"Y"," "),"") -> Y | I7: =IF(VLOOKUP($A11,Dates,17,)>0,VLOOKUP($A11,Dates,17,)-VLOOKUP($A11,Jobs,17,)," ") -> #VALUE! | K7: =IF(VLOOKUP($A7,Dates,19,)>0,"Y"," ") | L7: =IF(VLOOKUP($A7,Dates,19,)>0,VLOOKUP($A7,Dates,19,)-VLOOKUP($A7,Jobs,19,)," ") | M7: =IF(VLOOKUP($A7,Dates,20,)>0,"Y"," ") | N7: =IF(VLOOKUP($A7,Dates,20,)>0,VLOOKUP($A7,Dates,20,)-VLOOKUP($A7,Jobs,20,)," ") | O7: =IF(VLOOKUP($A7,Dates,21,)>0,"Y"," ") | P7: =IF(VLOOKUP($A7,Dates,21,)>0,VLOOKUP($A7,Dates,21,)-VLOOKUP($A7,Jobs,21,)," ") | Q7: =IF(VLOOKUP($A7,Dates,23,)>0,"Y"," ") -> Y | R7: =IF(VLOOKUP($A7,Dates,23,)>0,VLOOKUP($A7,Dates,23,)-VLOOKUP($A7,Jobs,23,)," ") -> -348 | S7: =IF(VLOOKUP($A7,Dates,24,)>0,"Y"," ") -> Y | T7: =IF(VLOOKUP($A7,Dates,24,)>0,VLOOKUP($A7,Dates,24,)-VLOOKUP($A7,Jobs,24,)," ") -> -173 | U7: =IF(VLOOKUP($A7,Dates,26,)>0,"Y"," ") -> Y | V7: =IF(VLOOKUP($A7,Dates,26,)>0,VLOOKUP($A7,Dates,26,)-VLOOKUP($A7,Jobs,26,)," ") -> -160 | W7: =IF(VLOOKUP($A7,Dates,27,)>0,"Y"," ") -> Y | X7: =IF(VLOOKUP($A7,Dates,27,)>0,VLOOKUP($A7,Dates,27,)-VLOOKUP($A7,Jobs,27,)," ") -> -168 | Y7: =IF(VLOOKUP($A7,Dates,28,)>0,"Y"," ") -> Y | Z7: =IF(VLOOKUP($A7,Dates,28,)>0,VLOOKUP($A7,Dates,28,)-VLOOKUP($A7,Jobs,28,)," ") -> -165 | AA7: =IF(VLOOKUP($A7,Dates,29,)>0,"Y"," ") -> Y | AB7: =IF(VLOOKUP($A7,Dates,29,)>0,VLOOKUP($A7,Dates,29,)-VLOOKUP($A7,Jobs,29,)," ") -> -139 | AC7: =IF(VLOOKUP($A7,Dates,30,)>0,"Y"," ") | AD7: =IF(VLOOKUP($A7,Dates,30,)>0,VLOOKUP($A7,Dates,30,)-VLOOKUP($A7,Jobs,30,)," ") | AE7: =IF(VLOOKUP($A7,Dates,31,)>0,"Y"," ") -> Y | AF7: =IF(VLOOKUP($A7,Dates,31,)>0,VLOOKUP($A7,Dates,31,)-VLOOKUP($A7,Jobs,31,)," ") -> -168 | AG7: =_xlfn.IFNA(VLOOKUP(A7,Dates,22,FALSE),"") -> 46230 | AH7: =_xlfn.IFNA(IF(Y7="Y","DONE",VLOOKUP(A7,'Date Calcs from Ship Date'!A:AE,27,0)),"") -> DONE | AI7: =IFERROR(AH7-TODAY(),0) -> 0 | AJ7: =_xlfn.IFNA(IF(AC7="Y","DONE",VLOOKUP(A7,'Date Calcs from Ship Date'!A:AE,29,0)),"") -> 46105 | AK7: =IFERROR(AJ7-TODAY(),0) -> 32 | AL7: =_xlfn.IFNA(IF(AA7="Y","DONE",VLOOKUP(A7,'Date Calcs from Ship Date'!A:AI,28,0)),"") -> DONE | AM7: =IFERROR(AL7-TODAY(),0) -> 0 | AN7: =IF(U7="Y","DONE",VLOOKUP(A7,'Date Calcs from Ship Date'!A:AE,25,0)) -> DONE | AO7: =IFERROR(AP7-AN7,0) -> 0 | AP7: =IF(AE7="Y","DONE",VLOOKUP(A7,'Date Calcs from Ship Date'!A:AE,30,0)) -> DONE | AQ7: =IFERROR(AP7-TODAY(),0) -> 0 | AR7: =_xlfn.IFNA(VLOOKUP(A7,'Date Calcs from Ship Date'!A:C,3,0),"") -> 46175 | AS7: =AG7-AR7 -> 55 | AU7: =IF(VLOOKUP(A7,Dates,32,)>0,VLOOKUP(A7,Dates,32,)," ")
A8: 25-055 | B8: =VLOOKUP(A8,Jobs,2,) -> Airgas | D8: =IF(VLOOKUP($A8,Jobs,8,)>0,"Y"," ") -> Y | E8: =IF(VLOOKUP($A8,Dates,8,)>0,VLOOKUP($A8,Dates,8,)-VLOOKUP($A8,Jobs,8,)," ") -> 54 | F8: =IF(VLOOKUP($A8,Dates,16,)>0,"Y"," ") -> Y | G8: =IF(VLOOKUP($A8,Dates,16,)>0,VLOOKUP($A8,Dates,16,)-VLOOKUP($A8,Jobs,16,)," ") -> 166 | H8: =_xlfn.IFNA(IF(VLOOKUP($A12,Dates,17,)>0,"Y"," "),"") -> Y | I8: =IF(VLOOKUP($A12,Dates,17,)>0,VLOOKUP($A12,Dates,17,)-VLOOKUP($A12,Jobs,17,)," ") -> #VALUE! | K8: =IF(VLOOKUP($A8,Dates,19,)>0,"Y"," ") -> Y | L8: =IF(VLOOKUP($A8,Dates,19,)>0,VLOOKUP($A8,Dates,19,)-VLOOKUP($A8,Jobs,19,)," ") -> 5 | M8: =IF(VLOOKUP($A8,Dates,20,)>0,"Y"," ") | N8: =IF(VLOOKUP($A8,Dates,20,)>0,VLOOKUP($A8,Dates,20,)-VLOOKUP($A8,Jobs,20,)," ") | O8: =IF(VLOOKUP($A8,Dates,21,)>0,"Y"," ") -> Y | P8: =IF(VLOOKUP($A8,Dates,21,)>0,VLOOKUP($A8,Dates,21,)-VLOOKUP($A8,Jobs,21,)," ") -> 0 | Q8: =IF(VLOOKUP($A8,Dates,23,)>0,"Y"," ") -> Y | R8: =IF(VLOOKUP($A8,Dates,23,)>0,VLOOKUP($A8,Dates,23,)-VLOOKUP($A8,Jobs,23,)," ") -> -166 | S8: =IF(VLOOKUP($A8,Dates,24,)>0,"Y"," ") -> Y | T8: =IF(VLOOKUP($A8,Dates,24,)>0,VLOOKUP($A8,Dates,24,)-VLOOKUP($A8,Jobs,24,)," ") -> 12 | U8: =IF(VLOOKUP($A8,Dates,26,)>0,"Y"," ") | V8: =IF(VLOOKUP($A8,Dates,26,)>0,VLOOKUP($A8,Dates,26,)-VLOOKUP($A8,Jobs,26,)," ") | W8: =IF(VLOOKUP($A8,Dates,27,)>0,"Y"," ") -> Y | X8: =IF(VLOOKUP($A8,Dates,27,)>0,VLOOKUP($A8,Dates,27,)-VLOOKUP($A8,Jobs,27,)," ") -> 7 | Y8: =IF(VLOOKUP($A8,Dates,28,)>0,"Y"," ") | Z8: =IF(VLOOKUP($A8,Dates,28,)>0,VLOOKUP($A8,Dates,28,)-VLOOKUP($A8,Jobs,28,)," ") | AA8: =IF(VLOOKUP($A8,Dates,29,)>0,"Y"," ") -> Y | AB8: =IF(VLOOKUP($A8,Dates,29,)>0,VLOOKUP($A8,Dates,29,)-VLOOKUP($A8,Jobs,29,)," ") -> 40 | AC8: =IF(VLOOKUP($A8,Dates,30,)>0,"Y"," ") -> Y | AD8: =IF(VLOOKUP($A8,Dates,30,)>0,VLOOKUP($A8,Dates,30,)-VLOOKUP($A8,Jobs,30,)," ") -> 46 | AE8: =IF(VLOOKUP($A8,Dates,31,)>0,"Y"," ") | AF8: =IF(VLOOKUP($A8,Dates,31,)>0,VLOOKUP($A8,Dates,31,)-VLOOKUP($A8,Jobs,31,)," ") | AG8: =_xlfn.IFNA(VLOOKUP(A8,Dates,22,FALSE),"") -> 46190 | AH8: =_xlfn.IFNA(IF(Y8="Y","DONE",VLOOKUP(A8,'Date Calcs from Ship Date'!A:AE,27,0)),"") -> 46098 | AI8: =IFERROR(AH8-TODAY(),0) -> 25 | AJ8: =_xlfn.IFNA(IF(AC8="Y","DONE",VLOOKUP(A8,'Date Calcs from Ship Date'!A:AE,29,0)),"") -> DONE | AK8: =IFERROR(AJ8-TODAY(),0) -> 0 | AL8: =_xlfn.IFNA(IF(AA8="Y","DONE",VLOOKUP(A8,'Date Calcs from Ship Date'!A:AI,28,0)),"") -> DONE | AM8: =IFERROR(AL8-TODAY(),0) -> 0 | AN8: =IF(U8="Y","DONE",VLOOKUP(A8,'Date Calcs from Ship Date'!A:AE,25,0)) -> 46105 | AO8: =IFERROR(AP8-AN8,0) -> 7 | AP8: =IF(AE8="Y","DONE",VLOOKUP(A8,'Date Calcs from Ship Date'!A:AE,30,0)) -> 46112 | AQ8: =IFERROR(AP8-TODAY(),0) -> 39 | AR8: =_xlfn.IFNA(VLOOKUP(A8,'Date Calcs from Ship Date'!A:C,3,0),"") -> 46168 | AS8: =AG8-AR8 -> 22 | AU8: =IF(VLOOKUP(A8,Dates,32,)>0,VLOOKUP(A8,Dates,32,)," ") | AV8: Head from California
A9: 25-066 | B9: =VLOOKUP(A9,Jobs,2,) -> Reco | D9: =IF(VLOOKUP($A9,Jobs,8,)>0,"Y"," ") -> Y | E9: =IF(VLOOKUP($A9,Dates,8,)>0,VLOOKUP($A9,Dates,8,)-VLOOKUP($A9,Jobs,8,)," ") -> 5 | F9: =IF(VLOOKUP($A9,Dates,16,)>0,"Y"," ") -> Y | G9: =IF(VLOOKUP($A9,Dates,16,)>0,VLOOKUP($A9,Dates,16,)-VLOOKUP($A9,Jobs,16,)," ") -> #VALUE! | H9: =_xlfn.IFNA(IF(VLOOKUP($A13,Dates,17,)>0,"Y"," "),"") -> Y | I9: =IF(VLOOKUP($A13,Dates,17,)>0,VLOOKUP($A13,Dates,17,)-VLOOKUP($A13,Jobs,17,)," ") -> #VALUE! | K9: =IF(VLOOKUP($A9,Dates,19,)>0,"Y"," ") -> Y | L9: =IF(VLOOKUP($A9,Dates,19,)>0,VLOOKUP($A9,Dates,19,)-VLOOKUP($A9,Jobs,19,)," ") -> 5 | M9: =IF(VLOOKUP($A9,Dates,20,)>0,"Y"," ") | N9: =IF(VLOOKUP($A9,Dates,20,)>0,VLOOKUP($A9,Dates,20,)-VLOOKUP($A9,Jobs,20,)," ") | O9: =IF(VLOOKUP($A9,Dates,21,)>0,"Y"," ") -> Y | P9: =IF(VLOOKUP($A9,Dates,21,)>0,VLOOKUP($A9,Dates,21,)-VLOOKUP($A9,Jobs,21,)," ") -> 0 | Q9: =IF(VLOOKUP($A9,Dates,23,)>0,"Y"," ") -> Y | R9: =IF(VLOOKUP($A9,Dates,23,)>0,VLOOKUP($A9,Dates,23,)-VLOOKUP($A9,Jobs,23,)," ") -> -237 | S9: =IF(VLOOKUP($A9,Dates,24,)>0,"Y"," ") -> Y | T9: =IF(VLOOKUP($A9,Dates,24,)>0,VLOOKUP($A9,Dates,24,)-VLOOKUP($A9,Jobs,24,)," ") -> -6 | U9: =IF(VLOOKUP($A9,Dates,26,)>0,"Y"," ") -> Y | V9: =IF(VLOOKUP($A9,Dates,26,)>0,VLOOKUP($A9,Dates,26,)-VLOOKUP($A9,Jobs,26,)," ") -> -5 | W9: =IF(VLOOKUP($A9,Dates,27,)>0,"Y"," ") -> Y | X9: =IF(VLOOKUP($A9,Dates,27,)>0,VLOOKUP($A9,Dates,27,)-VLOOKUP($A9,Jobs,27,)," ") -> -12 | Y9: =IF(VLOOKUP($A9,Dates,28,)>0,"Y"," ") -> Y | Z9: =IF(VLOOKUP($A9,Dates,28,)>0,VLOOKUP($A9,Dates,28,)-VLOOKUP($A9,Jobs,28,)," ") -> -17 | AA9: =IF(VLOOKUP($A9,Dates,29,)>0,"Y"," ") -> Y | AB9: =IF(VLOOKUP($A9,Dates,29,)>0,VLOOKUP($A9,Dates,29,)-VLOOKUP($A9,Jobs,29,)," ") -> 185 | AC9: =IF(VLOOKUP($A9,Dates,30,)>0,"Y"," ") -> Y | AD9: =IF(VLOOKUP($A9,Dates,30,)>0,VLOOKUP($A9,Dates,30,)-VLOOKUP($A9,Jobs,30,)," ") -> -10 | AE9: =IF(VLOOKUP($A9,Dates,31,)>0,"Y"," ") -> Y | AF9: =IF(VLOOKUP($A9,Dates,31,)>0,VLOOKUP($A9,Dates,31,)-VLOOKUP($A9,Jobs,31,)," ") -> 144 | AG9: =_xlfn.IFNA(VLOOKUP(A9,Dates,22,FALSE),"") -> 46111 | AH9: =_xlfn.IFNA(IF(Y9="Y","DONE",VLOOKUP(A9,'Date Calcs from Ship Date'!A:AE,27,0)),"") -> DONE | AI9: =IFERROR(AH9-TODAY(),0) -> 0 | AJ9: =_xlfn.IFNA(IF(AC9="Y","DONE",VLOOKUP(A9,'Date Calcs from Ship Date'!A:AE,29,0)),"") -> DONE | AK9: =IFERROR(AJ9-TODAY(),0) -> 0 | AL9: =_xlfn.IFNA(IF(AA9="Y","DONE",VLOOKUP(A9,'Date Calcs from Ship Date'!A:AI,28,0)),"") -> DONE | AM9: =IFERROR(AL9-TODAY(),0) -> 0 | AN9: =IF(U9="Y","DONE",VLOOKUP(A9,'Date Calcs from Ship Date'!A:AE,25,0)) -> DONE | AO9: =IFERROR(AP9-AN9,0) -> 0 | AP9: =IF(AE9="Y","DONE",VLOOKUP(A9,'Date Calcs from Ship Date'!A:AE,30,0)) -> DONE | AQ9: =IFERROR(AP9-TODAY(),0) -> 0 | AR9: =_xlfn.IFNA(VLOOKUP(A9,'Date Calcs from Ship Date'!A:C,3,0),"") -> 46090 | AS9: =AG9-AR9 -> 21 | AU9: =IF(VLOOKUP(A9,Dates,32,)>0,VLOOKUP(A9,Dates,32,)," ")
A10: 25-067 | B10: =VLOOKUP(A10,Jobs,2,) -> Reco | D10: =IF(VLOOKUP($A10,Jobs,8,)>0,"Y"," ") -> Y | E10: =IF(VLOOKUP($A10,Dates,8,)>0,VLOOKUP($A10,Dates,8,)-VLOOKUP($A10,Jobs,8,)," ") -> 5 | F10: =IF(VLOOKUP($A10,Dates,16,)>0,"Y"," ") -> Y | G10: =IF(VLOOKUP($A10,Dates,16,)>0,VLOOKUP($A10,Dates,16,)-VLOOKUP($A10,Jobs,16,)," ") -> #VALUE! | H10: =_xlfn.IFNA(IF(VLOOKUP($A14,Dates,17,)>0,"Y"," "),"") -> Y | I10: =IF(VLOOKUP($A14,Dates,17,)>0,VLOOKUP($A14,Dates,17,)-VLOOKUP($A14,Jobs,17,)," ") -> #VALUE! | K10: =IF(VLOOKUP($A10,Dates,19,)>0,"Y"," ") -> Y | L10: =IF(VLOOKUP($A10,Dates,19,)>0,VLOOKUP($A10,Dates,19,)-VLOOKUP($A10,Jobs,19,)," ") -> 5 | M10: =IF(VLOOKUP($A10,Dates,20,)>0,"Y"," ") | N10: =IF(VLOOKUP($A10,Dates,20,)>0,VLOOKUP($A10,Dates,20,)-VLOOKUP($A10,Jobs,20,)," ") | O10: =IF(VLOOKUP($A10,Dates,21,)>0,"Y"," ") -> Y | P10: =IF(VLOOKUP($A10,Dates,21,)>0,VLOOKUP($A10,Dates,21,)-VLOOKUP($A10,Jobs,21,)," ") -> 0 | Q10: =IF(VLOOKUP($A10,Dates,23,)>0,"Y"," ") -> Y | R10: =IF(VLOOKUP($A10,Dates,23,)>0,VLOOKUP($A10,Dates,23,)-VLOOKUP($A10,Jobs,23,)," ") -> -237 | S10: =IF(VLOOKUP($A10,Dates,24,)>0,"Y"," ") -> Y | T10: =IF(VLOOKUP($A10,Dates,24,)>0,VLOOKUP($A10,Dates,24,)-VLOOKUP($A10,Jobs,24,)," ") -> -6 | U10: =IF(VLOOKUP($A10,Dates,26,)>0,"Y"," ") -> Y | V10: =IF(VLOOKUP($A10,Dates,26,)>0,VLOOKUP($A10,Dates,26,)-VLOOKUP($A10,Jobs,26,)," ") -> -5 | W10: =IF(VLOOKUP($A10,Dates,27,)>0,"Y"," ") -> Y | X10: =IF(VLOOKUP($A10,Dates,27,)>0,VLOOKUP($A10,Dates,27,)-VLOOKUP($A10,Jobs,27,)," ") -> -12 | Y10: =IF(VLOOKUP($A10,Dates,28,)>0,"Y"," ") -> Y | Z10: =IF(VLOOKUP($A10,Dates,28,)>0,VLOOKUP($A10,Dates,28,)-VLOOKUP($A10,Jobs,28,)," ") -> -17 | AA10: =IF(VLOOKUP($A10,Dates,29,)>0,"Y"," ") -> Y | AB10: =IF(VLOOKUP($A10,Dates,29,)>0,VLOOKUP($A10,Dates,29,)-VLOOKUP($A10,Jobs,29,)," ") -> 185 | AC10: =IF(VLOOKUP($A10,Dates,30,)>0,"Y"," ") -> Y | AD10: =IF(VLOOKUP($A10,Dates,30,)>0,VLOOKUP($A10,Dates,30,)-VLOOKUP($A10,Jobs,30,)," ") -> -10 | AE10: =IF(VLOOKUP($A10,Dates,31,)>0,"Y"," ") -> Y | AF10: =IF(VLOOKUP($A10,Dates,31,)>0,VLOOKUP($A10,Dates,31,)-VLOOKUP($A10,Jobs,31,)," ") -> 144 | AG10: =_xlfn.IFNA(VLOOKUP(A10,Dates,22,FALSE),"") -> 46111 | AH10: =_xlfn.IFNA(IF(Y10="Y","DONE",VLOOKUP(A10,'Date Calcs from Ship Date'!A:AE,27,0)),"") -> DONE | AI10: =IFERROR(AH10-TODAY(),0) -> 0 | AJ10: =_xlfn.IFNA(IF(AC10="Y","DONE",VLOOKUP(A10,'Date Calcs from Ship Date'!A:AE,29,0)),"") -> DONE | AK10: =IFERROR(AJ10-TODAY(),0) -> 0 | AL10: =_xlfn.IFNA(IF(AA10="Y","DONE",VLOOKUP(A10,'Date Calcs from Ship Date'!A:AI,28,0)),"") -> DONE | AM10: =IFERROR(AL10-TODAY(),0) -> 0 | AN10: =IF(U10="Y","DONE",VLOOKUP(A10,'Date Calcs from Ship Date'!A:AE,25,0)) -> DONE | AO10: =IFERROR(AP10-AN10,0) -> 0 | AP10: =IF(AE10="Y","DONE",VLOOKUP(A10,'Date Calcs from Ship Date'!A:AE,30,0)) -> DONE | AQ10: =IFERROR(AP10-TODAY(),0) -> 0 | AR10: =_xlfn.IFNA(VLOOKUP(A10,'Date Calcs from Ship Date'!A:C,3,0),"") -> 46090 | AS10: =AG10-AR10 -> 21 | AU10: =IF(VLOOKUP(A10,Dates,32,)>0,VLOOKUP(A10,Dates,32,)," ")
A11: 25-068 | B11: =VLOOKUP(A11,Jobs,2,) -> Reco | D11: =IF(VLOOKUP($A11,Jobs,8,)>0,"Y"," ") -> Y | E11: =IF(VLOOKUP($A11,Dates,8,)>0,VLOOKUP($A11,Dates,8,)-VLOOKUP($A11,Jobs,8,)," ") -> 5 | F11: =IF(VLOOKUP($A11,Dates,16,)>0,"Y"," ") -> Y | G11: =IF(VLOOKUP($A11,Dates,16,)>0,VLOOKUP($A11,Dates,16,)-VLOOKUP($A11,Jobs,16,)," ") -> #VALUE! | H11: =_xlfn.IFNA(IF(VLOOKUP($A15,Dates,17,)>0,"Y"," "),"") -> Y | I11: =IF(VLOOKUP($A15,Dates,17,)>0,VLOOKUP($A15,Dates,17,)-VLOOKUP($A15,Jobs,17,)," ") -> -5 | K11: =IF(VLOOKUP($A11,Dates,19,)>0,"Y"," ") -> Y | L11: =IF(VLOOKUP($A11,Dates,19,)>0,VLOOKUP($A11,Dates,19,)-VLOOKUP($A11,Jobs,19,)," ") -> 5 | M11: =IF(VLOOKUP($A11,Dates,20,)>0,"Y"," ") | N11: =IF(VLOOKUP($A11,Dates,20,)>0,VLOOKUP($A11,Dates,20,)-VLOOKUP($A11,Jobs,20,)," ") | O11: =IF(VLOOKUP($A11,Dates,21,)>0,"Y"," ") -> Y | P11: =IF(VLOOKUP($A11,Dates,21,)>0,VLOOKUP($A11,Dates,21,)-VLOOKUP($A11,Jobs,21,)," ") -> 0 | Q11: =IF(VLOOKUP($A11,Dates,23,)>0,"Y"," ") -> Y | R11: =IF(VLOOKUP($A11,Dates,23,)>0,VLOOKUP($A11,Dates,23,)-VLOOKUP($A11,Jobs,23,)," ") -> -265 | S11: =IF(VLOOKUP($A11,Dates,24,)>0,"Y"," ") -> Y | T11: =IF(VLOOKUP($A11,Dates,24,)>0,VLOOKUP($A11,Dates,24,)-VLOOKUP($A11,Jobs,24,)," ") -> -6 | U11: =IF(VLOOKUP($A11,Dates,26,)>0,"Y"," ") -> Y | V11: =IF(VLOOKUP($A11,Dates,26,)>0,VLOOKUP($A11,Dates,26,)-VLOOKUP($A11,Jobs,26,)," ") -> -5 | W11: =IF(VLOOKUP($A11,Dates,27,)>0,"Y"," ") -> Y | X11: =IF(VLOOKUP($A11,Dates,27,)>0,VLOOKUP($A11,Dates,27,)-VLOOKUP($A11,Jobs,27,)," ") -> -12 | Y11: =IF(VLOOKUP($A11,Dates,28,)>0,"Y"," ") -> Y | Z11: =IF(VLOOKUP($A11,Dates,28,)>0,VLOOKUP($A11,Dates,28,)-VLOOKUP($A11,Jobs,28,)," ") -> -17 | AA11: =IF(VLOOKUP($A11,Dates,29,)>0,"Y"," ") -> Y | AB11: =IF(VLOOKUP($A11,Dates,29,)>0,VLOOKUP($A11,Dates,29,)-VLOOKUP($A11,Jobs,29,)," ") -> 185 | AC11: =IF(VLOOKUP($A11,Dates,30,)>0,"Y"," ") -> Y | AD11: =IF(VLOOKUP($A11,Dates,30,)>0,VLOOKUP($A11,Dates,30,)-VLOOKUP($A11,Jobs,30,)," ") -> -10 | AE11: =IF(VLOOKUP($A11,Dates,31,)>0,"Y"," ") -> Y | AF11: =IF(VLOOKUP($A11,Dates,31,)>0,VLOOKUP($A11,Dates,31,)-VLOOKUP($A11,Jobs,31,)," ") -> 172 | AG11: =_xlfn.IFNA(VLOOKUP(A11,Dates,22,FALSE),"") -> 46139 | AH11: =_xlfn.IFNA(IF(Y11="Y","DONE",VLOOKUP(A11,'Date Calcs from Ship Date'!A:AE,27,0)),"") -> DONE | AI11: =IFERROR(AH11-TODAY(),0) -> 0 | AJ11: =_xlfn.IFNA(IF(AC11="Y","DONE",VLOOKUP(A11,'Date Calcs from Ship Date'!A:AE,29,0)),"") -> DONE | AK11: =IFERROR(AJ11-TODAY(),0) -> 0 | AL11: =_xlfn.IFNA(IF(AA11="Y","DONE",VLOOKUP(A11,'Date Calcs from Ship Date'!A:AI,28,0)),"") -> DONE | AM11: =IFERROR(AL11-TODAY(),0) -> 0 | AN11: =IF(U11="Y","DONE",VLOOKUP(A11,'Date Calcs from Ship Date'!A:AE,25,0)) -> DONE | AO11: =IFERROR(AP11-AN11,0) -> 0 | AP11: =IF(AE11="Y","DONE",VLOOKUP(A11,'Date Calcs from Ship Date'!A:AE,30,0)) -> DONE | AQ11: =IFERROR(AP11-TODAY(),0) -> 0 | AR11: =_xlfn.IFNA(VLOOKUP(A11,'Date Calcs from Ship Date'!A:C,3,0),"") -> 46118 | AS11: =AG11-AR11 -> 21 | AU11: =IF(VLOOKUP(A11,Dates,32,)>0,VLOOKUP(A11,Dates,32,)," ")
