Workbook

Sheet Key Initiatives
A1: Key Initiatives - 2026
A3: Sales and Marketing: | B3: Grow order intake to $20.0 million and maintain margins
B4: Use OTTO to automate cost estimation workflow
B5: Hire Project Manager (U.S.) to improve project execution, customer communication, and On-Time Delivery
B6: Hire Estimator in India to support increased volume of RFQs and proposals
B7: Pursue high-volume projects with AI data centers via new Savannah-based production facility
B8: Leverage India's cost position to be more competitive on labor-intensive products in US market
B9: Maintain gross margins. Monitor costs and keep prices and VPH in line with inflation.
B10: Launch new website and continue to drive digital marketing efforts (SEO, social media, etc.)
B11: Utilize ZoomInfo to identify and target new, high-probability opportunities
A14: Operations: | B14: Increase U.S. capacity by 50% with less than 25% increase in shop floor headcount
B15: Establish new, high-volume / data center production facility in Savannah
B16: Improve day-to-day shop floor management and address production issues in real time
B17: Utilize new equipment (column & boom, cobot, Arc-Boss, etc.) to reduce labor input
B18: Increase shop floor headcount to keep customer lead times below 20 weeks
B19: Fill open Finishing Area Supervisor position to drive improvement in Finishing department
B20: Improve and stabilize entire India-to-U.S. supply chain, from order placement to Savannah delivery
B21: Pursue opportunities to source labor intensive assemblies (jackets, coils, etc.) from India
A24: Engineering: | B24: Leverage engineering resources to support growth and improve quality
B25: Raise the bar on ST&E engineering group in India. Improve quality and speed (calcs, drawings, BOMs, etc.)
B26: Use technology (Compress, Inventor, AI, etc.) to reduce drawing times
B27: Transition from AME Tank to Compress for API calculations
B28: Develop workflow automation application(s) to accelerate "Order-to-Shop Release" workflow
B29: Extend engineering expertise to include heat exchangers
A32: Quality: | B32: Define Savannah Tank's quality standards and ensure compliance across all manufacturing locations
B33: Retain ASME Section VIII, Div. 1 certification
B34: Establish written / visual Quality standards that define Savannah Tank's "premier" quality position
B35: Implement a Quality Management System that deploys our QC standards across all locations
B36: Hire additional QC Inspector to support growth and maintain QC vigilence on the shop floor
B37: Draft and implement written Quality improvement plan for U.S. operation. Make Quality meetings action-oriented.
B38: Build a reliable & timely system to thoroughly inspect and approve India fabrication prior to shipment to U.S.
B39: Attain ISO-9001 certification for Savannah Tank India
A42: People: | B42: Hire, retain, and develop key people. Improve safety on shop floor
B43: Hire additional welders / fabricators to support increased demand and staff new production facility
B44: Hire Project Manager to improve project execution and On-Time Delivery
B45: Update safety walk evaluation tool and conduct regular safety walks
B46: Expand and upgrade shop floor supervisors' office. Add QC inspection office.
B47: Make key hires in India (Estimator, Engineering Manager)

Sheet Top Level
A1: OGSM 2026 | C1: Savannah Tank and Equipment
A2: Version 1.0 | C2: "Quality You Can See. People You Can Trust."
A3: OBJECTIVES | B3: GOALS | D3: STRATEGIES | F3: MEASURES | G3: CHAMPION | H3: SOURCE DATA | I3: MEASURE
A4: What are we trying to achieve | B4: What success looks like | D4: How we’ll achieve success | F4: Measure we’ll use to track progress | I4: 2015
D6: Increase Sales and Marketing to Drive Order Flow and Maintain Healthy Backlog | E6: · | F6: Total orders > $20.0 million | G6: Chris | H6: Quote Log | I6: 6245641
E7: · | F7: Savannah Tank India Orders > $1.5 million | G7: Chris | H7: Quote Log | I7: 232
D8: Generate sufficient order flow to maximize available shop production time. Grow sales funnel through increased customer contact and digital marketing. Utilize Savannah Tank India to expand product range and reduce costs on labor-intensive products. | E8: · | F8: Weekly shop backlog > 12,000 hours throughout 2026 | G8: Chris | H8: Quote Log | I8: 26657907
E9: · | F9: Total 2025 Value Added Sales (Orders) > $160 / Labor Hour | G9: Chris
E10: · | F10: Number of inquiries > 300 (3-year average = 295) | G10: Chris
E11: · | F11: Quoted value at or above $100 million (20% "Win Rate") | G11: Chris
H12: Production Sch.
A13: VISION | H13: Drawing Error Log
A14: We will be the premier manufacturer of custom tanks, pressure vessels, and process equipment in the eastern United States. We consistently live up to our "Quality You Can See. People You Can Trust." mindset. | C14: 2026 Financials | D14: Increase Capacity and Drive Factory Improvement | E14: · | F14: New high-volume / data center production facility in operation by 3/1/2026 | G14: Dustin | H14: OTD of Drawing Log
C15: Revenue > $14.0 Million | D15: Expand capacity and profitably meet increased demand by making measureable improvements in Quality, Safety, Cost, and Speed (Delivery). Leverage India factory for additional capacity and labor-intensive products. | E15: · | F15: U.S. shop-wide Labor Efficiency of 93% or above (full-year average) | G15: Dustin | H15: Material Exceptions Log
C16: G.P. > $5.0 Million | E16: · | F16: U.S. On Time Completion at 90% or above (full-year average) | G16: Dustin
E17: · | F17: U.S. Rework hours < 1.25% of direct labor hours | G17: Dustin | H17: Major Material Variance Log
E18: · | F18: U.S. Cost of Quality < $1.75 per direct labor hour | G18: Dustin
E19: · | F19: U.S. Overhead < 25% of total shop hours | G19: Dustin | H19: JobBoss
E20: · | F20: India On Time Delivery at 90% or above (full-year average) | G20: Nick
H21: JobBoss
D22: Enhance Engineering Resources in US and India to Support Sales Growth. Bring India Engineering Team Up To Savannah Tank Standards. | E22: · | F22: Provide calculations to Sales team in 3 business days or less, with measured error rate less than 5% for 2026. | G22: Nick | H22: JobBoss
H23: JobBoss | I23: 0.11
E24: · | F24: Favorable cost variance on major raw materials > 3% vs. quoted prices | G24: Nick
D25: Support sales effort with timely design calculations and cost estimates. Reduce costs by strategically shifting engineering work from US to India. | E25: · | F25: India drawing accuracy > 90% "First Pass Approval Rate" by 2/1/2026 | G25: Nick | H25: Employee Retention Log
E26: · | F26: Use Compress & Inventor to reduce drawing times by 30% | G26: Nick
E27: · | F27: Add technical resource with expertise in heat transfer and heat exchangers | G27: Nick
D29: Build a business-wide Quality Management System that supports growth and clearly defines Savannah Tank's standards of excellence. | E29: · | F29: Zero customer complaints / quality "escapes" (U.S.) in 2026 | G29: John
E30: · | F30: Retain U.S. ASME certification with successful ASME Joint Review (May 2026) | G30: John
E31: · | F31: Develop and deploy Visual Quality Standards Guide across U.S. and India operations by 12/31/2026 | G31: John
D32: Establish and deploy a consistent set of quality standards across U.S. and India operations that aligns with our "premier" quality positioning. Define, document, and maintain clear acceptance standards across all facets of Savannah Tank's worldwide operations (fabrication, welding, finishing, etc.)
E33: · | F33: Implement comprehensive, reliable, and timely process to review and approve India fabrication prior to shipment to U.S. Process in place by 4/1/2026. | G33: John
E36: · | F36: Zero customer complaints / quality "escapes" (India) in 2026 | G36: Nick
E37: · | F37: Attain ISO-9001 certification in India by 6/30/2026 | G37: Nick
D39: Expand Savannah Tank Team in US and India to Meet Increased Customer Demand. Embed a Culture of Safety, Quality, and Efficiency on the Shop Floor. | E39: · | F39: US customer lead times less than 20 weeks throughout 2026 | G39: Dustin
E40: · | F40: Zero lost time accidents in 2026 (U.S.) | G40: Dustin
E41: · | F41: Zero OSHA violations / citations in 2026 | G41: Dustin
D42: Recruit skilled people and develop them to be the best in the industry. Continue to build a safety mindset on the shop floor. | H42: OSHA Log | I42: 0
E43: · | F43: Zero lost time accidents in 2026 (India) | G43: Nick | H43: OSHA Log | I43: 0

Sheet Sales & Marketing
A1: ='Top Level'!A1 -> OGSM 2026 | C1: ='Top Level'!C1:F1 -> Savannah Tank and Equipment
A2: ='Top Level'!A2 -> Version 1.0
A3: STRATEGY | B3: MEASURES | D3: ACTION PLANS | G3: CHAMPION
A4: How we’ll achieve success | B4: Measure we’ll use to track progress
A6: ='Top Level'!D6:D7 -> Increase Sales and Marketing to Drive Order Flow and Maintain Healthy Backlog | B6: · | C6: ='Top Level'!F6 -> Total orders > $20.0 million | D6: · | E6: Implement automated cost estimation application (OTTO MVP) to reduce estimation time. In daily use by 3/1/2026. | G6: Chris
B8: · | C8: ='Top Level'!F7 -> Savannah Tank India Orders > $1.5 million | D8: · | E8: Hire experienced estimator in India to support growing cost estimation demand in U.S. and India. In place by 3/1/2026. | G8: Nick
D10: · | E10: Hire Project Manager (U.S.) to improve project execution, customer communication, and On-Time Delivery. In place by 3/1/2026. | G10: Chris
A11: Generate sufficient order flow to maximize available shop production time. Grow sales funnel through increased customer contact and digital marketing. Utilize Savannah Tank India to expand product range and reduce costs on labor-intensive products. | B11: · | C11: ='Top Level'!F8 -> Weekly shop backlog > 12,000 hours throughout 2026 | G11: Chris
D13: · | E13: Leverage India's cost position and abundant skilled labor pool to expand U.S. product range to include heat exchangers and polished tanks. Sales from India > $1.5 million by 12/31/2025. | G13: Chris
B14: · | C14: ='Top Level'!F9 -> Total 2025 Value Added Sales (Orders) > $160 / Labor Hour
D16: · | E16: Expand network of contacts with EPCs through networking, referrals, meetings, and phone calls. 30 new contacts by 12/31/2025. | G16: Chris
B17: · | C17: ='Top Level'!F10 -> Number of inquiries > 300 (3-year average = 295)
D19: · | E19: Expand network of contacts with major chemical companies across the Southeast through networking, referrals, meetings, and phone calls. 30 new contacts by 12/31/2025. | G19: Chris
B20: · | C20: ='Top Level'!F11 -> Quoted value at or above $100 million (20% "Win Rate")
D22: · | E22: Maintain gross margins as material and labor costs rise. Monitor costs and keep prices and VPH in line with inflation.
E23: · | F23: Review target VPH against actual costs per hour on monthly basis starting 2/6/2025. | G23: David
E24: · | F24: Maintain $28 - $32 spread between quoted VPH and actual CPH. Monitor VPH monthly starting 2/6/2025. | G24: Chris
D26: · | E26: Expand and improve digital marketing efforts
E27: · | F27: Meet with SEO agency monthly to drive progress and track performance. Meetings to start in January 2025. | G27: David
E28: · | F28: Expand use of LinkedIn to continue to improve brand awareness and perception with customer base. Plan developed by 4/30/2025. | G28: David
D31: · | E31: Continue to add structure and transparency to sales management process
E32: · | F32: Hold weekly meeting to review sales metrics, prospecting activities, and sales funnel. Review production schedule and backlog to identify potential gaps and opportunities to fill them. Meetings to start 2/4/2025. | G32: David
E34: · | F34: Maintain Quote Log and Sales Funnel to guage anticipated order intake starting 1/6/2025 | G34: Chris
E35: · | F35: Maintain sales dashboard weekly starting 2/3/2025 | G35: Chris
E36: · | F36: Review sales metrics with management team monthly starting February 2025 | G36: Chris
E37: · | F37: Evaluate CRM systems for potential implementation in late 2025. 3-4 systems evaluated by 9/30/2025. | G37: Chris

Sheet Ops Improvement
A1: ='Top Level'!A1 -> OGSM 2026 | C1: ='Top Level'!C1:F1 -> Savannah Tank and Equipment
A2: ='Top Level'!A2 -> Version 1.0
A3: STRATEGY | B3: MEASURES | D3: ACTION PLANS | H3: CHAMPION
A4: How we’ll achieve success | B4: Measure we’ll use to track progress
A6: Increase Capacity and Drive Factory Improvement | B6: · | C6: ='Top Level'!F14 -> New high-volume / data center production facility in operation by 3/1/2026 | D6: · | E6: Continue to improve management and control of shop floor and daily work activities
E7: · | F7: Track and graph labor efficiency in the shop using JobBOSS on a weekly basis starting 1/5/2026. | H7: Dustin
E8: · | F8: Continue to track and graph rework hours vs. goal on a weekly basis starting 1/5/2026 | H8: John
A9: Expand capacity and profitably meet increased demand by making measureable improvements in Quality, Safety, Cost, and Speed (Delivery). Establish factory in India for additional capacity and to build labor-intensive products. | E9: · | F9: Track and graph On Time Completion statistics starting 3/15/2026 | H9: Dustin
B10: · | C10: ='Top Level'!F15 -> U.S. shop-wide Labor Efficiency of 93% or above (full-year average) | E10: · | F10: Supervisors to draft daily written work plans for each employee. Copies to Dustin and David daily starting 1/20/2025. | H10: Dustin
E11: · | F11: Check progress of work plans with supervisors 2 - 3x each day and address any significant variances from plan. Routine in place starting 1/20/2025 | H11: Dustin
B13: · | C13: ='Top Level'!F16 -> U.S. On Time Completion at 90% or above (full-year average) | E13: · | F13: Post weekly shop performance metrics (Safety, Quality, Efficiency, On-Time Completion, etc.) in shop starting 2/3/2026 | H13: Dustin
D15: · | E15: Utilize new equipment to increase shop floor productivity. Make jobs faster and easier.
E16: · | F16: Install and use column and boom sub-arc welding system to reduce outside round seam welding time by 40%. In use by 3/3/2025 | H16: Dustin
B17: · | C17: ='Top Level'!F17 -> U.S. Rework hours < 1.25% of direct labor hours
E18: · | F18: Install and use cobot welding system to automate RFSO nozzle making. Especially for data center tanks. In use by 2/2/2026. | H18: Dustin
E19: · | F19: Utilize cobot welding system to automate outside long seam shell welding. In use by 3/2/2025. | H19: Dustin
E20: · | F20: Utilize cobot welding system to automate jacket welding. In use by 6/15/2026 | H20: Dustin
B21: · | C21: ='Top Level'!F18 -> U.S. Cost of Quality < $1.75 per direct labor hour | E21: · | F21: Modify new plasma table to reduce layout time when cutting holes in dished and conical heads. Complete by 3/31/2025. | H21: Dustin
E22: · | F22: Make new under shell alignment wheels with hydraulic actuation to push shells into position during fit-up. First set in use by 4/15/2025. | H22: Dustin
B24: · | C24: ='Top Level'!F19 -> U.S. Overhead < 25% of total shop hours | E24: · | F24: Find new equipment to reduce time needed to wash tanks. Test new equipment by 3/31/2025 | H24: Dustin
E25: · | F25: Purchase Lissmac grinding machine to reduce part clean-up times. Installed by 9/1/2026. | H25: David
E26: · | F26: Get Arc-Boss welding system fully operational and implemented into regular shop use by 9/1/2025 | H26: Dustin
B27: · | C27: ='Top Level'!F20 -> India On Time Delivery at 90% or above (full-year average)
D28: · | E28: Increase shop floor workforce skill level
E29: · | F29: Increase recruitment efforts with greater emphasis on hiring experienced welders and fabricators starting 2/15/2025 | H29: Dustin
E30: · | F30: Create new employee training team and develop in-house training plans for on-boarding new hires. Trainers selected and program ready to use by 3/31/2025. | H30: Dustin
D33: · | E33: Establish operation in India to manufacture labor-intensive products and components
E34: · | F34: Legal entity established and management in place by 2/15/2025 | H34: David
E35: · | F35: Engineering, operations, and support staff in place by 5/1/2025 | H35: Nick
E36: · | F36: Weld procedures and QC processes in place by 6/15/2025 | H36: John
E37: · | F37: Facility operational and orders in production by 7/1/2025 | H37: David
D39: · | E39: Improve materials management function
E40: · | F40: Fill Receiving / Tool Room position by 2/1/2026 | H40: Dustin
E41: · | F41: Establish reorder points and quantities for all shop floor consumables by 4/15/2026 | H41: Dustin
E42: · | F42: Identify ways to reduce consumables costs. Bring consumables costs down to $4.65 / shop labor hour for 2025. | H42: Dustin

Sheet Engineering
A1: ='Top Level'!A1 -> OGSM 2026 | C1: ='Top Level'!C1:F1 -> Savannah Tank and Equipment
A2: ='Top Level'!A2 -> Version 1.0
A3: STRATEGY | B3: MEASURES | D3: ACTION PLANS | H3: CHAMPION
A4: How we’ll achieve success | B4: Measure we’ll use to track progress
A6: Utilize Engineering Resources in US and India to Support Sales Growth. Continue to Drive Quality Improvement. | B6: · | C6: ='Top Level'!F22 -> Provide calculations to Sales team in 3 business days or less, with measured error rate less than 5% for 2026. | D6: ·
D9: ·
B11: · | C11: ='Top Level'!F24 -> Favorable cost variance on major raw materials > 3% vs. quoted prices
A12: Support sales effort with timely design calculations and cost estimates. Reduce costs by strategically shifting production and engineering work from US to India. Continue to improve Quality management and documentation.
D13: ·
B15: · | C15: ='Top Level'!F25 -> India drawing accuracy > 90% "First Pass Approval Rate" by 2/1/2026 | D15: ·
D17: ·
B19: · | C19: ='Top Level'!F26 -> Use Compress & Inventor to reduce drawing times by 30%
D20: ·
B23: · | C23: ='Top Level'!F27 -> Add technical resource with expertise in heat transfer and heat exchangers | D23: ·
D27: ·

Sheet Quality
A1: ='Top Level'!A1 -> OGSM 2026 | C1: ='Top Level'!C1:F1 -> Savannah Tank and Equipment
A2: ='Top Level'!A2 -> Version 1.0
A3: STRATEGY | B3: MEASURES | D3: ACTION PLANS | H3: CHAMPION
A4: How we’ll achieve success | B4: Measure we’ll use to track progress
A6: Build a business-wide Quality Management System that supports growth and clearly defines Savannah Tank's standards of excellence. | B6: · | C6: ='Top Level'!F29 -> Zero customer complaints / quality "escapes" (U.S.) in 2026 | D6: ·
B9: · | C9: ='Top Level'!F30 -> Retain U.S. ASME certification with successful ASME Joint Review (May 2026) | D9: ·
D11: ·
A13: Establish and deploy a consistent set of quality standards across U.S. and India operations that aligns with our "premier" quality positioning. Define, document, and maintain clear acceptance standards across all facets of Savannah Tank's worldwide operations | B13: · | C13: ='Top Level'!F31 -> Develop and deploy Visual Quality Standards Guide across U.S. and India operations by 12/31/2026 | D13: ·
D15: ·
D17: ·
B18: · | C18: ='Top Level'!F33 -> Implement comprehensive, reliable, and timely process to review and approve India fabrication prior to shipment to U.S. Process in place by 4/1/2026.
D20: · | E20: Draft written Quality improvement action plan to address leading causes (top 2 in hours and top 2 in cost) of rework for 2024. Plan in place by 1/17/2025.
D23: · | E23: Improve Quality management and documentation
E24: · | F24: Continue bi-weekly meetings to review QC related issues and deliverables. Meetings to start week of 1/13/2025.
B25: · | C25: ='Top Level'!F36 -> Zero customer complaints / quality "escapes" (India) in 2026 | E25: · | F25: Continue to track progress and status of QC activities for each job. In use by 1/2/2024.
D27: · | E27: Draft written plan to manage Quality for products built in India (Savannah Tank India and elsewhere) by 3/3/2025.
B28: · | C28: ='Top Level'!F37 -> Attain ISO-9001 certification in India by 6/30/2026 | E28: · | F28: Criteria 1: Equipment built in India must be as good as or better than equipment built in Savannah
E29: · | F29: Criteria 2: All QC discrepancies to be identified and corrected in India -- not in Savannah
E30: · | F30: Criteria 3: Savannah Tank India to have ASME U and R stamps by 7/31/2025

Sheet People & Saftey
A1: ='Top Level'!A1 -> OGSM 2026 | C1: ='Top Level'!C1:F1 -> Savannah Tank and Equipment
A2: ='Top Level'!A2 -> Version 1.0
A3: STRATEGY | B3: MEASURES | D3: ACTION PLANS | H3: CHAMPION
A4: How we’ll achieve success | B4: Measure we’ll use to track progress
A6: ='Top Level'!D39 -> Expand Savannah Tank Team in US and India to Meet Increased Customer Demand. Embed a Culture of Safety, Quality, and Efficiency on the Shop Floor. | B6: · | C6: ='Top Level'!F39 -> US customer lead times less than 20 weeks throughout 2026 | D6: · | E6: Align Savannah Tank leadership team on 2026 objectives and goals
E7: · | F7: Get input from management team on 2026 initiatives and action plans. Plans agreed by 1/31/2026. | H7: David
E8: · | F8: Set and agree goals for each team member by 1/31/2026 | H8: David
B9: · | C9: ='Top Level'!F40 -> Zero lost time accidents in 2026 (U.S.) | E9: · | F9: Review progress against goals on a monthly basis starting March 2026 | H9: David
B11: · | C11: ='Top Level'!F41 -> Zero OSHA violations / citations in 2026 | D11: · | E11: Increase shop floor workforce engagement
E12: · | F12: Hold quarterly "state of the union" meetings with all shop employees starting Q1-2026 | H12: Dustin
E13: · | F13: Post weekly factory performance metrics (Safety, Quality, Efficiency, On-Time Completion, etc.) in shop starting 2/3/2025 | H13: Dustin
A14: Recruit skilled people and develop them to be the best in the industry. Continue to build a safety mindset on the shop floor. | B14: · | C14: ='Top Level'!F43 -> Zero lost time accidents in 2026 (India) | E14: · | F14: Implement incentives (lunches, gift cards, etc.) when shop performance targets are achieved starting February 2025 | H14: David
D16: · | E16: Increase shop floor workforce skill level
E17: · | F17: Increase recruitment efforts with greater emphasis on hiring experienced welders and fabricators starting 2/15/2025 | H17: Dustin
E18: · | F18: Create new employee training team and develop in-house training plans for on-boarding new hires. Trainers selected and program ready to use by 3/31/2025. | H18: Dustin
D21: · | E21: Continue to build a safety mindset on the shop floor
E22: · | F22: Continue to hold formal Safety meetings every month starting January 2025 | H22: Dustin
E23: · | F23: Update shop floor safety assessment tool by 1/15/2025 | H23: Dustin
E24: · | F24: Conduct bi-weekly safety walks with shop supervisors using new assessment tool starting week of 1/13/2025 | H24: Dustin
E25: · | F25: Continue to write-up accident and near miss reports within 1 day of any incident starting 1/6/2025 | H25: Dustin
E26: · | F26: Arrange "refresher" rigging safety class for all shop employees by 7/1/2025 | H26: Dustin
E27: · | F27: Implement "lift plans" for non-standard crane lifts and equipment moves. In place starting 1/6/2025. | H27: Dustin
D29: · | E29: Continue regular equipment inspections
E30: · | F30: Electrical and extension cords: Quarterly starting Q1-2025
E31: · | F31: Ladders: Quarterly starting Q1-2025
E32: · | F32: Safety harnesses and lanyards: Quarterly starting Q1-2025
E33: · | F33: Lifting straps, chains, plate clamps, and come alongs: Annually (Q3-2025)
D35: · | E35: Improve facility safety and security infrastructure
E36: · | F36: Upgrade security camera and alarm system. Implemented by 3/1/2025. | H36: David
E37: · | F37: Expand and upgrade employee break room by 6/30/2025. | H37: David
E38: · | F38: Add or replace security lighting in hydro area, management parking, and front gate. Complete by 3/1/2025. | H38: Keith

Sheet Tracker
A1: ='Top Level'!A1 -> OGSM 2026 | B1: ACTION PLAN TRACKING REGISTER
A2: ='Top Level'!A2 -> Version 1.0
A3: STRATEGY | B3: WORK STEP | C3: OWNER | D3: TIMING | E3: STATUS
A4: Sales | B4: Continue to flex office resources (Aalhad, Nick, Manish, etc.) as necessary to support quote volume starting 1/2/2024 | C4: David | D4: 45293 | E4: Ongoing
A5: Sales | B5: Maintain Quote Log and Sales Funnel to guage anticipated order intake starting 1/2/2024 | C5: Chris | D5: 45293
A6: Ops | B6: Track and graph labor efficiency in the shop using JobBOSS on a weekly basis starting 1/2/2024. | C6: Dustin | D6: 45293 | E6: Ongoing
A7: Ops | B7: Continue to track and graph rework hours vs. goal on a weekly basis starting 1/2/2024 | C7: John | D7: 45293 | E7: Ongoing
A8: Ops | B8: Re-launch formal Savannah Tank welding and fabrication training program by 1/2/2024 | C8: David | D8: 45293
A9: Eng | B9: Continue bi-weekly meetings to review QC related issues and deliverables. Meetings to start week of 1/2/2024. | C9: John | D9: 45293
A10: Eng | B10: Continue to track progress and status of QC activities for each job. In use by 1/2/2024. | C10: John | D10: 45293 | E10: Ongoing
A11: People | B11: Written investigation and corrective action report within 1 day of each accident or near miss starting 1/4/2024 | C11: Scott / Sammy | D11: 45295
A12: Sales | B12: Review sales metrics with management team 2x / month starting January 2022 | C12: Chris | D12: 45306
A13: Sales | B13: Ask customers for opportunity to quote agitators, spray balls, etc. when quoting new tanks starting January 2024 | C13: Chris | D13: 45306
A14: Sales | B14: Hold weekly meeting to review sales metrics, prospecting activities, and sales funnel. Review production schedule and backlog to identify potential gaps and opportunities to fill them. Meetings to start 1/30/2024. | C14: David | D14: 45321
A15: People | B15: Continue to hold formal Safety meetings every month starting January 2024 | C15: Scott / Sammy | D15: 45322 | E15: Ongoing
A16: Sales | B16: Hire new SEO agency to drive up Google search rankings. New agency in place by 2/1/2024. | C16: David | D16: 45323 | E16: Complete
A17: Ops | B17: Fill Receiving / Tool Room position by 2/1/2024 | C17: Scott | D17: 45323 | E17: Complete
A18: Sales | B18: Review target VPH against actual costs per hour on monthly basis starting 2/5/2024. | C18: David | D18: 45327 | E18: Ongoing
A19: Sales | B19: Maintain $28 - $32 spread between VPH and CPH. Monitor VPH monthly starting 2/5/2024. | C19: Chris | D19: 45327
A20: Sales | B20: Maintain sales dashboard weekly starting 2/5/2024 | C20: Chris | D20: 45327 | E20: Ongoing
A21: Ops | B21: Increase recruitment efforts with increased emphasis on hiring experienced welders and fabricators | C21: Trainer | D21: 45337
A22: Sales | B22: Contact MS Jeong for referrals and contacts within Enchem by 2/28/2024 | C22: David | D22: 45350 | E22: Complete
A23: Sales | B23: Meet with SEO agency monthly to drive progress and track performance. Meetings to start in February 2024. | C23: David | D23: 45350 | E23: Ongoing
A24: Eng | B24: Draft written Quality improvement action plan by 2/28/2024. Add to agenda at bi-weekly Quality meetings. | C24: John | D24: 45350 | E24: Need to update
A25: People | B25: Get input from management team on 2024 initiatives and action plans. Plans agreed by 2/28/2024. | C25: David | D25: 45350
A26: Ops | B26: Hire new Operations Manager to drive improvement on shop floor. Hired by 2/15/2024 | C26: David | D26: 45352 | E26: Complete
A27: People | B27: Set and agree goals for each team member by 3/15/2024 | C27: David | D27: 45366
A28: People | B28: Review progress against goals on a monthly basis starting March 2024 | C28: David | D28: 45366
A29: Eng | B29: Train Aalhad on cost estimation by 3/29/2024 | C29: Chris | D29: 45380
A30: People | B30: Draft new, more meaningful performance review form for shop floor employess by 3/29/2024. | C30: David / Dustin | D30: 45380 | E30: Complete
A31: People | B31: Electrical and extension cords: Quarterly | C31: Keith | D31: 45380
A32: People | B32: Ladders: Quarterly | C32: Keith | D32: 45380
A33: People | B33: Safety harnesses and lanyards: Quarterly | C33: Keith | D33: 45380
A34: People | B34: Lifting straps, chains, plate clamps, and come alongs: Quarterly | C34: Keith | D34: 45380
A35: Ops | B35: Attach easy-to-read sub-arc welding parameters to each sub-arc machine by 4/1/2024 | C35: Dustin | D35: 45383
A36: Ops | B36: Use new plasma table to layout and cut holes in dished and conical heads. In use by 4/1/2024. | C36: David | D36: 45383
A37: People | B37: 90-day reviews for all new shop employees | C37: Dustin | D37: 45383 | E37: Ongoing
A38: People | B38: Annual reviews for all employees every 12 months | C38: Dustin | D38: 45383 | E38: Ongoing
A39: Ops | B39: Maintain shopwide job boards with job numbers, target completion dates, build plans, etc. Fully deployed by 4/15/2024. | C39: Dustin | D39: 45397
A40: Ops | B40: Draft daily work plans to set "stretch" targets for each team member, each day starting 4/15/2024 | C40: Scott / Sammy | D40: 45397
...

Sheet 2021 Tracker
A1: ='Top Level'!A1 -> OGSM 2026 | B1: ACTION PLAN TRACKING REGISTER
A2: ='Top Level'!A2 -> Version 1.0
A3: STRATEGY | B3: WORK STEP | C3: OWNER | D3: TIMING | E3: STATUS
A4: Sales | B4: Continue to flex office resources (Nick, Ron, Rutang, etc.) as necessary to support quote volume starting 1/4/2021 | C4: David | D4: 44200 | E4: Ongoing
A5: Sales | B5: Continue to maintain sales funnel chart to manage and guage anticipated future order intake | C5: Adam | D5: 44200 | E5: Ongoing
A6: Operations | B6: Continue to track and graph labor efficiency in the shop using JobBOSS on a weekly basis starting 1/4/2021. | C6: Bob | D6: 44200 | E6: Ongoing
A7: Operations | B7: Track and graph rework hours vs. goal on a weekly basis starting 1/4/2021 | C7: Bob | D7: 44200 | E7: Ongoing
A8: Operations | B8: Draft next day's work plans daily before end of shift. Written work plans each day starting 1/4/2021. | C8: Scott / Sammy | D8: 44200 | E8: Ongoing
A9: Operations | B9: Communicate daily assignments to each team member at morning start-up meetings starting 1/4/2021 | C9: Bob | D9: 44200 | E9: Ongoing
A10: Operations | B10: Roll stainless shells two-at-a-time (where practical) starting 1/4/2021 | C10: Scott | D10: 44200 | E10: Ongoing
A11: Engineering | B11: Continue to hold internal drawing review meetings prior to releasing drawings to customer starting 1/4/2021 | C11: Nick | D11: 44200 | E11: Ongoing
A12: Engineering | B12: Set weekly Engineering meeting with structured time for training starting week of 1/4/2021 | C12: David | D12: 44200 | E12: Ongoing
A13: Engineering | B13: Maintain tracking system to track progress and status of QC activities for each job. In use by 1/4/2021. | C13: John | D13: 44200 | E13: Ongoing
A14: Engineering | B14: Continue to review and approve weekly shop supplies orders starting 1/4/2021 | C14: David | D14: 44200 | E14: Ongoing
A15: People | B15: Written investigation and corrective action report within 1 day of each accident or near miss starting 1/4/2021 | C15: Bob | D15: 44200 | E15: Ongoing
... A22: Sales | B22: Make weekly calls on target accounts and prospects (see list) starting week of 1/25/2021 | C22: Adam | D22: 44221 | E22: Ongoing
A23: People | B23: Continue to hold formal Safety meetings every month starting January 2021 | C23: Keith | D23: 44225
A24: Operations | B24: Maintain job boards with daily work assignments and targets. Fully deployed by 2/1/2021. | C24: Bob | D24: 44228
A25: Operations | B25: Utilize schedule boards to manage job progression through shop. Boards in use by 2/1/2021. | C25: Bob | D25: 44228
A26: Operations | B26: Track and graph On Time Completion statistics starting 2/1/2021 | C26: Bob | D26: 44228
A27: Operations | B27: Study, challenge, and approve daily work plans. After approval, bring work plans to David every day starting 2/1/2021 | C27: Bob | D27: 44228
A28: Operations | B28: Use new plasma table to trim and layout shells starting 2/1/2021 | C28: Scott | D28: 44228
A29: Operations | B29: Hold bi-weekly meeting to review equipment issues, maintenance records, and PM schedule starting 2/1/2021 | C29: David | D29: 44228 | E29: Ongoing
A30: Engineering | B30: Draft quarterly "lesson plan" defining training topics to be covered. Review quarterly starting 2/1/2021. | C30: Nick | D30: 44228
A31: Engineering | B31: Determine ST&E 2021 Quality KPIs. Track and graph on weekly / monthly basis starting 2/1/2021. | C31: John | D31: 44228
A32: Engineering | B32: Install SigmaNest and post processor on ESAB plasma table by 2/1/2021 | C32: Nick | D32: 44228 | E32: Not Possible
A33: Engineering | B33: Program plasma table (including cones and shell layouts) in Engineering office starting 2/1/2021 | C33: Nick | D33: 44228 | E33: Ongoing
A34: People | B34: Get input from management team on 2021 strategy and action plan. Inputs received and changes made by 2/1/2021. | C34: David | D34: 44228 | E34: 44256
A35: People | B35: Top management to review safety metrics and action plan monthly starting 2/4/2021 | C35: David | D35: 44231 | E35: 44259
A36: Sales | B36: Compress Savannah Tank brochure and PowerPoint presentation to smaller file size by 2/15/2021 | C36: David | D36: 44242 | E36: 44264
A37: Sales | B37: Add tracking graph for target accounts and prospecting goal. Complete by 2/15/2021. | C37: Adam | D37: 44242
A38: Sales | B38: Review sales metrics with management team 2x / month starting February 2021 | C38: Adam | D38: 44242
A39: Operations | B39: Track and graph shop downtime by cause starting 2/15/2021 | C39: Bob | D39: 44242
A40: Operations | B40: Attach easy-to-read sub-arc welding parameters to each sub-arc machine by 2/15/2021 | C40: Scott / Sammy | D40: 44242
A41: Operations | B41: Formalize preventive maintenance schedule for all critical equipment. PM performed as scheduled starting 2/15/2021. | C41: Bob | D41: 44242
A42: Engineering | B42: Measure and graph Drawing On Time Delivery starting 2/15/2021 | C42: Nick | D42: 44242
A43: Engineering | B43: Review and update Min / Max and Reorder points for each shop floor consumable item by 2/15/2021. | C43: Bob | D43: 44242
A44: People | B44: Develop and agree goals for each leadership team member by 2/15/2021 | C44: David | D44: 44242 | E44: 44258
A45: Sales | B45: Make minor revisions / updates to Savannah Tank brochure. Complete by 3/1/2021. | C45: David | D45: 44256 | E45: 44270
A46: Operations | B46: Visual cleanliness and organization standards for shop exterior (yard) by 4/12/2021 | C46: Bob | D46: 44298
...

Sheet 2019 Tracker
B1: ='Top Level'!A1 -> OGSM 2026 | C1: ACTION PLAN TRACKING REGISTER
B2: ='Top Level'!A2 -> Version 1.0
B3: STRATEGY | C3: WORK STEP | D3: OWNER | E3: TIMING | F3: STATUS
B4: Sales | C4: Analyze current quote pricing methodology and identify areas for improvement. Analysis complete by 1/18/2019. | D4: David | E4: 43483 | F4: Complete
B5: Sales | C5: Develop alternative(s) to current quote pricing methodology using Value Added Sales / Labor Hour as benchmark. Alternatives reviewed and analyzed by 2/18/2019. | D5: David | E5: 43514 | F5: Complete
B6: Sales | C6: Revised pricing methodology in use by 2/19/2019. | D6: Adam | E6: 43515 | F6: Complete
B7: Sales | C7: Pricing Plan - Review and adjust (if necessary) on monthly basis starting 4/1/2019. | D7: David | E7: 43556 | F7: Ongoing
B8: Sales | C8: Outbound Selling & Prospecting - Draft preliminary action plan by 2/18/2019 | D8: Adam | E8: 43514 | F8: Complete
B9: Sales | C9: Outbound Selling & Prospecting Plan - Add structure (targets, timing, etc.) and finalize action plan by 4/5/2019 | D9: Adam | E9: 43560 | F9: Complete
B10: Sales | C10: Outbound Selling & Prospecting - Shift office resources (Nick, Ron, etc.) as necessary to support quote volume. Resources available by 2/25/2019. | D10: David | E10: 43521 | F10: Ongoing
B11: Sales | C11: Make 15-20 calls per week on target accounts and prospects starting week of 2/25/2019 | D11: Adam | E11: 43521 | F11: Ongoing
B12: Sales | C12: Make 5-10 calls per week on target accounts and prospects starting week of 4/5/2019 | D12: David | E12: 43560 | F12: Now 6/20
B13: Sales | C13: New Website - Send new page outline, website copy, and photos to GoDaddy by 1/31/2019 | D13: David | E13: 43496 | F13: Complete
B14: Sales | C14: New website online by 4/15/2019 | D14: David | E14: 43570 | F14: Complete
B15: Sales | C15: Draft scope of work and objectives for SEO project. Scope and objectives agreed by 4/15/2019. | D15: Adam | E15: 43570 | F15: Now 6/21
... B20: Sales | C20: Create sales funnel / opportunity tracking chart to manage and guage to anticipated future order intake. In use and updated weekly in team meeting starting 1/21/2019. | D20: Adam | E20: 43486 | F20: Complete
B21: Sales | C21: Collect, consolidate, and maintain sales-related data to enable KPI reporting. Key metrics tracked by 3/18/2019. | D21: Sherri | E21: 43542 | F21: 43584
B22: Sales | C22: Build sales dashboard to track sales-related KPIs on weekly basis. Dashboard in use by 3/18/2019. | D22: David | E22: 43542 | F22: Complete
B23: Sales | C23: Improve semi-automated cost estimation program to streamline and standardize estimation process, and shorten review process. Revisions made by 4/15/2019. | D23: Adam | E23: 43570 | F23: Complete
B24: Sales | C24: Review and update labor estimation tables by 4/15/2019. | D24: David | E24: 43570 | F24: Complete
B25: Sales | C25: Develop standard templates for sales quotations, change orders, etc. New templates in use by 4/1/2019. | D25: Adam | E25: 43556 | F25: Complete
B26: Sales | C26: Research pharmaceutical equipment market by 4/15/2019 | D26: David | E26: 43570 | F26: Complete
B27: Sales | C27: Research heat exchanger market by 7/1/2019 | D27: David | E27: 43647
B28: Sales | C28: Research OEM market (i.e. JCB, Great Dane, Lummus, etc.) by 7/1/2019 | D28: Adam | E28: 43647
B29: Operations | C29: Maintain job boards with daily work assignments and "red / green" indicators. In use 1/2/2019. | D29: Scott | E29: 43467 | F29: Ongoing
B30: Operations | C30: Maintain weekly Downtime Quad Chart including SMART action log. In use 1/2/2019. | D30: Tim | E30: 43467 | F30: Ongoing
B31: Operations | C31: Track and graph labor efficiency in the shop using JobBOSS on a weekly basis starting 1/7/2019. | D31: David | E31: 43472 | F31: Ongoing
B32: Operations | C32: Track and investigate customer complaints on a weekly basis, and maintain record of causes starting 1/2/2019. | D32: Ron | E32: 43467 | F32: Ongoing
B33: Operations | C33: Track and graph rework hours on a weekly basis, and maintain record of causes starting 1/2/2019. | D33: Tim | E33: 43467 | F33: Ongoing
B34: Operations | C34: Track and graph On Time Completion statistics starting 4/1/2019. | D34: Sherri | E34: 43556 | F34: Now 6/30
B35: Operations | C35: Establish weekly operations review meetings with Tim and Scott starting 1/7/2019. | D35: David | E35: 43472 | F35: Ongoing
B36: Operations | C36: Draft next day's work plans with team leads daily before end of shift. Written work plans each day starting 1/4/2019. | D36: Scott | E36: 43469 | F36: Ongoing
B37: Operations | C37: Study, challenge, and approve daily work plans. Written sign-off starting 3/11/2019. | D37: Tim | E37: 43535 | F37: Ongoing
B38: Operations | C38: Audit and track work plan attainment daily starting 3/25/2019. | D38: Tim | E38: 43549 | F38: Ongoing
B39: Operations | C39: Roll stainless shells two-at-a-time (where possible) starting 3/25/2019 | D39: Tim | E39: 43549 | F39: Ongoing
B40: Operations | C40: Use plasma table to layout stainless shells starting 4/15/2019 | D40: Ron | E40: 43570 | F40: Testing
B41: Operations | C41: Reduce round seam welding times by 25% by 7/1/2019 | D41: Tim | E41: 43647
B42: Operations | C42: Attach easy-to-read sub-arc welding parameters to each sub-arc machine by 2/4/2019 | D42: Tim | E42: 43500 | F42: Complete
B43: Operations | C43: Modify existing fit-up rolls to improve turning consistency. 1st set by 3/5/2019. Remaining sets by 5/31/2019. | D43: Tim | E43: 43529 | F43: Tim to Check
B44: Operations | C44: Develop plan to correct variable speed drives to address known durability and adjustability issues by 3/29/2019 | D44: Ron | E44: 43553 | F44: Now 7/15
...

Sheet Sheet2
A3: Sales | B3: Continue to flex office resources (Aalhad, Nick, Manish, etc.) as necessary to support quote volume starting 1/2/2024 | C3: David | D3: 45293
A4: Sales | B4: Expand relationships in EV battery market. Generate at least $2 million in new EV battery orders by 12/31/2024. | C4: Chris | D4: 45657
A5: Sales | B5: Contact MS Jeong for referrals and contacts within Enchem by 2/28/2024 | C5: David | D5: 45350
A6: Sales | B6: New RFQs from Enchem > $750K by 12/31/2024 | C6: Chris | D6: 45657
A7: Sales | B7: Maintain regular contact with Chris and Kathy at SYMS. New orders from SYMS > $750K by 12/31/2024. | C7: Chris | D7: 45657
A8: Sales | B8: Use research and networking to make contacts at SK Battery, LG, and Panasonic. RFQs totalling more than $2 million from SK, LG & Panasonic (combined) by 12/31/2024. | C8: Chris | D8: 45657
A9: Sales | B9: Review target VPH against actual costs per hour on monthly basis starting 2/5/2024. | C9: David | D9: 45327
A10: Sales | B10: Maintain $28 - $32 spread between VPH and CPH. Monitor VPH monthly starting 2/5/2024. | C10: Chris | D10: 45327
A11: Sales | B11: Hire new SEO agency to drive up Google search rankings. New agency in place by 2/1/2024. | C11: David | D11: 45323
A12: Sales | B12: Meet with SEO agency monthly to drive progress and track performance. Meetings to start in February 2024. | C12: David | D12: 45350
A13: Sales | B13: Expand use of LinkedIn | C13: David
A14: Sales | B14: Hold weekly meeting to review sales metrics, prospecting activities, and sales funnel. Review production schedule and backlog to identify potential gaps and opportunities to fill them. Meetings to start 1/30/2024. | C14: David | D14: 45321
A15: Sales | B15: Maintain Quote Log and Sales Funnel to guage anticipated order intake starting 1/2/2024 | C15: Chris | D15: 45293
A16: Sales | B16: Maintain sales dashboard weekly starting 2/5/2024 | C16: Chris | D16: 45327
A17: Sales | B17: Review sales metrics with management team 2x / month starting January 2022 | C17: Chris | D17: 45306
A18: Sales | B18: Ask customers for opportunity to quote agitators, spray balls, etc. when quoting new tanks starting January 2024 | C18: Chris | D18: 45306
A19: Sales | B19: Analyze opportunity to build heat exchangers in India for US market under Savannah Tank name. Analysis complete by 7/1/2024. | C19: David | D19: 45474
A20: Sales | B20: Analyze opportunity to import a range of standard tanks from India. Analysis complete by 10/1/2024. | C20: David | D20: 45566
A21: Ops | B21: Hire new Operations Manager to drive improvement on shop floor. Hired by 2/15/2024 | C21: David | D21: 45352
A22: Ops | B22: Maintain job stands with job numbers, target completion dates, build plans, etc. Fully deployed by 3/1/2024. | C22: Dustin
A23: Ops | B23: Track and graph labor efficiency in the shop using JobBOSS on a weekly basis starting 1/2/2024. | C23: Dustin | D23: 45293
A24: Ops | B24: Continue to track and graph rework hours vs. goal on a weekly basis starting 1/2/2024 | C24: John | D24: 45293
A25: Ops | B25: Track and graph On Time Completion statistics starting 7/1/2024 | C25: Dustin | D25: 45474
A26: Ops | B26: Draft next day's work plans daily before end of shift. Written work plans each day starting 1/4/2022. | C26: Scott / Sammy
A27: Ops | B27: Study, challenge, and discuss daily work plans starting 1/10/2022 | C27: Dustin
A28: Ops | B28: Communicate daily assignments to each team member at morning start-up meetings starting 1/4/2022 | C28: Scott / Sammy
A29: Ops | B29: Reduce round seam welding times by 25% by 10/1/2024 | C29: Dustin | D29: 45566
A30: Ops | B30: Attach easy-to-read sub-arc welding parameters to each sub-arc machine by 3/1/2024 | C30: Dustin
A31: Ops | B31: Re-train all sub-arc operators on sub-arc set-up and operation (incl. video). Training complete by 3/18/2024 | C31: Jermaine
A32: Ops | B32: Test new, one-man sub-arc welding rig by 3/15/2024 | C32: Dustin
A33: Ops | B33: Use new plasma table to layout and cut holes in dished and conical heads. Operational by 3/1/2024. | C33: David | D33: 45352
A34: Ops | B34: Make new outriggers with hydraulic actuation to push shells into position. Prototype set complete by 6/3/2024 | C34: Dustin | D34: 45446
A35: Ops | B35: Utilize cobot welding system to semi-automate routine welding tasks. Cobot in use by 6/3/2024. | C35: Dustin | D35: 45446
A36: Ops | B36: Re-launch formal Savannah Tank welding and fabrication training program by 1/2/2024 | C36: David | D36: 45293
A37: Ops | B37: Increase recruitment efforts with increased emphasis on hiring experienced welders and fabricators | C37: Jermaine
A38: Ops | B38: Maintain skills / training matrix for shop floor personnel to identify skills gaps. Review quarterly starting 3Q24. | C38: Dustin | D38: 45474
A39: Ops | B39: Draft written job instrutions for key responsibilities (receiving, tank washing, pressure testing, etc.) | C39: Dustin
A40: Ops | B40: Legal entity established and management in place by 5/1/2024 | C40: David | D40: 45413
A41: Ops | B41: Engineering, operations, and support staff in place by 6/1/2024 | C41: Nick | D41: 45444
A42: Ops | B42: Weld procedures and QC processes in place by 6/15/2024 | C42: John | D42: 45458
...

Sheet Questions
A3: Work Plan Considerations:
A4: 1. | B4: Are the action items sufficient to achieve our desired outcomes (measures)? If not, what else do we need to do?
A5: 2. | B5: Are the action items necessary to achieve our desired outcomes (measures)? If not, what can safely be removed?
A6: 3. | B6: Does the timetable make sense? If not, what is a reasonable timetable for completion that protects the overall goal?
A7: 4. | B7: Are there any conflicting goals or worksteps?
A8: 5. | B8: Is the correct "Champion" selected?
