Workbook
Name Operation: '2020 Data'!$BT$22:$BU$162

Sheet 2026 Dashboard
D1: Savannah Tank Operations Dashboard | S1: - | T1: =TODAY() -> 46098
B3: 2026 Labor Efficiency - Shop Total | Q3: 2026 Rework - % Direct Hours
C30: Last Week | E30: ='2026 Data'!J11 -> 1.05 | G30: 4-Week Avg. | J30: ='2026 Data'!L11 -> 0.965 | L30: 8-Week Avg. | N30: ='2026 Data'!M11 -> 0.95 | R30: YTD Actual | T30: ='2025 Data'!AL57 -> 0.0027659641 | V30: YTD Max. Target | Y30: ='2025 Data'!AO55 -> 0.0125 | AA30: Difference | AC30: =T30-Y30 -> -0.0097340359 | AD30: pts
AM31: Overhead Speedometer Graph
AM34: Chart Parameters
B35: Operations Improvement Action Plan | AM35: Green | AN35: 20 | AP35: value | AQ35: 0.41
AM36: Yellow | AN36: 5 | AP36: pointer | AQ36: 0.01
B37: Action Item | L37: Resp. | N37: Timing | AM37: Red | AN37: 20 | AP37: end | AQ37: =0.99-AQ35-AQ36 -> 0.57
AM38: Invisible | AN38: 45
B39: Start using column & boom sub-arc welding manipulator to weld outside round seams. | L39: Dustin | N39: 45992
B43: Rebuild & install 10-ton crane in Pre-Fab area | L43: Dustin | N43: 46068 | AM43: Direct | AN43: 42699 | AO43: =AN43/AN45 -> 0.71709996
AM44: Indirect | AN44: 16845 | AO44: =AN44/AN45 -> 0.28290004
AM45: Total | AN45: =SUM(AN43:AN44) -> 59544
B47: Install new roof on Buildings 2 & 3 | L47: Dustin | N47: 46068
B51: Prepare dedicated small tank fabrication facility in old Maintenance shop. Be ready to go into production by 1/19/2026 | L51: Dustin / Sammy | N51: 46082
B55: Design & build prototype mini column & boom to weld inside round seams | L55: Dustin / Sammy | N55: 46068

Sheet 2026 Data
AZ1: Safety Data
F2: Weekly Labor Efficiency x Department | L2: Rolling Avg. Labor Efficiency | Q2: Labor Efficiency - Rolling 4 Weeks | W2: Labor Efficiency | AA2: 2026 Overhead Analysis | AF2: 2026 Overhead Analysis - Running Total | AK2: 2026 Rework Analysis | AR2: Rework x Month | BF2: Total | BG2: Rolling 12 Mos. | BL2: On Time Completion
A3: Year | B3: Week of | C3: Month | D3: Week | F3: Finishing | G3: Fit | H3: Pre-Fab | I3: Shipping | J3: Total | L3: 4 Weeks | M3: 8 Weeks | N3: 2025 Avg. | O3: '26 Target | Q3: Finishing | R3: Fit | S3: Pre-Fab | T3: Shipping | U3: Total | W3: Month | X3: Act. | Y3: Target | AA3: Direct | AB3: Overhead | AC3: Total | AD3: OH % Total | AF3: Direct | AG3: Overhead | AH3: Total | AI3: OH % Total | AK3: Rework | AL3: % Direct | AM3: Run Tot. | AN3: % Direct | AO3: '26 Target | AP3: 2025 Act | AR3: Month | AS3: Act. | AT3: Max Target | AU3: YTD Act. | BA3: Month | BB3: OSHA | BC3: First Aid | BD3: Near Miss | BE3: Total | BF3: Hours | BG3: OSHA | BH3: Hours | BI3: TCIR | BJ3: Target | BM3: Month | BN3: On Time | BO3: Late | BP3: Total | BQ3: % On Time | BR3: Goal | BU3: Oper | BV3: Est Hrs | BW3: Adj Est Hrs | BX3: Act Hrs | BY3: Eff % | BZ3: Hrs Lost
A4: 2026 | B4: 46027 | D4: 1 | F4: 0.38 | G4: 0.92 | H4: 1.04 | I4: 0.65 | J4: 0.94 | L4: 0.96 | M4: 0.9825 | N4: 0.96 | O4: 0.95 | W4: Jan | X4: 0.92 | Y4: 0.95 | AA4: 733.25 | AB4: 324.25 | AC4: =AA4+AB4 -> 1057.5 | AD4: =AB4/AC4 -> 0.30661939 | AF4: =AA4 -> 733.25 | AG4: =AB4 -> 324.25 | AH4: =SUM(AF4:AG4) -> 1057.5 | AI4: =AG4/AH4 -> 0.30661939 | AK4: ='QC Data 2026'!N4 -> 0 | AL4: =AK4/AA4 -> 0 | AM4: =AK4 -> 0 | AN4: =AM4/AF4 -> 0 | AO4: 0.0125 | AP4: 0.0187 | AR4: Jan | AS4: =AK4+AK5+AK6+AK7 -> 0 | AT4: 50 | AU4: =AS4 -> 0 | AV4: =AT4 -> 50 | AZ4: 2019 | BA4: Jan | BB4: 0 | BC4: 0 | BD4: 2 | BE4: =SUM(BB4:BD4) -> 2 | BF4: =3316.25+296 -> 3612.25 | BI4: 17.261561 | BL4: 2020 | BM4: Jan | BN4: 8 | BO4: 0 | BP4: =BN4+BO4 -> 8 | BQ4: =BN4/BP4 -> 1 | BR4: 0.95 | BU4: 645 | BV4: =VLOOKUP(BU4,Operation,2) -> Weld all Outside Seams | BW4: 942.98292 | BX4: 1390 | BY4: =BW4/BX4 -> 0.67840498 | BZ4: =BX4-BW4 -> 447.01708
A5: 2026 | B5: 46034 | D5: 2 | F5: 0.87 | G5: 1.1 | H5: 0.93 | I5: 0.52 | J5: 0.97 | L5: 0.975 | M5: 0.9425 | N5: 0.96 | O5: 0.95 | W5: Feb | X5: 0.94 | Y5: 0.95 | AA5: 752 | AB5: 410 | AC5: =AA5+AB5 -> 1162 | AD5: =AB5/AC5 -> 0.35283993 | AF5: =AF4+AA5 -> 1485.25 | AG5: =AG4+AB5 -> 734.25 | AH5: =AH4+AC5 -> 2219.5 | AI5: =AG5/AH5 -> 0.33081775 | AL5: =AK5/AA5 -> 0 | AM5: =AM4+AK5 -> 0 | AN5: =AM5/AF5 -> 0 | AO5: 0.0125 | AP5: 0.0187 | AR5: Feb | AS5: =AK8+AK9+AK10+AK11 -> 0 | AT5: 50 | AU5: =AU4+AS5 -> 0 | AV5: =AV4+AT5 -> 100 | AZ5: 2019 | BA5: Feb | BB5: 0 | BC5: 0 | BD5: 2 | BE5: =SUM(BB5:BD5) -> 2 | BF5: 2897.5 | BI5: 12.967646 | BL5: 2020 | BM5: Feb | BN5: 2 | BO5: 2 | BP5: =BN5+BO5 -> 4 | BQ5: =BN5/BP5 -> 0.5 | BR5: 0.95 | BU5: 605 | BV5: =VLOOKUP(BU5,Operation,2) -> Tack Shell Courses | BW5: 558 | BX5: 994.5 | BY5: =BW5/BX5 -> 0.56108597 | BZ5: =BX5-BW5 -> 436.5
A6: 2026 | B6: 46041 | C6: Jan | D6: 3 | F6: 0.69 | G6: 1.06 | H6: 0.98 | I6: 0.15 | J6: 0.92 | L6: 1.0075 | M6: 0.9425 | N6: 0.96 | O6: 0.95 | W6: Mar | Y6: 0.95 | AA6: 750.25 | AB6: 417.75 | AC6: =AA6+AB6 -> 1168 | AD6: =AB6/AC6 -> 0.35766267 | AF6: =AF5+AA6 -> 2235.5 | AG6: =AG5+AB6 -> 1152 | AH6: =AH5+AC6 -> 3387.5 | AI6: =AG6/AH6 -> 0.3400738 | AL6: =AK6/AA6 -> 0 | AM6: =AM5+AK6 -> 0 | AN6: =AM6/AF6 -> 0 | AO6: 0.0125 | AP6: 0.0187 | AR6: Mar | AS6: =AK12+AK13+AK14+AK15+AK16 -> 0 | AT6: 50 | AU6: =AU5+AS6 -> 0 | AV6: =AV5+AT6 -> 150 | AZ6: 2019 | BA6: Mar | BB6: 0 | BC6: 0 | BD6: 1 | BE6: =SUM(BB6:BD6) -> 1 | BF6: =3051.25+76.75 -> 3128 | BI6: 8.5594911 | BL6: 2020 | BM6: Mar | BN6: 12 | BO6: 2 | BP6: =BN6+BO6 -> 14 | BQ6: =BN6/BP6 -> 0.85714286 | BR6: 0.95 | BU6: 630 | BV6: =VLOOKUP(BU6,Operation,2) -> Install Internal Parts | BW6: 479.33818 | BX6: 808 | BY6: =BW6/BX6 -> 0.59324032 | BZ6: =BX6-BW6 -> 328.66182
A7: 2026 | B7: 46048 | D7: 4 | F7: 0.7 | G7: 0.89 | H7: 1.25 | I7: 0.59 | J7: 0.91 | L7: =AVERAGE(J4:J7) -> 0.935 | M7: 0.955 | N7: 0.96 | O7: 0.95 | W7: Apr | Y7: 0.95 | AA7: 661.5 | AB7: 447.25 | AC7: =AA7+AB7 -> 1108.75 | AD7: =AB7/AC7 -> 0.40338219 | AF7: =AF6+AA7 -> 2897 | AG7: =AG6+AB7 -> 1599.25 | AH7: =AH6+AC7 -> 4496.25 | AI7: =AG7/AH7 -> 0.35568529 | AL7: =AK7/AA7 -> 0 | AM7: =AM6+AK7 -> 0 | AN7: =AM7/AF7 -> 0 | AO7: 0.0125 | AP7: 0.0187 | AR7: Apr | AS7: =AK17+AK18+AK19+AK20 -> 0 | AT7: 50 | AU7: =AU6+AS7 -> 0 | AV7: =AV6+AT7 -> 200 | AZ7: 2019 | BA7: Apr | BB7: 0 | BC7: 0 | BD7: 1 | BE7: =SUM(BB7:BD7) -> 1 | BF7: =3140+641.25 -> 3781.25 | BI7: 8.4889643 | BL7: 2020 | BM7: Apr | BN7: 11 | BO7: 1 | BP7: =BN7+BO7 -> 12 | BQ7: =BN7/BP7 -> 0.91666667 | BR7: 0.95 | BU7: 305 | BV7: =VLOOKUP(BU7,Operation,2) -> BI, SQ, T&C Shells | BW7: 971.16692 | BX7: 1271 | BY7: =BW7/BX7 -> 0.76409671 | BZ7: =BX7-BW7 -> 299.83308
A8: 2026 | B8: 46055 | D8: 5 | F8: 0.65 | G8: 0.95 | H8: 1.23 | I8: 0.59 | J8: 0.93 | L8: =AVERAGE(J5:J8) -> 0.9325 | M8: 0.96 | N8: 0.96 | O8: 0.95 | W8: May | Y8: 0.95 | AA8: 729.5 | AB8: 500.75 | AC8: =AA8+AB8 -> 1230.25 | AD8: =AB8/AC8 -> 0.40703109 | AF8: =AF7+AA8 -> 3626.5 | AG8: =AG7+AB8 -> 2100 | AH8: =AH7+AC8 -> 5726.5 | AI8: =AG8/AH8 -> 0.36671614 | AL8: =AK8/AA8 -> 0 | AM8: =AM7+AK8 -> 0 | AN8: =AM8/AF8 -> 0 | AO8: 0.0125 | AP8: 0.0187 | AR8: May | AS8: =AK21+AK22+AK23+AK24 -> 0 | AT8: 50 | AU8: =AU7+AS8 -> 0 | AV8: =AV7+AT8 -> 250 | AZ8: 2019 | BA8: May | BB8: 0 | BC8: 1 | BD8: 0 | BE8: =SUM(BB8:BD8) -> 1 | BF8: =3438.75+443.5 -> 3882.25 | BI8: 8.5776627 | BL8: 2020 | BM8: May | BN8: 16 | BO8: 5 | BP8: =BN8+BO8 -> 21 | BQ8: =BN8/BP8 -> 0.76190476 | BR8: 0.95 | BU8: 800 | BV8: =VLOOKUP(BU8,Operation,2) -> Move Tank to Detail Rolls | BW8: 164.14545 | BX8: 461.5 | BY8: =BW8/BX8 -> 0.35567812 | BZ8: =BX8-BW8 -> 297.35455
A9: 2026 | B9: 46062 | D9: 6 | F9: 0.73 | G9: 0.97 | H9: 1.07 | I9: 1 | J9: 0.97 | L9: =AVERAGE(J6:J9) -> 0.9325 | M9: 0.975 | N9: 0.96 | O9: 0.95 | W9: Jun | Y9: 0.95 | AA9: 873.5 | AB9: 408 | AC9: =AA9+AB9 -> 1281.5 | AD9: =AB9/AC9 -> 0.3183769 | AF9: =AF8+AA9 -> 4500 | AG9: =AG8+AB9 -> 2508 | AH9: =AH8+AC9 -> 7008 | AI9: =AG9/AH9 -> 0.35787671 | AL9: =AK9/AA9 -> 0 | AM9: =AM8+AK9 -> 0 | AN9: =AM9/AF9 -> 0 | AO9: 0.0125 | AP9: 0.0187 | AR9: Jun | AS9: =AK25+AK26+AK27+AK28+AK29 -> 0 | AT9: 50 | AU9: =AU8+AS9 -> 0 | AV9: =AV8+AT9 -> 300 | AZ9: 2019 | BA9: Jun | BB9: 1 | BC9: 1 | BD9: 0 | BE9: =SUM(BB9:BD9) -> 2 | BF9: =3275+554.5 -> 3829.5 | BI9: 8.7407335 | BL9: 2020 | BM9: Jun | BN9: 10 | BO9: 0 | BP9: =BN9+BO9 -> 10 | BQ9: =BN9/BP9 -> 1 | BR9: 0.95 | BU9: 155 | BV9: =VLOOKUP(BU9,Operation,2) -> B&C parts-lugs, supp, etc | BW9: 769.92174 | BX9: 1061 | BY9: =BW9/BX9 -> 0.72565668 | BZ9: =BX9-BW9 -> 291.07826
A10: 2026 | B10: 46069 | C10: Feb | D10: 7 | F10: 0.61 | G10: 0.92 | H10: 1.01 | I10: 0.42 | J10: 0.91 | L10: =AVERAGE(J7:J10) -> 0.93 | M10: 0.95 | N10: 0.96 | O10: 0.95 | W10: Jul | Y10: 0.95 | AA10: 988 | AB10: 357 | AC10: =AA10+AB10 -> 1345 | AD10: =AB10/AC10 -> 0.26542751 | AF10: =AF9+AA10 -> 5488 | AG10: =AG9+AB10 -> 2865 | AH10: =AH9+AC10 -> 8353 | AI10: =AG10/AH10 -> 0.34299054 | AL10: =AK10/AA10 -> 0 | AM10: =AM9+AK10 -> 0 | AN10: =AM10/AF10 -> 0 | AO10: 0.0125 | AP10: 0.0187 | AR10: Jul | AS10: =AK30+AK31+AK32+AK33 -> 0 | AT10: 50 | AU10: =AU9+AS10 -> 0 | AV10: =AV9+AT10 -> 350 | AZ10: 2019 | BA10: Jul | BB10: 0 | BC10: 0 | BD10: 1 | BE10: =SUM(BB10:BD10) -> 1 | BF10: =3731.5+544 -> 4275.5 | BI10: 8.8880988 | BL10: 2020 | BM10: Jul | BN10: 9 | BO10: 2 | BP10: =BN10+BO10 -> 11 | BQ10: =BN10/BP10 -> 0.81818182 | BR10: 0.95 | BU10: 600 | BV10: =VLOOKUP(BU10,Operation,2) -> Fit Bottom Head to Shell | BW10: 732.67698 | BX10: 1012 | BY10: =BW10/BX10 -> 0.72398911 | BZ10: =BX10-BW10 -> 279.32302
A11: 2026 | B11: 46076 | D11: 8 | F11: 0.67 | G11: 0.96 | H11: 1.21 | I11: 0.93 | J11: 1.05 | L11: =AVERAGE(J8:J11) -> 0.965 | M11: =AVERAGE(J4:J11) -> 0.95 | N11: 0.96 | O11: 0.95 | W11: Aug | Y11: 0.95 | AA11: 1005.5 | AB11: 431 | AC11: =AA11+AB11 -> 1436.5 | AD11: =AB11/AC11 -> 0.30003481 | AF11: =AF10+AA11 -> 6493.5 | AG11: =AG10+AB11 -> 3296 | AH11: =AH10+AC11 -> 9789.5 | AI11: =AG11/AH11 -> 0.33668727 | AL11: =AK11/AA11 -> 0 | AM11: =AM10+AK11 -> 0 | AN11: =AM11/AF11 -> 0 | AO11: 0.0125 | AP11: 0.0187 | AR11: Aug | AS11: =AK34+AK35+AK36+AK37 -> 0 | AT11: 50 | AU11: =AU10+AS11 -> 0 | AV11: =AV10+AT11 -> 400 | AZ11: 2019 | BA11: Aug | BB11: 0 | BC11: 0 | BD11: 0 | BE11: =SUM(BB11:BD11) -> 0 | BF11: =3976.75+580 -> 4556.75 | BI11: 9.0443512 | BL11: 2020 | BM11: Aug | BN11: 6 | BO11: 4 | BP11: =BN11+BO11 -> 10 | BQ11: =BN11/BP11 -> 0.6 | BR11: 0.95 | BU11: 726 | BV11: =VLOOKUP(BU11,Operation,2) -> Weld Shell Nozz & M/Ws | BW11: 974.8 | BX11: 1225.25 | BY11: =BW11/BX11 -> 0.79559274 | BZ11: =BX11-BW11 -> 250.45
A12: 2026 | B12: 46083 | D12: 9 | F12: 0.55 | G12: 1.04 | H12: 0.97 | I12: 1 | J12: 0.95 | L12: =AVERAGE(J9:J12) -> 0.97 | M12: =AVERAGE(J5:J12) -> 0.95125 | N12: 0.96 | O12: 0.95 | W12: Sep | Y12: 0.95 | AA12: 947.25 | AB12: 453.25 | AC12: =AA12+AB12 -> 1400.5 | AD12: =AB12/AC12 -> 0.32363442 | AF12: =AF11+AA12 -> 7440.75 | AG12: =AG11+AB12 -> 3749.25 | AH12: =AH11+AC12 -> 11190 | AI12: =AG12/AH12 -> 0.33505362 | AL12: =AK12/AA12 -> 0 | AM12: =AM11+AK12 -> 0 | AN12: =AM12/AF12 -> 0 | AO12: 0.0125 | AP12: 0.0187 | AR12: Sep | AS12: =AK38+AK39+AK40+AK41+AK42 -> 0 | AT12: 50 | AU12: =AU11+AS12 -> 0 | AV12: =AV11+AT12 -> 450 | AZ12: 2019 | BA12: Sep | BB12: 0 | BC12: 0 | BD12: 0 | BE12: =SUM(BB12:BD12) -> 0 | BF12: =3393.75+819.75 -> 4213.5 | BI12: 4.6222469 | BL12: 2020 | BM12: Sep | BN12: 5 | BO12: 0 | BP12: =BN12+BO12 -> 5 | BQ12: =BN12/BP12 -> 1 | BR12: 0.95 | BU12: 105 | BV12: =VLOOKUP(BU12,Operation,2) -> Build Nozzles-Weld | BW12: 958.03206 | BX12: 1184.75 | BY12: =BW12/BX12 -> 0.80863647 | BZ12: =BX12-BW12 -> 226.71794
A13: 2026 | B13: 46090 | D13: 10 | L13: =AVERAGE(J10:J13) -> 0.97 | M13: =AVERAGE(J6:J13) -> 0.94857143 | N13: 0.96 | O13: 0.95 | W13: Oct | Y13: 0.95 | AA13: 921.75 | AB13: 426.5 | AC13: =AA13+AB13 -> 1348.25 | AD13: =AB13/AC13 -> 0.31633599 | AF13: =AF12+AA13 -> 8362.5 | AG13: =AG12+AB13 -> 4175.75 | AH13: =AH12+AC13 -> 12538.25 | AI13: =AG13/AH13 -> 0.33304089 | AL13: =AK13/AA13 -> 0 | AM13: =AM12+AK13 -> 0 | AN13: =AM13/AF13 -> 0 | AO13: 0.0125 | AP13: 0.0187 | AR13: Oct | AS13: =AK43+AK44+AK45+AK46 -> 0 | AT13: 50 | AU13: =AU12+AS13 -> 0 | AV13: =AV12+AT13 -> 500 | AZ13: 2019 | BA13: Oct | BB13: 1 | BC13: 0 | BD13: 2 | BE13: =SUM(BB13:BD13) -> 3 | BF13: =4652.5+1060.5 -> 5713 | BI13: 4.7229963 | BL13: 2020 | BM13: Oct | BN13: 6 | BO13: 0 | BP13: =BN13+BO13 -> 6 | BQ13: =BN13/BP13 -> 1 | BR13: 0.95 | BU13: 640 | BV13: =VLOOKUP(BU13,Operation,2) -> Fit Top to Shell-Weld | BW13: 539.9 | BX13: 753.75 | BY13: =BW13/BX13 -> 0.71628524 | BZ13: =BX13-BW13 -> 213.85
A14: 2026 | B14: 46097 | C14: Mar | D14: 11 | L14: =AVERAGE(J11:J14) -> 1 | M14: =AVERAGE(J7:J14) -> 0.95333333 | N14: 0.96 | O14: 0.95 | W14: Nov | Y14: 0.95 | AC14: =AA14+AB14 -> 0 | AD14: =AB14/AC14 -> #DIV/0! | AF14: =AF13+AA14 -> 8362.5 | AG14: =AG13+AB14 -> 4175.75 | AH14: =AH13+AC14 -> 12538.25 | AI14: =AG14/AH14 -> 0.33304089 | AL14: =AK14/AA14 -> #DIV/0! | AM14: =AM13+AK14 -> 0 | AN14: =AM14/AF14 -> 0 | AO14: 0.0125 | AP14: 0.0187 | AR14: Nov | AS14: =AK47+AK48+AK49+AK50 -> 0 | AT14: 50 | AU14: =AU13+AS14 -> 0 | AV14: =AV13+AT14 -> 550 | AZ14: 2019 | BA14: Nov | BB14: 0 | BC14: 0 | BD14: 0 | BE14: =SUM(BB14:BD14) -> 0 | BF14: 3740.75 | BI14: 9.797498 | BL14: 2020 | BM14: Nov | BN14: 9 | BO14: 0 | BP14: =BN14+BO14 -> 9 | BQ14: =BN14/BP14 -> 1 | BR14: 0.95
A15: 2026 | B15: 46104 | D15: 12 | L15: =AVERAGE(J12:J15) -> 0.95 | M15: =AVERAGE(J8:J15) -> 0.962 | N15: 0.96 | O15: 0.95 | W15: Dec | Y15: 0.95 | AC15: =AA15+AB15 -> 0 | AD15: =AB15/AC15 -> #DIV/0! | AF15: =AF14+AA15 -> 8362.5 | AG15: =AG14+AB15 -> 4175.75 | AH15: =AH14+AC15 -> 12538.25 | AI15: =AG15/AH15 -> 0.33304089 | AL15: =AK15/AA15 -> #DIV/0! | AM15: =AM14+AK15 -> 0 | AN15: =AM15/AF15 -> 0 | AO15: 0.0125 | AP15: 0.0187 | AR15: Dec | AS15: =AK51+AK52+AK53+AK54+AK55 -> 0 | AT15: 50 | AU15: =AU14+AS15 -> 0 | AV15: =AV14+AT15 -> 600 | AZ15: 2019 | BA15: Dec | BB15: 0 | BC15: 0 | BD15: 0 | BE15: =SUM(BB15:BD15) -> 0 | BF15: =3063.25+238 -> 3301.25 | BG15: =SUM(BB4:BB15) -> 2 | BH15: =SUM(BF4:BF15) -> 46931.5 | BI15: =BG15*200000/(BH15+1280) -> 8.2967757 | BJ15: 4 | BL15: 2020 | BM15: Dec | BN15: 14 | BO15: 6 | BP15: =BN15+BO15 -> 20 | BQ15: =BN15/BP15 -> 0.7 | BR15: 0.95
A16: 2026 | B16: 46111 | D16: 13 | L16: =AVERAGE(J13:J16) -> #DIV/0! | M16: =AVERAGE(J9:J16) -> 0.97 | N16: 0.96 | O16: 0.95 | AC16: =AA16+AB16 -> 0 | AD16: =AB16/AC16 -> #DIV/0! | AF16: =AF15+AA16 -> 8362.5 | AG16: =AG15+AB16 -> 4175.75 | AH16: =AH15+AC16 -> 12538.25 | AI16: =AG16/AH16 -> 0.33304089 | AL16: =AK16/AA16 -> #DIV/0! | AM16: =AM15+AK16 -> 0 | AN16: =AM16/AF16 -> 0 | AO16: 0.0125 | AP16: 0.0187 | AZ16: 2020 | BA16: Jan | BB16: 0 | BC16: 1 | BD16: 0 | BE16: =SUM(BB16:BD16) -> 1 | BF16: =3060.5+785.25 -> 3845.75 | BG16: =SUM(BB5:BB16) -> 2 | BH16: =SUM(BF5:BF16) -> 47165 | BI16: =BG16*200000/(BH16+1280) -> 8.256786 | BJ16: 4 | BL16: 2021 | BM16: Jan | BN16: 10 | BO16: 3 | BP16: =BN16+BO16 -> 13 | BQ16: =BN16/BP16 -> 0.76923077 | BR16: 0.95
A17: 2026 | B17: 46118 | D17: 14 | L17: =AVERAGE(J14:J17) -> #DIV/0! | M17: =AVERAGE(J10:J17) -> 0.97 | N17: 0.96 | O17: 0.95 | AC17: =AA17+AB17 -> 0 | AD17: =AB17/AC17 -> #DIV/0! | AF17: =AF16+AA17 -> 8362.5 | AG17: =AG16+AB17 -> 4175.75 | AH17: =AH16+AC17 -> 12538.25 | AI17: =AG17/AH17 -> 0.33304089 | AL17: =AK17/AA17 -> #DIV/0! | AM17: =AM16+AK17 -> 0 | AN17: =AM17/AF17 -> 0 | AO17: 0.0125 | AP17: 0.0187 | AR17: YTD | AS17: =SUM(AS4:AS16) -> 0 | AT17: =SUM(AT4:AT16) -> 600 | AZ17: 2020 | BA17: Feb | BB17: 0 | BC17: 0 | BD17: 1 | BE17: =SUM(BB17:BD17) -> 1 | BF17: =3042.5+613.75 -> 3656.25 | BG17: =SUM(BB6:BB17) -> 2 | BH17: =SUM(BF6:BF17) -> 47923.75 | BI17: =BG17*200000/(BH17+1280) -> 8.1294617 | BJ17: 4 | BL17: 2021 | BM17: Feb | BN17: 2 | BO17: 2 | BP17: =BN17+BO17 -> 4 | BQ17: =BN17/BP17 -> 0.5 | BR17: 0.95
A18: 2026 | B18: 46125 | D18: 15 | L18: =AVERAGE(J15:J18) -> #DIV/0! | M18: =AVERAGE(J11:J18) -> 1 | N18: 0.96 | O18: 0.95 | AC18: =AA18+AB18 -> 0 | AD18: =AB18/AC18 -> #DIV/0! | AF18: =AF17+AA18 -> 8362.5 | AG18: =AG17+AB18 -> 4175.75 | AH18: =AH17+AC18 -> 12538.25 | AI18: =AG18/AH18 -> 0.33304089 | AL18: =AK18/AA18 -> #DIV/0! | AM18: =AM17+AK18 -> 0 | AN18: =AM18/AF18 -> 0 | AO18: 0.0125 | AP18: 0.0187 | AZ18: 2020 | BA18: Mar | BB18: 0 | BC18: 0 | BD18: 1 | BE18: =SUM(BB18:BD18) -> 1 | BF18: =3452.5+791.25 -> 4243.75 | BG18: =SUM(BB7:BB18) -> 2 | BH18: =SUM(BF7:BF18) -> 49039.5 | BI18: =BG18*200000/(BH18+1280) -> 7.9492046 | BJ18: 4 | BL18: 2021 | BM18: Mar | BN18: 0 | BO18: 2 | BP18: 2 | BQ18: =BN18/BP18 -> 0 | BR18: 0.95
A19: 2026 | B19: 46132 | C19: Apr | D19: 16 | L19: =AVERAGE(J16:J19) -> #DIV/0! | M19: =AVERAGE(J12:J19) -> 0.95 | N19: 0.96 | O19: 0.95 | AC19: =AA19+AB19 -> 0 | AD19: =AB19/AC19 -> #DIV/0! | AF19: =AF18+AA19 -> 8362.5 | AG19: =AG18+AB19 -> 4175.75 | AH19: =AH18+AC19 -> 12538.25 | AI19: =AG19/AH19 -> 0.33304089 | AL19: =AK19/AA19 -> #DIV/0! | AM19: =AM18+AK19 -> 0 | AN19: =AM19/AF19 -> 0 | AO19: 0.0125 | AP19: 0.0187 | AZ19: 2020 | BA19: Apr | BB19: 0 | BC19: 1 | BD19: 1 | BE19: =SUM(BB19:BD19) -> 2 | BF19: =3935.5+777 -> 4712.5 | BG19: =SUM(BB8:BB19) -> 2 | BH19: =SUM(BF8:BF19) -> 49970.75 | BI19: =BG19*200000/(BH19+1280) -> 7.8047638 | BJ19: 4 | BL19: 2021 | BM19: Apr | BN19: 0 | BO19: 4 | BP19: 4 | BQ19: =BN19/BP19 -> 0 | BR19: 0.95
A20: 2026 | B20: 46139 | D20: 17 | L20: =AVERAGE(J17:J20) -> #DIV/0! | M20: =AVERAGE(J13:J20) -> #DIV/0! | N20: 0.96 | O20: 0.95 | AC20: =AA20+AB20 -> 0 | AD20: =AB20/AC20 -> #DIV/0! | AF20: =AF19+AA20 -> 8362.5 | AG20: =AG19+AB20 -> 4175.75 | AH20: =AH19+AC20 -> 12538.25 | AI20: =AG20/AH20 -> 0.33304089 | AL20: =AK20/AA20 -> #DIV/0! | AM20: =AM19+AK20 -> 0 | AN20: =AM20/AF20 -> 0 | AO20: 0.0125 | AP20: 0.0187 | AZ20: 2020 | BA20: May | BB20: 0 | BC20: 0 | BD20: 0 | BE20: =SUM(BB20:BD20) -> 0 | BF20: =3541+676 -> 4217 | BG20: =SUM(BB9:BB20) -> 2 | BH20: =SUM(BF9:BF20) -> 50305.5 | BI20: =BG20*200000/(BH20+1280) -> 7.754117 | BJ20: 4 | BL20: 2021 | BM20: May | BN20: 3 | BO20: 0 | BP20: 3 | BQ20: =BN20/BP20 -> 1 | BR20: 0.95
A21: 2026 | B21: 46146 | D21: 18 | L21: =AVERAGE(J18:J21) -> #DIV/0! | M21: =AVERAGE(J14:J21) -> #DIV/0! | N21: 0.96 | O21: 0.95 | AC21: =AA21+AB21 -> 0 | AD21: =AB21/AC21 -> #DIV/0! | AF21: =AF20+AA21 -> 8362.5 | AG21: =AG20+AB21 -> 4175.75 | AH21: =AH20+AC21 -> 12538.25 | AI21: =AG21/AH21 -> 0.33304089 | AL21: =AK21/AA21 -> #DIV/0! | AM21: =AM20+AK21 -> 0 | AN21: =AM21/AF21 -> 0 | AO21: 0.0125 | AP21: 0.0187 | AZ21: 2020 | BA21: Jun | BB21: 0 | BC21: 1 | BD21: 3 | BE21: =SUM(BB21:BD21) -> 4 | BF21: 4153 | BG21: =SUM(BB10:BB21) -> 1 | BH21: =SUM(BF10:BF21) -> 50629 | BI21: =BG21*200000/(BH21+1280) -> 3.8528964 | BJ21: 4 | BL21: 2021 | BM21: Jun | BR21: 0.95
A22: 2026 | B22: 46153 | D22: 19 | L22: =AVERAGE(J19:J22) -> #DIV/0! | M22: =AVERAGE(J15:J22) -> #DIV/0! | N22: 0.96 | O22: 0.95 | AC22: =AA22+AB22 -> 0 | AD22: =AB22/AC22 -> #DIV/0! | AF22: =AF21+AA22 -> 8362.5 | AG22: =AG21+AB22 -> 4175.75 | AH22: =AH21+AC22 -> 12538.25 | AI22: =AG22/AH22 -> 0.33304089 | AL22: =AK22/AA22 -> #DIV/0! | AM22: =AM21+AK22 -> 0 | AN22: =AM22/AF22 -> 0 | AO22: 0.0125 | AP22: 0.0187 | AZ22: 2020 | BA22: Jul | BB22: 0 | BC22: 1 | BD22: 3 | BE22: =SUM(BB22:BD22) -> 4 | BF22: 3759.75 | BG22: =SUM(BB11:BB22) -> 1 | BH22: =SUM(BF11:BF22) -> 50113.25 | BI22: =BG22*200000/(BH22+1280) -> 3.8915616 | BJ22: 4 | BL22: 2021 | BM22: Jul | BR22: 0.95
A23: 2026 | B23: 46160 | C23: May | D23: 20 | L23: =AVERAGE(J20:J23) -> #DIV/0! | M23: =AVERAGE(J16:J23) -> #DIV/0! | N23: 0.96 | O23: 0.95 | AC23: =AA23+AB23 -> 0 | AD23: =AB23/AC23 -> #DIV/0! | AF23: =AF22+AA23 -> 8362.5 | AG23: =AG22+AB23 -> 4175.75 | AH23: =AH22+AC23 -> 12538.25 | AI23: =AG23/AH23 -> 0.33304089 | AL23: =AK23/AA23 -> #DIV/0! | AM23: =AM22+AK23 -> 0 | AN23: =AM23/AF23 -> 0 | AO23: 0.0125 | AP23: 0.0187 | AZ23: 2020 | BA23: Aug | BB23: 0 | BC23: 2 | BD23: 0 | BE23: =SUM(BB23:BD23) -> 2 | BF23: 4286 | BG23: =SUM(BB12:BB23) -> 1 | BH23: =SUM(BF12:BF23) -> 49842.5 | BI23: =BG23*200000/(BH23+1280) -> 3.9121717 | BJ23: 4 | BL23: 2021 | BM23: Aug | BR23: 0.95
A24: 2026 | B24: 46167 | D24: 21 | L24: =AVERAGE(J21:J24) -> #DIV/0! | M24: =AVERAGE(J17:J24) -> #DIV/0! | N24: 0.96 | O24: 0.95 | AC24: =AA24+AB24 -> 0 | AD24: =AB24/AC24 -> #DIV/0! | AF24: =AF23+AA24 -> 8362.5 | AG24: =AG23+AB24 -> 4175.75 | AH24: =AH23+AC24 -> 12538.25 | AI24: =AG24/AH24 -> 0.33304089 | AL24: =AK24/AA24 -> #DIV/0! | AM24: =AM23+AK24 -> 0 | AN24: =AM24/AF24 -> 0 | AO24: 0.0125 | AP24: 0.0187 | AZ24: 2020 | BA24: Sep | BB24: 0 | BC24: 2 | BD24: 0 | BE24: =SUM(BB24:BD24) -> 2 | BF24: 4497 | BG24: =SUM(BB13:BB24) -> 1 | BH24: =SUM(BF13:BF24) -> 50126 | BI24: =BG24*200000/(BH24+1280) -> 3.8905964 | BJ24: 4 | BL24: 2021 | BM24: Sep | BR24: 0.95
A25: 2026 | B25: 46174 | D25: 22 | L25: =AVERAGE(J22:J25) -> #DIV/0! | M25: =AVERAGE(J18:J25) -> #DIV/0! | N25: 0.96 | O25: 0.95 | AC25: =AA25+AB25 -> 0 | AD25: =AB25/AC25 -> #DIV/0! | AF25: =AF24+AA25 -> 8362.5 | AG25: =AG24+AB25 -> 4175.75 | AH25: =AH24+AC25 -> 12538.25 | AI25: =AG25/AH25 -> 0.33304089 | AL25: =AK25/AA25 -> #DIV/0! | AM25: =AM24+AK25 -> 0 | AN25: =AM25/AF25 -> 0 | AO25: 0.0125 | AP25: 0.0187 | AZ25: 2020 | BA25: Oct | BB25: 0 | BC25: 0 | BD25: 1 | BE25: =SUM(BB25:BD25) -> 1 | BF25: 4461.75 | BG25: =SUM(BB14:BB25) -> 0 | BH25: =SUM(BF14:BF25) -> 48874.75 | BI25: =BG25*200000/(BH25+1280) -> 0 | BJ25: 4 | BL25: 2021 | BM25: Oct | BR25: 0.95
A26: 2026 | B26: 46181 | D26: 23 | L26: =AVERAGE(J23:J26) -> #DIV/0! | M26: =AVERAGE(J19:J26) -> #DIV/0! | N26: 0.96 | O26: 0.95 | AC26: =AA26+AB26 -> 0 | AD26: =AB26/AC26 -> #DIV/0! | AF26: =AF25+AA26 -> 8362.5 | AG26: =AG25+AB26 -> 4175.75 | AH26: =AH25+AC26 -> 12538.25 | AI26: =AG26/AH26 -> 0.33304089 | AL26: =AK26/AA26 -> #DIV/0! | AM26: =AM25+AK26 -> 0 | AN26: =AM26/AF26 -> 0 | AO26: 0.0125 | AP26: 0.0187 | AZ26: 2020 | BA26: Nov | BB26: 0 | BC26: 2 | BD26: 0 | BE26: =SUM(BB26:BD26) -> 2 | BF26: 3802.25 | BG26: =SUM(BB15:BB26) -> 0 | BH26: =SUM(BF15:BF26) -> 48936.25 | BI26: =BG26*200000/(BH26+1280) -> 0 | BJ26: 4 | BL26: 2021 | BM26: Nov | BR26: 0.95
A27: 2026 | B27: 46188 | C27: Jun | D27: 24 | L27: =AVERAGE(J24:J27) -> #DIV/0! | M27: =AVERAGE(J20:J27) -> #DIV/0! | N27: 0.96 | O27: 0.95 | AC27: =AA27+AB27 -> 0 | AD27: =AB27/AC27 -> #DIV/0! | AF27: =AF26+AA27 -> 8362.5 | AG27: =AG26+AB27 -> 4175.75 | AH27: =AH26+AC27 -> 12538.25 | AI27: =AG27/AH27 -> 0.33304089 | AL27: =AK27/AA27 -> #DIV/0! | AM27: =AM26+AK27 -> 0 | AN27: =AM27/AF27 -> 0 | AO27: 0.0125 | AP27: 0.0187 | AZ27: 2020 | BA27: Dec | BB27: 0 | BC27: 1 | BD27: 0 | BE27: =SUM(BB27:BD27) -> 1 | BF27: 3848.25 | BG27: =SUM(BB16:BB27) -> 0 | BH27: =SUM(BF16:BF27) -> 49483.25 | BI27: =BG27*200000/(BH27+1280) -> 0 | BJ27: 4 | BL27: 2021 | BM27: Dec | BR27: 0.95
A28: 2026 | B28: 46195 | D28: 25 | L28: =AVERAGE(J25:J28) -> #DIV/0! | M28: =AVERAGE(J21:J28) -> #DIV/0! | N28: 0.96 | O28: 0.95 | AC28: =AA28+AB28 -> 0 | AD28: =AB28/AC28 -> #DIV/0! | AF28: =AF27+AA28 -> 8362.5 | AG28: =AG27+AB28 -> 4175.75 | AH28: =AH27+AC28 -> 12538.25 | AI28: =AG28/AH28 -> 0.33304089 | AL28: =AK28/AA28 -> #DIV/0! | AM28: =AM27+AK28 -> 0 | AN28: =AM28/AF28 -> 0 | AO28: 0.0125 | AP28: 0.0187 | AZ28: 2021 | BA28: Jan | BB28: 0 | BC28: 0 | BD28: 1 | BE28: =SUM(BB28:BD28) -> 1 | BF28: 2984.25 | BG28: =SUM(BB17:BB28) -> 0 | BH28: =SUM(BF17:BF28) -> 48621.75 | BI28: =BG28*200000/(BH28+1280) -> 0 | BJ28: 2 | BL28: 2022 | BM28: Jan | BO28: 3
A29: 2026 | B29: 46202 | D29: 26 | L29: =AVERAGE(J26:J29) -> #DIV/0! | M29: =AVERAGE(J22:J29) -> #DIV/0! | N29: 0.96 | O29: 0.95 | AC29: =AA29+AB29 -> 0 | AD29: =AB29/AC29 -> #DIV/0! | AF29: =AF28+AA29 -> 8362.5 | AG29: =AG28+AB29 -> 4175.75 | AH29: =AH28+AC29 -> 12538.25 | AI29: =AG29/AH29 -> 0.33304089 | AL29: =AK29/AA29 -> #DIV/0! | AM29: =AM28+AK29 -> 0 | AN29: =AM29/AF29 -> 0 | AO29: 0.0125 | AP29: 0.0187 | AZ29: 2021 | BA29: Feb | BB29: 0 | BC29: 0 | BD29: 0 | BE29: =SUM(BB29:BD29) -> 0 | BF29: 3347.5 | BG29: =SUM(BB18:BB29) -> 0 | BH29: =SUM(BF18:BF29) -> 48313 | BI29: =BG29*200000/(BH29+1280) -> 0 | BJ29: 2 | BL29: 2022 | BM29: Feb
A30: 2026 | B30: 46209 | D30: 27 | L30: =AVERAGE(J27:J30) -> #DIV/0! | M30: =AVERAGE(J23:J30) -> #DIV/0! | N30: 0.96 | O30: 0.95 | AC30: =AA30+AB30 -> 0 | AD30: =AB30/AC30 -> #DIV/0! | AF30: =AF29+AA30 -> 8362.5 | AG30: =AG29+AB30 -> 4175.75 | AH30: =AH29+AC30 -> 12538.25 | AI30: =AG30/AH30 -> 0.33304089 | AL30: =AK30/AA30 -> #DIV/0! | AM30: =AM29+AK30 -> 0 | AN30: =AM30/AF30 -> 0 | AO30: 0.0125 | AP30: 0.0187 | AZ30: 2021 | BA30: Mar | BB30: 0 | BC30: 0 | BD30: 3 | BE30: =SUM(BB30:BD30) -> 3 | BF30: 3695.25 | BG30: =SUM(BB19:BB30) -> 0 | BH30: =SUM(BF19:BF30) -> 47764.5 | BI30: =BG30*200000/(BH30+1280) -> 0 | BJ30: 2 | BL30: 2022 | BM30: Mar
A31: 2026 | B31: 46216 | D31: 28 | L31: =AVERAGE(J28:J31) -> #DIV/0! | M31: =AVERAGE(J24:J31) -> #DIV/0! | N31: 0.96 | O31: 0.95 | AC31: =AA31+AB31 -> 0 | AD31: =AB31/AC31 -> #DIV/0! | AF31: =AF30+AA31 -> 8362.5 | AG31: =AG30+AB31 -> 4175.75 | AH31: =AH30+AC31 -> 12538.25 | AI31: =AG31/AH31 -> 0.33304089 | AL31: =AK31/AA31 -> #DIV/0! | AM31: =AM30+AK31 -> 0 | AN31: =AM31/AF31 -> 0 | AO31: 0.0125 | AP31: 0.0187 | AZ31: 2021 | BA31: Apr | BB31: 0 | BC31: 1 | BD31: 0 | BE31: =SUM(BB31:BD31) -> 1 | BF31: 2841.5 | BG31: =SUM(BB20:BB31) -> 0 | BH31: =SUM(BF20:BF31) -> 45893.5 | BI31: =BG31*200000/(BH31+1280) -> 0 | BJ31: 2 | BL31: 2022 | BM31: Apr
A32: 2026 | B32: 46223 | C32: Jul | D32: 29 | L32: =AVERAGE(J29:J32) -> #DIV/0! | M32: =AVERAGE(J25:J32) -> #DIV/0! | N32: 0.96 | O32: 0.95 | AC32: =AA32+AB32 -> 0 | AD32: =AB32/AC32 -> #DIV/0! | AF32: =AF31+AA32 -> 8362.5 | AG32: =AG31+AB32 -> 4175.75 | AH32: =AH31+AC32 -> 12538.25 | AI32: =AG32/AH32 -> 0.33304089 | AL32: =AK32/AA32 -> #DIV/0! | AM32: =AM31+AK32 -> 0 | AN32: =AM32/AF32 -> 0 | AO32: 0.0125 | AP32: 0.0187 | AZ32: 2021 | BA32: May | BB32: 0 | BC32: 0 | BD32: 0 | BE32: =SUM(BB32:BD32) -> 0 | BF32: 2637.75 | BG32: =SUM(BB21:BB32) -> 0 | BH32: =SUM(BF21:BF32) -> 44314.25 | BI32: =BG32*200000/(BH32+1280) -> 0 | BJ32: 2 | BL32: 2022 | BM32: May
A33: 2026 | B33: 46230 | D33: 30 | L33: =AVERAGE(J30:J33) -> #DIV/0! | M33: =AVERAGE(J26:J33) -> #DIV/0! | N33: 0.96 | O33: 0.95 | AC33: =AA33+AB33 -> 0 | AD33: =AB33/AC33 -> #DIV/0! | AF33: =AF32+AA47 -> 8362.5 | AG33: =AG32+AB47 -> 4175.75 | AH33: =AH32+AC33 -> 12538.25 | AI33: =AG33/AH33 -> 0.33304089 | AL33: =AK33/AA33 -> #DIV/0! | AM33: =AM32+AK33 -> 0 | AN33: =AM33/AF33 -> 0 | AO33: 0.0125 | AP33: 0.0187 | AZ33: 2021 | BA33: Jun | BB33: 0 | BC33: 2 | BD33: 0 | BE33: =SUM(BB33:BD33) -> 2 | BF33: 4042.75 | BG33: =SUM(BB22:BB33) -> 0 | BH33: =SUM(BF22:BF33) -> 44204 | BI33: =BG33*200000/(BH33+1280) -> 0 | BJ33: 2 | BL33: 2022 | BM33: Jun
A34: 2026 | B34: 46237 | D34: 31 | L34: =AVERAGE(J31:J34) -> #DIV/0! | M34: =AVERAGE(J27:J34) -> #DIV/0! | N34: 0.96 | O34: 0.95 | AC34: =AA34+AB34 -> 0 | AD34: =AB34/AC34 -> #DIV/0! | AF34: =AF33+AA48 -> 8362.5 | AG34: =AG33+AB48 -> 4175.75 | AH34: =AH33+AC34 -> 12538.25 | AI34: =AG34/AH34 -> 0.33304089 | AL34: =AK34/AA34 -> #DIV/0! | AM34: =AM33+AK34 -> 0 | AN34: =AM34/AF34 -> 0 | AO34: 0.0125 | AP34: 0.0187 | AZ34: 2021 | BA34: Jul | BB34: 0 | BC34: 1 | BD34: 0 | BE34: =SUM(BB34:BD34) -> 1 | BF34: 3331 | BG34: =SUM(BB23:BB34) -> 0 | BH34: =SUM(BF23:BF34) -> 43775.25 | BI34: =BG34*200000/(BH34+1280) -> 0 | BJ34: 2 | BL34: 2022 | BM34: Jul
A35: 2026 | B35: 46244 | D35: 32 | L35: =AVERAGE(J32:J35) -> #DIV/0! | M35: =AVERAGE(J28:J35) -> #DIV/0! | N35: 0.96 | O35: 0.95 | AC35: =AA35+AB35 -> 0 | AD35: =AB35/AC35 -> #DIV/0! | AF35: =AF34+AA49 -> 8362.5 | AG35: =AG34+AB49 -> 4175.75 | AH35: =AH34+AC35 -> 12538.25 | AI35: =AG35/AH35 -> 0.33304089 | AL35: =AK35/AA35 -> #DIV/0! | AM35: =AM34+AK35 -> 0 | AN35: =AM35/AF35 -> 0 | AO35: 0.0125 | AP35: 0.0187 | AZ35: 2021 | BA35: Aug | BB35: 0 | BC35: 1 | BD35: 0 | BE35: =SUM(BB35:BD35) -> 1 | BF35: 3369 | BG35: =SUM(BB24:BB35) -> 0 | BH35: =SUM(BF24:BF35) -> 42858.25 | BI35: =BG35*200000/(BH35+1280) -> 0 | BJ35: 2 | BL35: 2022 | BM35: Aug | BU35: Operation | BV35: Description
A36: 2026 | B36: 46251 | C36: Aug | D36: 33 | L36: =AVERAGE(J33:J38) -> #DIV/0! | M36: =AVERAGE(J29:J38) -> #DIV/0! | N36: 0.96 | O36: 0.95 | AC36: =AA36+AB36 -> 0 | AD36: =AB36/AC36 -> #DIV/0! | AF36: =AF35+AA50 -> 8362.5 | AG36: =AG35+AB50 -> 4175.75 | AH36: =AH35+AC36 -> 12538.25 | AI36: =AG36/AH36 -> 0.33304089 | AL36: =AK36/AA36 -> #DIV/0! | AM36: =AM35+AK36 -> 0 | AN36: =AM36/AF36 -> 0 | AO36: 0.0125 | AP36: 0.0187 | AZ36: 2021 | BA36: Sep | BB36: 0 | BC36: 1 | BD36: 0 | BE36: =SUM(BB36:BD36) -> 1 | BF36: 3255 | BG36: =SUM(BB25:BB36) -> 0 | BH36: =SUM(BF25:BF36) -> 41616.25 | BI36: =BG36*200000/(BH36+1280) -> 0 | BJ36: 2 | BL36: 2022 | BM36: Sep | BU36: 100 | BV36: Cut Nozzle Pipe and Clean
A37: 2026 | B37: 46258 | D37: 34 | L37: =AVERAGE(J34:J37) -> #DIV/0! | M37: =AVERAGE(J30:J37) -> #DIV/0! | N37: 0.96 | O37: 0.95 | AC37: =AA37+AB37 -> 0 | AD37: =AB37/AC37 -> #DIV/0! | AF37: =AF36+AA51 -> 8362.5 | AG37: =AG36+AB51 -> 4175.75 | AH37: =AH36+AC37 -> 12538.25 | AI37: =AG37/AH37 -> 0.33304089 | AL37: =AK37/AA37 -> #DIV/0! | AM37: =AM36+AK37 -> 0 | AN37: =AM37/AF37 -> 0 | AO37: 0.0125 | AP37: 0.0187 | AZ37: 2021 | BA37: Oct | BB37: 0 | BC37: 1 | BD37: 2 | BE37: =SUM(BB37:BD37) -> 3 | BF37: 5129 | BG37: =SUM(BB26:BB37) -> 0 | BH37: =SUM(BF26:BF37) -> 42283.5 | BI37: =BG37*200000/(BH37+1280) -> 0 | BJ37: 2 | BL37: 2022 | BM37: Oct | BU37: 105 | BV37: Build Nozzles-Weld
A38: 2026 | B38: 46265 | D38: 35 | L38: =AVERAGE(J35:J38) -> #DIV/0! | M38: =AVERAGE(J31:J38) -> #DIV/0! | N38: 0.96 | O38: 0.95 | AC38: =AA38+AB38 -> 0 | AD38: =AB38/AC38 -> #DIV/0! | AF38: =AF37+AA52 -> 8362.5 | AG38: =AG37+AB52 -> 4175.75 | AH38: =AH37+AC38 -> 12538.25 | AI38: =AG38/AH38 -> 0.33304089 | AL38: =AK38/AA38 -> #DIV/0! | AM38: =AM37+AK38 -> 0 | AN38: =AM38/AF38 -> 0 | AO38: 0.0125 | AP38: 0.0187 | AZ38: 2021 | BA38: Nov | BB38: 0 | BC38: 1 | BD38: 2 | BE38: =SUM(BB38:BD38) -> 3 | BF38: 5102 | BG38: =SUM(BB27:BB38) -> 0 | BH38: =SUM(BF27:BF38) -> 43583.25 | BI38: =BG38*200000/(BH38+1280) -> 0 | BJ38: 2 | BL38: 2022 | BM38: Nov | BU38: 107 | BV38: Build Repads for Nozzles
A39: 2026 | B39: 46272 | D39: 36 | L39: =AVERAGE(J37:J39) -> #DIV/0! | M39: =AVERAGE(J32:J39) -> #DIV/0! | N39: 0.96 | O39: 0.95 | AC39: =AA39+AB39 -> 0 | AD39: =AB39/AC39 -> #DIV/0! | AF39: =AF38+AA53 -> 8362.5 | AG39: =AG38+AB53 -> 4175.75 | AH39: =AH38+AC39 -> 12538.25 | AI39: =AG39/AH39 -> 0.33304089 | AL39: =AK39/AA39 -> #DIV/0! | AM39: =AM38+AK39 -> 0 | AN39: =AM39/AF39 -> 0 | AO39: 0.0125 | AP39: 0.0187 | AZ39: 2021 | BA39: Dec | BB39: 0 | BC39: 1 | BD39: 0 | BE39: =SUM(BB39:BD39) -> 1 | BF39: 5019 | BG39: =SUM(BB28:BB39) -> 0 | BH39: =SUM(BF28:BF39) -> 44754 | BI39: =BG39*200000/(BH39+1280) -> 0 | BJ39: 2 | BL39: 2022 | BM39: Dec | BU39: 110 | BV39: Build Dip Tubes-Weld
A40: 2026 | B40: 46279 | C40: Sep | D40: 37 | L40: =AVERAGE(J37:J40) -> #DIV/0! | M40: =AVERAGE(J33:J40) -> #DIV/0! | N40: 0.96 | O40: 0.95 | AC40: =AA40+AB40 -> 0 | AD40: =AB40/AC40 -> #DIV/0! | AF40: =AF39+AA54 -> 8362.5 | AG40: =AG39+AB54 -> 4175.75 | AH40: =AH39+AC40 -> 12538.25 | AI40: =AG40/AH40 -> 0.33304089 | AL40: =AK40/AA40 -> #DIV/0! | AM40: =AM39+AK40 -> 0 | AN40: =AM40/AF40 -> 0 | AO40: 0.0125 | AP40: 0.0187 | AZ40: 2022 | BA40: Jan | BB40: 0 | BC40: 1 | BD40: 1 | BE40: =SUM(BB40:BD40) -> 2 | BF40: 4683 | BG40: =SUM(BB29:BB40) -> 0 | BH40: =SUM(BF29:BF40) -> 46452.75 | BI40: =BG40*200000/(BH40+1280) -> 0 | BJ40: 2 | BL40: 2022 | BM40: YTD | BN40: =SUM(BN16:BN27) -> 15 | BO40: =SUM(BO16:BO27) -> 11 | BP40: =BN40+BO40 -> 26 | BQ40: =BN40/BP40 -> 0.57692308 | BR40: 0.95 | BU40: 115 | BV40: Make Manway Parts
...

Sheet 2025 Dashboard
D1: Savannah Tank Operations Dashboard | S1: - | T1: =TODAY() -> 46098
B3: 2025 Labor Efficiency - Shop Total | Q3: 2025 Rework - % Direct Hours
C30: Last Week | E30: ='2025 Data'!J53 -> 1.01 | G30: 4-Week Avg. | J30: ='2025 Data'!L53 -> 1.0075 | L30: 8-Week Avg. | N30: ='2025 Data'!M53 -> 0.975 | R30: YTD Actual | T30: ='2025 Data'!AL57 -> 0.0027659641 | V30: YTD Max. Target | Y30: ='2025 Data'!AO55 -> 0.0125 | AA30: Difference | AC30: =T30-Y30 -> -0.0097340359 | AD30: pts
AM31: Overhead Speedometer Graph
AM34: Chart Parameters
B35: Operations Improvement Action Plan | AM35: Green | AN35: 20 | AP35: value | AQ35: 0.41
AM36: Yellow | AN36: 5 | AP36: pointer | AQ36: 0.01
B37: Action Item | L37: Resp. | N37: Timing | AM37: Red | AN37: 20 | AP37: end | AQ37: =0.99-AQ35-AQ36 -> 0.57
AM38: Invisible | AN38: 45
B39: Start using column & boom sub-arc welding manipulator to weld outside round seams. | L39: Dustin | N39: 45992
B43: Rebuild & install 10-ton crane in Pre-Fab area | L43: Dustin | N43: 46053 | AM43: Direct | AN43: 42699 | AO43: =AN43/AN45 -> 0.71709996
AM44: Indirect | AN44: 16845 | AO44: =AN44/AN45 -> 0.28290004
AM45: Total | AN45: =SUM(AN43:AN44) -> 59544
B47: Relocate Maintenance shop to back building | L47: Dustin | N47: 46022
B51: Prepare dedicated small tank fabrication facility in old Maintenance shop. Be ready to go into production by 1/19/2026 | L51: Dustin / Sammy | N51: 46041
B55: Design & build prototype mini column & boom to weld inside round seams | L55: Dustin / Sammy | N55: 46068

Sheet 2025 Data
AZ1: Safety Data
F2: Weekly Labor Efficiency x Department | L2: Rolling Avg. Labor Efficiency | Q2: Labor Efficiency - Rolling 4 Weeks | W2: Labor Efficiency | AA2: Overhead Analysis | AF2: Overhead Analysis - Running Total | AK2: Rework Analysis | AR2: Rework x Month | BF2: Total | BG2: Rolling 12 Mos. | BL2: On Time Completion
A3: Year | B3: Week of | C3: Month | D3: Week | F3: Finishing | G3: Fit | H3: Pre-Fab | I3: Shipping | J3: Total | L3: 4 Weeks | M3: 8 Weeks | N3: 2024 Avg. | O3: Target | Q3: Finishing | R3: Fit | S3: Pre-Fab | T3: Shipping | U3: Total | W3: Month | X3: Act. | Y3: Target | AA3: Direct | AB3: Overhead | AC3: Total | AD3: OH % Total | AF3: Direct | AG3: Overhead | AH3: Total | AI3: OH % Total | AK3: Rework | AL3: % Direct | AM3: Run Tot. | AN3: % Direct | AO3: Max | AP3: 2024 Act | AR3: Month | AS3: Act. | AT3: Max Target | AU3: YTD Act. | BA3: Month | BB3: OSHA | BC3: First Aid | BD3: Near Miss | BE3: Total | BF3: Hours | BG3: OSHA | BH3: Hours | BI3: TCIR | BJ3: Target | BM3: Month | BN3: On Time | BO3: Late | BP3: Total | BQ3: % On Time | BR3: Goal | BU3: Oper | BV3: Est Hrs | BW3: Adj Est Hrs | BX3: Act Hrs | BY3: Eff % | BZ3: Hrs Lost
A4: 2025 | B4: 45656 | D4: 1 | F4: 0.56 | G4: 0.69 | H4: 0.82 | I4: 1 | J4: 0.72 | L4: NA | M4: NA | N4: 0.83 | O4: 0.88 | W4: Jan | Y4: 0.95 | AA4: 322.5 | AB4: 162.5 | AC4: =AA4+AB4 -> 485 | AD4: =AB4/AC4 -> 0.33505155 | AF4: =AA4 -> 322.5 | AG4: =AB4 -> 162.5 | AH4: =SUM(AF4:AG4) -> 485 | AI4: =AG4/AH4 -> 0.33505155 | AK4: ='QC Data 2026'!N4 -> 0 | AL4: =AK4/AA4 -> 0 | AM4: =AK4 -> 0 | AN4: =AM4/AF4 -> 0 | AO4: 0.0125 | AP4: 0.019 | AR4: Jan | AS4: =AK4+AK5+AK6+AK7 -> 35 | AT4: 50 | AU4: =AS4 -> 35 | AV4: =AT4 -> 50 | AZ4: 2019 | BA4: Jan | BB4: 0 | BC4: 0 | BD4: 2 | BE4: =SUM(BB4:BD4) -> 2 | BF4: =3316.25+296 -> 3612.25 | BI4: 17.261561 | BL4: 2020 | BM4: Jan | BN4: 8 | BO4: 0 | BP4: =BN4+BO4 -> 8 | BQ4: =BN4/BP4 -> 1 | BR4: 0.95 | BU4: 645 | BV4: =VLOOKUP(BU4,Operation,2) -> Weld all Outside Seams | BW4: 942.98292 | BX4: 1390 | BY4: =BW4/BX4 -> 0.67840498 | BZ4: =BX4-BW4 -> 447.01708
A5: 2025 | B5: 45663 | D5: 2 | F5: 0.46 | G5: 0.66 | H5: 0.87 | I5: 0.43 | J5: 0.73 | L5: NA | M5: NA | N5: 0.83 | O5: 0.88 | W5: Feb | Y5: 0.95 | AA5: 493 | AB5: 332.5 | AC5: =AA5+AB5 -> 825.5 | AD5: =AB5/AC5 -> 0.40278619 | AF5: =AF4+AA5 -> 815.5 | AG5: =AG4+AB5 -> 495 | AH5: =AH4+AC5 -> 1310.5 | AI5: =AG5/AH5 -> 0.37771843 | AK5: ='QC Data 2026'!N5 -> 14 | AL5: =AK5/AA5 -> 0.028397566 | AM5: =AM4+AK5 -> 14 | AN5: =AM5/AF5 -> 0.017167382 | AO5: 0.0125 | AP5: 0.019 | AR5: Feb | AS5: =AK8+AK9+AK10+AK11 -> 18.5 | AT5: 50 | AU5: =AU4+AS5 -> 53.5 | AV5: =AV4+AT5 -> 100 | AZ5: 2019 | BA5: Feb | BB5: 0 | BC5: 0 | BD5: 2 | BE5: =SUM(BB5:BD5) -> 2 | BF5: 2897.5 | BI5: 12.967646 | BL5: 2020 | BM5: Feb | BN5: 2 | BO5: 2 | BP5: =BN5+BO5 -> 4 | BQ5: =BN5/BP5 -> 0.5 | BR5: 0.95 | BU5: 605 | BV5: =VLOOKUP(BU5,Operation,2) -> Tack Shell Courses | BW5: 558 | BX5: 994.5 | BY5: =BW5/BX5 -> 0.56108597 | BZ5: =BX5-BW5 -> 436.5
A6: 2025 | B6: 45670 | C6: Jan | D6: 3 | F6: 1.25 | G6: 0.99 | H6: 0.98 | I6: 0.44 | J6: 0.96 | L6: NA | M6: NA | N6: 0.83 | O6: 0.88 | W6: Mar | Y6: 0.95 | AA6: 403 | AB6: 348.25 | AC6: =AA6+AB6 -> 751.25 | AD6: =AB6/AC6 -> 0.46356073 | AF6: =AF5+AA6 -> 1218.5 | AG6: =AG5+AB6 -> 843.25 | AH6: =AH5+AC6 -> 2061.75 | AI6: =AG6/AH6 -> 0.40899721 | AK6: ='QC Data 2026'!N6 -> 0 | AL6: =AK6/AA6 -> 0 | AM6: =AM5+AK6 -> 14 | AN6: =AM6/AF6 -> 0.011489536 | AO6: 0.0125 | AP6: 0.019 | AR6: Mar | AS6: =AK12+AK13+AK14+AK15+AK16 -> 13 | AT6: 50 | AU6: =AU5+AS6 -> 66.5 | AV6: =AV5+AT6 -> 150 | AZ6: 2019 | BA6: Mar | BB6: 0 | BC6: 0 | BD6: 1 | BE6: =SUM(BB6:BD6) -> 1 | BF6: =3051.25+76.75 -> 3128 | BI6: 8.5594911 | BL6: 2020 | BM6: Mar | BN6: 12 | BO6: 2 | BP6: =BN6+BO6 -> 14 | BQ6: =BN6/BP6 -> 0.85714286 | BR6: 0.95 | BU6: 630 | BV6: =VLOOKUP(BU6,Operation,2) -> Install Internal Parts | BW6: 479.33818 | BX6: 808 | BY6: =BW6/BX6 -> 0.59324032 | BZ6: =BX6-BW6 -> 328.66182
A7: 2025 | B7: 45677 | D7: 4 | F7: 1 | G7: 1.08 | H7: 1.15 | I7: 0.92 | J7: 1.1 | L7: =AVERAGE(J4:J7) -> 0.8775 | M7: NA | N7: 0.83 | O7: 0.88 | W7: Apr | Y7: 0.95 | AA7: 138.25 | AB7: 221.5 | AC7: =AA7+AB7 -> 359.75 | AD7: =AB7/AC7 -> 0.61570535 | AF7: =AF6+AA7 -> 1356.75 | AG7: =AG6+AB7 -> 1064.75 | AH7: =AH6+AC7 -> 2421.5 | AI7: =AG7/AH7 -> 0.43970679 | AK7: 21 | AL7: =AK7/AA7 -> 0.15189873 | AM7: =AM6+AK7 -> 35 | AN7: =AM7/AF7 -> 0.025796941 | AO7: 0.0125 | AP7: 0.019 | AR7: Apr | AS7: =AK17+AK18+AK19+AK20 -> 0 | AT7: 50 | AU7: =AU6+AS7 -> 66.5 | AV7: =AV6+AT7 -> 200 | AZ7: 2019 | BA7: Apr | BB7: 0 | BC7: 0 | BD7: 1 | BE7: =SUM(BB7:BD7) -> 1 | BF7: =3140+641.25 -> 3781.25 | BI7: 8.4889643 | BL7: 2020 | BM7: Apr | BN7: 11 | BO7: 1 | BP7: =BN7+BO7 -> 12 | BQ7: =BN7/BP7 -> 0.91666667 | BR7: 0.95 | BU7: 305 | BV7: =VLOOKUP(BU7,Operation,2) -> BI, SQ, T&C Shells | BW7: 971.16692 | BX7: 1271 | BY7: =BW7/BX7 -> 0.76409671 | BZ7: =BX7-BW7 -> 299.83308
A8: 2025 | B8: 45684 | D8: 5 | F8: 1 | G8: 0.82 | H8: 1.07 | I8: 0.43 | J8: 0.9 | L8: =AVERAGE(J5:J8) -> 0.9225 | M8: NA | N8: 0.83 | O8: 0.88 | W8: May | Y8: 0.95 | AA8: 313.5 | AB8: 487.25 | AC8: =AA8+AB8 -> 800.75 | AD8: =AB8/AC8 -> 0.60849204 | AF8: =AF7+AA8 -> 1670.25 | AG8: =AG7+AB8 -> 1552 | AH8: =AH7+AC8 -> 3222.25 | AI8: =AG8/AH8 -> 0.48165102 | AK8: ='QC Data 2026'!N8 -> 9.5 | AL8: =AK8/AA8 -> 0.03030303 | AM8: =AM7+AK8 -> 44.5 | AN8: =AM8/AF8 -> 0.026642718 | AO8: 0.0125 | AP8: 0.019 | AR8: May | AS8: =AK21+AK22+AK23+AK24 -> 0 | AT8: 50 | AU8: =AU7+AS8 -> 66.5 | AV8: =AV7+AT8 -> 250 | AZ8: 2019 | BA8: May | BB8: 0 | BC8: 1 | BD8: 0 | BE8: =SUM(BB8:BD8) -> 1 | BF8: =3438.75+443.5 -> 3882.25 | BI8: 8.5776627 | BL8: 2020 | BM8: May | BN8: 16 | BO8: 5 | BP8: =BN8+BO8 -> 21 | BQ8: =BN8/BP8 -> 0.76190476 | BR8: 0.95 | BU8: 800 | BV8: =VLOOKUP(BU8,Operation,2) -> Move Tank to Detail Rolls | BW8: 164.14545 | BX8: 461.5 | BY8: =BW8/BX8 -> 0.35567812 | BZ8: =BX8-BW8 -> 297.35455
A9: 2025 | B9: 45691 | D9: 6 | F9: 1 | G9: 1.01 | H9: 1.01 | I9: 1.03 | J9: 1.01 | L9: =AVERAGE(J6:J9) -> 0.9925 | M9: NA | N9: 0.83 | O9: 0.88 | W9: Jun | Y9: 0.95 | AA9: 285.75 | AB9: 412 | AC9: =AA9+AB9 -> 697.75 | AD9: =AB9/AC9 -> 0.59046937 | AF9: =AF8+AA9 -> 1956 | AG9: =AG8+AB9 -> 1964 | AH9: =AH8+AC9 -> 3920 | AI9: =AG9/AH9 -> 0.50102041 | AK9: ='QC Data 2026'!N9 -> 0 | AL9: =AK9/AA9 -> 0 | AM9: =AM8+AK9 -> 44.5 | AN9: =AM9/AF9 -> 0.022750511 | AO9: 0.0125 | AP9: 0.019 | AR9: Jun | AS9: =AK25+AK26+AK27+AK28+AK29 -> 0 | AT9: 50 | AU9: =AU8+AS9 -> 66.5 | AV9: =AV8+AT9 -> 300 | AZ9: 2019 | BA9: Jun | BB9: 1 | BC9: 1 | BD9: 0 | BE9: =SUM(BB9:BD9) -> 2 | BF9: =3275+554.5 -> 3829.5 | BI9: 8.7407335 | BL9: 2020 | BM9: Jun | BN9: 10 | BO9: 0 | BP9: =BN9+BO9 -> 10 | BQ9: =BN9/BP9 -> 1 | BR9: 0.95 | BU9: 155 | BV9: =VLOOKUP(BU9,Operation,2) -> B&C parts-lugs, supp, etc | BW9: 769.92174 | BX9: 1061 | BY9: =BW9/BX9 -> 0.72565668 | BZ9: =BX9-BW9 -> 291.07826
A10: 2025 | B10: 45698 | C10: Feb | D10: 7 | F10: 1.67 | G10: 1.01 | H10: 1.31 | I10: 1 | J10: 1.08 | L10: =AVERAGE(J7:J10) -> 1.0225 | M10: NA | N10: 0.83 | O10: 0.88 | W10: Jul | Y10: 0.95 | AA10: 226 | AB10: 423 | AC10: =AA10+AB10 -> 649 | AD10: =AB10/AC10 -> 0.65177196 | AF10: =AF9+AA10 -> 2182 | AG10: =AG9+AB10 -> 2387 | AH10: =AH9+AC10 -> 4569 | AI10: =AG10/AH10 -> 0.52243379 | AK10: ='QC Data 2026'!N10 -> 9 | AL10: =AK10/AA10 -> 0.039823009 | AM10: =AM9+AK10 -> 53.5 | AN10: =AM10/AF10 -> 0.02451879 | AO10: 0.0125 | AP10: 0.019 | AR10: Jul | AS10: =AK30+AK31+AK32+AK33 -> 0 | AT10: 50 | AU10: =AU9+AS10 -> 66.5 | AV10: =AV9+AT10 -> 350 | AZ10: 2019 | BA10: Jul | BB10: 0 | BC10: 0 | BD10: 1 | BE10: =SUM(BB10:BD10) -> 1 | BF10: =3731.5+544 -> 4275.5 | BI10: 8.8880988 | BL10: 2020 | BM10: Jul | BN10: 9 | BO10: 2 | BP10: =BN10+BO10 -> 11 | BQ10: =BN10/BP10 -> 0.81818182 | BR10: 0.95 | BU10: 600 | BV10: =VLOOKUP(BU10,Operation,2) -> Fit Bottom Head to Shell | BW10: 732.67698 | BX10: 1012 | BY10: =BW10/BX10 -> 0.72398911 | BZ10: =BX10-BW10 -> 279.32302
A11: 2025 | B11: 45705 | D11: 8 | F11: 0.89 | G11: 0.98 | H11: 0.49 | I11: 1 | J11: 0.88 | L11: =AVERAGE(J8:J11) -> 0.9675 | M11: =AVERAGE(J4:J11) -> 0.9225 | N11: 0.83 | O11: 0.88 | W11: Aug | Y11: 0.95 | AA11: 169.5 | AB11: 481 | AC11: =AA11+AB11 -> 650.5 | AD11: =AB11/AC11 -> 0.73943121 | AF11: =AF10+AA11 -> 2351.5 | AG11: =AG10+AB11 -> 2868 | AH11: =AH10+AC11 -> 5219.5 | AI11: =AG11/AH11 -> 0.54947792 | AK11: ='QC Data 2026'!N11 -> 0 | AL11: =AK11/AA11 -> 0 | AM11: =AM10+AK11 -> 53.5 | AN11: =AM11/AF11 -> 0.022751435 | AO11: 0.0125 | AP11: 0.019 | AR11: Aug | AS11: =AK34+AK35+AK36+AK37 -> 0 | AT11: 50 | AU11: =AU10+AS11 -> 66.5 | AV11: =AV10+AT11 -> 400 | AZ11: 2019 | BA11: Aug | BB11: 0 | BC11: 0 | BD11: 0 | BE11: =SUM(BB11:BD11) -> 0 | BF11: =3976.75+580 -> 4556.75 | BI11: 9.0443512 | BL11: 2020 | BM11: Aug | BN11: 6 | BO11: 4 | BP11: =BN11+BO11 -> 10 | BQ11: =BN11/BP11 -> 0.6 | BR11: 0.95 | BU11: 726 | BV11: =VLOOKUP(BU11,Operation,2) -> Weld Shell Nozz & M/Ws | BW11: 974.8 | BX11: 1225.25 | BY11: =BW11/BX11 -> 0.79559274 | BZ11: =BX11-BW11 -> 250.45
A12: 2025 | B12: 45712 | D12: 9 | F12: 0.96 | G12: 1.21 | H12: 0.92 | I12: 1 | J12: 1.03 | L12: =AVERAGE(J9:J12) -> 1 | M12: =AVERAGE(J5:J12) -> 0.96125 | N12: 0.83 | O12: 0.88 | W12: Sep | Y12: 0.95 | AA12: 153.25 | AB12: 534.75 | AC12: =AA12+AB12 -> 688 | AD12: =AB12/AC12 -> 0.77725291 | AF12: =AF11+AA12 -> 2504.75 | AG12: =AG11+AB12 -> 3402.75 | AH12: =AH11+AC12 -> 5907.5 | AI12: =AG12/AH12 -> 0.57600508 | AK12: ='QC Data 2026'!N12 -> 10 | AL12: =AK12/AA12 -> 0.065252855 | AM12: =AM11+AK12 -> 63.5 | AN12: =AM12/AF12 -> 0.025351832 | AO12: 0.0125 | AP12: 0.019 | AR12: Sep | AS12: =AK38+AK39+AK40+AK41+AK42 -> 0 | AT12: 50 | AU12: =AU11+AS12 -> 66.5 | AV12: =AV11+AT12 -> 450 | AZ12: 2019 | BA12: Sep | BB12: 0 | BC12: 0 | BD12: 0 | BE12: =SUM(BB12:BD12) -> 0 | BF12: =3393.75+819.75 -> 4213.5 | BI12: 4.6222469 | BL12: 2020 | BM12: Sep | BN12: 5 | BO12: 0 | BP12: =BN12+BO12 -> 5 | BQ12: =BN12/BP12 -> 1 | BR12: 0.95 | BU12: 105 | BV12: =VLOOKUP(BU12,Operation,2) -> Build Nozzles-Weld | BW12: 958.03206 | BX12: 1184.75 | BY12: =BW12/BX12 -> 0.80863647 | BZ12: =BX12-BW12 -> 226.71794
A13: 2025 | B13: 45719 | D13: 10 | F13: 1.15 | G13: 0.75 | H13: 0.94 | I13: 1 | J13: 0.87 | L13: =AVERAGE(J10:J13) -> 0.965 | M13: =AVERAGE(J6:J13) -> 0.97875 | N13: 0.83 | O13: 0.88 | W13: Oct | Y13: 0.95 | AA13: 186.5 | AB13: 505 | AC13: =AA13+AB13 -> 691.5 | AD13: =AB13/AC13 -> 0.73029646 | AF13: =AF12+AA13 -> 2691.25 | AG13: =AG12+AB13 -> 3907.75 | AH13: =AH12+AC13 -> 6599 | AI13: =AG13/AH13 -> 0.59217306 | AK13: ='QC Data 2026'!N13 -> 0 | AL13: =AK13/AA13 -> 0 | AM13: =AM12+AK13 -> 63.5 | AN13: =AM13/AF13 -> 0.023594984 | AO13: 0.0125 | AP13: 0.019 | AR13: Oct | AS13: =AK43+AK44+AK45+AK46 -> 0 | AT13: 50 | AU13: =AU12+AS13 -> 66.5 | AV13: =AV12+AT13 -> 500 | AZ13: 2019 | BA13: Oct | BB13: 1 | BC13: 0 | BD13: 2 | BE13: =SUM(BB13:BD13) -> 3 | BF13: =4652.5+1060.5 -> 5713 | BI13: 4.7229963 | BL13: 2020 | BM13: Oct | BN13: 6 | BO13: 0 | BP13: =BN13+BO13 -> 6 | BQ13: =BN13/BP13 -> 1 | BR13: 0.95 | BU13: 640 | BV13: =VLOOKUP(BU13,Operation,2) -> Fit Top to Shell-Weld | BW13: 539.9 | BX13: 753.75 | BY13: =BW13/BX13 -> 0.71628524 | BZ13: =BX13-BW13 -> 213.85
A14: 2025 | B14: 45726 | C14: Mar | D14: 11 | F14: 1 | G14: 0.67 | H14: 0.95 | I14: 1.07 | J14: 0.84 | L14: =AVERAGE(J11:J14) -> 0.905 | M14: =AVERAGE(J7:J14) -> 0.96375 | N14: 0.83 | O14: 0.88 | W14: Nov | Y14: 0.95 | AA14: 157 | AB14: 506 | AC14: =AA14+AB14 -> 663 | AD14: =AB14/AC14 -> 0.76319759 | AF14: =AF13+AA14 -> 2848.25 | AG14: =AG13+AB14 -> 4413.75 | AH14: =AH13+AC14 -> 7262 | AI14: =AG14/AH14 -> 0.60778711 | AK14: ='QC Data 2026'!N14 -> 3 | AL14: =AK14/AA14 -> 0.01910828 | AM14: =AM13+AK14 -> 66.5 | AN14: =AM14/AF14 -> 0.02334767 | AO14: 0.0125 | AP14: 0.019 | AR14: Nov | AS14: =AK47+AK48+AK49+AK50 -> 0 | AT14: 50 | AU14: =AU13+AS14 -> 66.5 | AV14: =AV13+AT14 -> 550 | AZ14: 2019 | BA14: Nov | BB14: 0 | BC14: 0 | BD14: 0 | BE14: =SUM(BB14:BD14) -> 0 | BF14: 3740.75 | BI14: 9.797498 | BL14: 2020 | BM14: Nov | BN14: 9 | BO14: 0 | BP14: =BN14+BO14 -> 9 | BQ14: =BN14/BP14 -> 1 | BR14: 0.95
A15: 2025 | B15: 45733 | D15: 12 | F15: 1 | G15: 1.14 | H15: 0.97 | I15: 1.36 | J15: 0.95 | L15: =AVERAGE(J12:J15) -> 0.9225 | M15: =AVERAGE(J8:J15) -> 0.945 | N15: 0.83 | O15: 0.88 | W15: Dec | Y15: 0.95 | AA15: 114 | AB15: 459.5 | AC15: =AA15+AB15 -> 573.5 | AD15: =AB15/AC15 -> 0.80122058 | AF15: =AF14+AA15 -> 2962.25 | AG15: =AG14+AB15 -> 4873.25 | AH15: =AH14+AC15 -> 7835.5 | AI15: =AG15/AH15 -> 0.62194499 | AK15: ='QC Data 2026'!N15 -> 0 | AL15: =AK15/AA15 -> 0 | AM15: =AM14+AK15 -> 66.5 | AN15: =AM15/AF15 -> 0.022449152 | AO15: 0.0125 | AP15: 0.019 | AR15: Dec | AS15: =AK51+AK52+AK53+AK54+AK55 -> 0 | AT15: 50 | AU15: =AU14+AS15 -> 66.5 | AV15: =AV14+AT15 -> 600 | AZ15: 2019 | BA15: Dec | BB15: 0 | BC15: 0 | BD15: 0 | BE15: =SUM(BB15:BD15) -> 0 | BF15: =3063.25+238 -> 3301.25 | BG15: =SUM(BB4:BB15) -> 2 | BH15: =SUM(BF4:BF15) -> 46931.5 | BI15: =BG15*200000/(BH15+1280) -> 8.2967757 | BJ15: 4 | BL15: 2020 | BM15: Dec | BN15: 14 | BO15: 6 | BP15: =BN15+BO15 -> 20 | BQ15: =BN15/BP15 -> 0.7 | BR15: 0.95
A16: 2025 | B16: 45740 | D16: 13 | F16: 0.97 | G16: 1.05 | H16: 0.97 | I16: 1 | J16: 0.98 | L16: =AVERAGE(J13:J16) -> 0.91 | M16: =AVERAGE(J9:J16) -> 0.955 | N16: 0.83 | O16: 0.88 | AA16: 231 | AB16: 310 | AC16: =AA16+AB16 -> 541 | AD16: =AB16/AC16 -> 0.57301294 | AF16: =AF15+AA16 -> 3193.25 | AG16: =AG15+AB16 -> 5183.25 | AH16: =AH15+AC16 -> 8376.5 | AI16: =AG16/AH16 -> 0.6187847 | AK16: ='QC Data 2026'!N16 -> 0 | AL16: =AK16/AA16 -> 0 | AM16: =AM15+AK16 -> 66.5 | AN16: =AM16/AF16 -> 0.020825178 | AO16: 0.0125 | AP16: 0.019 | AZ16: 2020 | BA16: Jan | BB16: 0 | BC16: 1 | BD16: 0 | BE16: =SUM(BB16:BD16) -> 1 | BF16: =3060.5+785.25 -> 3845.75 | BG16: =SUM(BB5:BB16) -> 2 | BH16: =SUM(BF5:BF16) -> 47165 | BI16: =BG16*200000/(BH16+1280) -> 8.256786 | BJ16: 4 | BL16: 2021 | BM16: Jan | BN16: 10 | BO16: 3 | BP16: =BN16+BO16 -> 13 | BQ16: =BN16/BP16 -> 0.76923077 | BR16: 0.95
A17: 2025 | B17: 45747 | D17: 14 | F17: 1.14 | G17: 0.98 | H17: 0.97 | I17: 1 | J17: 0.99 | L17: =AVERAGE(J14:J17) -> 0.94 | M17: =AVERAGE(J10:J17) -> 0.9525 | N17: 0.83 | O17: 0.88 | AA17: 127.5 | AB17: 458 | AC17: =AA17+AB17 -> 585.5 | AD17: =AB17/AC17 -> 0.7822374 | AF17: =AF16+AA17 -> 3320.75 | AG17: =AG16+AB17 -> 5641.25 | AH17: =AH16+AC17 -> 8962 | AI17: =AG17/AH17 -> 0.62946329 | AK17: ='QC Data 2026'!N17 -> 0 | AL17: =AK17/AA17 -> 0 | AM17: =AM16+AK17 -> 66.5 | AN17: =AM17/AF17 -> 0.020025597 | AO17: 0.0125 | AP17: 0.019 | AR17: YTD | AS17: =SUM(AS4:AS16) -> 66.5 | AT17: =SUM(AT4:AT16) -> 600 | AZ17: 2020 | BA17: Feb | BB17: 0 | BC17: 0 | BD17: 1 | BE17: =SUM(BB17:BD17) -> 1 | BF17: =3042.5+613.75 -> 3656.25 | BG17: =SUM(BB6:BB17) -> 2 | BH17: =SUM(BF6:BF17) -> 47923.75 | BI17: =BG17*200000/(BH17+1280) -> 8.1294617 | BJ17: 4 | BL17: 2021 | BM17: Feb | BN17: 2 | BO17: 2 | BP17: =BN17+BO17 -> 4 | BQ17: =BN17/BP17 -> 0.5 | BR17: 0.95
A18: 2025 | B18: 45754 | D18: 15 | F18: 2 | G18: 0.82 | H18: 1.11 | I18: 1.17 | J18: 0.85 | L18: =AVERAGE(J15:J18) -> 0.9425 | M18: =AVERAGE(J11:J18) -> 0.92375 | N18: 0.83 | O18: 0.88 | AA18: 116.5 | AB18: 374.5 | AC18: =AA18+AB18 -> 491 | AD18: =AB18/AC18 -> 0.76272912 | AF18: =AF17+AA18 -> 3437.25 | AG18: =AG17+AB18 -> 6015.75 | AH18: =AH17+AC18 -> 9453 | AI18: =AG18/AH18 -> 0.63638527 | AK18: ='QC Data 2026'!N18 -> 0 | AL18: =AK18/AA18 -> 0 | AM18: =AM17+AK18 -> 66.5 | AN18: =AM18/AF18 -> 0.019346862 | AO18: 0.0125 | AP18: 0.019 | AZ18: 2020 | BA18: Mar | BB18: 0 | BC18: 0 | BD18: 1 | BE18: =SUM(BB18:BD18) -> 1 | BF18: =3452.5+791.25 -> 4243.75 | BG18: =SUM(BB7:BB18) -> 2 | BH18: =SUM(BF7:BF18) -> 49039.5 | BI18: =BG18*200000/(BH18+1280) -> 7.9492046 | BJ18: 4 | BL18: 2021 | BM18: Mar | BN18: 0 | BO18: 2 | BP18: 2 | BQ18: =BN18/BP18 -> 0 | BR18: 0.95
A19: 2025 | B19: 45761 | C19: Apr | D19: 16 | F19: 1.07 | G19: 0.93 | H19: 0.84 | I19: 1 | J19: 0.9 | L19: =AVERAGE(J16:J19) -> 0.93 | M19: =AVERAGE(J12:J19) -> 0.92625 | N19: 0.83 | O19: 0.88 | AA19: 117 | AB19: 452.5 | AC19: =AA19+AB19 -> 569.5 | AD19: =AB19/AC19 -> 0.79455663 | AF19: =AF18+AA19 -> 3554.25 | AG19: =AG18+AB19 -> 6468.25 | AH19: =AH18+AC19 -> 10022.5 | AI19: =AG19/AH19 -> 0.64537291 | AK19: ='QC Data 2026'!N19 -> 0 | AL19: =AK19/AA19 -> 0 | AM19: =AM18+AK19 -> 66.5 | AN19: =AM19/AF19 -> 0.018709995 | AO19: 0.0125 | AP19: 0.019 | AZ19: 2020 | BA19: Apr | BB19: 0 | BC19: 1 | BD19: 1 | BE19: =SUM(BB19:BD19) -> 2 | BF19: =3935.5+777 -> 4712.5 | BG19: =SUM(BB8:BB19) -> 2 | BH19: =SUM(BF8:BF19) -> 49970.75 | BI19: =BG19*200000/(BH19+1280) -> 7.8047638 | BJ19: 4 | BL19: 2021 | BM19: Apr | BN19: 0 | BO19: 4 | BP19: 4 | BQ19: =BN19/BP19 -> 0 | BR19: 0.95
A20: 2025 | B20: 45768 | D20: 17 | F20: 1.5 | G20: 0.96 | H20: 1 | I20: 1 | J20: 1.19 | L20: =AVERAGE(J17:J20) -> 0.9825 | M20: =AVERAGE(J13:J20) -> 0.94625 | N20: 0.83 | O20: 0.88 | AA20: 97 | AB20: 402.75 | AC20: =AA20+AB20 -> 499.75 | AD20: =AB20/AC20 -> 0.80590295 | AF20: =AF19+AA20 -> 3651.25 | AG20: =AG19+AB20 -> 6871 | AH20: =AH19+AC20 -> 10522.25 | AI20: =AG20/AH20 -> 0.65299722 | AK20: ='QC Data 2026'!N20 -> 0 | AL20: =AK20/AA20 -> 0 | AM20: =AM19+AK20 -> 66.5 | AN20: =AM20/AF20 -> 0.018212941 | AO20: 0.0125 | AP20: 0.019 | AZ20: 2020 | BA20: May | BB20: 0 | BC20: 0 | BD20: 0 | BE20: =SUM(BB20:BD20) -> 0 | BF20: =3541+676 -> 4217 | BG20: =SUM(BB9:BB20) -> 2 | BH20: =SUM(BF9:BF20) -> 50305.5 | BI20: =BG20*200000/(BH20+1280) -> 7.754117 | BJ20: 4 | BL20: 2021 | BM20: May | BN20: 3 | BO20: 0 | BP20: 3 | BQ20: =BN20/BP20 -> 1 | BR20: 0.95
A21: 2025 | B21: 45775 | D21: 18 | F21: 0.5 | G21: 0.92 | H21: 1.06 | I21: 1 | J21: 0.98 | L21: =AVERAGE(J18:J21) -> 0.98 | M21: =AVERAGE(J14:J21) -> 0.96 | N21: 0.83 | O21: 0.88 | AA21: 131.75 | AB21: 469 | AC21: =AA21+AB21 -> 600.75 | AD21: =AB21/AC21 -> 0.7806908 | AF21: =AF20+AA21 -> 3783 | AG21: =AG20+AB21 -> 7340 | AH21: =AH20+AC21 -> 11123 | AI21: =AG21/AH21 -> 0.65989391 | AK21: ='QC Data 2026'!N21 -> 0 | AL21: =AK21/AA21 -> 0 | AM21: =AM20+AK21 -> 66.5 | AN21: =AM21/AF21 -> 0.017578641 | AO21: 0.0125 | AP21: 0.019 | AZ21: 2020 | BA21: Jun | BB21: 0 | BC21: 1 | BD21: 3 | BE21: =SUM(BB21:BD21) -> 4 | BF21: 4153 | BG21: =SUM(BB10:BB21) -> 1 | BH21: =SUM(BF10:BF21) -> 50629 | BI21: =BG21*200000/(BH21+1280) -> 3.8528964 | BJ21: 4 | BL21: 2021 | BM21: Jun | BR21: 0.95
A22: 2025 | B22: 45782 | D22: 19 | F22: 0.6 | G22: 0.63 | H22: 1.19 | I22: 1 | J22: 1.03 | L22: =AVERAGE(J19:J22) -> 1.025 | M22: =AVERAGE(J15:J22) -> 0.98375 | N22: 0.83 | O22: 0.88 | AA22: 227 | AB22: 338 | AC22: =AA22+AB22 -> 565 | AD22: =AB22/AC22 -> 0.59823009 | AF22: =AF21+AA22 -> 4010 | AG22: =AG21+AB22 -> 7678 | AH22: =AH21+AC22 -> 11688 | AI22: =AG22/AH22 -> 0.65691307 | AK22: ='QC Data 2026'!N22 -> 0 | AL22: =AK22/AA22 -> 0 | AM22: =AM21+AK22 -> 66.5 | AN22: =AM22/AF22 -> 0.016583541 | AO22: 0.0125 | AP22: 0.019 | AZ22: 2020 | BA22: Jul | BB22: 0 | BC22: 1 | BD22: 3 | BE22: =SUM(BB22:BD22) -> 4 | BF22: 3759.75 | BG22: =SUM(BB11:BB22) -> 1 | BH22: =SUM(BF11:BF22) -> 50113.25 | BI22: =BG22*200000/(BH22+1280) -> 3.8915616 | BJ22: 4 | BL22: 2021 | BM22: Jul | BR22: 0.95
A23: 2025 | B23: 45789 | C23: May | D23: 20 | F23: 0.84 | G23: 1.07 | H23: 1.19 | I23: 1 | J23: 1.15 | L23: =AVERAGE(J20:J23) -> 1.0875 | M23: =AVERAGE(J16:J23) -> 1.00875 | N23: 0.83 | O23: 0.88 | AA23: 372.5 | AB23: 255.25 | AC23: =AA23+AB23 -> 627.75 | AD23: =AB23/AC23 -> 0.40661091 | AF23: =AF22+AA23 -> 4382.5 | AG23: =AG22+AB23 -> 7933.25 | AH23: =AH22+AC23 -> 12315.75 | AI23: =AG23/AH23 -> 0.64415484 | AK23: ='QC Data 2026'!N23 -> 0 | AL23: =AK23/AA23 -> 0 | AM23: =AM22+AK23 -> 66.5 | AN23: =AM23/AF23 -> 0.015173987 | AO23: 0.0125 | AP23: 0.019 | AZ23: 2020 | BA23: Aug | BB23: 0 | BC23: 2 | BD23: 0 | BE23: =SUM(BB23:BD23) -> 2 | BF23: 4286 | BG23: =SUM(BB12:BB23) -> 1 | BH23: =SUM(BF12:BF23) -> 49842.5 | BI23: =BG23*200000/(BH23+1280) -> 3.9121717 | BJ23: 4 | BL23: 2021 | BM23: Aug | BR23: 0.95
A24: 2025 | B24: 45796 | D24: 21 | F24: 1.65 | G24: 1.15 | H24: 1.2 | I24: 0.8 | J24: 1.2 | L24: =AVERAGE(J21:J24) -> 1.09 | M24: =AVERAGE(J17:J24) -> 1.03625 | N24: 0.83 | O24: 0.88 | AA24: 464.5 | AB24: 242.75 | AC24: =AA24+AB24 -> 707.25 | AD24: =AB24/AC24 -> 0.34323082 | AF24: =AF23+AA24 -> 4847 | AG24: =AG23+AB24 -> 8176 | AH24: =AH23+AC24 -> 13023 | AI24: =AG24/AH24 -> 0.62781233 | AK24: ='QC Data 2026'!N24 -> 0 | AL24: =AK24/AA24 -> 0 | AM24: =AM23+AK24 -> 66.5 | AN24: =AM24/AF24 -> 0.013719827 | AO24: 0.0125 | AP24: 0.019 | AZ24: 2020 | BA24: Sep | BB24: 0 | BC24: 2 | BD24: 0 | BE24: =SUM(BB24:BD24) -> 2 | BF24: 4497 | BG24: =SUM(BB13:BB24) -> 1 | BH24: =SUM(BF13:BF24) -> 50126 | BI24: =BG24*200000/(BH24+1280) -> 3.8905964 | BJ24: 4 | BL24: 2021 | BM24: Sep | BR24: 0.95
A25: 2025 | B25: 45803 | D25: 22 | F25: 1 | G25: 1.07 | H25: 1.35 | I25: 1.33 | J25: 1.25 | L25: =AVERAGE(J22:J25) -> 1.1575 | M25: =AVERAGE(J18:J25) -> 1.06875 | N25: 0.83 | O25: 0.88 | AA25: 346.25 | AB25: 180.75 | AC25: =AA25+AB25 -> 527 | AD25: =AB25/AC25 -> 0.34297913 | AF25: =AF24+AA25 -> 5193.25 | AG25: =AG24+AB25 -> 8356.75 | AH25: =AH24+AC25 -> 13550 | AI25: =AG25/AH25 -> 0.61673432 | AK25: ='QC Data 2026'!N25 -> 0 | AL25: =AK25/AA25 -> 0 | AM25: =AM24+AK25 -> 66.5 | AN25: =AM25/AF25 -> 0.012805084 | AO25: 0.0125 | AP25: 0.019 | AZ25: 2020 | BA25: Oct | BB25: 0 | BC25: 0 | BD25: 1 | BE25: =SUM(BB25:BD25) -> 1 | BF25: 4461.75 | BG25: =SUM(BB14:BB25) -> 0 | BH25: =SUM(BF14:BF25) -> 48874.75 | BI25: =BG25*200000/(BH25+1280) -> 0 | BJ25: 4 | BL25: 2021 | BM25: Oct | BR25: 0.95
A26: 2025 | B26: 45810 | D26: 23 | F26: 1 | G26: 1.08 | H26: 1.34 | I26: 0.75 | J26: 1.24 | L26: =AVERAGE(J23:J26) -> 1.21 | M26: =AVERAGE(J19:J26) -> 1.1175 | N26: 0.83 | O26: 0.88 | AA26: 449 | AB26: 294.5 | AC26: =AA26+AB26 -> 743.5 | AD26: =AB26/AC26 -> 0.39609953 | AF26: =AF25+AA26 -> 5642.25 | AG26: =AG25+AB26 -> 8651.25 | AH26: =AH25+AC26 -> 14293.5 | AI26: =AG26/AH26 -> 0.60525763 | AK26: ='QC Data 2026'!N26 -> 0 | AL26: =AK26/AA26 -> 0 | AM26: =AM25+AK26 -> 66.5 | AN26: =AM26/AF26 -> 0.011786078 | AO26: 0.0125 | AP26: 0.019 | AZ26: 2020 | BA26: Nov | BB26: 0 | BC26: 2 | BD26: 0 | BE26: =SUM(BB26:BD26) -> 2 | BF26: 3802.25 | BG26: =SUM(BB15:BB26) -> 0 | BH26: =SUM(BF15:BF26) -> 48936.25 | BI26: =BG26*200000/(BH26+1280) -> 0 | BJ26: 4 | BL26: 2021 | BM26: Nov | BR26: 0.95
A27: 2025 | B27: 45817 | C27: Jun | D27: 24 | F27: 1 | G27: 0.79 | H27: 1.06 | I27: 1 | J27: 0.92 | L27: =AVERAGE(J24:J27) -> 1.1525 | M27: =AVERAGE(J20:J27) -> 1.12 | N27: 0.83 | O27: 0.88 | AA27: 323 | AB27: 327 | AC27: =AA27+AB27 -> 650 | AD27: =AB27/AC27 -> 0.50307692 | AF27: =AF26+AA27 -> 5965.25 | AG27: =AG26+AB27 -> 8978.25 | AH27: =AH26+AC27 -> 14943.5 | AI27: =AG27/AH27 -> 0.60081306 | AK27: ='QC Data 2026'!N27 -> 0 | AL27: =AK27/AA27 -> 0 | AM27: =AM26+AK27 -> 66.5 | AN27: =AM27/AF27 -> 0.011147898 | AO27: 0.0125 | AP27: 0.019 | AZ27: 2020 | BA27: Dec | BB27: 0 | BC27: 1 | BD27: 0 | BE27: =SUM(BB27:BD27) -> 1 | BF27: 3848.25 | BG27: =SUM(BB16:BB27) -> 0 | BH27: =SUM(BF16:BF27) -> 49483.25 | BI27: =BG27*200000/(BH27+1280) -> 0 | BJ27: 4 | BL27: 2021 | BM27: Dec | BR27: 0.95
A28: 2025 | B28: 45824 | D28: 25 | F28: 1.55 | G28: 0.84 | H28: 1.12 | I28: 1 | J28: 1.04 | L28: =AVERAGE(J25:J28) -> 1.1125 | M28: =AVERAGE(J21:J28) -> 1.10125 | N28: 0.83 | O28: 0.88 | AA28: 585.5 | AB28: 201.5 | AC28: =AA28+AB28 -> 787 | AD28: =AB28/AC28 -> 0.25603558 | AF28: =AF27+AA28 -> 6550.75 | AG28: =AG27+AB28 -> 9179.75 | AH28: =AH27+AC28 -> 15730.5 | AI28: =AG28/AH28 -> 0.58356378 | AK28: ='QC Data 2026'!N28 -> 0 | AL28: =AK28/AA28 -> 0 | AM28: =AM27+AK28 -> 66.5 | AN28: =AM28/AF28 -> 0.010151509 | AO28: 0.0125 | AP28: 0.019 | AZ28: 2021 | BA28: Jan | BB28: 0 | BC28: 0 | BD28: 1 | BE28: =SUM(BB28:BD28) -> 1 | BF28: 2984.25 | BG28: =SUM(BB17:BB28) -> 0 | BH28: =SUM(BF17:BF28) -> 48621.75 | BI28: =BG28*200000/(BH28+1280) -> 0 | BJ28: 2 | BL28: 2022 | BM28: Jan | BO28: 3
A29: 2025 | B29: 45831 | D29: 26 | F29: 0.87 | G29: 1.02 | H29: 1.03 | I29: 1.03 | J29: 1 | L29: =AVERAGE(J26:J29) -> 1.05 | M29: =AVERAGE(J22:J29) -> 1.10375 | N29: 0.83 | O29: 0.88 | AA29: 548 | AB29: 229.25 | AC29: =AA29+AB29 -> 777.25 | AD29: =AB29/AC29 -> 0.29495014 | AF29: =AF28+AA29 -> 7098.75 | AG29: =AG28+AB29 -> 9409 | AH29: =AH28+AC29 -> 16507.75 | AI29: =AG29/AH29 -> 0.56997471 | AK29: ='QC Data 2026'!N29 -> 0 | AL29: =AK29/AA29 -> 0 | AM29: =AM28+AK29 -> 66.5 | AN29: =AM29/AF29 -> 0.0093678465 | AO29: 0.0125 | AP29: 0.019 | AZ29: 2021 | BA29: Feb | BB29: 0 | BC29: 0 | BD29: 0 | BE29: =SUM(BB29:BD29) -> 0 | BF29: 3347.5 | BG29: =SUM(BB18:BB29) -> 0 | BH29: =SUM(BF18:BF29) -> 48313 | BI29: =BG29*200000/(BH29+1280) -> 0 | BJ29: 2 | BL29: 2022 | BM29: Feb
A30: 2025 | B30: 45838 | D30: 27 | F30: 1.36 | G30: 0.99 | H30: 0.9 | I30: 1 | J30: 0.94 | L30: =AVERAGE(J27:J30) -> 0.975 | M30: =AVERAGE(J23:J30) -> 1.0925 | N30: 0.83 | O30: 0.88 | AA30: 473.75 | AB30: 232 | AC30: =AA30+AB30 -> 705.75 | AD30: =AB30/AC30 -> 0.3287283 | AF30: =AF29+AA30 -> 7572.5 | AG30: =AG29+AB30 -> 9641 | AH30: =AH29+AC30 -> 17213.5 | AI30: =AG30/AH30 -> 0.56008366 | AK30: ='QC Data 2026'!N30 -> 0 | AL30: =AK30/AA30 -> 0 | AM30: =AM29+AK30 -> 66.5 | AN30: =AM30/AF30 -> 0.0087817762 | AO30: 0.0125 | AP30: 0.019 | AZ30: 2021 | BA30: Mar | BB30: 0 | BC30: 0 | BD30: 3 | BE30: =SUM(BB30:BD30) -> 3 | BF30: 3695.25 | BG30: =SUM(BB19:BB30) -> 0 | BH30: =SUM(BF19:BF30) -> 47764.5 | BI30: =BG30*200000/(BH30+1280) -> 0 | BJ30: 2 | BL30: 2022 | BM30: Mar
A31: 2025 | B31: 45845 | D31: 28 | F31: 0.91 | G31: 1.01 | H31: 0.98 | I31: 1 | J31: 0.99 | L31: =AVERAGE(J28:J31) -> 0.9925 | M31: =AVERAGE(J24:J31) -> 1.0725 | N31: 0.83 | O31: 0.88 | AA31: 590 | AB31: 314.75 | AC31: =AA31+AB31 -> 904.75 | AD31: =AB31/AC31 -> 0.34788616 | AF31: =AF30+AA31 -> 8162.5 | AG31: =AG30+AB31 -> 9955.75 | AH31: =AH30+AC31 -> 18118.25 | AI31: =AG31/AH31 -> 0.5494874 | AK31: ='QC Data 2026'!N31 -> 0 | AL31: =AK31/AA31 -> 0 | AM31: =AM30+AK31 -> 66.5 | AN31: =AM31/AF31 -> 0.0081470138 | AO31: 0.0125 | AP31: 0.019 | AZ31: 2021 | BA31: Apr | BB31: 0 | BC31: 1 | BD31: 0 | BE31: =SUM(BB31:BD31) -> 1 | BF31: 2841.5 | BG31: =SUM(BB20:BB31) -> 0 | BH31: =SUM(BF20:BF31) -> 45893.5 | BI31: =BG31*200000/(BH31+1280) -> 0 | BJ31: 2 | BL31: 2022 | BM31: Apr
